Workbook
Name _10월_변동내역_메모_확인: #REF!
Name _Order1: 255
Name _Order2: 255
Name asd: #REF!
Name HTML_CodePage: 949
Name HTML_Control: {"'손익현황'!$A$1:$J$29"}
Name HTML_Description: ""
Name HTML_Email: ""
Name HTML_Header: "손익현황"
Name HTML_LastUpdate: "99-04-13"
Name HTML_LineAfter: FALSE
Name HTML_LineBefore: FALSE
Name HTML_Name: "윤찬영"
Name HTML_OBDlg2: TRUE
Name HTML_OBDlg4: TRUE
Name HTML_OS: 0
Name HTML_PathFile: "C:\d7100\MyHTML.htm"
Name HTML_Title: "결산요약보고3월"
Name MPLS: #REF!
Name MPLS2: #REF!
Name MPLSLine: #REF!
Name N_A: #REF!
Name O: #REF!
Name P: #REF!
Name PC: [1]목록!$T$7:$T$9
Name X: #REF!
Name 건물: {"'손익현황'!$A$1:$J$29"}
Name 건물임.: {"'손익현황'!$A$1:$J$29"}
Name 공: {"'손익현황'!$A$1:$J$29"}
Name 공구: {"'손익현황'!$A$1:$J$29"}
Name 공구기구: {"'손익현황'!$A$1:$J$29"}
Name 구: {"'손익현황'!$A$1:$J$29"}
Name 구축물: {"'손익현황'!$A$1:$J$29"}
Name 구축물임: {"'손익현황'!$A$1:$J$29"}
Name 기계장치: {"'손익현황'!$A$1:$J$29"}
Name 기술2팀: #REF!
Name 기준반영: #REF!
Name 네트워크: [1]목록!$R$7:$R$9
Name 담당자: [1]목록!$A$36:$A$66
Name 동의여부: #REF!
Name 보안시스템: [1]목록!$S$7:$S$10
Name ㅅㅅㅅ: {"'손익현황'!$A$1:$J$29"}
Name 서버: [1]목록!$Q$7:$Q$8
Name 적정성: #REF!
Name 종류: [1]목록!$P$7:$P$10
Name 차량운반구: {"'손익현황'!$A$1:$J$29"}
Name 훈: 255

Sheet 표지
F11: 45992

Sheet 자산목록
A1: ■ 자산목록
A3: No. | B3: 호스트명 | C3: IP | D3: 제조업체 | E3: 구분 | F3: 모델명 | G3: OS/SW | H3: 버전 | I3: 자산명/용도 | J3: 설치위치 | K3: 부서 | L3: 담당자 | M3: 비고 | N3: 자산 평가
N4: 기밀성 | O4: 무결성 | P4: 가용성 | Q4: 등급 | R4: 점수(Hidden)
A5: 1 | B5: WEB-HQ-Ubuntu | C5: 10.10.40.1 | G5: Ubuntu | H5: 24.04.2 LTS | I5: Web 서버 / 딩동독 서비스 | J5: 본사 DMZ망 | K5: 본사 개발팀 | L5: 김민준 | N5: 3 | O5: 3 | P5: 3 | Q5: =IF(R5>=7,"H",IF(R5>=5,"M","L")) -> H | R5: =SUM(N5:P5) -> 9
A6: 2 | B6: LOG_HQ_Rocky | C6: 10.10.40.3 | G6: Rocky | H6: 8.1 | I6: 본사 LOG 서버 | J6: 본사 DMZ망 | K6: 본사 개발팀 | L6: 이서연 | N6: 3 | O6: 3 | P6: 3 | Q6: =IF(R6>=7,"H",IF(R6>=5,"M","L")) -> H | R6: =SUM(N6:P6) -> 9
A7: 4 | B7: DB_HQ_Rocky | C7: 10.10.40.18 | G7: Rocky | H7: 8.1 | I7: 본사 DB 서버 | J7: 본사 서버망 | K7: 지사 개발팀 | L7: 박지훈 | N7: 3 | O7: 3 | P7: 3 | Q7: =IF(R7>=7,"H",IF(R7>=5,"M","L")) -> H | R7: =SUM(N7:P7) -> 9
A8: 4 | B8: BDB_HQ_Rocky | C8: 10.10.40.33 | G8: Rocky | H8: 8.1 | I8: DB 백업 서버 / 지사 DB 백업 | J8: 본사 백업망 | K8: 본사 개발팀 | L8: 이지훈 | N8: 3 | O8: 3 | P8: 3 | Q8: =IF(R8>=7,"H",IF(R8>=5,"M","L")) -> H | R8: =SUM(N8:P8) -> 9
A9: 5 | B9: BLOG_HQ_Rocky | C9: 10.10.40.34 | G9: Rocky | H9: 8.1 | I9: LOG 백업 서버 / 지사 LOG 백업 | J9: 본사 백업망 | K9: 지사 개발팀 | L9: 김승우 | N9: 3 | O9: 3 | P9: 3 | Q9: =IF(R9>=7,"H",IF(R9>=5,"M","L")) -> H | R9: =SUM(N9:P9) -> 9
A10: 6 | B10: PHP_BR_Rocky | C10: 10.200.40.1 | G10: Rocky | H10: 8.1 | I10: PHP 서버 / 딩동몰 서비스 | J10: 지사 DMZ망 | K10: 본사 개발팀 | L10: 강도윤 | N10: 3 | O10: 3 | P10: 3 | Q10: =IF(R10>=7,"H",IF(R10>=5,"M","L")) -> H | R10: =SUM(N10:P10) -> 9
A11: 7 | B11: LOG_BR_Rocky | C11: 10.200.40.3 | G11: Rocky | H11: 8.1 | I11: 지사 LOG 서버 | J11: 지사 DMZ망 | K11: 지사 개발팀 | L11: 조아린 | N11: 3 | O11: 3 | P11: 3 | Q11: =IF(R11>=7,"H",IF(R11>=5,"M","L")) -> H | R11: =SUM(N11:P11) -> 9
A12: 8 | B12: DB_BR_Rocky | C12: 10.200.40.18 | G12: Rocky | H12: 8.1 | I12: 지사 DB 서버 | J12: 지사 서버망 | K12: 본사 전산팀 | L12: 윤은우 | N12: 3 | O12: 3 | P12: 3 | Q12: =IF(R12>=7,"H",IF(R12>=5,"M","L")) -> H | R12: =SUM(N12:P12) -> 9
A13: 9 | B13: BDB_BR_Rocky | C13: 10.200.40.33 | G13: Rocky | H13: 8.1 | I13: DB 백업 서버 / 본사 DB 백업 | J13: 지사 백업망 | K13: 본사 전산팀 | L13: 장예나 | N13: 3 | O13: 3 | P13: 3 | Q13: =IF(R13>=7,"H",IF(R13>=5,"M","L")) -> H | R13: =SUM(N13:P13) -> 9
A14: 10 | B14: BLOG_BR_Rocky | C14: 10.200.40.34 | G14: Rocky | H14: 8.1 | I14: LOG 백업 서버 / 본사 LOG 백업 | J14: 지사 백업망 | K14: 본사 전산팀 | L14: 임시우 | N14: 3 | O14: 3 | P14: 3 | Q14: =IF(R14>=7,"H",IF(R14>=5,"M","L")) -> H | R14: =SUM(N14:P14) -> 9

Sheet parm(hidden)
B2: 1. 분류 Code
B3: Code
B4: Linux Server
B6: 2. 중요도, 자산등급, 위협도 점수
B7: 중요도 | C7: 점수
B8: H | C8: 3
B9: M | C9: 2
B10: L | C10: 1
B12: 3. 점검결과 점수
B13: 점검 결과 | C13: 점수
C14: 취약점 진단 | D14: 위험평가
B15: Y | C15: 1 | D15: 0
B16: N | C16: 0 | D16: 3 | F16: P | G16: 0.5 | H16: 0.5
B17: N/A | C17: 0 | D17: 0
B18: R/A | C18: 0 | D18: 0
B19: Y(즉시조치) | C19: 1 | D19: 0
B21: 4. DoA
B22: DoA
B23: 21
B25: 5. 자산등급 점수 범위 | F25: 8_2. 위험평가 방법론
B26: 위험 등급 | C26: 점수 범위
C27: 최저 | D27: 최고
B28: H | C28: 7 | D28: 9
B29: M | C29: 5 | D29: 6
B30: L | C30: 3 | D30: 4
B32: 6. 위협도 점수 범위
B33: 위험 등급 | C33: 점수 범위
C34: 최저 | D34: 최고
B35: H | C35: 5 | D35: 6
B36: M | C36: 4 | D36: 4
B37: L | C37: 2 | D37: 3
B39: 7. 위험도 점수 범위
B40: 위험 등급 | C40: 점수 범위
C41: 최저 | D41: 최고
B42: H | C42: =$B$23 -> 21 | D42: 30
B43: M | C43: 11 | D43: =$C$42-1 -> 20
B44: L | C44: 1 | D44: =$C$43-1 -> 10
B46: 8. 위험도 평가표
B47: 8_1. 위험도 평가표
B48: V' | C48: 보호대책 | D48: Y=0(보호대책 있음) | M48: N=1(보호대책 없음)
...

Sheet ChkList
A1: ■ 자산목록
A3: 취약점 진단항목 | F3: 개선방안 및 보호대책
A4: 분류 | B4: 항목코드 | C4: 진단항목 | D4: 중요도 | E4: 위험도 | F4: Linux
A5: 계정 관리 | B5: U-01 | C5: root 계정 원격 접속 제한 | D5: H | E5: 3 | F5: root 계정의 원격 접속을 차단하고 일반 사용자 계정으로 로그인 후 su 또는 sudo를 사용하도록 설정
A6: 계정 관리 | B6: U-02 | C6: 비밀번호 관리정책 설정 | D6: H | E6: 3 | F6: 비밀번호 복잡도, 최소 길이, 최대 사용기간 등을 적용하여 안전한 비밀번호 관리정책을 설정
A7: 계정 관리 | B7: U-03 | C7: 계정 잠금 임계값 설정 | D7: H | E7: 3 | F7: 로그인 실패 횟수에 따른 계정 잠금 정책을 적용하여 무차별 대입 공격을 방지
A8: 계정 관리 | B8: U-04 | C8: 비밀번호 파일 보호 | D8: H | E8: 3 | F8: 쉐도우 비밀번호를 사용하거나 비밀번호를 암호화하여 저장·관리하도록 설정
A9: 계정 관리 | B9: U-05 | C9: root 이외의 UID가 ‘0’ 금지 | D9: H | E9: 3 | F9: UID가 0인 계정을 root 계정으로만 제한하고 불필요한 UID 0 계정을 삭제 또는 변경
A10: 계정 관리 | B10: U-06 | C10: 사용자 계정 su 기능 제한 | D10: H | E10: 3 | F10: su 명령어 사용 권한을 wheel 등 관리자 그룹으로 제한
A11: 계정 관리 | B11: U-07 | C11: 불필요한 계정 제거 | D11: L | E11: 1 | F11: 장기간 미사용 계정 및 불필요한 기본 계정을 삭제 또는 잠금 처리
A12: 계정 관리 | B12: U-08 | C12: 관리자 그룹에 최소한의 계정 포함 | D12: M | E12: 2 | F12: 관리자 그룹에는 반드시 필요한 사용자만 포함하도록 관리
A13: 계정 관리 | B13: U-09 | C13: 계정이 존재하지 않는 GID 금지 | D13: L | E13: 1 | F13: 존재하지 않는 그룹(GID)을 사용하는 계정을 수정하거나 삭제
A14: 계정 관리 | B14: U-10 | C14: 동일한 UID 금지 | D14: M | E14: 2 | F14: 동일한 UID를 사용하는 계정이 없도록 변경하여 계정을 고유하게 관리
A15: 계정 관리 | B15: U-11 | C15: 사용자 Shell 점검 | D15: L | E15: 1 | F15: 로그인이 불필요한 계정은 /bin/false 또는 /sbin/nologin 등 로그인 불가능한 Shell을 사용하도록 설정
A16: 계정 관리 | B16: U-12 | C16: 세션 종료 시간 설정 | D16: L | E16: 1 | F16: TMOUT 등 세션 자동 종료 시간을 설정하여 일정 시간 미사용 시 자동 로그아웃되도록 설정
... A71: 로그 관리 | B71: U-67 | C71: 로그 디렉터리 소유자 및 권한 설정 | D71: M | E71: 2 | F71: 로그 디렉터리의 소유자 및 접근 권한을 적절하게 설정

Sheet 취약점 진단 통계
A1: ■ 자산목록
A3: 1) 영역별 보안수준
A4: 분류 | E4: 진단 결과 | J4: 중요도점수
E5: 전체항목 | F5: 진단항목 | G5: 양호 | H5: 취약 | I5: 해당없음 | J5: 전체점수 | K5: 평가점수 | L5: 보안수준
A6: 계정 관리 | E6: =SUMIF('취약점 진단 항목별 통계'!$A:$A,$A6&"*",'취약점 진단 항목별 통계'!$F:$F) -> 65 | F6: =E6-I6 -> 65 | G6: =SUMIF('취약점 진단 항목별 통계'!$A:$A,$A6&"*",'취약점 진단 항목별 통계'!$G:$G)+SUMIF('취약점 진단 항목별 통계'!$A:$A,$A6&"*",'취약점 진단 항목별 통계'!$H:$H) -> 59 | H6: =SUMIF('취약점 진단 항목별 통계'!$A:$A,$A6&"*",'취약점 진단 항목별 통계'!$I:$I) -> 6 | I6: =SUMIF('취약점 진단 항목별 통계'!$A:$A,$A6&"*",'취약점 진단 항목별 통계'!$J:$J) -> 0 | J6: =SUMIF('취약점 진단 항목별 통계'!$A:$A,$A6&"*",'취약점 진단 항목별 통계'!$K:$K) -> 140 | K6: =SUMIF('취약점 진단 항목별 통계'!$A:$A,$A6&"*",'취약점 진단 항목별 통계'!$L:$L) -> 122 | L6: =IF($I6=$E6, "N/A", (K6/J6)) -> 0.87142857
A7: 파일 및 디렉터리 관리 | E7: =SUMIF('취약점 진단 항목별 통계'!$A:$A,$A7&"*",'취약점 진단 항목별 통계'!$F:$F) -> 100 | F7: =E7-I7 -> 100 | G7: =SUMIF('취약점 진단 항목별 통계'!$A:$A,$A7&"*",'취약점 진단 항목별 통계'!$G:$G)+SUMIF('취약점 진단 항목별 통계'!$A:$A,$A7&"*",'취약점 진단 항목별 통계'!$H:$H) -> 55 | H7: =SUMIF('취약점 진단 항목별 통계'!$A:$A,$A7&"*",'취약점 진단 항목별 통계'!$I:$I) -> 45 | I7: =SUMIF('취약점 진단 항목별 통계'!$A:$A,$A7&"*",'취약점 진단 항목별 통계'!$J:$J) -> 0 | J7: =SUMIF('취약점 진단 항목별 통계'!$A:$A,$A7&"*",'취약점 진단 항목별 통계'!$K:$K) -> 265 | K7: =SUMIF('취약점 진단 항목별 통계'!$A:$A,$A7&"*",'취약점 진단 항목별 통계'!$L:$L) -> 140 | L7: =IF($I7=$E7, "N/A", (K7/J7)) -> 0.52830189
A8: 서비스 관리 | E8: =SUMIF('취약점 진단 항목별 통계'!$A:$A,$A8&"*",'취약점 진단 항목별 통계'!$F:$F) -> 150 | F8: =E8-I8 -> 150 | G8: =SUMIF('취약점 진단 항목별 통계'!$A:$A,$A8&"*",'취약점 진단 항목별 통계'!$G:$G)+SUMIF('취약점 진단 항목별 통계'!$A:$A,$A8&"*",'취약점 진단 항목별 통계'!$H:$H) -> 122 | H8: =SUMIF('취약점 진단 항목별 통계'!$A:$A,$A8&"*",'취약점 진단 항목별 통계'!$I:$I) -> 23 | I8: =SUMIF('취약점 진단 항목별 통계'!$A:$A,$A8&"*",'취약점 진단 항목별 통계'!$J:$J) -> 0 | J8: =SUMIF('취약점 진단 항목별 통계'!$A:$A,$A8&"*",'취약점 진단 항목별 통계'!$K:$K) -> 375 | K8: =SUMIF('취약점 진단 항목별 통계'!$A:$A,$A8&"*",'취약점 진단 항목별 통계'!$L:$L) -> 315 | L8: =IF($I8=$E8, "N/A", (K8/J8)) -> 0.84
A9: 패치 관리 | E9: =SUMIF('취약점 진단 항목별 통계'!$A:$A,$A9&"*",'취약점 진단 항목별 통계'!$F:$F) -> 5 | F9: =E9-I9 -> 5 | G9: =SUMIF('취약점 진단 항목별 통계'!$A:$A,$A9&"*",'취약점 진단 항목별 통계'!$G:$G)+SUMIF('취약점 진단 항목별 통계'!$A:$A,$A9&"*",'취약점 진단 항목별 통계'!$H:$H) -> 5 | H9: =SUMIF('취약점 진단 항목별 통계'!$A:$A,$A9&"*",'취약점 진단 항목별 통계'!$I:$I) -> 0 | I9: =SUMIF('취약점 진단 항목별 통계'!$A:$A,$A9&"*",'취약점 진단 항목별 통계'!$J:$J) -> 0 | J9: =SUMIF('취약점 진단 항목별 통계'!$A:$A,$A9&"*",'취약점 진단 항목별 통계'!$K:$K) -> 15 | K9: =SUMIF('취약점 진단 항목별 통계'!$A:$A,$A9&"*",'취약점 진단 항목별 통계'!$L:$L) -> 15 | L9: =IF($I9=$E9, "N/A", (K9/J9)) -> 1
A10: 로그 관리 | E10: =SUMIF('취약점 진단 항목별 통계'!$A:$A,$A10&"*",'취약점 진단 항목별 통계'!$F:$F) -> 15 | F10: =E10-I10 -> 15 | G10: =SUMIF('취약점 진단 항목별 통계'!$A:$A,$A10&"*",'취약점 진단 항목별 통계'!$G:$G)+SUMIF('취약점 진단 항목별 통계'!$A:$A,$A10&"*",'취약점 진단 항목별 통계'!$H:$H) -> 15 | H10: =SUMIF('취약점 진단 항목별 통계'!$A:$A,$A10&"*",'취약점 진단 항목별 통계'!$I:$I) -> 0 | I10: =SUMIF('취약점 진단 항목별 통계'!$A:$A,$A10&"*",'취약점 진단 항목별 통계'!$J:$J) -> 0 | J10: =SUMIF('취약점 진단 항목별 통계'!$A:$A,$A10&"*",'취약점 진단 항목별 통계'!$K:$K) -> 30 | K10: =SUMIF('취약점 진단 항목별 통계'!$A:$A,$A10&"*",'취약점 진단 항목별 통계'!$L:$L) -> 30 | L10: =IF($I10=$E10, "N/A", (K10/J10)) -> 1
A11: 계 | E11: =SUM(E6:E10) -> 335 | F11: =SUM(F6:F10) -> 335 | G11: =SUM(G6:G10) -> 256 | H11: =SUM(H6:H10) -> 74 | I11: =SUM(I6:I10) -> 0 | J11: =SUM(J6:J10) -> 825 | K11: =SUM(K6:K10) -> 622 | L11: =IFERROR(K11/J11, 0) -> 0.75393939
A39: 2) 장비별 보안수준
A40: 장비 구분 | E40: 진단 결과 | J40: 중요도점수
E41: 전체항목 | F41: 진단항목 | G41: 양호 | H41: 취약 | I41: 해당없음 | J41: 전체점수 | K41: 평가점수 | L41: 보안수준
A42: =HYPERLINK("[" & MID(CELL("filename"),SEARCH("[",CELL("filename"))+1, SEARCH("]",CELL("filename"))-SEARCH("[",CELL("filename"))-1) & "]" & INDIRECT(ADDRESS(ROW()-37,2,1,TRUE,"자산목록")) & "!A1",INDIRECT(ADDRESS(ROW()-37,2,1,TRUE,"자산목록"))) -> WEB-HQ-Ubuntu | C42: =IFERROR(VLOOKUP($A42,자산목록!$B$1:$M$835,6,FALSE),"-") -> Ubuntu | E42: =IFERROR(INDIRECT(ADDRESS(17, 4, 1,TRUE,$A42)),0) -> 59 | F42: =E42-I42 -> 59 | G42: =IFERROR(INDIRECT(ADDRESS(17, 5, 1,TRUE,$A42)),0) -> 39 | H42: =IFERROR(INDIRECT(ADDRESS(17, 6, 1,TRUE,$A42)),0) -> 20 | I42: =IFERROR(INDIRECT(ADDRESS(17, 7, 1,TRUE,$A42)),0) -> 0 | J42: =IFERROR(INDIRECT(ADDRESS(17, 18, 1,TRUE,$A42)),0) -> 146 | K42: =IFERROR(INDIRECT(ADDRESS(17, 19, 1,TRUE,$A42)),0) -> 90 | L42: =IFERROR(INDIRECT(ADDRESS(17,8, 1,TRUE,$A42)),0) -> 0.61643836
A43: =HYPERLINK("[" & MID(CELL("filename"),SEARCH("[",CELL("filename"))+1, SEARCH("]",CELL("filename"))-SEARCH("[",CELL("filename"))-1) & "]" & INDIRECT(ADDRESS(ROW()-37,2,1,TRUE,"자산목록")) & "!A1",INDIRECT(ADDRESS(ROW()-37,2,1,TRUE,"자산목록"))) -> LOG_HQ_Rocky | C43: =IFERROR(VLOOKUP($A43,자산목록!$B$1:$M$835,6,FALSE),"-") -> Rocky | E43: =IFERROR(INDIRECT(ADDRESS(17, 4, 1,TRUE,$A43)),0) -> 59 | F43: =E43-I43 -> 59 | G43: =IFERROR(INDIRECT(ADDRESS(17, 5, 1,TRUE,$A43)),0) -> 41 | H43: =IFERROR(INDIRECT(ADDRESS(17, 6, 1,TRUE,$A43)),0) -> 18 | I43: =IFERROR(INDIRECT(ADDRESS(17, 7, 1,TRUE,$A43)),0) -> 0 | J43: =IFERROR(INDIRECT(ADDRESS(17, 18, 1,TRUE,$A43)),0) -> 146 | K43: =IFERROR(INDIRECT(ADDRESS(17, 19, 1,TRUE,$A43)),0) -> 96 | L43: =IFERROR(INDIRECT(ADDRESS(17,8, 1,TRUE,$A43)),0) -> 0.65753425
A44: =HYPERLINK("[" & MID(CELL("filename"),SEARCH("[",CELL("filename"))+1, SEARCH("]",CELL("filename"))-SEARCH("[",CELL("filename"))-1) & "]" & INDIRECT(ADDRESS(ROW()-37,2,1,TRUE,"자산목록")) & "!A1",INDIRECT(ADDRESS(ROW()-37,2,1,TRUE,"자산목록"))) -> DB_HQ_Rocky | C44: =IFERROR(VLOOKUP($A44,자산목록!$B$1:$M$835,6,FALSE),"-") -> Rocky | E44: =IFERROR(INDIRECT(ADDRESS(17, 4, 1,TRUE,$A44)),0) -> 59 | F44: =E44-I44 -> 59 | G44: =IFERROR(INDIRECT(ADDRESS(17, 5, 1,TRUE,$A44)),0) -> 41 | H44: =IFERROR(INDIRECT(ADDRESS(17, 6, 1,TRUE,$A44)),0) -> 18 | I44: =IFERROR(INDIRECT(ADDRESS(17, 7, 1,TRUE,$A44)),0) -> 0 | J44: =IFERROR(INDIRECT(ADDRESS(17, 18, 1,TRUE,$A44)),0) -> 146 | K44: =IFERROR(INDIRECT(ADDRESS(17, 19, 1,TRUE,$A44)),0) -> 96 | L44: =IFERROR(INDIRECT(ADDRESS(17,8, 1,TRUE,$A44)),0) -> 0.65753425
A45: =HYPERLINK("[" & MID(CELL("filename"),SEARCH("[",CELL("filename"))+1, SEARCH("]",CELL("filename"))-SEARCH("[",CELL("filename"))-1) & "]" & INDIRECT(ADDRESS(ROW()-37,2,1,TRUE,"자산목록")) & "!A1",INDIRECT(ADDRESS(ROW()-37,2,1,TRUE,"자산목록"))) -> BDB_HQ_Rocky | C45: =IFERROR(VLOOKUP($A45,자산목록!$B$1:$M$835,6,FALSE),"-") -> Rocky | E45: =IFERROR(INDIRECT(ADDRESS(17, 4, 1,TRUE,$A45)),0) -> 59 | F45: =E45-I45 -> 59 | G45: =IFERROR(INDIRECT(ADDRESS(17, 5, 1,TRUE,$A45)),0) -> 39 | H45: =IFERROR(INDIRECT(ADDRESS(17, 6, 1,TRUE,$A45)),0) -> 20 | I45: =IFERROR(INDIRECT(ADDRESS(17, 7, 1,TRUE,$A45)),0) -> 0 | J45: =IFERROR(INDIRECT(ADDRESS(17, 18, 1,TRUE,$A45)),0) -> 146 | K45: =IFERROR(INDIRECT(ADDRESS(17, 19, 1,TRUE,$A45)),0) -> 90 | L45: =IFERROR(INDIRECT(ADDRESS(17,8, 1,TRUE,$A45)),0) -> 0.61643836
A46: =HYPERLINK("[" & MID(CELL("filename"),SEARCH("[",CELL("filename"))+1, SEARCH("]",CELL("filename"))-SEARCH("[",CELL("filename"))-1) & "]" & INDIRECT(ADDRESS(ROW()-37,2,1,TRUE,"자산목록")) & "!A1",INDIRECT(ADDRESS(ROW()-37,2,1,TRUE,"자산목록"))) -> BLOG_HQ_Rocky | C46: =IFERROR(VLOOKUP($A46,자산목록!$B$1:$M$835,6,FALSE),"-") -> Rocky | E46: =IFERROR(INDIRECT(ADDRESS(17, 4, 1,TRUE,$A46)),0) -> 59 | F46: =E46-I46 -> 59 | G46: =IFERROR(INDIRECT(ADDRESS(17, 5, 1,TRUE,$A46)),0) -> 39 | H46: =IFERROR(INDIRECT(ADDRESS(17, 6, 1,TRUE,$A46)),0) -> 20 | I46: =IFERROR(INDIRECT(ADDRESS(17, 7, 1,TRUE,$A46)),0) -> 0 | J46: =IFERROR(INDIRECT(ADDRESS(17, 18, 1,TRUE,$A46)),0) -> 146 | K46: =IFERROR(INDIRECT(ADDRESS(17, 19, 1,TRUE,$A46)),0) -> 90 | L46: =IFERROR(INDIRECT(ADDRESS(17,8, 1,TRUE,$A46)),0) -> 0.61643836
A47: =HYPERLINK("[" & MID(CELL("filename"),SEARCH("[",CELL("filename"))+1, SEARCH("]",CELL("filename"))-SEARCH("[",CELL("filename"))-1) & "]" & INDIRECT(ADDRESS(ROW()-37,2,1,TRUE,"자산목록")) & "!A1",INDIRECT(ADDRESS(ROW()-37,2,1,TRUE,"자산목록"))) -> PHP_BR_Rocky | C47: =IFERROR(VLOOKUP($A47,자산목록!$B$1:$M$835,6,FALSE),"-") -> Rocky | E47: =IFERROR(INDIRECT(ADDRESS(17, 4, 1,TRUE,$A47)),0) -> 59 | F47: =E47-I47 -> 59 | G47: =IFERROR(INDIRECT(ADDRESS(17, 5, 1,TRUE,$A47)),0) -> 59 | H47: =IFERROR(INDIRECT(ADDRESS(17, 6, 1,TRUE,$A47)),0) -> 0 | I47: =IFERROR(INDIRECT(ADDRESS(17, 7, 1,TRUE,$A47)),0) -> 0 | J47: =IFERROR(INDIRECT(ADDRESS(17, 18, 1,TRUE,$A47)),0) -> 146 | K47: =IFERROR(INDIRECT(ADDRESS(17, 19, 1,TRUE,$A47)),0) -> 146 | L47: =IFERROR(INDIRECT(ADDRESS(17,8, 1,TRUE,$A47)),0) -> 1
A48: =HYPERLINK("[" & MID(CELL("filename"),SEARCH("[",CELL("filename"))+1, SEARCH("]",CELL("filename"))-SEARCH("[",CELL("filename"))-1) & "]" & INDIRECT(ADDRESS(ROW()-37,2,1,TRUE,"자산목록")) & "!A1",INDIRECT(ADDRESS(ROW()-37,2,1,TRUE,"자산목록"))) -> LOG_BR_Rocky | C48: =IFERROR(VLOOKUP($A48,자산목록!$B$1:$M$835,6,FALSE),"-") -> Rocky | E48: =IFERROR(INDIRECT(ADDRESS(17, 4, 1,TRUE,$A48)),0) -> 59 | F48: =E48-I48 -> 59 | G48: =IFERROR(INDIRECT(ADDRESS(17, 5, 1,TRUE,$A48)),0) -> 59 | H48: =IFERROR(INDIRECT(ADDRESS(17, 6, 1,TRUE,$A48)),0) -> 0 | I48: =IFERROR(INDIRECT(ADDRESS(17, 7, 1,TRUE,$A48)),0) -> 0 | J48: =IFERROR(INDIRECT(ADDRESS(17, 18, 1,TRUE,$A48)),0) -> 146 | K48: =IFERROR(INDIRECT(ADDRESS(17, 19, 1,TRUE,$A48)),0) -> 146 | L48: =IFERROR(INDIRECT(ADDRESS(17,8, 1,TRUE,$A48)),0) -> 1
A49: =HYPERLINK("[" & MID(CELL("filename"),SEARCH("[",CELL("filename"))+1, SEARCH("]",CELL("filename"))-SEARCH("[",CELL("filename"))-1) & "]" & INDIRECT(ADDRESS(ROW()-37,2,1,TRUE,"자산목록")) & "!A1",INDIRECT(ADDRESS(ROW()-37,2,1,TRUE,"자산목록"))) -> DB_BR_Rocky | C49: =IFERROR(VLOOKUP($A49,자산목록!$B$1:$M$835,6,FALSE),"-") -> Rocky | E49: =IFERROR(INDIRECT(ADDRESS(17, 4, 1,TRUE,$A49)),0) -> 59 | F49: =E49-I49 -> 59 | G49: =IFERROR(INDIRECT(ADDRESS(17, 5, 1,TRUE,$A49)),0) -> 59 | H49: =IFERROR(INDIRECT(ADDRESS(17, 6, 1,TRUE,$A49)),0) -> 0 | I49: =IFERROR(INDIRECT(ADDRESS(17, 7, 1,TRUE,$A49)),0) -> 0 | J49: =IFERROR(INDIRECT(ADDRESS(17, 18, 1,TRUE,$A49)),0) -> 146 | K49: =IFERROR(INDIRECT(ADDRESS(17, 19, 1,TRUE,$A49)),0) -> 146 | L49: =IFERROR(INDIRECT(ADDRESS(17,8, 1,TRUE,$A49)),0) -> 1
A50: =HYPERLINK("[" & MID(CELL("filename"),SEARCH("[",CELL("filename"))+1, SEARCH("]",CELL("filename"))-SEARCH("[",CELL("filename"))-1) & "]" & INDIRECT(ADDRESS(ROW()-37,2,1,TRUE,"자산목록")) & "!A1",INDIRECT(ADDRESS(ROW()-37,2,1,TRUE,"자산목록"))) -> BDB_BR_Rocky | C50: =IFERROR(VLOOKUP($A50,자산목록!$B$1:$M$835,6,FALSE),"-") -> Rocky | E50: =IFERROR(INDIRECT(ADDRESS(17, 4, 1,TRUE,$A50)),0) -> 59 | F50: =E50-I50 -> 59 | G50: =IFERROR(INDIRECT(ADDRESS(17, 5, 1,TRUE,$A50)),0) -> 59 | H50: =IFERROR(INDIRECT(ADDRESS(17, 6, 1,TRUE,$A50)),0) -> 0 | I50: =IFERROR(INDIRECT(ADDRESS(17, 7, 1,TRUE,$A50)),0) -> 0 | J50: =IFERROR(INDIRECT(ADDRESS(17, 18, 1,TRUE,$A50)),0) -> 146 | K50: =IFERROR(INDIRECT(ADDRESS(17, 19, 1,TRUE,$A50)),0) -> 146 | L50: =IFERROR(INDIRECT(ADDRESS(17,8, 1,TRUE,$A50)),0) -> 1
A51: =HYPERLINK("[" & MID(CELL("filename"),SEARCH("[",CELL("filename"))+1, SEARCH("]",CELL("filename"))-SEARCH("[",CELL("filename"))-1) & "]" & INDIRECT(ADDRESS(ROW()-37,2,1,TRUE,"자산목록")) & "!A1",INDIRECT(ADDRESS(ROW()-37,2,1,TRUE,"자산목록"))) -> BLOG_BR_Rocky | C51: =IFERROR(VLOOKUP($A51,자산목록!$B$1:$M$835,6,FALSE),"-") -> Rocky | E51: =IFERROR(INDIRECT(ADDRESS(17, 4, 1,TRUE,$A51)),0) -> 59 | F51: =E51-I51 -> 59 | G51: =IFERROR(INDIRECT(ADDRESS(17, 5, 1,TRUE,$A51)),0) -> 59 | H51: =IFERROR(INDIRECT(ADDRESS(17, 6, 1,TRUE,$A51)),0) -> 0 | I51: =IFERROR(INDIRECT(ADDRESS(17, 7, 1,TRUE,$A51)),0) -> 0 | J51: =IFERROR(INDIRECT(ADDRESS(17, 18, 1,TRUE,$A51)),0) -> 146 | K51: =IFERROR(INDIRECT(ADDRESS(17, 19, 1,TRUE,$A51)),0) -> 146 | L51: =IFERROR(INDIRECT(ADDRESS(17,8, 1,TRUE,$A51)),0) -> 1
A52: 계 | E52: =SUM(E42:E42) -> 59 | F52: =SUM(F42:F42) -> 59 | G52: =SUM(G42:G42) -> 39 | H52: =SUM(H42:H42) -> 20 | I52: =SUM(I42:I42) -> 0 | J52: =SUM(J42:J42) -> 146 | K52: =SUM(K42:K42) -> 90 | L52: =IFERROR(K52/J52, 0) -> 0.61643836

Sheet 취약점 진단 통계 (이행)
A1: ■ 자산목록
A3: 1) 영역별 보안수준
A4: 분류 | E4: 진단 결과 | J4: 이행 결과 | O4: 중요도점수
E5: 전체항목 | F5: 진단항목 | G5: 양호 | H5: 취약 | I5: 해당없음 | J5: 조치 | K5: 미조치 | L5: 위험수용 | M5: 해당없음 | N5: 잔여취약점 (미조치+위험수용) | O5: 전체점수 (이행전) | P5: 전체점수 (이행후) | Q5: 평가점수 (이행전) | R5: 평가점수 (이행후) | S5: 이행율 | T5: 보안수준 (이행 전) | U5: 보안수준 (이행 후)
A6: 계정 관리 | E6: =SUMIF('취약점 진단 항목별 통계 (이행)'!$A:$A,$A6&"*",'취약점 진단 항목별 통계 (이행)'!$F:$F) -> 65 | F6: =E6-I6 -> 65 | G6: =SUMIF('취약점 진단 항목별 통계'!$A:$A,$A6&"*",'취약점 진단 항목별 통계'!$G:$G)+SUMIF('취약점 진단 항목별 통계'!$A:$A,$A6&"*",'취약점 진단 항목별 통계'!$H:$H) -> 59 | H6: =SUMIF('취약점 진단 항목별 통계'!$A:$A,$A6&"*",'취약점 진단 항목별 통계'!$I:$I) -> 6 | I6: =SUMIF('취약점 진단 항목별 통계'!$A:$A,$A6&"*",'취약점 진단 항목별 통계'!$J:$J) -> 0 | J6: =SUMIF('취약점 진단 항목별 통계 (이행)'!$A:$A,$A6&"*",'취약점 진단 항목별 통계 (이행)'!$K:$K) -> 6 | K6: =SUMIF('취약점 진단 항목별 통계 (이행)'!$A:$A,$A6&"*",'취약점 진단 항목별 통계 (이행)'!$L:$L) -> 0 | L6: =SUMIF('취약점 진단 항목별 통계 (이행)'!$A:$A,$A6&"*",'취약점 진단 항목별 통계 (이행)'!$M:$M) -> 0 | M6: =SUMIF('취약점 진단 항목별 통계 (이행)'!$A:$A,$A6&"*",'취약점 진단 항목별 통계 (이행)'!$N:$N) -> 0 | N6: =K6+L6 -> 0 | O6: =SUMIF('취약점 진단 항목별 통계 (이행)'!$A:$A,$A6&"*",'취약점 진단 항목별 통계 (이행)'!$O:$O) -> 140 | P6: =SUMIF('취약점 진단 항목별 통계 (이행)'!$A:$A,$A6&"*",'취약점 진단 항목별 통계 (이행)'!$P:$P) -> 140 | Q6: =SUMIF('취약점 진단 항목별 통계 (이행)'!$A:$A,$A6&"*",'취약점 진단 항목별 통계 (이행)'!$Q:$Q) -> 122 | R6: =SUMIF('취약점 진단 항목별 통계 (이행)'!$A:$A,$A6&"*",'취약점 진단 항목별 통계 (이행)'!$R:$R) -> 140 | S6: =IFERROR(K6/(C6-(L6-F6)),"N/A") -> 0 | T6: =IF($I6=$E6, "N/A", (Q6/O6)) -> 0.87142857 | U6: =IF(OR(H6=G6, G6=I6),"N/A", R6/P6) -> 1
A7: 파일 및 디렉터리 관리 | E7: =SUMIF('취약점 진단 항목별 통계 (이행)'!$A:$A,$A7&"*",'취약점 진단 항목별 통계 (이행)'!$F:$F) -> 100 | F7: =E7-I7 -> 100 | G7: =SUMIF('취약점 진단 항목별 통계'!$A:$A,$A7&"*",'취약점 진단 항목별 통계'!$G:$G)+SUMIF('취약점 진단 항목별 통계'!$A:$A,$A7&"*",'취약점 진단 항목별 통계'!$H:$H) -> 55 | H7: =SUMIF('취약점 진단 항목별 통계'!$A:$A,$A7&"*",'취약점 진단 항목별 통계'!$I:$I) -> 45 | I7: =SUMIF('취약점 진단 항목별 통계'!$A:$A,$A7&"*",'취약점 진단 항목별 통계'!$J:$J) -> 0 | J7: =SUMIF('취약점 진단 항목별 통계 (이행)'!$A:$A,$A7&"*",'취약점 진단 항목별 통계 (이행)'!$K:$K) -> 45 | K7: =SUMIF('취약점 진단 항목별 통계 (이행)'!$A:$A,$A7&"*",'취약점 진단 항목별 통계 (이행)'!$L:$L) -> 0 | L7: =SUMIF('취약점 진단 항목별 통계 (이행)'!$A:$A,$A7&"*",'취약점 진단 항목별 통계 (이행)'!$M:$M) -> 0 | M7: =SUMIF('취약점 진단 항목별 통계 (이행)'!$A:$A,$A7&"*",'취약점 진단 항목별 통계 (이행)'!$N:$N) -> 0 | N7: =K7+L7 -> 0 | O7: =SUMIF('취약점 진단 항목별 통계 (이행)'!$A:$A,$A7&"*",'취약점 진단 항목별 통계 (이행)'!$O:$O) -> 265 | P7: =SUMIF('취약점 진단 항목별 통계 (이행)'!$A:$A,$A7&"*",'취약점 진단 항목별 통계 (이행)'!$P:$P) -> 265 | Q7: =SUMIF('취약점 진단 항목별 통계 (이행)'!$A:$A,$A7&"*",'취약점 진단 항목별 통계 (이행)'!$Q:$Q) -> 140 | R7: =SUMIF('취약점 진단 항목별 통계 (이행)'!$A:$A,$A7&"*",'취약점 진단 항목별 통계 (이행)'!$R:$R) -> 265 | S7: =IFERROR(K7/(C7-(L7-F7)),"N/A") -> 0 | T7: =IF($I7=$E7, "N/A", (Q7/O7)) -> 0.52830189 | U7: =IF(OR(H7=G7, G7=I7),"N/A", R7/P7) -> 1
A8: 서비스 관리 | E8: =SUMIF('취약점 진단 항목별 통계 (이행)'!$A:$A,$A8&"*",'취약점 진단 항목별 통계 (이행)'!$F:$F) -> 150 | F8: =E8-I8 -> 150 | G8: =SUMIF('취약점 진단 항목별 통계'!$A:$A,$A8&"*",'취약점 진단 항목별 통계'!$G:$G)+SUMIF('취약점 진단 항목별 통계'!$A:$A,$A8&"*",'취약점 진단 항목별 통계'!$H:$H) -> 122 | H8: =SUMIF('취약점 진단 항목별 통계'!$A:$A,$A8&"*",'취약점 진단 항목별 통계'!$I:$I) -> 23 | I8: =SUMIF('취약점 진단 항목별 통계'!$A:$A,$A8&"*",'취약점 진단 항목별 통계'!$J:$J) -> 0 | J8: =SUMIF('취약점 진단 항목별 통계 (이행)'!$A:$A,$A8&"*",'취약점 진단 항목별 통계 (이행)'!$K:$K) -> 23 | K8: =SUMIF('취약점 진단 항목별 통계 (이행)'!$A:$A,$A8&"*",'취약점 진단 항목별 통계 (이행)'!$L:$L) -> 0 | L8: =SUMIF('취약점 진단 항목별 통계 (이행)'!$A:$A,$A8&"*",'취약점 진단 항목별 통계 (이행)'!$M:$M) -> 0 | M8: =SUMIF('취약점 진단 항목별 통계 (이행)'!$A:$A,$A8&"*",'취약점 진단 항목별 통계 (이행)'!$N:$N) -> 0 | N8: =K8+L8 -> 0 | O8: =SUMIF('취약점 진단 항목별 통계 (이행)'!$A:$A,$A8&"*",'취약점 진단 항목별 통계 (이행)'!$O:$O) -> 375 | P8: =SUMIF('취약점 진단 항목별 통계 (이행)'!$A:$A,$A8&"*",'취약점 진단 항목별 통계 (이행)'!$P:$P) -> 375 | Q8: =SUMIF('취약점 진단 항목별 통계 (이행)'!$A:$A,$A8&"*",'취약점 진단 항목별 통계 (이행)'!$Q:$Q) -> 315 | R8: =SUMIF('취약점 진단 항목별 통계 (이행)'!$A:$A,$A8&"*",'취약점 진단 항목별 통계 (이행)'!$R:$R) -> 360 | S8: =IFERROR(K8/(C8-(L8-F8)),"N/A") -> 0 | T8: =IF($I8=$E8, "N/A", (Q8/O8)) -> 0.84 | U8: =IF(OR(H8=G8, G8=I8),"N/A", R8/P8) -> 0.96
A9: 패치 관리 | E9: =SUMIF('취약점 진단 항목별 통계 (이행)'!$A:$A,$A9&"*",'취약점 진단 항목별 통계 (이행)'!$F:$F) -> 5 | F9: =E9-I9 -> 5 | G9: =SUMIF('취약점 진단 항목별 통계'!$A:$A,$A9&"*",'취약점 진단 항목별 통계'!$G:$G)+SUMIF('취약점 진단 항목별 통계'!$A:$A,$A9&"*",'취약점 진단 항목별 통계'!$H:$H) -> 5 | H9: =SUMIF('취약점 진단 항목별 통계'!$A:$A,$A9&"*",'취약점 진단 항목별 통계'!$I:$I) -> 0 | I9: =SUMIF('취약점 진단 항목별 통계'!$A:$A,$A9&"*",'취약점 진단 항목별 통계'!$J:$J) -> 0 | J9: =SUMIF('취약점 진단 항목별 통계 (이행)'!$A:$A,$A9&"*",'취약점 진단 항목별 통계 (이행)'!$K:$K) -> 0 | K9: =SUMIF('취약점 진단 항목별 통계 (이행)'!$A:$A,$A9&"*",'취약점 진단 항목별 통계 (이행)'!$L:$L) -> 0 | L9: =SUMIF('취약점 진단 항목별 통계 (이행)'!$A:$A,$A9&"*",'취약점 진단 항목별 통계 (이행)'!$M:$M) -> 0 | M9: =SUMIF('취약점 진단 항목별 통계 (이행)'!$A:$A,$A9&"*",'취약점 진단 항목별 통계 (이행)'!$N:$N) -> 0 | N9: =K9+L9 -> 0 | O9: =SUMIF('취약점 진단 항목별 통계 (이행)'!$A:$A,$A9&"*",'취약점 진단 항목별 통계 (이행)'!$O:$O) -> 15 | P9: =SUMIF('취약점 진단 항목별 통계 (이행)'!$A:$A,$A9&"*",'취약점 진단 항목별 통계 (이행)'!$P:$P) -> 15 | Q9: =SUMIF('취약점 진단 항목별 통계 (이행)'!$A:$A,$A9&"*",'취약점 진단 항목별 통계 (이행)'!$Q:$Q) -> 15 | R9: =SUMIF('취약점 진단 항목별 통계 (이행)'!$A:$A,$A9&"*",'취약점 진단 항목별 통계 (이행)'!$R:$R) -> 15 | S9: =IFERROR(K9/(C9-(L9-F9)),"N/A") -> 0 | T9: =IF($I9=$E9, "N/A", (Q9/O9)) -> 1 | U9: =IF(OR(H9=G9, G8=I9), 1, R9/P9) -> 1
A10: 로그 관리 | E10: =SUMIF('취약점 진단 항목별 통계 (이행)'!$A:$A,$A10&"*",'취약점 진단 항목별 통계 (이행)'!$F:$F) -> 15 | F10: =E10-I10 -> 15 | G10: =SUMIF('취약점 진단 항목별 통계'!$A:$A,$A10&"*",'취약점 진단 항목별 통계'!$G:$G)+SUMIF('취약점 진단 항목별 통계'!$A:$A,$A10&"*",'취약점 진단 항목별 통계'!$H:$H) -> 15 | H10: =SUMIF('취약점 진단 항목별 통계'!$A:$A,$A10&"*",'취약점 진단 항목별 통계'!$I:$I) -> 0 | I10: =SUMIF('취약점 진단 항목별 통계'!$A:$A,$A10&"*",'취약점 진단 항목별 통계'!$J:$J) -> 0 | J10: =SUMIF('취약점 진단 항목별 통계 (이행)'!$A:$A,$A10&"*",'취약점 진단 항목별 통계 (이행)'!$K:$K) -> 0 | K10: =SUMIF('취약점 진단 항목별 통계 (이행)'!$A:$A,$A10&"*",'취약점 진단 항목별 통계 (이행)'!$L:$L) -> 0 | L10: =SUMIF('취약점 진단 항목별 통계 (이행)'!$A:$A,$A10&"*",'취약점 진단 항목별 통계 (이행)'!$M:$M) -> 0 | M10: =SUMIF('취약점 진단 항목별 통계 (이행)'!$A:$A,$A10&"*",'취약점 진단 항목별 통계 (이행)'!$N:$N) -> 0 | N10: =K10+L10 -> 0 | O10: =SUMIF('취약점 진단 항목별 통계 (이행)'!$A:$A,$A10&"*",'취약점 진단 항목별 통계 (이행)'!$O:$O) -> 30 | P10: =SUMIF('취약점 진단 항목별 통계 (이행)'!$A:$A,$A10&"*",'취약점 진단 항목별 통계 (이행)'!$P:$P) -> 30 | Q10: =SUMIF('취약점 진단 항목별 통계 (이행)'!$A:$A,$A10&"*",'취약점 진단 항목별 통계 (이행)'!$Q:$Q) -> 30 | R10: =SUMIF('취약점 진단 항목별 통계 (이행)'!$A:$A,$A10&"*",'취약점 진단 항목별 통계 (이행)'!$R:$R) -> 30 | S10: =IFERROR(K10/(C10-(L10-F10)),"N/A") -> 0 | T10: =IF($I10=$E10, "N/A", (Q10/O10)) -> 1 | U10: =IF(OR(H10=G10, G10=I10),"N/A", R10/P10) -> 1
A11: 계 | E11: =SUM(E6:E10) -> 335 | F11: =SUM(F6:F10) -> 335 | G11: =SUM(G6:G10) -> 256 | H11: =SUM(H6:H10) -> 74 | I11: =SUM(I6:I10) -> 0 | J11: =SUM(J6:J10) -> 74 | K11: =SUM(K6:K10) -> 0 | L11: =SUM(L6:L10) -> 0 | ... R11: =SUM(R6:R10) -> 810 | S11: =IFERROR($J11/($H11-(M11-I11)),"N/A") -> 1 | T11: =IF($I11=$E11, "N/A", (Q11/O11)) -> 0.75393939 | U11: =IF(OR($I11=$E11,$E11=$M11),"N/A", ($R11/$P11)) -> 0.98181818
A39: 2) 장비별 보안수준
A40: 장비 구분 | E40: 진단 결과 | J40: 이행 결과 | O40: 중요도점수
E41: 전체항목 | F41: 진단항목 | G41: 양호 | H41: 취약 | I41: 해당없음 | J41: 조치 | K41: 미조치 | L41: 위험수용 | M41: 해당없음 | N41: 잔여취약점 (미조치+위험수용) | O41: 전체점수 (이행전) | P41: 전체점수 (이행후) | Q41: 평가점수 (이행전) | R41: 평가점수 (이행후) | S41: 이행율 | T41: 보안수준 (이행 전) | U41: 보안수준 (이행 후)
A42: =HYPERLINK("[" & MID(CELL("filename"),SEARCH("[",CELL("filename"))+1, SEARCH("]",CELL("filename"))-SEARCH("[",CELL("filename"))-1) & "]" & INDIRECT(ADDRESS(ROW()-37,2,1,TRUE,"자산목록")) & "!A1",INDIRECT(ADDRESS(ROW()-37,2,1,TRUE,"자산목록"))) -> WEB-HQ-Ubuntu | C42: =IFERROR(VLOOKUP($A42,자산목록!$B$1:$M$835,6,FALSE),"-") -> Ubuntu | E42: =IFERROR(INDIRECT(ADDRESS(17, 4, 1,TRUE,$A42)),0) -> 59 | F42: =E42-I42 -> 59 | G42: =IFERROR(INDIRECT(ADDRESS(17,5, 1,TRUE,$A42)),0) -> 39 | H42: =IFERROR(INDIRECT(ADDRESS(17,6, 1,TRUE,$A42)),0) -> 20 | I42: =IFERROR(INDIRECT(ADDRESS(17,7, 1,TRUE,$A42)),0) -> 0 | J42: =IFERROR(INDIRECT(ADDRESS(17,10, 1,TRUE,$A42)),0) -> 20 | K42: =IFERROR(INDIRECT(ADDRESS(17,11, 1,TRUE,$A42)),0) -> 0 | L42: =IFERROR(INDIRECT(ADDRESS(17,12, 1,TRUE,$A42)),0) -> 0 | M42: =IFERROR(INDIRECT(ADDRESS(17,13, 1,TRUE,$A42)),0) -> 0 | N42: =K42+L42 -> 0 | O42: =IFERROR(INDIRECT(ADDRESS(17,18, 1,TRUE,$A42)),0) -> 146 | P42: =IFERROR(INDIRECT(ADDRESS(17,21, 1,TRUE,$A42)),0) -> 146 | Q42: =IFERROR(INDIRECT(ADDRESS(17,19, 1,TRUE,$A42)),0) -> 90 | R42: =IFERROR(INDIRECT(ADDRESS(17,20, 1,TRUE,$A42)),0) -> 146 | S42: =IFERROR(INDIRECT(ADDRESS(17,14, 1,TRUE,$A42)),0) -> 1 | T42: =IFERROR(INDIRECT(ADDRESS(17,8, 1,TRUE,$A42)),0) -> 0.61643836 | U42: =IFERROR(INDIRECT(ADDRESS(17,15, 1,TRUE,$A42)),0) -> 1
A43: =HYPERLINK("[" & MID(CELL("filename"),SEARCH("[",CELL("filename"))+1, SEARCH("]",CELL("filename"))-SEARCH("[",CELL("filename"))-1) & "]" & INDIRECT(ADDRESS(ROW()-37,2,1,TRUE,"자산목록")) & "!A1",INDIRECT(ADDRESS(ROW()-37,2,1,TRUE,"자산목록"))) -> LOG_HQ_Rocky | C43: =IFERROR(VLOOKUP($A43,자산목록!$B$1:$M$835,6,FALSE),"-") -> Rocky | E43: =IFERROR(INDIRECT(ADDRESS(17, 4, 1,TRUE,$A43)),0) -> 59 | F43: =E43-I43 -> 59 | G43: =IFERROR(INDIRECT(ADDRESS(17,5, 1,TRUE,$A43)),0) -> 41 | H43: =IFERROR(INDIRECT(ADDRESS(17,6, 1,TRUE,$A43)),0) -> 18 | I43: =IFERROR(INDIRECT(ADDRESS(17,7, 1,TRUE,$A43)),0) -> 0 | J43: =IFERROR(INDIRECT(ADDRESS(17,10, 1,TRUE,$A43)),0) -> 18 | K43: =IFERROR(INDIRECT(ADDRESS(17,11, 1,TRUE,$A43)),0) -> 0 | L43: =IFERROR(INDIRECT(ADDRESS(17,12, 1,TRUE,$A43)),0) -> 0 | M43: =IFERROR(INDIRECT(ADDRESS(17,13, 1,TRUE,$A43)),0) -> 0 | N43: =K43+L43 -> 0 | O43: =IFERROR(INDIRECT(ADDRESS(17,18, 1,TRUE,$A43)),0) -> 146 | P43: =IFERROR(INDIRECT(ADDRESS(17,21, 1,TRUE,$A43)),0) -> 146 | Q43: =IFERROR(INDIRECT(ADDRESS(17,19, 1,TRUE,$A43)),0) -> 96 | R43: =IFERROR(INDIRECT(ADDRESS(17,20, 1,TRUE,$A43)),0) -> 146 | S43: =IFERROR(INDIRECT(ADDRESS(17,14, 1,TRUE,$A43)),0) -> 1 | T43: =IFERROR(INDIRECT(ADDRESS(17,8, 1,TRUE,$A43)),0) -> 0.65753425 | U43: =IFERROR(INDIRECT(ADDRESS(17,15, 1,TRUE,$A43)),0) -> 1
A44: =HYPERLINK("[" & MID(CELL("filename"),SEARCH("[",CELL("filename"))+1, SEARCH("]",CELL("filename"))-SEARCH("[",CELL("filename"))-1) & "]" & INDIRECT(ADDRESS(ROW()-37,2,1,TRUE,"자산목록")) & "!A1",INDIRECT(ADDRESS(ROW()-37,2,1,TRUE,"자산목록"))) -> DB_HQ_Rocky | C44: =IFERROR(VLOOKUP($A44,자산목록!$B$1:$M$835,6,FALSE),"-") -> Rocky | E44: =IFERROR(INDIRECT(ADDRESS(17, 4, 1,TRUE,$A44)),0) -> 59 | F44: =E44-I44 -> 59 | G44: =IFERROR(INDIRECT(ADDRESS(17,5, 1,TRUE,$A44)),0) -> 41 | H44: =IFERROR(INDIRECT(ADDRESS(17,6, 1,TRUE,$A44)),0) -> 18 | I44: =IFERROR(INDIRECT(ADDRESS(17,7, 1,TRUE,$A44)),0) -> 0 | J44: =IFERROR(INDIRECT(ADDRESS(17,10, 1,TRUE,$A44)),0) -> 18 | K44: =IFERROR(INDIRECT(ADDRESS(17,11, 1,TRUE,$A44)),0) -> 0 | L44: =IFERROR(INDIRECT(ADDRESS(17,12, 1,TRUE,$A44)),0) -> 0 | M44: =IFERROR(INDIRECT(ADDRESS(17,13, 1,TRUE,$A44)),0) -> 0 | N44: =K44+L44 -> 0 | O44: =IFERROR(INDIRECT(ADDRESS(17,18, 1,TRUE,$A44)),0) -> 146 | P44: =IFERROR(INDIRECT(ADDRESS(17,21, 1,TRUE,$A44)),0) -> 146 | Q44: =IFERROR(INDIRECT(ADDRESS(17,19, 1,TRUE,$A44)),0) -> 96 | R44: =IFERROR(INDIRECT(ADDRESS(17,20, 1,TRUE,$A44)),0) -> 146 | S44: =IFERROR(INDIRECT(ADDRESS(17,14, 1,TRUE,$A44)),0) -> 1 | T44: =IFERROR(INDIRECT(ADDRESS(17,8, 1,TRUE,$A44)),0) -> 0.65753425 | U44: =IFERROR(INDIRECT(ADDRESS(17,15, 1,TRUE,$A44)),0) -> 1
A45: =HYPERLINK("[" & MID(CELL("filename"),SEARCH("[",CELL("filename"))+1, SEARCH("]",CELL("filename"))-SEARCH("[",CELL("filename"))-1) & "]" & INDIRECT(ADDRESS(ROW()-37,2,1,TRUE,"자산목록")) & "!A1",INDIRECT(ADDRESS(ROW()-37,2,1,TRUE,"자산목록"))) -> BDB_HQ_Rocky | C45: =IFERROR(VLOOKUP($A45,자산목록!$B$1:$M$835,6,FALSE),"-") -> Rocky | E45: =IFERROR(INDIRECT(ADDRESS(17, 4, 1,TRUE,$A45)),0) -> 59 | F45: =E45-I45 -> 59 | G45: =IFERROR(INDIRECT(ADDRESS(17,5, 1,TRUE,$A45)),0) -> 39 | H45: =IFERROR(INDIRECT(ADDRESS(17,6, 1,TRUE,$A45)),0) -> 20 | I45: =IFERROR(INDIRECT(ADDRESS(17,7, 1,TRUE,$A45)),0) -> 0 | J45: =IFERROR(INDIRECT(ADDRESS(17,10, 1,TRUE,$A45)),0) -> 20 | K45: =IFERROR(INDIRECT(ADDRESS(17,11, 1,TRUE,$A45)),0) -> 0 | L45: =IFERROR(INDIRECT(ADDRESS(17,12, 1,TRUE,$A45)),0) -> 0 | M45: =IFERROR(INDIRECT(ADDRESS(17,13, 1,TRUE,$A45)),0) -> 0 | N45: =K45+L45 -> 0 | O45: =IFERROR(INDIRECT(ADDRESS(17,18, 1,TRUE,$A45)),0) -> 146 | P45: =IFERROR(INDIRECT(ADDRESS(17,21, 1,TRUE,$A45)),0) -> 146 | Q45: =IFERROR(INDIRECT(ADDRESS(17,19, 1,TRUE,$A45)),0) -> 90 | R45: =IFERROR(INDIRECT(ADDRESS(17,20, 1,TRUE,$A45)),0) -> 146 | S45: =IFERROR(INDIRECT(ADDRESS(17,14, 1,TRUE,$A45)),0) -> 1 | T45: =IFERROR(INDIRECT(ADDRESS(17,8, 1,TRUE,$A45)),0) -> 0.61643836 | U45: =IFERROR(INDIRECT(ADDRESS(17,15, 1,TRUE,$A45)),0) -> 1
A46: =HYPERLINK("[" & MID(CELL("filename"),SEARCH("[",CELL("filename"))+1, SEARCH("]",CELL("filename"))-SEARCH("[",CELL("filename"))-1) & "]" & INDIRECT(ADDRESS(ROW()-37,2,1,TRUE,"자산목록")) & "!A1",INDIRECT(ADDRESS(ROW()-37,2,1,TRUE,"자산목록"))) -> BLOG_HQ_Rocky | C46: =IFERROR(VLOOKUP($A46,자산목록!$B$1:$M$835,6,FALSE),"-") -> Rocky | E46: =IFERROR(INDIRECT(ADDRESS(17, 4, 1,TRUE,$A46)),0) -> 59 | F46: =E46-I46 -> 59 | G46: =IFERROR(INDIRECT(ADDRESS(17,5, 1,TRUE,$A46)),0) -> 39 | H46: =IFERROR(INDIRECT(ADDRESS(17,6, 1,TRUE,$A46)),0) -> 20 | I46: =IFERROR(INDIRECT(ADDRESS(17,7, 1,TRUE,$A46)),0) -> 0 | J46: =IFERROR(INDIRECT(ADDRESS(17,10, 1,TRUE,$A46)),0) -> 20 | K46: =IFERROR(INDIRECT(ADDRESS(17,11, 1,TRUE,$A46)),0) -> 0 | L46: =IFERROR(INDIRECT(ADDRESS(17,12, 1,TRUE,$A46)),0) -> 0 | M46: =IFERROR(INDIRECT(ADDRESS(17,13, 1,TRUE,$A46)),0) -> 0 | N46: =K46+L46 -> 0 | O46: =IFERROR(INDIRECT(ADDRESS(17,18, 1,TRUE,$A46)),0) -> 146 | P46: =IFERROR(INDIRECT(ADDRESS(17,21, 1,TRUE,$A46)),0) -> 146 | Q46: =IFERROR(INDIRECT(ADDRESS(17,19, 1,TRUE,$A46)),0) -> 90 | R46: =IFERROR(INDIRECT(ADDRESS(17,20, 1,TRUE,$A46)),0) -> 146 | S46: =IFERROR(INDIRECT(ADDRESS(17,14, 1,TRUE,$A46)),0) -> 1 | T46: =IFERROR(INDIRECT(ADDRESS(17,8, 1,TRUE,$A46)),0) -> 0.61643836 | U46: =IFERROR(INDIRECT(ADDRESS(17,15, 1,TRUE,$A46)),0) -> 1
A47: =HYPERLINK("[" & MID(CELL("filename"),SEARCH("[",CELL("filename"))+1, SEARCH("]",CELL("filename"))-SEARCH("[",CELL("filename"))-1) & "]" & INDIRECT(ADDRESS(ROW()-37,2,1,TRUE,"자산목록")) & "!A1",INDIRECT(ADDRESS(ROW()-37,2,1,TRUE,"자산목록"))) -> PHP_BR_Rocky | C47: =IFERROR(VLOOKUP($A47,자산목록!$B$1:$M$835,6,FALSE),"-") -> Rocky | E47: =IFERROR(INDIRECT(ADDRESS(17, 4, 1,TRUE,$A47)),0) -> 59 | F47: =E47-I47 -> 59 | G47: =IFERROR(INDIRECT(ADDRESS(17,5, 1,TRUE,$A47)),0) -> 59 | H47: =IFERROR(INDIRECT(ADDRESS(17,6, 1,TRUE,$A47)),0) -> 0 | I47: =IFERROR(INDIRECT(ADDRESS(17,7, 1,TRUE,$A47)),0) -> 0 | J47: =IFERROR(INDIRECT(ADDRESS(17,10, 1,TRUE,$A47)),0) -> 0 | K47: =IFERROR(INDIRECT(ADDRESS(17,11, 1,TRUE,$A47)),0) -> 0 | L47: =IFERROR(INDIRECT(ADDRESS(17,12, 1,TRUE,$A47)),0) -> 0 | M47: =IFERROR(INDIRECT(ADDRESS(17,13, 1,TRUE,$A47)),0) -> 0 | N47: =K47+L47 -> 0 | O47: =IFERROR(INDIRECT(ADDRESS(17,18, 1,TRUE,$A47)),0) -> 146 | P47: =IFERROR(INDIRECT(ADDRESS(17,21, 1,TRUE,$A47)),0) -> 146 | Q47: =IFERROR(INDIRECT(ADDRESS(17,19, 1,TRUE,$A47)),0) -> 146 | R47: =IFERROR(INDIRECT(ADDRESS(17,20, 1,TRUE,$A47)),0) -> 146 | S47: =IFERROR(INDIRECT(ADDRESS(17,14, 1,TRUE,$A47)),0) -> N/A | T47: =IFERROR(INDIRECT(ADDRESS(17,8, 1,TRUE,$A47)),0) -> 1 | U47: =IFERROR(INDIRECT(ADDRESS(17,15, 1,TRUE,$A47)),0) -> 1
A48: =HYPERLINK("[" & MID(CELL("filename"),SEARCH("[",CELL("filename"))+1, SEARCH("]",CELL("filename"))-SEARCH("[",CELL("filename"))-1) & "]" & INDIRECT(ADDRESS(ROW()-37,2,1,TRUE,"자산목록")) & "!A1",INDIRECT(ADDRESS(ROW()-37,2,1,TRUE,"자산목록"))) -> LOG_BR_Rocky | C48: =IFERROR(VLOOKUP($A48,자산목록!$B$1:$M$835,6,FALSE),"-") -> Rocky | E48: =IFERROR(INDIRECT(ADDRESS(17, 4, 1,TRUE,$A48)),0) -> 59 | F48: =E48-I48 -> 59 | G48: =IFERROR(INDIRECT(ADDRESS(17,5, 1,TRUE,$A48)),0) -> 59 | H48: =IFERROR(INDIRECT(ADDRESS(17,6, 1,TRUE,$A48)),0) -> 0 | I48: =IFERROR(INDIRECT(ADDRESS(17,7, 1,TRUE,$A48)),0) -> 0 | J48: =IFERROR(INDIRECT(ADDRESS(17,10, 1,TRUE,$A48)),0) -> 0 | K48: =IFERROR(INDIRECT(ADDRESS(17,11, 1,TRUE,$A48)),0) -> 0 | L48: =IFERROR(INDIRECT(ADDRESS(17,12, 1,TRUE,$A48)),0) -> 0 | M48: =IFERROR(INDIRECT(ADDRESS(17,13, 1,TRUE,$A48)),0) -> 0 | N48: =K48+L48 -> 0 | O48: =IFERROR(INDIRECT(ADDRESS(17,18, 1,TRUE,$A48)),0) -> 146 | P48: =IFERROR(INDIRECT(ADDRESS(17,21, 1,TRUE,$A48)),0) -> 146 | Q48: =IFERROR(INDIRECT(ADDRESS(17,19, 1,TRUE,$A48)),0) -> 146 | R48: =IFERROR(INDIRECT(ADDRESS(17,20, 1,TRUE,$A48)),0) -> 146 | S48: =IFERROR(INDIRECT(ADDRESS(17,14, 1,TRUE,$A48)),0) -> N/A | T48: =IFERROR(INDIRECT(ADDRESS(17,8, 1,TRUE,$A48)),0) -> 1 | U48: =IFERROR(INDIRECT(ADDRESS(17,15, 1,TRUE,$A48)),0) -> 1
A49: =HYPERLINK("[" & MID(CELL("filename"),SEARCH("[",CELL("filename"))+1, SEARCH("]",CELL("filename"))-SEARCH("[",CELL("filename"))-1) & "]" & INDIRECT(ADDRESS(ROW()-37,2,1,TRUE,"자산목록")) & "!A1",INDIRECT(ADDRESS(ROW()-37,2,1,TRUE,"자산목록"))) -> DB_BR_Rocky | C49: =IFERROR(VLOOKUP($A49,자산목록!$B$1:$M$835,6,FALSE),"-") -> Rocky | E49: =IFERROR(INDIRECT(ADDRESS(17, 4, 1,TRUE,$A49)),0) -> 59 | F49: =E49-I49 -> 59 | G49: =IFERROR(INDIRECT(ADDRESS(17,5, 1,TRUE,$A49)),0) -> 59 | H49: =IFERROR(INDIRECT(ADDRESS(17,6, 1,TRUE,$A49)),0) -> 0 | I49: =IFERROR(INDIRECT(ADDRESS(17,7, 1,TRUE,$A49)),0) -> 0 | J49: =IFERROR(INDIRECT(ADDRESS(17,10, 1,TRUE,$A49)),0) -> 0 | K49: =IFERROR(INDIRECT(ADDRESS(17,11, 1,TRUE,$A49)),0) -> 0 | L49: =IFERROR(INDIRECT(ADDRESS(17,12, 1,TRUE,$A49)),0) -> 0 | M49: =IFERROR(INDIRECT(ADDRESS(17,13, 1,TRUE,$A49)),0) -> 0 | N49: =K49+L49 -> 0 | O49: =IFERROR(INDIRECT(ADDRESS(17,18, 1,TRUE,$A49)),0) -> 146 | P49: =IFERROR(INDIRECT(ADDRESS(17,21, 1,TRUE,$A49)),0) -> 146 | Q49: =IFERROR(INDIRECT(ADDRESS(17,19, 1,TRUE,$A49)),0) -> 146 | R49: =IFERROR(INDIRECT(ADDRESS(17,20, 1,TRUE,$A49)),0) -> 146 | S49: =IFERROR(INDIRECT(ADDRESS(17,14, 1,TRUE,$A49)),0) -> N/A | T49: =IFERROR(INDIRECT(ADDRESS(17,8, 1,TRUE,$A49)),0) -> 1 | U49: =IFERROR(INDIRECT(ADDRESS(17,15, 1,TRUE,$A49)),0) -> 1
A50: =HYPERLINK("[" & MID(CELL("filename"),SEARCH("[",CELL("filename"))+1, SEARCH("]",CELL("filename"))-SEARCH("[",CELL("filename"))-1) & "]" & INDIRECT(ADDRESS(ROW()-37,2,1,TRUE,"자산목록")) & "!A1",INDIRECT(ADDRESS(ROW()-37,2,1,TRUE,"자산목록"))) -> BDB_BR_Rocky | C50: =IFERROR(VLOOKUP($A50,자산목록!$B$1:$M$835,6,FALSE),"-") -> Rocky | E50: =IFERROR(INDIRECT(ADDRESS(17, 4, 1,TRUE,$A50)),0) -> 59 | F50: =E50-I50 -> 59 | G50: =IFERROR(INDIRECT(ADDRESS(17,5, 1,TRUE,$A50)),0) -> 59 | H50: =IFERROR(INDIRECT(ADDRESS(17,6, 1,TRUE,$A50)),0) -> 0 | I50: =IFERROR(INDIRECT(ADDRESS(17,7, 1,TRUE,$A50)),0) -> 0 | J50: =IFERROR(INDIRECT(ADDRESS(17,10, 1,TRUE,$A50)),0) -> 0 | K50: =IFERROR(INDIRECT(ADDRESS(17,11, 1,TRUE,$A50)),0) -> 0 | L50: =IFERROR(INDIRECT(ADDRESS(17,12, 1,TRUE,$A50)),0) -> 0 | M50: =IFERROR(INDIRECT(ADDRESS(17,13, 1,TRUE,$A50)),0) -> 0 | N50: =K50+L50 -> 0 | O50: =IFERROR(INDIRECT(ADDRESS(17,18, 1,TRUE,$A50)),0) -> 146 | P50: =IFERROR(INDIRECT(ADDRESS(17,21, 1,TRUE,$A50)),0) -> 146 | Q50: =IFERROR(INDIRECT(ADDRESS(17,19, 1,TRUE,$A50)),0) -> 146 | R50: =IFERROR(INDIRECT(ADDRESS(17,20, 1,TRUE,$A50)),0) -> 146 | S50: =IFERROR(INDIRECT(ADDRESS(17,14, 1,TRUE,$A50)),0) -> N/A | T50: =IFERROR(INDIRECT(ADDRESS(17,8, 1,TRUE,$A50)),0) -> 1 | U50: =IFERROR(INDIRECT(ADDRESS(17,15, 1,TRUE,$A50)),0) -> 1
A51: =HYPERLINK("[" & MID(CELL("filename"),SEARCH("[",CELL("filename"))+1, SEARCH("]",CELL("filename"))-SEARCH("[",CELL("filename"))-1) & "]" & INDIRECT(ADDRESS(ROW()-37,2,1,TRUE,"자산목록")) & "!A1",INDIRECT(ADDRESS(ROW()-37,2,1,TRUE,"자산목록"))) -> BLOG_BR_Rocky | C51: =IFERROR(VLOOKUP($A51,자산목록!$B$1:$M$835,6,FALSE),"-") -> Rocky | E51: =IFERROR(INDIRECT(ADDRESS(17, 4, 1,TRUE,$A51)),0) -> 59 | F51: =E51-I51 -> 59 | G51: =IFERROR(INDIRECT(ADDRESS(17,5, 1,TRUE,$A51)),0) -> 59 | H51: =IFERROR(INDIRECT(ADDRESS(17,6, 1,TRUE,$A51)),0) -> 0 | I51: =IFERROR(INDIRECT(ADDRESS(17,7, 1,TRUE,$A51)),0) -> 0 | J51: =IFERROR(INDIRECT(ADDRESS(17,10, 1,TRUE,$A51)),0) -> 0 | K51: =IFERROR(INDIRECT(ADDRESS(17,11, 1,TRUE,$A51)),0) -> 0 | L51: =IFERROR(INDIRECT(ADDRESS(17,12, 1,TRUE,$A51)),0) -> 0 | M51: =IFERROR(INDIRECT(ADDRESS(17,13, 1,TRUE,$A51)),0) -> 0 | N51: =K51+L51 -> 0 | O51: =IFERROR(INDIRECT(ADDRESS(17,18, 1,TRUE,$A51)),0) -> 146 | P51: =IFERROR(INDIRECT(ADDRESS(17,21, 1,TRUE,$A51)),0) -> 146 | Q51: =IFERROR(INDIRECT(ADDRESS(17,19, 1,TRUE,$A51)),0) -> 146 | R51: =IFERROR(INDIRECT(ADDRESS(17,20, 1,TRUE,$A51)),0) -> 146 | S51: =IFERROR(INDIRECT(ADDRESS(17,14, 1,TRUE,$A51)),0) -> N/A | T51: =IFERROR(INDIRECT(ADDRESS(17,8, 1,TRUE,$A51)),0) -> 1 | U51: =IFERROR(INDIRECT(ADDRESS(17,15, 1,TRUE,$A51)),0) -> 1
A52: 계 | E52: =SUM(E42:E51) -> 590 | F52: =SUM(F42:F51) -> 590 | G52: =SUM(G42:G51) -> 494 | H52: =SUM(H42:H51) -> 96 | I52: =SUM(I42:I51) -> 0 | J52: =SUM(J42:J51) -> 96 | K52: =SUM(K42:K51) -> 0 | L52: =SUM(L42:L51) -> 0 | ... R52: =SUM(R42:R51) -> 1460 | S52: =IFERROR($J52/($H52-(M52-I52)),"N/A") -> 1 | T52: =IF($I52=$E52, "N/A", (Q52/O52)) -> 0.81643836 | U52: =IF(OR($I52=$E52,$E52=$M52),"N/A", ($R52/$P52)) -> 1

Sheet 취약점 진단 항목별 통계
A1: ■ 자산목록
A3: =ChkList!A4 -> 분류 | C3: =ChkList!C4 -> 진단항목 | D3: =ChkList!D4 -> 중요도 | F3: 진단 통계 | K3: 중요도 점수 | M3: 진단결과 | N3: 진단결과 | O3: 진단결과 | P3: 진단결과 | Q3: 진단결과
F4: 전체 | G4: 양호 | H4: 즉시조치 | I4: 취약 | J4: N/A | K4: 전체 | L4: 평가 | M4: =HYPERLINK("[" & MID(CELL("filename"),SEARCH("[",CELL("filename"))+1, SEARCH("]",CELL("filename"))-SEARCH("[",CELL("filename"))-1) & "]" & INDIRECT(ADDRESS(COLUMN()-8,2,1,TRUE,"자산목록")) & "!A1",INDIRECT(ADDRESS(COLUMN()-8,2,1,TRUE,"자산목록"))) -> WEB-HQ-Ubuntu | N4: =HYPERLINK("[" & MID(CELL("filename"),SEARCH("[",CELL("filename"))+1, SEARCH("]",CELL("filename"))-SEARCH("[",CELL("filename"))-1) & "]" & INDIRECT(ADDRESS(COLUMN()-8,2,1,TRUE,"자산목록")) & "!A1",INDIRECT(ADDRESS(COLUMN()-8,2,1,TRUE,"자산목록"))) -> LOG_HQ_Rocky | O4: =HYPERLINK("[" & MID(CELL("filename"),SEARCH("[",CELL("filename"))+1, SEARCH("]",CELL("filename"))-SEARCH("[",CELL("filename"))-1) & "]" & INDIRECT(ADDRESS(COLUMN()-8,2,1,TRUE,"자산목록")) & "!A1",INDIRECT(ADDRESS(COLUMN()-8,2,1,TRUE,"자산목록"))) -> DB_HQ_Rocky | P4: =HYPERLINK("[" & MID(CELL("filename"),SEARCH("[",CELL("filename"))+1, SEARCH("]",CELL("filename"))-SEARCH("[",CELL("filename"))-1) & "]" & INDIRECT(ADDRESS(COLUMN()-8,2,1,TRUE,"자산목록")) & "!A1",INDIRECT(ADDRESS(COLUMN()-8,2,1,TRUE,"자산목록"))) -> BDB_HQ_Rocky | Q4: =HYPERLINK("[" & MID(CELL("filename"),SEARCH("[",CELL("filename"))+1, SEARCH("]",CELL("filename"))-SEARCH("[",CELL("filename"))-1) & "]" & INDIRECT(ADDRESS(COLUMN()-8,2,1,TRUE,"자산목록")) & "!A1",INDIRECT(ADDRESS(COLUMN()-8,2,1,TRUE,"자산목록"))) -> BLOG_HQ_Rocky
A5: =ChkList!A5 -> 계정 관리 | B5: =ChkList!B5 -> U-01 | C5: =ChkList!C5 -> root 계정 원격 접속 제한 | D5: =ChkList!D5 -> H | E5: =ChkList!E5 -> 3 | F5: =COUNTA($M5:INDIRECT(ADDRESS(ROW(),MATCH("",$4:$4,-1),1,1))) -> 5 | G5: =COUNTIF($M5:INDIRECT(ADDRESS(ROW(),MATCH("",$4:$4,-1),1,1)),"조치완료(Y)")+COUNTIF($M5:INDIRECT(ADDRESS(ROW(),MATCH("",$4:$4,-1),1,1)),"Y") -> 5 | H5: =COUNTIF($M5:INDIRECT(ADDRESS(ROW(),MATCH("",$4:$4,-1),1,1)),"Y(즉시조치)")+COUNTIF($M5:INDIRECT(ADDRESS(ROW(),MATCH("",$4:$4,-1),1,1)),"조치완료(즉시조치)") -> 0 | I5: =COUNTIF($M5:INDIRECT(ADDRESS(ROW(),MATCH("",$4:$4,-1),1,1)),"N") -> 0 | J5: =COUNTIF($M5:INDIRECT(ADDRESS(ROW(),MATCH("",$4:$4,-1),1,1)),"N/A")+COUNTIF($M5:INDIRECT(ADDRESS(ROW(),MATCH("",$4:$4,-1),1,1)),"조치완료(N/A)") -> 0 | K5: =VLOOKUP($D5,'parm(hidden)'!$B$8:$C$10,2,FALSE)*($F5-$J5) -> 15 | L5: =VLOOKUP($D5,'parm(hidden)'!$B$8:$C$10,2,FALSE)*($G5+$H5) -> 15 | M5: =HYPERLINK("[" & MID(CELL("filename"),SEARCH("[",CELL("filename"))+1, SEARCH("]",CELL("filename"))-SEARCH("[",CELL("filename"))-1) & "]" & ADDRESS(ROW()+16,8,1,TRUE,M$4),INDIRECT(ADDRESS(ROW()+16,8,1,TRUE,M$4))) -> Y | N5: =HYPERLINK("[" & MID(CELL("filename"),SEARCH("[",CELL("filename"))+1, SEARCH("]",CELL("filename"))-SEARCH("[",CELL("filename"))-1) & "]" & ADDRESS(ROW()+16,8,1,TRUE,N$4),INDIRECT(ADDRESS(ROW()+16,8,1,TRUE,N$4))) -> Y | O5: =HYPERLINK("[" & MID(CELL("filename"),SEARCH("[",CELL("filename"))+1, SEARCH("]",CELL("filename"))-SEARCH("[",CELL("filename"))-1) & "]" & ADDRESS(ROW()+16,8,1,TRUE,O$4),INDIRECT(ADDRESS(ROW()+16,8,1,TRUE,O$4))) -> Y | P5: =HYPERLINK("[" & MID(CELL("filename"),SEARCH("[",CELL("filename"))+1, SEARCH("]",CELL("filename"))-SEARCH("[",CELL("filename"))-1) & "]" & ADDRESS(ROW()+16,8,1,TRUE,P$4),INDIRECT(ADDRESS(ROW()+16,8,1,TRUE,P$4))) -> Y | Q5: =HYPERLINK("[" & MID(CELL("filename"),SEARCH("[",CELL("filename"))+1, SEARCH("]",CELL("filename"))-SEARCH("[",CELL("filename"))-1) & "]" & ADDRESS(ROW()+16,8,1,TRUE,Q$4),INDIRECT(ADDRESS(ROW()+16,8,1,TRUE,Q$4))) -> Y
A6: =ChkList!A6 -> 계정 관리 | B6: =ChkList!B6 -> U-02 | C6: =ChkList!C6 -> 비밀번호 관리정책 설정 | D6: =ChkList!D6 -> H | E6: =ChkList!E6 -> 3 | F6: =COUNTA($M6:INDIRECT(ADDRESS(ROW(),MATCH("",$4:$4,-1),1,1))) -> 5 | G6: =COUNTIF($M6:INDIRECT(ADDRESS(ROW(),MATCH("",$4:$4,-1),1,1)),"조치완료(Y)")+COUNTIF($M6:INDIRECT(ADDRESS(ROW(),MATCH("",$4:$4,-1),1,1)),"Y") -> 2 | H6: =COUNTIF($M6:INDIRECT(ADDRESS(ROW(),MATCH("",$4:$4,-1),1,1)),"Y(즉시조치)")+COUNTIF($M6:INDIRECT(ADDRESS(ROW(),MATCH("",$4:$4,-1),1,1)),"조치완료(즉시조치)") -> 0 | I6: =COUNTIF($M6:INDIRECT(ADDRESS(ROW(),MATCH("",$4:$4,-1),1,1)),"N") -> 3 | J6: =COUNTIF($M6:INDIRECT(ADDRESS(ROW(),MATCH("",$4:$4,-1),1,1)),"N/A")+COUNTIF($M6:INDIRECT(ADDRESS(ROW(),MATCH("",$4:$4,-1),1,1)),"조치완료(N/A)") -> 0 | K6: =VLOOKUP($D6,'parm(hidden)'!$B$8:$C$10,2,FALSE)*($F6-$J6) -> 15 | L6: =VLOOKUP($D6,'parm(hidden)'!$B$8:$C$10,2,FALSE)*($G6+$H6) -> 6 | M6: =HYPERLINK("[" & MID(CELL("filename"),SEARCH("[",CELL("filename"))+1, SEARCH("]",CELL("filename"))-SEARCH("[",CELL("filename"))-1) & "]" & ADDRESS(ROW()+16,8,1,TRUE,M$4),INDIRECT(ADDRESS(ROW()+16,8,1,TRUE,M$4))) -> N | N6: =HYPERLINK("[" & MID(CELL("filename"),SEARCH("[",CELL("filename"))+1, SEARCH("]",CELL("filename"))-SEARCH("[",CELL("filename"))-1) & "]" & ADDRESS(ROW()+16,8,1,TRUE,N$4),INDIRECT(ADDRESS(ROW()+16,8,1,TRUE,N$4))) -> Y | O6: =HYPERLINK("[" & MID(CELL("filename"),SEARCH("[",CELL("filename"))+1, SEARCH("]",CELL("filename"))-SEARCH("[",CELL("filename"))-1) & "]" & ADDRESS(ROW()+16,8,1,TRUE,O$4),INDIRECT(ADDRESS(ROW()+16,8,1,TRUE,O$4))) -> Y | P6: =HYPERLINK("[" & MID(CELL("filename"),SEARCH("[",CELL("filename"))+1, SEARCH("]",CELL("filename"))-SEARCH("[",CELL("filename"))-1) & "]" & ADDRESS(ROW()+16,8,1,TRUE,P$4),INDIRECT(ADDRESS(ROW()+16,8,1,TRUE,P$4))) -> N | Q6: =HYPERLINK("[" & MID(CELL("filename"),SEARCH("[",CELL("filename"))+1, SEARCH("]",CELL("filename"))-SEARCH("[",CELL("filename"))-1) & "]" & ADDRESS(ROW()+16,8,1,TRUE,Q$4),INDIRECT(ADDRESS(ROW()+16,8,1,TRUE,Q$4))) -> N
A7: =ChkList!A7 -> 계정 관리 | B7: =ChkList!B7 -> U-03 | C7: =ChkList!C7 -> 계정 잠금 임계값 설정 | D7: =ChkList!D7 -> H | E7: =ChkList!E7 -> 3 | F7: =COUNTA($M7:INDIRECT(ADDRESS(ROW(),MATCH("",$4:$4,-1),1,1))) -> 5 | G7: =COUNTIF($M7:INDIRECT(ADDRESS(ROW(),MATCH("",$4:$4,-1),1,1)),"조치완료(Y)")+COUNTIF($M7:INDIRECT(ADDRESS(ROW(),MATCH("",$4:$4,-1),1,1)),"Y") -> 2 | H7: =COUNTIF($M7:INDIRECT(ADDRESS(ROW(),MATCH("",$4:$4,-1),1,1)),"Y(즉시조치)")+COUNTIF($M7:INDIRECT(ADDRESS(ROW(),MATCH("",$4:$4,-1),1,1)),"조치완료(즉시조치)") -> 0 | I7: =COUNTIF($M7:INDIRECT(ADDRESS(ROW(),MATCH("",$4:$4,-1),1,1)),"N") -> 3 | J7: =COUNTIF($M7:INDIRECT(ADDRESS(ROW(),MATCH("",$4:$4,-1),1,1)),"N/A")+COUNTIF($M7:INDIRECT(ADDRESS(ROW(),MATCH("",$4:$4,-1),1,1)),"조치완료(N/A)") -> 0 | K7: =VLOOKUP($D7,'parm(hidden)'!$B$8:$C$10,2,FALSE)*($F7-$J7) -> 15 | L7: =VLOOKUP($D7,'parm(hidden)'!$B$8:$C$10,2,FALSE)*($G7+$H7) -> 6 | M7: =HYPERLINK("[" & MID(CELL("filename"),SEARCH("[",CELL("filename"))+1, SEARCH("]",CELL("filename"))-SEARCH("[",CELL("filename"))-1) & "]" & ADDRESS(ROW()+16,8,1,TRUE,M$4),INDIRECT(ADDRESS(ROW()+16,8,1,TRUE,M$4))) -> N | N7: =HYPERLINK("[" & MID(CELL("filename"),SEARCH("[",CELL("filename"))+1, SEARCH("]",CELL("filename"))-SEARCH("[",CELL("filename"))-1) & "]" & ADDRESS(ROW()+16,8,1,TRUE,N$4),INDIRECT(ADDRESS(ROW()+16,8,1,TRUE,N$4))) -> Y | O7: =HYPERLINK("[" & MID(CELL("filename"),SEARCH("[",CELL("filename"))+1, SEARCH("]",CELL("filename"))-SEARCH("[",CELL("filename"))-1) & "]" & ADDRESS(ROW()+16,8,1,TRUE,O$4),INDIRECT(ADDRESS(ROW()+16,8,1,TRUE,O$4))) -> Y | P7: =HYPERLINK("[" & MID(CELL("filename"),SEARCH("[",CELL("filename"))+1, SEARCH("]",CELL("filename"))-SEARCH("[",CELL("filename"))-1) & "]" & ADDRESS(ROW()+16,8,1,TRUE,P$4),INDIRECT(ADDRESS(ROW()+16,8,1,TRUE,P$4))) -> N | Q7: =HYPERLINK("[" & MID(CELL("filename"),SEARCH("[",CELL("filename"))+1, SEARCH("]",CELL("filename"))-SEARCH("[",CELL("filename"))-1) & "]" & ADDRESS(ROW()+16,8,1,TRUE,Q$4),INDIRECT(ADDRESS(ROW()+16,8,1,TRUE,Q$4))) -> N
A8: =ChkList!A8 -> 계정 관리 | B8: =ChkList!B8 -> U-04 | C8: =ChkList!C8 -> 비밀번호 파일 보호 | D8: =ChkList!D8 -> H | E8: =ChkList!E8 -> 3 | F8: =COUNTA($M8:INDIRECT(ADDRESS(ROW(),MATCH("",$4:$4,-1),1,1))) -> 5 | G8: =COUNTIF($M8:INDIRECT(ADDRESS(ROW(),MATCH("",$4:$4,-1),1,1)),"조치완료(Y)")+COUNTIF($M8:INDIRECT(ADDRESS(ROW(),MATCH("",$4:$4,-1),1,1)),"Y") -> 5 | H8: =COUNTIF($M8:INDIRECT(ADDRESS(ROW(),MATCH("",$4:$4,-1),1,1)),"Y(즉시조치)")+COUNTIF($M8:INDIRECT(ADDRESS(ROW(),MATCH("",$4:$4,-1),1,1)),"조치완료(즉시조치)") -> 0 | I8: =COUNTIF($M8:INDIRECT(ADDRESS(ROW(),MATCH("",$4:$4,-1),1,1)),"N") -> 0 | J8: =COUNTIF($M8:INDIRECT(ADDRESS(ROW(),MATCH("",$4:$4,-1),1,1)),"N/A")+COUNTIF($M8:INDIRECT(ADDRESS(ROW(),MATCH("",$4:$4,-1),1,1)),"조치완료(N/A)") -> 0 | K8: =VLOOKUP($D8,'parm(hidden)'!$B$8:$C$10,2,FALSE)*($F8-$J8) -> 15 | L8: =VLOOKUP($D8,'parm(hidden)'!$B$8:$C$10,2,FALSE)*($G8+$H8) -> 15 | M8: =HYPERLINK("[" & MID(CELL("filename"),SEARCH("[",CELL("filename"))+1, SEARCH("]",CELL("filename"))-SEARCH("[",CELL("filename"))-1) & "]" & ADDRESS(ROW()+16,8,1,TRUE,M$4),INDIRECT(ADDRESS(ROW()+16,8,1,TRUE,M$4))) -> Y | N8: =HYPERLINK("[" & MID(CELL("filename"),SEARCH("[",CELL("filename"))+1, SEARCH("]",CELL("filename"))-SEARCH("[",CELL("filename"))-1) & "]" & ADDRESS(ROW()+16,8,1,TRUE,N$4),INDIRECT(ADDRESS(ROW()+16,8,1,TRUE,N$4))) -> Y | O8: =HYPERLINK("[" & MID(CELL("filename"),SEARCH("[",CELL("filename"))+1, SEARCH("]",CELL("filename"))-SEARCH("[",CELL("filename"))-1) & "]" & ADDRESS(ROW()+16,8,1,TRUE,O$4),INDIRECT(ADDRESS(ROW()+16,8,1,TRUE,O$4))) -> Y | P8: =HYPERLINK("[" & MID(CELL("filename"),SEARCH("[",CELL("filename"))+1, SEARCH("]",CELL("filename"))-SEARCH("[",CELL("filename"))-1) & "]" & ADDRESS(ROW()+16,8,1,TRUE,P$4),INDIRECT(ADDRESS(ROW()+16,8,1,TRUE,P$4))) -> Y | Q8: =HYPERLINK("[" & MID(CELL("filename"),SEARCH("[",CELL("filename"))+1, SEARCH("]",CELL("filename"))-SEARCH("[",CELL("filename"))-1) & "]" & ADDRESS(ROW()+16,8,1,TRUE,Q$4),INDIRECT(ADDRESS(ROW()+16,8,1,TRUE,Q$4))) -> Y
A9: =ChkList!A9 -> 계정 관리 | B9: =ChkList!B9 -> U-05 | C9: =ChkList!C9 -> root 이외의 UID가 ‘0’ 금지 | D9: =ChkList!D9 -> H | E9: =ChkList!E9 -> 3 | F9: =COUNTA($M9:INDIRECT(ADDRESS(ROW(),MATCH("",$4:$4,-1),1,1))) -> 5 | G9: =COUNTIF($M9:INDIRECT(ADDRESS(ROW(),MATCH("",$4:$4,-1),1,1)),"조치완료(Y)")+COUNTIF($M9:INDIRECT(ADDRESS(ROW(),MATCH("",$4:$4,-1),1,1)),"Y") -> 5 | H9: =COUNTIF($M9:INDIRECT(ADDRESS(ROW(),MATCH("",$4:$4,-1),1,1)),"Y(즉시조치)")+COUNTIF($M9:INDIRECT(ADDRESS(ROW(),MATCH("",$4:$4,-1),1,1)),"조치완료(즉시조치)") -> 0 | I9: =COUNTIF($M9:INDIRECT(ADDRESS(ROW(),MATCH("",$4:$4,-1),1,1)),"N") -> 0 | J9: =COUNTIF($M9:INDIRECT(ADDRESS(ROW(),MATCH("",$4:$4,-1),1,1)),"N/A")+COUNTIF($M9:INDIRECT(ADDRESS(ROW(),MATCH("",$4:$4,-1),1,1)),"조치완료(N/A)") -> 0 | K9: =VLOOKUP($D9,'parm(hidden)'!$B$8:$C$10,2,FALSE)*($F9-$J9) -> 15 | L9: =VLOOKUP($D9,'parm(hidden)'!$B$8:$C$10,2,FALSE)*($G9+$H9) -> 15 | M9: =HYPERLINK("[" & MID(CELL("filename"),SEARCH("[",CELL("filename"))+1, SEARCH("]",CELL("filename"))-SEARCH("[",CELL("filename"))-1) & "]" & ADDRESS(ROW()+16,8,1,TRUE,M$4),INDIRECT(ADDRESS(ROW()+16,8,1,TRUE,M$4))) -> Y | N9: =HYPERLINK("[" & MID(CELL("filename"),SEARCH("[",CELL("filename"))+1, SEARCH("]",CELL("filename"))-SEARCH("[",CELL("filename"))-1) & "]" & ADDRESS(ROW()+16,8,1,TRUE,N$4),INDIRECT(ADDRESS(ROW()+16,8,1,TRUE,N$4))) -> Y | O9: =HYPERLINK("[" & MID(CELL("filename"),SEARCH("[",CELL("filename"))+1, SEARCH("]",CELL("filename"))-SEARCH("[",CELL("filename"))-1) & "]" & ADDRESS(ROW()+16,8,1,TRUE,O$4),INDIRECT(ADDRESS(ROW()+16,8,1,TRUE,O$4))) -> Y | P9: =HYPERLINK("[" & MID(CELL("filename"),SEARCH("[",CELL("filename"))+1, SEARCH("]",CELL("filename"))-SEARCH("[",CELL("filename"))-1) & "]" & ADDRESS(ROW()+16,8,1,TRUE,P$4),INDIRECT(ADDRESS(ROW()+16,8,1,TRUE,P$4))) -> Y | Q9: =HYPERLINK("[" & MID(CELL("filename"),SEARCH("[",CELL("filename"))+1, SEARCH("]",CELL("filename"))-SEARCH("[",CELL("filename"))-1) & "]" & ADDRESS(ROW()+16,8,1,TRUE,Q$4),INDIRECT(ADDRESS(ROW()+16,8,1,TRUE,Q$4))) -> Y
A10: =ChkList!A10 -> 계정 관리 | B10: =ChkList!B10 -> U-06 | C10: =ChkList!C10 -> 사용자 계정 su 기능 제한 | D10: =ChkList!D10 -> H | E10: =ChkList!E10 -> 3 | F10: =COUNTA($M10:INDIRECT(ADDRESS(ROW(),MATCH("",$4:$4,-1),1,1))) -> 5 | G10: =COUNTIF($M10:INDIRECT(ADDRESS(ROW(),MATCH("",$4:$4,-1),1,1)),"조치완료(Y)")+COUNTIF($M10:INDIRECT(ADDRESS(ROW(),MATCH("",$4:$4,-1),1,1)),"Y") -> 5 | H10: =COUNTIF($M10:INDIRECT(ADDRESS(ROW(),MATCH("",$4:$4,-1),1,1)),"Y(즉시조치)")+COUNTIF($M10:INDIRECT(ADDRESS(ROW(),MATCH("",$4:$4,-1),1,1)),"조치완료(즉시조치)") -> 0 | I10: =COUNTIF($M10:INDIRECT(ADDRESS(ROW(),MATCH("",$4:$4,-1),1,1)),"N") -> 0 | J10: =COUNTIF($M10:INDIRECT(ADDRESS(ROW(),MATCH("",$4:$4,-1),1,1)),"N/A")+COUNTIF($M10:INDIRECT(ADDRESS(ROW(),MATCH("",$4:$4,-1),1,1)),"조치완료(N/A)") -> 0 | K10: =VLOOKUP($D10,'parm(hidden)'!$B$8:$C$10,2,FALSE)*($F10-$J10) -> 15 | L10: =VLOOKUP($D10,'parm(hidden)'!$B$8:$C$10,2,FALSE)*($G10+$H10) -> 15 | M10: =HYPERLINK("[" & MID(CELL("filename"),SEARCH("[",CELL("filename"))+1, SEARCH("]",CELL("filename"))-SEARCH("[",CELL("filename"))-1) & "]" & ADDRESS(ROW()+16,8,1,TRUE,M$4),INDIRECT(ADDRESS(ROW()+16,8,1,TRUE,M$4))) -> Y | N10: =HYPERLINK("[" & MID(CELL("filename"),SEARCH("[",CELL("filename"))+1, SEARCH("]",CELL("filename"))-SEARCH("[",CELL("filename"))-1) & "]" & ADDRESS(ROW()+16,8,1,TRUE,N$4),INDIRECT(ADDRESS(ROW()+16,8,1,TRUE,N$4))) -> Y | O10: =HYPERLINK("[" & MID(CELL("filename"),SEARCH("[",CELL("filename"))+1, SEARCH("]",CELL("filename"))-SEARCH("[",CELL("filename"))-1) & "]" & ADDRESS(ROW()+16,8,1,TRUE,O$4),INDIRECT(ADDRESS(ROW()+16,8,1,TRUE,O$4))) -> Y | P10: =HYPERLINK("[" & MID(CELL("filename"),SEARCH("[",CELL("filename"))+1, SEARCH("]",CELL("filename"))-SEARCH("[",CELL("filename"))-1) & "]" & ADDRESS(ROW()+16,8,1,TRUE,P$4),INDIRECT(ADDRESS(ROW()+16,8,1,TRUE,P$4))) -> Y | Q10: =HYPERLINK("[" & MID(CELL("filename"),SEARCH("[",CELL("filename"))+1, SEARCH("]",CELL("filename"))-SEARCH("[",CELL("filename"))-1) & "]" & ADDRESS(ROW()+16,8,1,TRUE,Q$4),INDIRECT(ADDRESS(ROW()+16,8,1,TRUE,Q$4))) -> Y
A11: =ChkList!A11 -> 계정 관리 | B11: =ChkList!B11 -> U-07 | C11: =ChkList!C11 -> 불필요한 계정 제거 | D11: =ChkList!D11 -> L | E11: =ChkList!E11 -> 1 | F11: =COUNTA($M11:INDIRECT(ADDRESS(ROW(),MATCH("",$4:$4,-1),1,1))) -> 5 | G11: =COUNTIF($M11:INDIRECT(ADDRESS(ROW(),MATCH("",$4:$4,-1),1,1)),"조치완료(Y)")+COUNTIF($M11:INDIRECT(ADDRESS(ROW(),MATCH("",$4:$4,-1),1,1)),"Y") -> 5 | H11: =COUNTIF($M11:INDIRECT(ADDRESS(ROW(),MATCH("",$4:$4,-1),1,1)),"Y(즉시조치)")+COUNTIF($M11:INDIRECT(ADDRESS(ROW(),MATCH("",$4:$4,-1),1,1)),"조치완료(즉시조치)") -> 0 | I11: =COUNTIF($M11:INDIRECT(ADDRESS(ROW(),MATCH("",$4:$4,-1),1,1)),"N") -> 0 | J11: =COUNTIF($M11:INDIRECT(ADDRESS(ROW(),MATCH("",$4:$4,-1),1,1)),"N/A")+COUNTIF($M11:INDIRECT(ADDRESS(ROW(),MATCH("",$4:$4,-1),1,1)),"조치완료(N/A)") -> 0 | K11: =VLOOKUP($D11,'parm(hidden)'!$B$8:$C$10,2,FALSE)*($F11-$J11) -> 5 | L11: =VLOOKUP($D11,'parm(hidden)'!$B$8:$C$10,2,FALSE)*($G11+$H11) -> 5 | M11: =HYPERLINK("[" & MID(CELL("filename"),SEARCH("[",CELL("filename"))+1, SEARCH("]",CELL("filename"))-SEARCH("[",CELL("filename"))-1) & "]" & ADDRESS(ROW()+16,8,1,TRUE,M$4),INDIRECT(ADDRESS(ROW()+16,8,1,TRUE,M$4))) -> Y | N11: =HYPERLINK("[" & MID(CELL("filename"),SEARCH("[",CELL("filename"))+1, SEARCH("]",CELL("filename"))-SEARCH("[",CELL("filename"))-1) & "]" & ADDRESS(ROW()+16,8,1,TRUE,N$4),INDIRECT(ADDRESS(ROW()+16,8,1,TRUE,N$4))) -> Y | O11: =HYPERLINK("[" & MID(CELL("filename"),SEARCH("[",CELL("filename"))+1, SEARCH("]",CELL("filename"))-SEARCH("[",CELL("filename"))-1) & "]" & ADDRESS(ROW()+16,8,1,TRUE,O$4),INDIRECT(ADDRESS(ROW()+16,8,1,TRUE,O$4))) -> Y | P11: =HYPERLINK("[" & MID(CELL("filename"),SEARCH("[",CELL("filename"))+1, SEARCH("]",CELL("filename"))-SEARCH("[",CELL("filename"))-1) & "]" & ADDRESS(ROW()+16,8,1,TRUE,P$4),INDIRECT(ADDRESS(ROW()+16,8,1,TRUE,P$4))) -> Y | Q11: =HYPERLINK("[" & MID(CELL("filename"),SEARCH("[",CELL("filename"))+1, SEARCH("]",CELL("filename"))-SEARCH("[",CELL("filename"))-1) & "]" & ADDRESS(ROW()+16,8,1,TRUE,Q$4),INDIRECT(ADDRESS(ROW()+16,8,1,TRUE,Q$4))) -> Y
A12: =ChkList!A12 -> 계정 관리 | B12: =ChkList!B12 -> U-08 | C12: =ChkList!C12 -> 관리자 그룹에 최소한의 계정 포함 | D12: =ChkList!D12 -> M | E12: =ChkList!E12 -> 2 | F12: =COUNTA($M12:INDIRECT(ADDRESS(ROW(),MATCH("",$4:$4,-1),1,1))) -> 5 | G12: =COUNTIF($M12:INDIRECT(ADDRESS(ROW(),MATCH("",$4:$4,-1),1,1)),"조치완료(Y)")+COUNTIF($M12:INDIRECT(ADDRESS(ROW(),MATCH("",$4:$4,-1),1,1)),"Y") -> 5 | H12: =COUNTIF($M12:INDIRECT(ADDRESS(ROW(),MATCH("",$4:$4,-1),1,1)),"Y(즉시조치)")+COUNTIF($M12:INDIRECT(ADDRESS(ROW(),MATCH("",$4:$4,-1),1,1)),"조치완료(즉시조치)") -> 0 | I12: =COUNTIF($M12:INDIRECT(ADDRESS(ROW(),MATCH("",$4:$4,-1),1,1)),"N") -> 0 | J12: =COUNTIF($M12:INDIRECT(ADDRESS(ROW(),MATCH("",$4:$4,-1),1,1)),"N/A")+COUNTIF($M12:INDIRECT(ADDRESS(ROW(),MATCH("",$4:$4,-1),1,1)),"조치완료(N/A)") -> 0 | K12: =VLOOKUP($D12,'parm(hidden)'!$B$8:$C$10,2,FALSE)*($F12-$J12) -> 10 | L12: =VLOOKUP($D12,'parm(hidden)'!$B$8:$C$10,2,FALSE)*($G12+$H12) -> 10 | M12: =HYPERLINK("[" & MID(CELL("filename"),SEARCH("[",CELL("filename"))+1, SEARCH("]",CELL("filename"))-SEARCH("[",CELL("filename"))-1) & "]" & ADDRESS(ROW()+16,8,1,TRUE,M$4),INDIRECT(ADDRESS(ROW()+16,8,1,TRUE,M$4))) -> Y | N12: =HYPERLINK("[" & MID(CELL("filename"),SEARCH("[",CELL("filename"))+1, SEARCH("]",CELL("filename"))-SEARCH("[",CELL("filename"))-1) & "]" & ADDRESS(ROW()+16,8,1,TRUE,N$4),INDIRECT(ADDRESS(ROW()+16,8,1,TRUE,N$4))) -> Y | O12: =HYPERLINK("[" & MID(CELL("filename"),SEARCH("[",CELL("filename"))+1, SEARCH("]",CELL("filename"))-SEARCH("[",CELL("filename"))-1) & "]" & ADDRESS(ROW()+16,8,1,TRUE,O$4),INDIRECT(ADDRESS(ROW()+16,8,1,TRUE,O$4))) -> Y | P12: =HYPERLINK("[" & MID(CELL("filename"),SEARCH("[",CELL("filename"))+1, SEARCH("]",CELL("filename"))-SEARCH("[",CELL("filename"))-1) & "]" & ADDRESS(ROW()+16,8,1,TRUE,P$4),INDIRECT(ADDRESS(ROW()+16,8,1,TRUE,P$4))) -> Y | Q12: =HYPERLINK("[" & MID(CELL("filename"),SEARCH("[",CELL("filename"))+1, SEARCH("]",CELL("filename"))-SEARCH("[",CELL("filename"))-1) & "]" & ADDRESS(ROW()+16,8,1,TRUE,Q$4),INDIRECT(ADDRESS(ROW()+16,8,1,TRUE,Q$4))) -> Y
A13: =ChkList!A13 -> 계정 관리 | B13: =ChkList!B13 -> U-09 | C13: =ChkList!C13 -> 계정이 존재하지 않는 GID 금지 | D13: =ChkList!D13 -> L | E13: =ChkList!E13 -> 1 | F13: =COUNTA($M13:INDIRECT(ADDRESS(ROW(),MATCH("",$4:$4,-1),1,1))) -> 5 | G13: =COUNTIF($M13:INDIRECT(ADDRESS(ROW(),MATCH("",$4:$4,-1),1,1)),"조치완료(Y)")+COUNTIF($M13:INDIRECT(ADDRESS(ROW(),MATCH("",$4:$4,-1),1,1)),"Y") -> 5 | H13: =COUNTIF($M13:INDIRECT(ADDRESS(ROW(),MATCH("",$4:$4,-1),1,1)),"Y(즉시조치)")+COUNTIF($M13:INDIRECT(ADDRESS(ROW(),MATCH("",$4:$4,-1),1,1)),"조치완료(즉시조치)") -> 0 | I13: =COUNTIF($M13:INDIRECT(ADDRESS(ROW(),MATCH("",$4:$4,-1),1,1)),"N") -> 0 | J13: =COUNTIF($M13:INDIRECT(ADDRESS(ROW(),MATCH("",$4:$4,-1),1,1)),"N/A")+COUNTIF($M13:INDIRECT(ADDRESS(ROW(),MATCH("",$4:$4,-1),1,1)),"조치완료(N/A)") -> 0 | K13: =VLOOKUP($D13,'parm(hidden)'!$B$8:$C$10,2,FALSE)*($F13-$J13) -> 5 | L13: =VLOOKUP($D13,'parm(hidden)'!$B$8:$C$10,2,FALSE)*($G13+$H13) -> 5 | M13: =HYPERLINK("[" & MID(CELL("filename"),SEARCH("[",CELL("filename"))+1, SEARCH("]",CELL("filename"))-SEARCH("[",CELL("filename"))-1) & "]" & ADDRESS(ROW()+16,8,1,TRUE,M$4),INDIRECT(ADDRESS(ROW()+16,8,1,TRUE,M$4))) -> Y | N13: =HYPERLINK("[" & MID(CELL("filename"),SEARCH("[",CELL("filename"))+1, SEARCH("]",CELL("filename"))-SEARCH("[",CELL("filename"))-1) & "]" & ADDRESS(ROW()+16,8,1,TRUE,N$4),INDIRECT(ADDRESS(ROW()+16,8,1,TRUE,N$4))) -> Y | O13: =HYPERLINK("[" & MID(CELL("filename"),SEARCH("[",CELL("filename"))+1, SEARCH("]",CELL("filename"))-SEARCH("[",CELL("filename"))-1) & "]" & ADDRESS(ROW()+16,8,1,TRUE,O$4),INDIRECT(ADDRESS(ROW()+16,8,1,TRUE,O$4))) -> Y | P13: =HYPERLINK("[" & MID(CELL("filename"),SEARCH("[",CELL("filename"))+1, SEARCH("]",CELL("filename"))-SEARCH("[",CELL("filename"))-1) & "]" & ADDRESS(ROW()+16,8,1,TRUE,P$4),INDIRECT(ADDRESS(ROW()+16,8,1,TRUE,P$4))) -> Y | Q13: =HYPERLINK("[" & MID(CELL("filename"),SEARCH("[",CELL("filename"))+1, SEARCH("]",CELL("filename"))-SEARCH("[",CELL("filename"))-1) & "]" & ADDRESS(ROW()+16,8,1,TRUE,Q$4),INDIRECT(ADDRESS(ROW()+16,8,1,TRUE,Q$4))) -> Y
