Workbook
Name _10월_변동내역_메모_확인: #REF!
Name _Order1: 255
Name _Order2: 255
Name asd: #REF!
Name HTML_CodePage: 949
Name HTML_Control: {"'손익현황'!$A$1:$J$29"}
Name HTML_Description: ""
Name HTML_Email: ""
Name HTML_Header: "손익현황"
Name HTML_LastUpdate: "99-04-13"
Name HTML_LineAfter: FALSE
Name HTML_LineBefore: FALSE
Name HTML_Name: "윤찬영"
Name HTML_OBDlg2: TRUE
Name HTML_OBDlg4: TRUE
Name HTML_OS: 0
Name HTML_PathFile: "C:\d7100\MyHTML.htm"
Name HTML_Title: "결산요약보고3월"
Name MPLS: #REF!
Name MPLS2: #REF!
Name MPLSLine: #REF!
Name N_A: #REF!
Name O: #REF!
Name P: #REF!
Name X: #REF!
Name 건물: {"'손익현황'!$A$1:$J$29"}
Name 건물임.: {"'손익현황'!$A$1:$J$29"}
Name 공: {"'손익현황'!$A$1:$J$29"}
Name 공구: {"'손익현황'!$A$1:$J$29"}
Name 공구기구: {"'손익현황'!$A$1:$J$29"}
Name 구: {"'손익현황'!$A$1:$J$29"}
Name 구축물: {"'손익현황'!$A$1:$J$29"}
Name 구축물임: {"'손익현황'!$A$1:$J$29"}
Name 기계장치: {"'손익현황'!$A$1:$J$29"}
Name 기술2팀: #REF!
Name 기준반영: #REF!
Name 동의여부: #REF!
Name ㅅㅅㅅ: {"'손익현황'!$A$1:$J$29"}
Name 적정성: #REF!
Name 차량운반구: {"'손익현황'!$A$1:$J$29"}
Name 훈: 255

Sheet 표지
F11: 46219

Sheet 자산목록
A1: ■ 자산목록
A3: No. | B3: 호스트명 | C3: IP | D3: 제조업체 | E3: 구분 | F3: 모델명 | G3: OS/SW | H3: 버전 | I3: 자산명/용도 | J3: 설치위치 | K3: 부서 | L3: 담당자 | M3: 비고 | N3: 자산 평가
N4: 기밀성 | O4: 무결성 | P4: 가용성 | Q4: 등급 | R4: 점수(Hidden)
A5: 1 | B5: DHCP_HQ_Win | C5: 10.10.40.17 | D5: Microsoft | E5: - | F5: - | G5: - | H5: 2016 | I5: 본사 DHCP 서버 | J5: 내부망 | K5: 본사 | L5: 이재원 | N5: 3 | O5: 3 | P5: 3 | Q5: =IF(R5>=7,"H",IF(R5>=5,"M","L")) -> H | R5: =SUM(N5:P5) -> 9
A6: 2 | B6: DNS_HQ_Win | C6: 10.10.40.2 | D6: Microsoft | E6: - | F6: - | G6: - | H6: 2016 | I6: 본사 DNS 서버 | J6: DMZ | K6: 본사 | L6: 박성민 | N6: 3 | O6: 3 | P6: 3 | Q6: =IF(R6>=7,"H",IF(R6>=5,"M","L")) -> H | R6: =SUM(N6:P6) -> 9
A7: 3 | B7: DHCP_BR_Win | C7: 10.200.40.17 | D7: Microsoft | E7: - | F7: - | G7: - | H7: 2016 | I7: 지사 DHCP서버 | J7: 내부망 | K7: 지사 | L7: 김도현 | N7: 3 | O7: 3 | P7: 3 | Q7: =IF(R7>=7,"H",IF(R7>=5,"M","L")) -> H | R7: =SUM(N7:P7) -> 9
A8: 4 | B8: DNS_BR_Win | C8: 10.200.40.2 | D8: Microsoft | E8: - | F8: - | G8: - | H8: 2016 | I8: 지사 DNS서버 | J8: DMZ | K8: 지사 | L8: 정하늘 | N8: 3 | O8: 3 | P8: 3 | Q8: =IF(R8>=7,"H",IF(R8>=5,"M","L")) -> H | R8: =SUM(N8:P8) -> 9
T21: ㄴ

Sheet parm(hidden)
B2: 1. 분류 Code
B3: Code
B4: NW
B6: 2. 중요도, 자산등급, 위협도 점수
B7: 중요도 | C7: 점수
B8: H | C8: 3
B9: M | C9: 2
B10: L | C10: 1
B12: 3. 점검결과 점수
B13: 점검 결과 | C13: 점수
C14: 취약점 진단 | D14: 위험평가
B15: Y | C15: 1 | D15: 0
B16: N | C16: 0 | D16: 3 | F16: P | G16: 0.5 | H16: 0.5
B17: N/A | C17: 0 | D17: 0
B18: R/A | C18: 0 | D18: 0
B19: Y(즉시조치) | C19: 1 | D19: 0
B21: 4. DoA
B22: DoA
B23: 21
B25: 5. 자산등급 점수 범위 | F25: 8_2. 위험평가 방법론
B26: 위험 등급 | C26: 점수 범위
C27: 최저 | D27: 최고
B28: H | C28: 7 | D28: 9
B29: M | C29: 5 | D29: 6
B30: L | C30: 3 | D30: 4
B32: 6. 위협도 점수 범위
B33: 위험 등급 | C33: 점수 범위
C34: 최저 | D34: 최고
B35: H | C35: 5 | D35: 6
B36: M | C36: 4 | D36: 4
B37: L | C37: 2 | D37: 3
B39: 7. 위험도 점수 범위
B40: 위험 등급 | C40: 점수 범위
C41: 최저 | D41: 최고
B42: H | C42: =$B$23 -> 21 | D42: 30
B43: M | C43: 11 | D43: =$C$42-1 -> 20
B44: L | C44: 1 | D44: =$C$43-1 -> 10
B46: 8. 위험도 평가표
B47: 8_1. 위험도 평가표
B48: V' | C48: 보호대책 | D48: Y=0(보호대책 있음) | M48: N=1(보호대책 없음)
...

Sheet ChkList
A1: ■ Check List
A3: 취약점 진단항목 | F3: 개선방안 및 보호대책
A4: 분류 | B4: 항목코드 | C4: 진단항목 | D4: 중요도 | E4: 위험도 | F4: windows
A5: 계정 관리 | B5: W-01 | C5: Administrator 계정 이름 변경 등 보안성 강화 | D5: H | E5: 3 | F5: Administrator 기본 계정 이름 변경 및 보안성이 있는 비밀번호 설정
A6: 계정 관리 | B6: W-02 | C6: Guest 계정 비활성화 | D6: H | E6: 3 | F6: Guest 계정 비활성화
A7: 계정 관리 | B7: W-03 | C7: 불필요한 계정 제거 | D7: H | E7: 3 | F7: 현재 계정 현황 확인 후 불필요한 계정 삭제
A8: 계정 관리 | B8: W-04 | C8: 계정 잠금 임계값 설정 | D8: H | E8: 3 | F8: 계정 잠금 임계값을 5 이하의 값으로 설정
A9: 계정 관리 | B9: W-05 | C9: 해독 가능한 암호화를 사용하여 암호 저장 해제 | D9: H | E9: 3 | F9: “해독 가능한 암호화를 사용하여 암호 저장”을 “사용 안 함”으로 설정
A10: 계정 관리 | B10: W-06 | C10: 관리자 그룹에 최소한의 사용자 포함 | D10: H | E10: 3 | F10: Administrators 그룹에 포함된 불필요한 계정 제거
A11: 계정 관리 | B11: W-07 | C11: Everyone 사용 권한을 익명 사용자에 적용 | D11: M | E11: 2 | F11: “Everyone 사용 권한을 익명 사용자에게 적용”정책을 “사용 안 함”으로 설정
A12: 계정 관리 | B12: W-08 | C12: 계정 잠금 기간 설정 | D12: M | E12: 2 | F12: “계정 잠금 기간” 및 “잠금 기간 원래대로 설정 기간” 60분 이상으로 설정
A13: 계정 관리 | B13: W-09 | C13: 비밀번호 관리 정책 설정 | D13: H | E13: 3 | F13: 비밀번호 복잡성, 최소 비밀번호 길이, 최대/최소 사용 기간을 기준에 맞게 설정
A14: 계정 관리 | B14: W-10 | C14: 마지막 사용자 이름 표시 안 함 | D14: M | E14: 2 | F14: ※ Windows NT: 마지막으로 로그온한 사용자 이름 표시 안 함 설정 ※ Windows 2000: 로그온 스크린에 마지막 사용자 이름 표시 안 함 사용 설정 ※ Windows 2003, 2008, 2012, 2016, 2019, 2022: 대화형 로그온: 마지막 사용자 이름 표시 안 함 사용 설정
A15: 계정 관리 | B15: W-11 | C15: 로컬 로그온 허용 | D15: M | E15: 2 | F15: Administrators, IUSR_ 외 다른 계정 및 그룹의 로컬 로그온 제한
A16: 계정 관리 | B16: W-12 | C16: 익명 SID/이름 변환 허용 해제 | D16: M | E16: 2 | F16: “네트워크 액세스: 익명 SID/이름 변환 허용” 정책 “사용 안 함” 설정
... A68: 보안 관리 | B68: W-64 | C68: 윈도우 방화벽 설정 | D68: M | E68: 2 | F68: Windows 방화벽 “사용”으로 설정

Sheet 취약점 진단 통계
A1: ■ 영역별/장비별 보안수준 통계
A3: 1) 영역별 보안수준
A4: 분류 | E4: 진단 결과 | J4: 중요도점수
E5: 전체항목 | F5: 진단항목 | G5: 양호 | H5: 취약 | I5: 해당없음 | J5: 전체점수 | K5: 평가점수 | L5: 보안수준
A6: 계정 관리 | E6: =SUMIF('취약점 진단 항목별 통계'!$A:$A,$A6&"*",'취약점 진단 항목별 통계'!$F:$F) -> 56 | F6: =E6-I6 -> 56 | G6: =SUMIF('취약점 진단 항목별 통계'!$A:$A,$A6&"*",'취약점 진단 항목별 통계'!$G:$G)+SUMIF('취약점 진단 항목별 통계'!$A:$A,$A6&"*",'취약점 진단 항목별 통계'!$H:$H) -> 29 | H6: =SUMIF('취약점 진단 항목별 통계'!$A:$A,$A6&"*",'취약점 진단 항목별 통계'!$I:$I) -> 27 | I6: =SUMIF('취약점 진단 항목별 통계'!$A:$A,$A6&"*",'취약점 진단 항목별 통계'!$J:$J) -> 0 | J6: =SUMIF('취약점 진단 항목별 통계'!$A:$A,$A6&"*",'취약점 진단 항목별 통계'!$K:$K) -> 140 | K6: =SUMIF('취약점 진단 항목별 통계'!$A:$A,$A6&"*",'취약점 진단 항목별 통계'!$L:$L) -> 77 | L6: =IF($I6=$E6,"N/A",(K6/J6)) -> 0.55
A7: 서비스 관리 | E7: =SUMIF('취약점 진단 항목별 통계'!$A:$A,$A7&"*",'취약점 진단 항목별 통계'!$F:$F) -> 92 | F7: =E7-I7 -> 91 | G7: =SUMIF('취약점 진단 항목별 통계'!$A:$A,$A7&"*",'취약점 진단 항목별 통계'!$G:$G)+SUMIF('취약점 진단 항목별 통계'!$A:$A,$A7&"*",'취약점 진단 항목별 통계'!$H:$H) -> 20 | H7: =SUMIF('취약점 진단 항목별 통계'!$A:$A,$A7&"*",'취약점 진단 항목별 통계'!$I:$I) -> 71 | I7: =SUMIF('취약점 진단 항목별 통계'!$A:$A,$A7&"*",'취약점 진단 항목별 통계'!$J:$J) -> 1 | J7: =SUMIF('취약점 진단 항목별 통계'!$A:$A,$A7&"*",'취약점 진단 항목별 통계'!$K:$K) -> 258 | K7: =SUMIF('취약점 진단 항목별 통계'!$A:$A,$A7&"*",'취약점 진단 항목별 통계'!$L:$L) -> 56 | L7: =IF($I7=$E7,"N/A",(K7/J7)) -> 0.21705426
A8: 패치 관리 | E8: =SUMIF('취약점 진단 항목별 통계'!$A:$A,$A8&"*",'취약점 진단 항목별 통계'!$F:$F) -> 8 | F8: =E8-I8 -> 8 | G8: =SUMIF('취약점 진단 항목별 통계'!$A:$A,$A8&"*",'취약점 진단 항목별 통계'!$G:$G)+SUMIF('취약점 진단 항목별 통계'!$A:$A,$A8&"*",'취약점 진단 항목별 통계'!$H:$H) -> 2 | H8: =SUMIF('취약점 진단 항목별 통계'!$A:$A,$A8&"*",'취약점 진단 항목별 통계'!$I:$I) -> 6 | I8: =SUMIF('취약점 진단 항목별 통계'!$A:$A,$A8&"*",'취약점 진단 항목별 통계'!$J:$J) -> 0 | J8: =SUMIF('취약점 진단 항목별 통계'!$A:$A,$A8&"*",'취약점 진단 항목별 통계'!$K:$K) -> 24 | K8: =SUMIF('취약점 진단 항목별 통계'!$A:$A,$A8&"*",'취약점 진단 항목별 통계'!$L:$L) -> 6 | L8: =IF($I8=$E8,"N/A",(K8/J8)) -> 0.25
A9: 로그 관리 | E9: =SUMIF('취약점 진단 항목별 통계'!$A:$A,$A9&"*",'취약점 진단 항목별 통계'!$F:$F) -> 16 | F9: =E9-I9 -> 16 | G9: =SUMIF('취약점 진단 항목별 통계'!$A:$A,$A9&"*",'취약점 진단 항목별 통계'!$G:$G)+SUMIF('취약점 진단 항목별 통계'!$A:$A,$A9&"*",'취약점 진단 항목별 통계'!$H:$H) -> 6 | H9: =SUMIF('취약점 진단 항목별 통계'!$A:$A,$A9&"*",'취약점 진단 항목별 통계'!$I:$I) -> 10 | I9: =SUMIF('취약점 진단 항목별 통계'!$A:$A,$A9&"*",'취약점 진단 항목별 통계'!$J:$J) -> 0 | J9: =SUMIF('취약점 진단 항목별 통계'!$A:$A,$A9&"*",'취약점 진단 항목별 통계'!$K:$K) -> 36 | K9: =SUMIF('취약점 진단 항목별 통계'!$A:$A,$A9&"*",'취약점 진단 항목별 통계'!$L:$L) -> 12 | L9: =IF($I9=$E9,"N/A",(K9/J9)) -> 0.33333333
A10: 보안 관리 | E10: =SUMIF('취약점 진단 항목별 통계'!$A:$A,$A10&"*",'취약점 진단 항목별 통계'!$F:$F) -> 84 | F10: =E10-I10 -> 84 | G10: =SUMIF('취약점 진단 항목별 통계'!$A:$A,$A10&"*",'취약점 진단 항목별 통계'!$G:$G)+SUMIF('취약점 진단 항목별 통계'!$A:$A,$A10&"*",'취약점 진단 항목별 통계'!$H:$H) -> 24 | H10: =SUMIF('취약점 진단 항목별 통계'!$A:$A,$A10&"*",'취약점 진단 항목별 통계'!$I:$I) -> 40 | I10: =SUMIF('취약점 진단 항목별 통계'!$A:$A,$A10&"*",'취약점 진단 항목별 통계'!$J:$J) -> 0 | J10: =SUMIF('취약점 진단 항목별 통계'!$A:$A,$A10&"*",'취약점 진단 항목별 통계'!$K:$K) -> 204 | K10: =SUMIF('취약점 진단 항목별 통계'!$A:$A,$A10&"*",'취약점 진단 항목별 통계'!$L:$L) -> 51 | L10: =IF($I10=$E10,"N/A",(K10/J10)) -> 0.25
A11: 계 | E11: =SUM(E6:E10) -> 256 | F11: =SUM(F6:F10) -> 255 | G11: =SUM(G6:G10) -> 81 | H11: =SUM(H6:H10) -> 154 | I11: =SUM(I6:I10) -> 1 | J11: =SUM(J6:J10) -> 662 | K11: =SUM(K6:K10) -> 202 | L11: =IFERROR(K11/J11,0) -> 0.30513595
A39: 2) 장비별 보안수준
A40: 장비 구분 | E40: 진단 결과 | J40: 중요도점수
E41: 전체항목 | F41: 진단항목 | G41: 양호 | H41: 취약 | I41: 해당없음 | J41: 전체점수 | K41: 평가점수 | L41: 보안수준
A42: =HYPERLINK("["&MID(CELL("filename"),SEARCH("[",CELL("filename"))+1,SEARCH("]",CELL("filename"))-SEARCH("[",CELL("filename"))-1)&"]"&INDIRECT(ADDRESS(ROW()-37,2,1,TRUE,"자산목록"))&"!A1",INDIRECT(ADDRESS(ROW()-37,2,1,TRUE,"자산목록"))) -> DHCP_HQ_Win | C42: =IFERROR(VLOOKUP($A42,자산목록!$B$1:$M$838,8,FALSE),"-") -> 본사 DHCP 서버 | E42: =IFERROR(INDIRECT(ADDRESS(17,4,1,TRUE,$A42)),0) -> 20 | F42: =E42-I42 -> 20 | G42: =IFERROR(INDIRECT(ADDRESS(17,5,1,TRUE,$A42)),0) -> 19 | H42: =IFERROR(INDIRECT(ADDRESS(17,6,1,TRUE,$A42)),0) -> 15 | I42: =IFERROR(INDIRECT(ADDRESS(17,7,1,TRUE,$A42)),0) -> 0 | J42: =IFERROR(INDIRECT(ADDRESS(17,18,1,TRUE,$A42)),0) -> 0 | K42: =IFERROR(INDIRECT(ADDRESS(17,19,1,TRUE,$A42)),0) -> 1 | L42: =IFERROR(INDIRECT(ADDRESS(17,8,1,TRUE,$A42)),0) -> 0
A43: =HYPERLINK("["&MID(CELL("filename"),SEARCH("[",CELL("filename"))+1,SEARCH("]",CELL("filename"))-SEARCH("[",CELL("filename"))-1)&"]"&INDIRECT(ADDRESS(ROW()-37,2,1,TRUE,"자산목록"))&"!A1",INDIRECT(ADDRESS(ROW()-37,2,1,TRUE,"자산목록"))) -> DNS_HQ_Win | C43: =IFERROR(VLOOKUP($A43,자산목록!$B$1:$M$838,8,FALSE),"-") -> 본사 DNS 서버 | E43: =IFERROR(INDIRECT(ADDRESS(17,4,1,TRUE,$A43)),0) -> 20 | F43: =E43-I43 -> 20 | G43: =IFERROR(INDIRECT(ADDRESS(17,5,1,TRUE,$A43)),0) -> 4 | H43: =IFERROR(INDIRECT(ADDRESS(17,6,1,TRUE,$A43)),0) -> 10 | I43: =IFERROR(INDIRECT(ADDRESS(17,7,1,TRUE,$A43)),0) -> 0 | J43: =IFERROR(INDIRECT(ADDRESS(17,18,1,TRUE,$A43)),0) -> 48 | K43: =IFERROR(INDIRECT(ADDRESS(17,19,1,TRUE,$A43)),0) -> 0 | L43: =IFERROR(INDIRECT(ADDRESS(17,8,1,TRUE,$A43)),0) -> 0
A44: =HYPERLINK("["&MID(CELL("filename"),SEARCH("[",CELL("filename"))+1,SEARCH("]",CELL("filename"))-SEARCH("[",CELL("filename"))-1)&"]"&INDIRECT(ADDRESS(ROW()-37,2,1,TRUE,"자산목록"))&"!A1",INDIRECT(ADDRESS(ROW()-37,2,1,TRUE,"자산목록"))) -> DHCP_BR_Win | C44: =IFERROR(VLOOKUP($A44,자산목록!$B$1:$M$838,8,FALSE),"-") -> 지사 DHCP서버 | E44: =IFERROR(INDIRECT(ADDRESS(17,4,1,TRUE,$A44)),0) -> 20 | F44: =E44-I44 -> 20 | G44: =IFERROR(INDIRECT(ADDRESS(17,5,1,TRUE,$A44)),0) -> 4 | H44: =IFERROR(INDIRECT(ADDRESS(17,6,1,TRUE,$A44)),0) -> 10 | I44: =IFERROR(INDIRECT(ADDRESS(17,7,1,TRUE,$A44)),0) -> 0 | J44: =IFERROR(INDIRECT(ADDRESS(17,18,1,TRUE,$A44)),0) -> 48 | K44: =IFERROR(INDIRECT(ADDRESS(17,19,1,TRUE,$A44)),0) -> 0 | L44: =IFERROR(INDIRECT(ADDRESS(17,8,1,TRUE,$A44)),0) -> 0
A45: =HYPERLINK("["&MID(CELL("filename"),SEARCH("[",CELL("filename"))+1,SEARCH("]",CELL("filename"))-SEARCH("[",CELL("filename"))-1)&"]"&INDIRECT(ADDRESS(ROW()-37,2,1,TRUE,"자산목록"))&"!A1",INDIRECT(ADDRESS(ROW()-37,2,1,TRUE,"자산목록"))) -> DNS_BR_Win | C45: =IFERROR(VLOOKUP($A45,자산목록!$B$1:$M$838,8,FALSE),"-") -> 지사 DNS서버 | E45: =IFERROR(INDIRECT(ADDRESS(17,4,1,TRUE,$A45)),0) -> 20 | F45: =E45-I45 -> 20 | G45: =IFERROR(INDIRECT(ADDRESS(17,5,1,TRUE,$A45)),0) -> 4 | H45: =IFERROR(INDIRECT(ADDRESS(17,6,1,TRUE,$A45)),0) -> 10 | I45: =IFERROR(INDIRECT(ADDRESS(17,7,1,TRUE,$A45)),0) -> 0 | J45: =IFERROR(INDIRECT(ADDRESS(17,18,1,TRUE,$A45)),0) -> 48 | K45: =IFERROR(INDIRECT(ADDRESS(17,19,1,TRUE,$A45)),0) -> 0 | L45: =IFERROR(INDIRECT(ADDRESS(17,8,1,TRUE,$A45)),0) -> 0
A46: =HYPERLINK("["&MID(CELL("filename"),SEARCH("[",CELL("filename"))+1,SEARCH("]",CELL("filename"))-SEARCH("[",CELL("filename"))-1)&"]"&INDIRECT(ADDRESS(ROW()-37,2,1,TRUE,"자산목록"))&"!A1",INDIRECT(ADDRESS(ROW()-37,2,1,TRUE,"자산목록"))) -> 0 | C46: =IFERROR(VLOOKUP($A46,자산목록!$B$1:$M$838,8,FALSE),"-") -> - | E46: =IFERROR(INDIRECT(ADDRESS(17,4,1,TRUE,$A46)),0) -> 0 | F46: =E46-I46 -> 0 | G46: =IFERROR(INDIRECT(ADDRESS(17,5,1,TRUE,$A46)),0) -> 0 | H46: =IFERROR(INDIRECT(ADDRESS(17,6,1,TRUE,$A46)),0) -> 0 | I46: =IFERROR(INDIRECT(ADDRESS(17,7,1,TRUE,$A46)),0) -> 0 | J46: =IFERROR(INDIRECT(ADDRESS(17,18,1,TRUE,$A46)),0) -> 0 | K46: =IFERROR(INDIRECT(ADDRESS(17,19,1,TRUE,$A46)),0) -> 0 | L46: =IFERROR(INDIRECT(ADDRESS(17,8,1,TRUE,$A46)),0) -> 0
A47: =HYPERLINK("["&MID(CELL("filename"),SEARCH("[",CELL("filename"))+1,SEARCH("]",CELL("filename"))-SEARCH("[",CELL("filename"))-1)&"]"&INDIRECT(ADDRESS(ROW()-37,2,1,TRUE,"자산목록"))&"!A1",INDIRECT(ADDRESS(ROW()-37,2,1,TRUE,"자산목록"))) -> 0 | C47: =IFERROR(VLOOKUP($A47,자산목록!$B$1:$M$838,8,FALSE),"-") -> - | E47: =IFERROR(INDIRECT(ADDRESS(17,4,1,TRUE,$A47)),0) -> 0 | F47: =E47-I47 -> 0 | G47: =IFERROR(INDIRECT(ADDRESS(17,5,1,TRUE,$A47)),0) -> 0 | H47: =IFERROR(INDIRECT(ADDRESS(17,6,1,TRUE,$A47)),0) -> 0 | I47: =IFERROR(INDIRECT(ADDRESS(17,7,1,TRUE,$A47)),0) -> 0 | J47: =IFERROR(INDIRECT(ADDRESS(17,18,1,TRUE,$A47)),0) -> 0 | K47: =IFERROR(INDIRECT(ADDRESS(17,19,1,TRUE,$A47)),0) -> 0 | L47: =IFERROR(INDIRECT(ADDRESS(17,8,1,TRUE,$A47)),0) -> 0
A48: =HYPERLINK("["&MID(CELL("filename"),SEARCH("[",CELL("filename"))+1,SEARCH("]",CELL("filename"))-SEARCH("[",CELL("filename"))-1)&"]"&INDIRECT(ADDRESS(ROW()-37,2,1,TRUE,"자산목록"))&"!A1",INDIRECT(ADDRESS(ROW()-37,2,1,TRUE,"자산목록"))) -> 0 | C48: =IFERROR(VLOOKUP($A48,자산목록!$B$1:$M$838,8,FALSE),"-") -> - | E48: =IFERROR(INDIRECT(ADDRESS(17,4,1,TRUE,$A48)),0) -> 0 | F48: =E48-I48 -> 0 | G48: =IFERROR(INDIRECT(ADDRESS(17,5,1,TRUE,$A48)),0) -> 0 | H48: =IFERROR(INDIRECT(ADDRESS(17,6,1,TRUE,$A48)),0) -> 0 | I48: =IFERROR(INDIRECT(ADDRESS(17,7,1,TRUE,$A48)),0) -> 0 | J48: =IFERROR(INDIRECT(ADDRESS(17,18,1,TRUE,$A48)),0) -> 0 | K48: =IFERROR(INDIRECT(ADDRESS(17,19,1,TRUE,$A48)),0) -> 0 | L48: =IFERROR(INDIRECT(ADDRESS(17,8,1,TRUE,$A48)),0) -> 0
A49: 계 | E49: =SUM(E42:E42) -> 20 | F49: =SUM(F42:F42) -> 20 | G49: =SUM(G42:G42) -> 19 | H49: =SUM(H42:H42) -> 15 | I49: =SUM(I42:I42) -> 0 | J49: =SUM(J42:J42) -> 0 | K49: =SUM(K42:K42) -> 1 | L49: =IFERROR(K49/J49,0) -> 0

Sheet 취약점 진단 통계 (이행)
A1: ■ 영역별/장비별 보안수준 통계
A3: 1) 영역별 보안수준
A4: 분류 | E4: 진단 결과 | J4: 이행 결과 | O4: 중요도점수
E5: 전체항목 | F5: 진단항목 | G5: 양호 | H5: 취약 | I5: 해당없음 | J5: 조치 | K5: 미조치 | L5: 위험수용 | M5: 해당없음 | N5: 잔여취약점 (미조치+위험수용) | O5: 전체점수 (이행전) | P5: 전체점수 (이행후) | Q5: 평가점수 (이행전) | R5: 평가점수 (이행후) | S5: 이행율 | T5: 보안수준 (이행 전) | U5: 보안수준 (이행 후)
A6: 계정 관리 | E6: =SUMIF('취약점 진단 항목별 통계 (이행)'!$A:$A,$A6&"*",'취약점 진단 항목별 통계 (이행)'!$F:$F) -> 28 | F6: =E6-I6 -> 28 | G6: =SUMIF('취약점 진단 항목별 통계'!$A:$A,$A6&"*",'취약점 진단 항목별 통계'!$G:$G)+SUMIF('취약점 진단 항목별 통계'!$A:$A,$A6&"*",'취약점 진단 항목별 통계'!$H:$H) -> 29 | H6: =SUMIF('취약점 진단 항목별 통계'!$A:$A,$A6&"*",'취약점 진단 항목별 통계'!$I:$I) -> 27 | I6: =SUMIF('취약점 진단 항목별 통계'!$A:$A,$A6&"*",'취약점 진단 항목별 통계'!$J:$J) -> 0 | J6: =SUMIF('취약점 진단 항목별 통계 (이행)'!$A:$A,$A6&"*",'취약점 진단 항목별 통계 (이행)'!$K:$K) -> 9 | K6: =SUMIF('취약점 진단 항목별 통계 (이행)'!$A:$A,$A6&"*",'취약점 진단 항목별 통계 (이행)'!$L:$L) -> 0 | L6: =SUMIF('취약점 진단 항목별 통계 (이행)'!$A:$A,$A6&"*",'취약점 진단 항목별 통계 (이행)'!$M:$M) -> 0 | M6: =SUMIF('취약점 진단 항목별 통계 (이행)'!$A:$A,$A6&"*",'취약점 진단 항목별 통계 (이행)'!$N:$N) -> 0 | N6: =K6+L6 -> 0 | O6: =SUMIF('취약점 진단 항목별 통계 (이행)'!$A:$A,$A6&"*",'취약점 진단 항목별 통계 (이행)'!$O:$O) -> 70 | P6: =SUMIF('취약점 진단 항목별 통계 (이행)'!$A:$A,$A6&"*",'취약점 진단 항목별 통계 (이행)'!$P:$P) -> 70 | Q6: =SUMIF('취약점 진단 항목별 통계 (이행)'!$A:$A,$A6&"*",'취약점 진단 항목별 통계 (이행)'!$Q:$Q) -> 74 | R6: =SUMIF('취약점 진단 항목별 통계 (이행)'!$A:$A,$A6&"*",'취약점 진단 항목별 통계 (이행)'!$R:$R) -> 96 | S6: =IFERROR($J6/($H6-(M6-I6)),"N/A") -> 0.33333333 | T6: =IF($I6=$E6,"N/A",(Q6/O6)) -> 1.0571429 | U6: =IF(OR($I6=$E6,$E6=$M6),"N/A",($R6/$P6)) -> 1.3714286
A7: 접근 관리 | E7: =SUMIF('취약점 진단 항목별 통계 (이행)'!$A:$A,$A7&"*",'취약점 진단 항목별 통계 (이행)'!$F:$F) -> 0 | F7: =E7-I7 -> 0 | G7: =SUMIF('취약점 진단 항목별 통계'!$A:$A,$A7&"*",'취약점 진단 항목별 통계'!$G:$G)+SUMIF('취약점 진단 항목별 통계'!$A:$A,$A7&"*",'취약점 진단 항목별 통계'!$H:$H) -> 0 | H7: =SUMIF('취약점 진단 항목별 통계'!$A:$A,$A7&"*",'취약점 진단 항목별 통계'!$I:$I) -> 0 | I7: =SUMIF('취약점 진단 항목별 통계'!$A:$A,$A7&"*",'취약점 진단 항목별 통계'!$J:$J) -> 0 | J7: =SUMIF('취약점 진단 항목별 통계 (이행)'!$A:$A,$A7&"*",'취약점 진단 항목별 통계 (이행)'!$K:$K) -> 0 | K7: =SUMIF('취약점 진단 항목별 통계 (이행)'!$A:$A,$A7&"*",'취약점 진단 항목별 통계 (이행)'!$L:$L) -> 0 | L7: =SUMIF('취약점 진단 항목별 통계 (이행)'!$A:$A,$A7&"*",'취약점 진단 항목별 통계 (이행)'!$M:$M) -> 0 | M7: =SUMIF('취약점 진단 항목별 통계 (이행)'!$A:$A,$A7&"*",'취약점 진단 항목별 통계 (이행)'!$N:$N) -> 0 | N7: =K7+L7 -> 0 | O7: =SUMIF('취약점 진단 항목별 통계 (이행)'!$A:$A,$A7&"*",'취약점 진단 항목별 통계 (이행)'!$O:$O) -> 0 | P7: =SUMIF('취약점 진단 항목별 통계 (이행)'!$A:$A,$A7&"*",'취약점 진단 항목별 통계 (이행)'!$P:$P) -> 0 | Q7: =SUMIF('취약점 진단 항목별 통계 (이행)'!$A:$A,$A7&"*",'취약점 진단 항목별 통계 (이행)'!$Q:$Q) -> 0 | R7: =SUMIF('취약점 진단 항목별 통계 (이행)'!$A:$A,$A7&"*",'취약점 진단 항목별 통계 (이행)'!$R:$R) -> 0 | S7: =IFERROR($J7/($H7-(M7-I7)),"N/A") -> N/A | T7: =IF($I7=$E7,"N/A",(Q7/O7)) -> N/A | U7: =IF(OR($I7=$E7,$E7=$M7),"N/A",($R7/$P7)) -> N/A
A8: 패치 관리 | E8: =SUMIF('취약점 진단 항목별 통계 (이행)'!$A:$A,$A8&"*",'취약점 진단 항목별 통계 (이행)'!$F:$F) -> 4 | F8: =E8-I8 -> 4 | G8: =SUMIF('취약점 진단 항목별 통계'!$A:$A,$A8&"*",'취약점 진단 항목별 통계'!$G:$G)+SUMIF('취약점 진단 항목별 통계'!$A:$A,$A8&"*",'취약점 진단 항목별 통계'!$H:$H) -> 2 | H8: =SUMIF('취약점 진단 항목별 통계'!$A:$A,$A8&"*",'취약점 진단 항목별 통계'!$I:$I) -> 6 | I8: =SUMIF('취약점 진단 항목별 통계'!$A:$A,$A8&"*",'취약점 진단 항목별 통계'!$J:$J) -> 0 | J8: =SUMIF('취약점 진단 항목별 통계 (이행)'!$A:$A,$A8&"*",'취약점 진단 항목별 통계 (이행)'!$K:$K) -> 0 | K8: =SUMIF('취약점 진단 항목별 통계 (이행)'!$A:$A,$A8&"*",'취약점 진단 항목별 통계 (이행)'!$L:$L) -> 0 | L8: =SUMIF('취약점 진단 항목별 통계 (이행)'!$A:$A,$A8&"*",'취약점 진단 항목별 통계 (이행)'!$M:$M) -> 0 | M8: =SUMIF('취약점 진단 항목별 통계 (이행)'!$A:$A,$A8&"*",'취약점 진단 항목별 통계 (이행)'!$N:$N) -> 2 | N8: =K8+L8 -> 0 | O8: =SUMIF('취약점 진단 항목별 통계 (이행)'!$A:$A,$A8&"*",'취약점 진단 항목별 통계 (이행)'!$O:$O) -> 12 | P8: =SUMIF('취약점 진단 항목별 통계 (이행)'!$A:$A,$A8&"*",'취약점 진단 항목별 통계 (이행)'!$P:$P) -> 6 | Q8: =SUMIF('취약점 진단 항목별 통계 (이행)'!$A:$A,$A8&"*",'취약점 진단 항목별 통계 (이행)'!$Q:$Q) -> 6 | R8: =SUMIF('취약점 진단 항목별 통계 (이행)'!$A:$A,$A8&"*",'취약점 진단 항목별 통계 (이행)'!$R:$R) -> 6 | S8: =IFERROR($J8/($H8-(M8-I8)),"N/A") -> 0 | T8: =IF($I8=$E8,"N/A",(Q8/O8)) -> 0.5 | U8: =IF(OR($I8=$E8,$E8=$M8),"N/A",($R8/$P8)) -> 1
A9: 로그 관리 | E9: =SUMIF('취약점 진단 항목별 통계 (이행)'!$A:$A,$A9&"*",'취약점 진단 항목별 통계 (이행)'!$F:$F) -> 8 | F9: =E9-I9 -> 8 | G9: =SUMIF('취약점 진단 항목별 통계'!$A:$A,$A9&"*",'취약점 진단 항목별 통계'!$G:$G)+SUMIF('취약점 진단 항목별 통계'!$A:$A,$A9&"*",'취약점 진단 항목별 통계'!$H:$H) -> 6 | H9: =SUMIF('취약점 진단 항목별 통계'!$A:$A,$A9&"*",'취약점 진단 항목별 통계'!$I:$I) -> 10 | I9: =SUMIF('취약점 진단 항목별 통계'!$A:$A,$A9&"*",'취약점 진단 항목별 통계'!$J:$J) -> 0 | J9: =SUMIF('취약점 진단 항목별 통계 (이행)'!$A:$A,$A9&"*",'취약점 진단 항목별 통계 (이행)'!$K:$K) -> 1 | K9: =SUMIF('취약점 진단 항목별 통계 (이행)'!$A:$A,$A9&"*",'취약점 진단 항목별 통계 (이행)'!$L:$L) -> 1 | L9: =SUMIF('취약점 진단 항목별 통계 (이행)'!$A:$A,$A9&"*",'취약점 진단 항목별 통계 (이행)'!$M:$M) -> 0 | M9: =SUMIF('취약점 진단 항목별 통계 (이행)'!$A:$A,$A9&"*",'취약점 진단 항목별 통계 (이행)'!$N:$N) -> 2 | N9: =K9+L9 -> 1 | O9: =SUMIF('취약점 진단 항목별 통계 (이행)'!$A:$A,$A9&"*",'취약점 진단 항목별 통계 (이행)'!$O:$O) -> 14 | P9: =SUMIF('취약점 진단 항목별 통계 (이행)'!$A:$A,$A9&"*",'취약점 진단 항목별 통계 (이행)'!$P:$P) -> 10 | Q9: =SUMIF('취약점 진단 항목별 통계 (이행)'!$A:$A,$A9&"*",'취약점 진단 항목별 통계 (이행)'!$Q:$Q) -> 11 | R9: =SUMIF('취약점 진단 항목별 통계 (이행)'!$A:$A,$A9&"*",'취약점 진단 항목별 통계 (이행)'!$R:$R) -> 12 | S9: =IFERROR($J9/($H9-(M9-I9)),"N/A") -> 0.125 | T9: =IF($I9=$E9,"N/A",(Q9/O9)) -> 0.78571429 | U9: =IF(OR($I9=$E9,$E9=$M9),"N/A",($R9/$P9)) -> 1.2
A10: 기능 관리 | E10: =SUMIF('취약점 진단 항목별 통계 (이행)'!$A:$A,$A10&"*",'취약점 진단 항목별 통계 (이행)'!$F:$F) -> 0 | F10: =E10-I10 -> 0 | G10: =SUMIF('취약점 진단 항목별 통계'!$A:$A,$A10&"*",'취약점 진단 항목별 통계'!$G:$G)+SUMIF('취약점 진단 항목별 통계'!$A:$A,$A10&"*",'취약점 진단 항목별 통계'!$H:$H) -> 0 | H10: =SUMIF('취약점 진단 항목별 통계'!$A:$A,$A10&"*",'취약점 진단 항목별 통계'!$I:$I) -> 0 | I10: =SUMIF('취약점 진단 항목별 통계'!$A:$A,$A10&"*",'취약점 진단 항목별 통계'!$J:$J) -> 0 | J10: =SUMIF('취약점 진단 항목별 통계 (이행)'!$A:$A,$A10&"*",'취약점 진단 항목별 통계 (이행)'!$K:$K) -> 0 | K10: =SUMIF('취약점 진단 항목별 통계 (이행)'!$A:$A,$A10&"*",'취약점 진단 항목별 통계 (이행)'!$L:$L) -> 0 | L10: =SUMIF('취약점 진단 항목별 통계 (이행)'!$A:$A,$A10&"*",'취약점 진단 항목별 통계 (이행)'!$M:$M) -> 0 | M10: =SUMIF('취약점 진단 항목별 통계 (이행)'!$A:$A,$A10&"*",'취약점 진단 항목별 통계 (이행)'!$N:$N) -> 0 | N10: =K10+L10 -> 0 | O10: =SUMIF('취약점 진단 항목별 통계 (이행)'!$A:$A,$A10&"*",'취약점 진단 항목별 통계 (이행)'!$O:$O) -> 0 | P10: =SUMIF('취약점 진단 항목별 통계 (이행)'!$A:$A,$A10&"*",'취약점 진단 항목별 통계 (이행)'!$P:$P) -> 0 | Q10: =SUMIF('취약점 진단 항목별 통계 (이행)'!$A:$A,$A10&"*",'취약점 진단 항목별 통계 (이행)'!$Q:$Q) -> 0 | R10: =SUMIF('취약점 진단 항목별 통계 (이행)'!$A:$A,$A10&"*",'취약점 진단 항목별 통계 (이행)'!$R:$R) -> 0 | S10: =IFERROR($J10/($H10-(M10-I10)),"N/A") -> N/A | T10: =IF($I10=$E10,"N/A",(Q10/O10)) -> N/A | U10: =IF(OR($I10=$E10,$E10=$M10),"N/A",($R10/$P10)) -> N/A
A11: 계 | E11: =SUM(E6:E10) -> 40 | F11: =SUM(F6:F10) -> 40 | G11: =SUM(G6:G10) -> 37 | H11: =SUM(H6:H10) -> 43 | I11: =SUM(I6:I10) -> 0 | J11: =SUM(J6:J10) -> 10 | K11: =SUM(K6:K10) -> 1 | L11: =SUM(L6:L10) -> 0 | ... R11: =SUM(R6:R10) -> 114 | S11: =IFERROR($J11/($H11-(M11-I11)),"N/A") -> 0.25641026 | T11: =IF($I11=$E11,"N/A",(Q11/O11)) -> 0.94791667 | U11: =IF(OR($I11=$E11,$E11=$M11),"N/A",($R11/$P11)) -> 1.3255814
A39: 2) 장비별 보안수준
A40: 장비 구분 | E40: 진단 결과 | J40: 이행 결과 | O40: 중요도점수
E41: 전체항목 | F41: 진단항목 | G41: 양호 | H41: 취약 | I41: 해당없음 | J41: 조치 | K41: 미조치 | L41: 위험수용 | M41: 해당없음 | N41: 잔여취약점 (미조치+위험수용) | O41: 전체점수 (이행전) | P41: 전체점수 (이행후) | Q41: 평가점수 (이행전) | R41: 평가점수 (이행후) | S41: 이행율 | T41: 보안수준 (이행 전) | U41: 보안수준 (이행 후)
A42: =HYPERLINK("["&MID(CELL("filename"),SEARCH("[",CELL("filename"))+1,SEARCH("]",CELL("filename"))-SEARCH("[",CELL("filename"))-1)&"]"&INDIRECT(ADDRESS(ROW()-37,2,1,TRUE,"자산목록"))&"!A1",INDIRECT(ADDRESS(ROW()-37,2,1,TRUE,"자산목록"))) -> DHCP_HQ_Win | C42: =IFERROR(VLOOKUP($A42,자산목록!$B$1:$M$838,8,FALSE),"-") -> 본사 DHCP 서버 | E42: =IFERROR(INDIRECT(ADDRESS(17,4,1,TRUE,$A42)),0) -> 20 | F42: =E42-I42 -> 20 | G42: =IFERROR(INDIRECT(ADDRESS(17,5,1,TRUE,$A42)),0) -> 19 | H42: =IFERROR(INDIRECT(ADDRESS(17,6,1,TRUE,$A42)),0) -> 15 | I42: =IFERROR(INDIRECT(ADDRESS(17,7,1,TRUE,$A42)),0) -> 0 | J42: =IFERROR(INDIRECT(ADDRESS(17,10,1,TRUE,$A42)),0) -> 0 | K42: =IFERROR(INDIRECT(ADDRESS(17,11,1,TRUE,$A42)),0) -> 1 | L42: =IFERROR(INDIRECT(ADDRESS(17,12,1,TRUE,$A42)),0) -> 0 | M42: =IFERROR(INDIRECT(ADDRESS(17,13,1,TRUE,$A42)),0) -> 0 | N42: =K42+L42 -> 1 | O42: =IFERROR(INDIRECT(ADDRESS(17,18,1,TRUE,$A42)),0) -> 0 | P42: =IFERROR(INDIRECT(ADDRESS(17,21,1,TRUE,$A42)),0) -> 37 | Q42: =IFERROR(INDIRECT(ADDRESS(17,19,1,TRUE,$A42)),0) -> 1 | R42: =IFERROR(INDIRECT(ADDRESS(17,20,1,TRUE,$A42)),0) -> 46 | S42: =IFERROR(INDIRECT(ADDRESS(17,14,1,TRUE,$A42)),0) -> 0 | T42: =IFERROR(INDIRECT(ADDRESS(17,8,1,TRUE,$A42)),0) -> 0 | U42: =IFERROR(INDIRECT(ADDRESS(17,15,1,TRUE,$A42)),0) -> 1.2432432
A43: =HYPERLINK("["&MID(CELL("filename"),SEARCH("[",CELL("filename"))+1,SEARCH("]",CELL("filename"))-SEARCH("[",CELL("filename"))-1)&"]"&INDIRECT(ADDRESS(ROW()-37,2,1,TRUE,"자산목록"))&"!A1",INDIRECT(ADDRESS(ROW()-37,2,1,TRUE,"자산목록"))) -> DNS_HQ_Win | C43: =IFERROR(VLOOKUP($A43,자산목록!$B$1:$M$838,8,FALSE),"-") -> 본사 DNS 서버 | E43: =IFERROR(INDIRECT(ADDRESS(17,4,1,TRUE,$A43)),0) -> 20 | F43: =E43-I43 -> 20 | G43: =IFERROR(INDIRECT(ADDRESS(17,5,1,TRUE,$A43)),0) -> 4 | H43: =IFERROR(INDIRECT(ADDRESS(17,6,1,TRUE,$A43)),0) -> 10 | I43: =IFERROR(INDIRECT(ADDRESS(17,7,1,TRUE,$A43)),0) -> 0 | J43: =IFERROR(INDIRECT(ADDRESS(17,10,1,TRUE,$A43)),0) -> 10 | K43: =IFERROR(INDIRECT(ADDRESS(17,11,1,TRUE,$A43)),0) -> 0 | L43: =IFERROR(INDIRECT(ADDRESS(17,12,1,TRUE,$A43)),0) -> 0 | M43: =IFERROR(INDIRECT(ADDRESS(17,13,1,TRUE,$A43)),0) -> 6 | N43: =K43+L43 -> 0 | O43: =IFERROR(INDIRECT(ADDRESS(17,18,1,TRUE,$A43)),0) -> 48 | P43: =IFERROR(INDIRECT(ADDRESS(17,21,1,TRUE,$A43)),0) -> 35 | Q43: =IFERROR(INDIRECT(ADDRESS(17,19,1,TRUE,$A43)),0) -> 0 | R43: =IFERROR(INDIRECT(ADDRESS(17,20,1,TRUE,$A43)),0) -> 35 | S43: =IFERROR(INDIRECT(ADDRESS(17,14,1,TRUE,$A43)),0) -> 2.5 | T43: =IFERROR(INDIRECT(ADDRESS(17,8,1,TRUE,$A43)),0) -> 0 | U43: =IFERROR(INDIRECT(ADDRESS(17,15,1,TRUE,$A43)),0) -> 1
A44: 계 | E44: =SUM(E42:E43) -> 40 | F44: =SUM(F42:F43) -> 40 | G44: =SUM(G42:G43) -> 23 | H44: =SUM(H42:H43) -> 25 | I44: =SUM(I42:I43) -> 0 | J44: =SUM(J42:J43) -> 10 | K44: =SUM(K42:K43) -> 1 | L44: =SUM(L42:L43) -> 0 | ... R44: =SUM(R42:R43) -> 81 | S44: =IFERROR($J44/($H44-(M44-I44)),"N/A") -> 0.52631579 | T44: =IF($I44=$E44,"N/A",(Q44/O44)) -> 0.020833333 | U44: =IF(OR($I44=$E44,$E44=$M44),"N/A",($R44/$P44)) -> 1.125

Sheet 취약점 진단 항목별 통계
A1: ■ 취약점 진단 항목별 통계
A3: =ChkList!A4 -> 분류 | C3: =ChkList!C4 -> 진단항목 | D3: =ChkList!D4 -> 중요도 | F3: 진단 통계 | K3: 중요도 점수 | M3: 진단결과 | N3: 진단결과 | O3: 진단결과 | P3: 진단결과
F4: 전체 | G4: 양호 | H4: 즉시조치 | I4: 취약 | J4: N/A | K4: 전체 | L4: 평가 | M4: =HYPERLINK("["&MID(CELL("filename"),SEARCH("[",CELL("filename"))+1,SEARCH("]",CELL("filename"))-SEARCH("[",CELL("filename"))-1)&"]"&INDIRECT(ADDRESS(COLUMN()-8,2,1,TRUE,"자산목록"))&"!A1",INDIRECT(ADDRESS(COLUMN()-8,2,1,TRUE,"자산목록"))) -> DHCP_HQ_Win | N4: =HYPERLINK("["&MID(CELL("filename"),SEARCH("[",CELL("filename"))+1,SEARCH("]",CELL("filename"))-SEARCH("[",CELL("filename"))-1)&"]"&INDIRECT(ADDRESS(COLUMN()-8,2,1,TRUE,"자산목록"))&"!A1",INDIRECT(ADDRESS(COLUMN()-8,2,1,TRUE,"자산목록"))) -> DNS_HQ_Win | O4: =HYPERLINK("["&MID(CELL("filename"),SEARCH("[",CELL("filename"))+1,SEARCH("]",CELL("filename"))-SEARCH("[",CELL("filename"))-1)&"]"&INDIRECT(ADDRESS(COLUMN()-8,2,1,TRUE,"자산목록"))&"!A1",INDIRECT(ADDRESS(COLUMN()-8,2,1,TRUE,"자산목록"))) -> DHCP_BR_Win | P4: =HYPERLINK("["&MID(CELL("filename"),SEARCH("[",CELL("filename"))+1,SEARCH("]",CELL("filename"))-SEARCH("[",CELL("filename"))-1)&"]"&INDIRECT(ADDRESS(COLUMN()-8,2,1,TRUE,"자산목록"))&"!A1",INDIRECT(ADDRESS(COLUMN()-8,2,1,TRUE,"자산목록"))) -> DNS_BR_Win
A5: =ChkList!$A5 -> 계정 관리 | B5: =ChkList!$B5 -> W-01 | C5: =ChkList!$C5 -> Administrator 계정 이름 변경 등 보안성 강화 | D5: =ChkList!$D5 -> H | E5: =ChkList!E5 -> 3 | F5: =COUNTA($M5:INDIRECT(ADDRESS(ROW(),MATCH("",$4:$4,-1),1,1))) -> 4 | G5: =COUNTIF($M5:INDIRECT(ADDRESS(ROW(),MATCH("",$4:$4,-1),1,1)),"조치완료(Y)")+COUNTIF($M5:INDIRECT(ADDRESS(ROW(),MATCH("",$4:$4,-1),1,1)),"Y") -> 1 | H5: =COUNTIF($M5:INDIRECT(ADDRESS(ROW(),MATCH("",$4:$4,-1),1,1)),"Y(즉시조치)")+COUNTIF($M5:INDIRECT(ADDRESS(ROW(),MATCH("",$4:$4,-1),1,1)),"조치완료(즉시조치)") -> 0 | I5: =COUNTIF($M5:INDIRECT(ADDRESS(ROW(),MATCH("",$4:$4,-1),1,1)),"N") -> 3 | J5: =COUNTIF($M5:INDIRECT(ADDRESS(ROW(),MATCH("",$4:$4,-1),1,1)),"N/A")+COUNTIF($M5:INDIRECT(ADDRESS(ROW(),MATCH("",$4:$4,-1),1,1)),"조치완료(N/A)") -> 0 | K5: =VLOOKUP($D5,'parm(hidden)'!$B$8:$C$10,2,FALSE)*($F5-$J5) -> 12 | L5: =VLOOKUP($D5,'parm(hidden)'!$B$8:$C$10,2,FALSE)*($G5+$H5) -> 3 | M5: =HYPERLINK("["&MID(CELL("filename"),SEARCH("[",CELL("filename"))+1,SEARCH("]",CELL("filename"))-SEARCH("[",CELL("filename"))-1)&"]"&ADDRESS(ROW()+16,8,1,TRUE,M$4),INDIRECT(ADDRESS(ROW()+16,8,1,TRUE,M$4))) -> Y | N5: =HYPERLINK("["&MID(CELL("filename"),SEARCH("[",CELL("filename"))+1,SEARCH("]",CELL("filename"))-SEARCH("[",CELL("filename"))-1)&"]"&ADDRESS(ROW()+16,8,1,TRUE,N$4),INDIRECT(ADDRESS(ROW()+16,8,1,TRUE,N$4))) -> N | O5: =HYPERLINK("["&MID(CELL("filename"),SEARCH("[",CELL("filename"))+1,SEARCH("]",CELL("filename"))-SEARCH("[",CELL("filename"))-1)&"]"&ADDRESS(ROW()+16,8,1,TRUE,O$4),INDIRECT(ADDRESS(ROW()+16,8,1,TRUE,O$4))) -> N | P5: =HYPERLINK("["&MID(CELL("filename"),SEARCH("[",CELL("filename"))+1,SEARCH("]",CELL("filename"))-SEARCH("[",CELL("filename"))-1)&"]"&ADDRESS(ROW()+16,8,1,TRUE,P$4),INDIRECT(ADDRESS(ROW()+16,8,1,TRUE,P$4))) -> N
A6: =ChkList!$A6 -> 계정 관리 | B6: =ChkList!$B6 -> W-02 | C6: =ChkList!$C6 -> Guest 계정 비활성화 | D6: H | E6: =IF(D6="H",3,IF(D6="M",2,IF(D6="L",1,""))) -> 3 | F6: =COUNTA($M6:INDIRECT(ADDRESS(ROW(),MATCH("",$4:$4,-1),1,1))) -> 4 | G6: =COUNTIF($M6:INDIRECT(ADDRESS(ROW(),MATCH("",$4:$4,-1),1,1)),"조치완료(Y)")+COUNTIF($M6:INDIRECT(ADDRESS(ROW(),MATCH("",$4:$4,-1),1,1)),"Y") -> 1 | H6: =COUNTIF($M6:INDIRECT(ADDRESS(ROW(),MATCH("",$4:$4,-1),1,1)),"Y(즉시조치)")+COUNTIF($M6:INDIRECT(ADDRESS(ROW(),MATCH("",$4:$4,-1),1,1)),"조치완료(즉시조치)") -> 0 | I6: =COUNTIF($M6:INDIRECT(ADDRESS(ROW(),MATCH("",$4:$4,-1),1,1)),"N") -> 3 | J6: =COUNTIF($M6:INDIRECT(ADDRESS(ROW(),MATCH("",$4:$4,-1),1,1)),"N/A")+COUNTIF($M6:INDIRECT(ADDRESS(ROW(),MATCH("",$4:$4,-1),1,1)),"조치완료(N/A)") -> 0 | K6: =VLOOKUP($D6,'parm(hidden)'!$B$8:$C$10,2,FALSE)*($F6-$J6) -> 12 | L6: =VLOOKUP($D6,'parm(hidden)'!$B$8:$C$10,2,FALSE)*($G6+$H6) -> 3 | M6: =HYPERLINK("["&MID(CELL("filename"),SEARCH("[",CELL("filename"))+1,SEARCH("]",CELL("filename"))-SEARCH("[",CELL("filename"))-1)&"]"&ADDRESS(ROW()+16,8,1,TRUE,M$4),INDIRECT(ADDRESS(ROW()+16,8,1,TRUE,M$4))) -> Y | N6: =HYPERLINK("["&MID(CELL("filename"),SEARCH("[",CELL("filename"))+1,SEARCH("]",CELL("filename"))-SEARCH("[",CELL("filename"))-1)&"]"&ADDRESS(ROW()+16,8,1,TRUE,N$4),INDIRECT(ADDRESS(ROW()+16,8,1,TRUE,N$4))) -> N | O6: =HYPERLINK("["&MID(CELL("filename"),SEARCH("[",CELL("filename"))+1,SEARCH("]",CELL("filename"))-SEARCH("[",CELL("filename"))-1)&"]"&ADDRESS(ROW()+16,8,1,TRUE,O$4),INDIRECT(ADDRESS(ROW()+16,8,1,TRUE,O$4))) -> N | P6: =HYPERLINK("["&MID(CELL("filename"),SEARCH("[",CELL("filename"))+1,SEARCH("]",CELL("filename"))-SEARCH("[",CELL("filename"))-1)&"]"&ADDRESS(ROW()+16,8,1,TRUE,P$4),INDIRECT(ADDRESS(ROW()+16,8,1,TRUE,P$4))) -> N
A7: =ChkList!$A7 -> 계정 관리 | B7: =ChkList!$B7 -> W-03 | C7: =ChkList!$C7 -> 불필요한 계정 제거 | D7: H | E7: =IF(D7="H",3,IF(D7="M",2,IF(D7="L",1,""))) -> 3 | F7: =COUNTA($M7:INDIRECT(ADDRESS(ROW(),MATCH("",$4:$4,-1),1,1))) -> 4 | G7: =COUNTIF($M7:INDIRECT(ADDRESS(ROW(),MATCH("",$4:$4,-1),1,1)),"조치완료(Y)")+COUNTIF($M7:INDIRECT(ADDRESS(ROW(),MATCH("",$4:$4,-1),1,1)),"Y") -> 4 | H7: =COUNTIF($M7:INDIRECT(ADDRESS(ROW(),MATCH("",$4:$4,-1),1,1)),"Y(즉시조치)")+COUNTIF($M7:INDIRECT(ADDRESS(ROW(),MATCH("",$4:$4,-1),1,1)),"조치완료(즉시조치)") -> 0 | I7: =COUNTIF($M7:INDIRECT(ADDRESS(ROW(),MATCH("",$4:$4,-1),1,1)),"N") -> 0 | J7: =COUNTIF($M7:INDIRECT(ADDRESS(ROW(),MATCH("",$4:$4,-1),1,1)),"N/A")+COUNTIF($M7:INDIRECT(ADDRESS(ROW(),MATCH("",$4:$4,-1),1,1)),"조치완료(N/A)") -> 0 | K7: =VLOOKUP($D7,'parm(hidden)'!$B$8:$C$10,2,FALSE)*($F7-$J7) -> 12 | L7: =VLOOKUP($D7,'parm(hidden)'!$B$8:$C$10,2,FALSE)*($G7+$H7) -> 12 | M7: =HYPERLINK("["&MID(CELL("filename"),SEARCH("[",CELL("filename"))+1,SEARCH("]",CELL("filename"))-SEARCH("[",CELL("filename"))-1)&"]"&ADDRESS(ROW()+16,8,1,TRUE,M$4),INDIRECT(ADDRESS(ROW()+16,8,1,TRUE,M$4))) -> Y | N7: =HYPERLINK("["&MID(CELL("filename"),SEARCH("[",CELL("filename"))+1,SEARCH("]",CELL("filename"))-SEARCH("[",CELL("filename"))-1)&"]"&ADDRESS(ROW()+16,8,1,TRUE,N$4),INDIRECT(ADDRESS(ROW()+16,8,1,TRUE,N$4))) -> Y | O7: =HYPERLINK("["&MID(CELL("filename"),SEARCH("[",CELL("filename"))+1,SEARCH("]",CELL("filename"))-SEARCH("[",CELL("filename"))-1)&"]"&ADDRESS(ROW()+16,8,1,TRUE,O$4),INDIRECT(ADDRESS(ROW()+16,8,1,TRUE,O$4))) -> Y | P7: =HYPERLINK("["&MID(CELL("filename"),SEARCH("[",CELL("filename"))+1,SEARCH("]",CELL("filename"))-SEARCH("[",CELL("filename"))-1)&"]"&ADDRESS(ROW()+16,8,1,TRUE,P$4),INDIRECT(ADDRESS(ROW()+16,8,1,TRUE,P$4))) -> Y
A8: =ChkList!$A8 -> 계정 관리 | B8: =ChkList!$B8 -> W-04 | C8: =ChkList!$C8 -> 계정 잠금 임계값 설정 | D8: H | E8: =IF(D8="H",3,IF(D8="M",2,IF(D8="L",1,""))) -> 3 | F8: =COUNTA($M8:INDIRECT(ADDRESS(ROW(),MATCH("",$4:$4,-1),1,1))) -> 4 | G8: =COUNTIF($M8:INDIRECT(ADDRESS(ROW(),MATCH("",$4:$4,-1),1,1)),"조치완료(Y)")+COUNTIF($M8:INDIRECT(ADDRESS(ROW(),MATCH("",$4:$4,-1),1,1)),"Y") -> 1 | H8: =COUNTIF($M8:INDIRECT(ADDRESS(ROW(),MATCH("",$4:$4,-1),1,1)),"Y(즉시조치)")+COUNTIF($M8:INDIRECT(ADDRESS(ROW(),MATCH("",$4:$4,-1),1,1)),"조치완료(즉시조치)") -> 0 | I8: =COUNTIF($M8:INDIRECT(ADDRESS(ROW(),MATCH("",$4:$4,-1),1,1)),"N") -> 3 | J8: =COUNTIF($M8:INDIRECT(ADDRESS(ROW(),MATCH("",$4:$4,-1),1,1)),"N/A")+COUNTIF($M8:INDIRECT(ADDRESS(ROW(),MATCH("",$4:$4,-1),1,1)),"조치완료(N/A)") -> 0 | K8: =VLOOKUP($D8,'parm(hidden)'!$B$8:$C$10,2,FALSE)*($F8-$J8) -> 12 | L8: =VLOOKUP($D8,'parm(hidden)'!$B$8:$C$10,2,FALSE)*($G8+$H8) -> 3 | M8: =HYPERLINK("["&MID(CELL("filename"),SEARCH("[",CELL("filename"))+1,SEARCH("]",CELL("filename"))-SEARCH("[",CELL("filename"))-1)&"]"&ADDRESS(ROW()+16,8,1,TRUE,M$4),INDIRECT(ADDRESS(ROW()+16,8,1,TRUE,M$4))) -> Y | N8: =HYPERLINK("["&MID(CELL("filename"),SEARCH("[",CELL("filename"))+1,SEARCH("]",CELL("filename"))-SEARCH("[",CELL("filename"))-1)&"]"&ADDRESS(ROW()+16,8,1,TRUE,N$4),INDIRECT(ADDRESS(ROW()+16,8,1,TRUE,N$4))) -> N | O8: =HYPERLINK("["&MID(CELL("filename"),SEARCH("[",CELL("filename"))+1,SEARCH("]",CELL("filename"))-SEARCH("[",CELL("filename"))-1)&"]"&ADDRESS(ROW()+16,8,1,TRUE,O$4),INDIRECT(ADDRESS(ROW()+16,8,1,TRUE,O$4))) -> N | P8: =HYPERLINK("["&MID(CELL("filename"),SEARCH("[",CELL("filename"))+1,SEARCH("]",CELL("filename"))-SEARCH("[",CELL("filename"))-1)&"]"&ADDRESS(ROW()+16,8,1,TRUE,P$4),INDIRECT(ADDRESS(ROW()+16,8,1,TRUE,P$4))) -> N
A9: =ChkList!$A9 -> 계정 관리 | B9: =ChkList!$B9 -> W-05 | C9: =ChkList!$C9 -> 해독 가능한 암호화를 사용하여 암호 저장 해제 | D9: H | E9: =IF(D9="H",3,IF(D9="M",2,IF(D9="L",1,""))) -> 3 | F9: =COUNTA($M9:INDIRECT(ADDRESS(ROW(),MATCH("",$4:$4,-1),1,1))) -> 4 | G9: =COUNTIF($M9:INDIRECT(ADDRESS(ROW(),MATCH("",$4:$4,-1),1,1)),"조치완료(Y)")+COUNTIF($M9:INDIRECT(ADDRESS(ROW(),MATCH("",$4:$4,-1),1,1)),"Y") -> 4 | H9: =COUNTIF($M9:INDIRECT(ADDRESS(ROW(),MATCH("",$4:$4,-1),1,1)),"Y(즉시조치)")+COUNTIF($M9:INDIRECT(ADDRESS(ROW(),MATCH("",$4:$4,-1),1,1)),"조치완료(즉시조치)") -> 0 | I9: =COUNTIF($M9:INDIRECT(ADDRESS(ROW(),MATCH("",$4:$4,-1),1,1)),"N") -> 0 | J9: =COUNTIF($M9:INDIRECT(ADDRESS(ROW(),MATCH("",$4:$4,-1),1,1)),"N/A")+COUNTIF($M9:INDIRECT(ADDRESS(ROW(),MATCH("",$4:$4,-1),1,1)),"조치완료(N/A)") -> 0 | K9: =VLOOKUP($D9,'parm(hidden)'!$B$8:$C$10,2,FALSE)*($F9-$J9) -> 12 | L9: =VLOOKUP($D9,'parm(hidden)'!$B$8:$C$10,2,FALSE)*($G9+$H9) -> 12 | M9: =HYPERLINK("["&MID(CELL("filename"),SEARCH("[",CELL("filename"))+1,SEARCH("]",CELL("filename"))-SEARCH("[",CELL("filename"))-1)&"]"&ADDRESS(ROW()+16,8,1,TRUE,M$4),INDIRECT(ADDRESS(ROW()+16,8,1,TRUE,M$4))) -> Y | N9: =HYPERLINK("["&MID(CELL("filename"),SEARCH("[",CELL("filename"))+1,SEARCH("]",CELL("filename"))-SEARCH("[",CELL("filename"))-1)&"]"&ADDRESS(ROW()+16,8,1,TRUE,N$4),INDIRECT(ADDRESS(ROW()+16,8,1,TRUE,N$4))) -> Y | O9: =HYPERLINK("["&MID(CELL("filename"),SEARCH("[",CELL("filename"))+1,SEARCH("]",CELL("filename"))-SEARCH("[",CELL("filename"))-1)&"]"&ADDRESS(ROW()+16,8,1,TRUE,O$4),INDIRECT(ADDRESS(ROW()+16,8,1,TRUE,O$4))) -> Y | P9: =HYPERLINK("["&MID(CELL("filename"),SEARCH("[",CELL("filename"))+1,SEARCH("]",CELL("filename"))-SEARCH("[",CELL("filename"))-1)&"]"&ADDRESS(ROW()+16,8,1,TRUE,P$4),INDIRECT(ADDRESS(ROW()+16,8,1,TRUE,P$4))) -> Y
A10: =ChkList!$A10 -> 계정 관리 | B10: =ChkList!$B10 -> W-06 | C10: =ChkList!$C10 -> 관리자 그룹에 최소한의 사용자 포함 | D10: H | E10: =IF(D10="H",3,IF(D10="M",2,IF(D10="L",1,""))) -> 3 | F10: =COUNTA($M10:INDIRECT(ADDRESS(ROW(),MATCH("",$4:$4,-1),1,1))) -> 4 | G10: =COUNTIF($M10:INDIRECT(ADDRESS(ROW(),MATCH("",$4:$4,-1),1,1)),"조치완료(Y)")+COUNTIF($M10:INDIRECT(ADDRESS(ROW(),MATCH("",$4:$4,-1),1,1)),"Y") -> 4 | H10: =COUNTIF($M10:INDIRECT(ADDRESS(ROW(),MATCH("",$4:$4,-1),1,1)),"Y(즉시조치)")+COUNTIF($M10:INDIRECT(ADDRESS(ROW(),MATCH("",$4:$4,-1),1,1)),"조치완료(즉시조치)") -> 0 | I10: =COUNTIF($M10:INDIRECT(ADDRESS(ROW(),MATCH("",$4:$4,-1),1,1)),"N") -> 0 | J10: =COUNTIF($M10:INDIRECT(ADDRESS(ROW(),MATCH("",$4:$4,-1),1,1)),"N/A")+COUNTIF($M10:INDIRECT(ADDRESS(ROW(),MATCH("",$4:$4,-1),1,1)),"조치완료(N/A)") -> 0 | K10: =VLOOKUP($D10,'parm(hidden)'!$B$8:$C$10,2,FALSE)*($F10-$J10) -> 12 | L10: =VLOOKUP($D10,'parm(hidden)'!$B$8:$C$10,2,FALSE)*($G10+$H10) -> 12 | M10: =HYPERLINK("["&MID(CELL("filename"),SEARCH("[",CELL("filename"))+1,SEARCH("]",CELL("filename"))-SEARCH("[",CELL("filename"))-1)&"]"&ADDRESS(ROW()+16,8,1,TRUE,M$4),INDIRECT(ADDRESS(ROW()+16,8,1,TRUE,M$4))) -> Y | N10: =HYPERLINK("["&MID(CELL("filename"),SEARCH("[",CELL("filename"))+1,SEARCH("]",CELL("filename"))-SEARCH("[",CELL("filename"))-1)&"]"&ADDRESS(ROW()+16,8,1,TRUE,N$4),INDIRECT(ADDRESS(ROW()+16,8,1,TRUE,N$4))) -> Y | O10: =HYPERLINK("["&MID(CELL("filename"),SEARCH("[",CELL("filename"))+1,SEARCH("]",CELL("filename"))-SEARCH("[",CELL("filename"))-1)&"]"&ADDRESS(ROW()+16,8,1,TRUE,O$4),INDIRECT(ADDRESS(ROW()+16,8,1,TRUE,O$4))) -> Y | P10: =HYPERLINK("["&MID(CELL("filename"),SEARCH("[",CELL("filename"))+1,SEARCH("]",CELL("filename"))-SEARCH("[",CELL("filename"))-1)&"]"&ADDRESS(ROW()+16,8,1,TRUE,P$4),INDIRECT(ADDRESS(ROW()+16,8,1,TRUE,P$4))) -> Y
A11: =ChkList!$A11 -> 계정 관리 | B11: =ChkList!$B11 -> W-07 | C11: =ChkList!$C11 -> Everyone 사용 권한을 익명 사용자에 적용 | D11: H | E11: =IF(D11="H",3,IF(D11="M",2,IF(D11="L",1,""))) -> 3 | F11: =COUNTA($M11:INDIRECT(ADDRESS(ROW(),MATCH("",$4:$4,-1),1,1))) -> 4 | G11: =COUNTIF($M11:INDIRECT(ADDRESS(ROW(),MATCH("",$4:$4,-1),1,1)),"조치완료(Y)")+COUNTIF($M11:INDIRECT(ADDRESS(ROW(),MATCH("",$4:$4,-1),1,1)),"Y") -> 4 | H11: =COUNTIF($M11:INDIRECT(ADDRESS(ROW(),MATCH("",$4:$4,-1),1,1)),"Y(즉시조치)")+COUNTIF($M11:INDIRECT(ADDRESS(ROW(),MATCH("",$4:$4,-1),1,1)),"조치완료(즉시조치)") -> 0 | I11: =COUNTIF($M11:INDIRECT(ADDRESS(ROW(),MATCH("",$4:$4,-1),1,1)),"N") -> 0 | J11: =COUNTIF($M11:INDIRECT(ADDRESS(ROW(),MATCH("",$4:$4,-1),1,1)),"N/A")+COUNTIF($M11:INDIRECT(ADDRESS(ROW(),MATCH("",$4:$4,-1),1,1)),"조치완료(N/A)") -> 0 | K11: =VLOOKUP($D11,'parm(hidden)'!$B$8:$C$10,2,FALSE)*($F11-$J11) -> 12 | L11: =VLOOKUP($D11,'parm(hidden)'!$B$8:$C$10,2,FALSE)*($G11+$H11) -> 12 | M11: =HYPERLINK("["&MID(CELL("filename"),SEARCH("[",CELL("filename"))+1,SEARCH("]",CELL("filename"))-SEARCH("[",CELL("filename"))-1)&"]"&ADDRESS(ROW()+16,8,1,TRUE,M$4),INDIRECT(ADDRESS(ROW()+16,8,1,TRUE,M$4))) -> Y | N11: =HYPERLINK("["&MID(CELL("filename"),SEARCH("[",CELL("filename"))+1,SEARCH("]",CELL("filename"))-SEARCH("[",CELL("filename"))-1)&"]"&ADDRESS(ROW()+16,8,1,TRUE,N$4),INDIRECT(ADDRESS(ROW()+16,8,1,TRUE,N$4))) -> Y | O11: =HYPERLINK("["&MID(CELL("filename"),SEARCH("[",CELL("filename"))+1,SEARCH("]",CELL("filename"))-SEARCH("[",CELL("filename"))-1)&"]"&ADDRESS(ROW()+16,8,1,TRUE,O$4),INDIRECT(ADDRESS(ROW()+16,8,1,TRUE,O$4))) -> Y | P11: =HYPERLINK("["&MID(CELL("filename"),SEARCH("[",CELL("filename"))+1,SEARCH("]",CELL("filename"))-SEARCH("[",CELL("filename"))-1)&"]"&ADDRESS(ROW()+16,8,1,TRUE,P$4),INDIRECT(ADDRESS(ROW()+16,8,1,TRUE,P$4))) -> Y
A12: =ChkList!$A12 -> 계정 관리 | B12: =ChkList!$B12 -> W-08 | C12: =ChkList!$C12 -> 계정 잠금 기간 설정 | D12: M | E12: =IF(D12="H",3,IF(D12="M",2,IF(D12="L",1,""))) -> 2 | F12: =COUNTA($M12:INDIRECT(ADDRESS(ROW(),MATCH("",$4:$4,-1),1,1))) -> 4 | G12: =COUNTIF($M12:INDIRECT(ADDRESS(ROW(),MATCH("",$4:$4,-1),1,1)),"조치완료(Y)")+COUNTIF($M12:INDIRECT(ADDRESS(ROW(),MATCH("",$4:$4,-1),1,1)),"Y") -> 1 | H12: =COUNTIF($M12:INDIRECT(ADDRESS(ROW(),MATCH("",$4:$4,-1),1,1)),"Y(즉시조치)")+COUNTIF($M12:INDIRECT(ADDRESS(ROW(),MATCH("",$4:$4,-1),1,1)),"조치완료(즉시조치)") -> 0 | I12: =COUNTIF($M12:INDIRECT(ADDRESS(ROW(),MATCH("",$4:$4,-1),1,1)),"N") -> 3 | J12: =COUNTIF($M12:INDIRECT(ADDRESS(ROW(),MATCH("",$4:$4,-1),1,1)),"N/A")+COUNTIF($M12:INDIRECT(ADDRESS(ROW(),MATCH("",$4:$4,-1),1,1)),"조치완료(N/A)") -> 0 | K12: =VLOOKUP($D12,'parm(hidden)'!$B$8:$C$10,2,FALSE)*($F12-$J12) -> 8 | L12: =VLOOKUP($D12,'parm(hidden)'!$B$8:$C$10,2,FALSE)*($G12+$H12) -> 2 | M12: =HYPERLINK("["&MID(CELL("filename"),SEARCH("[",CELL("filename"))+1,SEARCH("]",CELL("filename"))-SEARCH("[",CELL("filename"))-1)&"]"&ADDRESS(ROW()+16,8,1,TRUE,M$4),INDIRECT(ADDRESS(ROW()+16,8,1,TRUE,M$4))) -> Y | N12: =HYPERLINK("["&MID(CELL("filename"),SEARCH("[",CELL("filename"))+1,SEARCH("]",CELL("filename"))-SEARCH("[",CELL("filename"))-1)&"]"&ADDRESS(ROW()+16,8,1,TRUE,N$4),INDIRECT(ADDRESS(ROW()+16,8,1,TRUE,N$4))) -> N | O12: =HYPERLINK("["&MID(CELL("filename"),SEARCH("[",CELL("filename"))+1,SEARCH("]",CELL("filename"))-SEARCH("[",CELL("filename"))-1)&"]"&ADDRESS(ROW()+16,8,1,TRUE,O$4),INDIRECT(ADDRESS(ROW()+16,8,1,TRUE,O$4))) -> N | P12: =HYPERLINK("["&MID(CELL("filename"),SEARCH("[",CELL("filename"))+1,SEARCH("]",CELL("filename"))-SEARCH("[",CELL("filename"))-1)&"]"&ADDRESS(ROW()+16,8,1,TRUE,P$4),INDIRECT(ADDRESS(ROW()+16,8,1,TRUE,P$4))) -> N
A13: =ChkList!$A13 -> 계정 관리 | B13: =ChkList!$B13 -> W-09 | C13: =ChkList!$C13 -> 비밀번호 관리 정책 설정 | D13: M | E13: =IF(D13="H",3,IF(D13="M",2,IF(D13="L",1,""))) -> 2 | F13: =COUNTA($M13:INDIRECT(ADDRESS(ROW(),MATCH("",$4:$4,-1),1,1))) -> 4 | G13: =COUNTIF($M13:INDIRECT(ADDRESS(ROW(),MATCH("",$4:$4,-1),1,1)),"조치완료(Y)")+COUNTIF($M13:INDIRECT(ADDRESS(ROW(),MATCH("",$4:$4,-1),1,1)),"Y") -> 1 | H13: =COUNTIF($M13:INDIRECT(ADDRESS(ROW(),MATCH("",$4:$4,-1),1,1)),"Y(즉시조치)")+COUNTIF($M13:INDIRECT(ADDRESS(ROW(),MATCH("",$4:$4,-1),1,1)),"조치완료(즉시조치)") -> 0 | I13: =COUNTIF($M13:INDIRECT(ADDRESS(ROW(),MATCH("",$4:$4,-1),1,1)),"N") -> 3 | J13: =COUNTIF($M13:INDIRECT(ADDRESS(ROW(),MATCH("",$4:$4,-1),1,1)),"N/A")+COUNTIF($M13:INDIRECT(ADDRESS(ROW(),MATCH("",$4:$4,-1),1,1)),"조치완료(N/A)") -> 0 | K13: =VLOOKUP($D13,'parm(hidden)'!$B$8:$C$10,2,FALSE)*($F13-$J13) -> 8 | L13: =VLOOKUP($D13,'parm(hidden)'!$B$8:$C$10,2,FALSE)*($G13+$H13) -> 2 | M13: =HYPERLINK("["&MID(CELL("filename"),SEARCH("[",CELL("filename"))+1,SEARCH("]",CELL("filename"))-SEARCH("[",CELL("filename"))-1)&"]"&ADDRESS(ROW()+16,8,1,TRUE,M$4),INDIRECT(ADDRESS(ROW()+16,8,1,TRUE,M$4))) -> Y | N13: =HYPERLINK("["&MID(CELL("filename"),SEARCH("[",CELL("filename"))+1,SEARCH("]",CELL("filename"))-SEARCH("[",CELL("filename"))-1)&"]"&ADDRESS(ROW()+16,8,1,TRUE,N$4),INDIRECT(ADDRESS(ROW()+16,8,1,TRUE,N$4))) -> N | O13: =HYPERLINK("["&MID(CELL("filename"),SEARCH("[",CELL("filename"))+1,SEARCH("]",CELL("filename"))-SEARCH("[",CELL("filename"))-1)&"]"&ADDRESS(ROW()+16,8,1,TRUE,O$4),INDIRECT(ADDRESS(ROW()+16,8,1,TRUE,O$4))) -> N | P13: =HYPERLINK("["&MID(CELL("filename"),SEARCH("[",CELL("filename"))+1,SEARCH("]",CELL("filename"))-SEARCH("[",CELL("filename"))-1)&"]"&ADDRESS(ROW()+16,8,1,TRUE,P$4),INDIRECT(ADDRESS(ROW()+16,8,1,TRUE,P$4))) -> N
A14: =ChkList!$A14 -> 계정 관리 | B14: =ChkList!$B14 -> W-10 | C14: =ChkList!$C14 -> 마지막 사용자 이름 표시 안 함 | D14: M | E14: =IF(D14="H",3,IF(D14="M",2,IF(D14="L",1,""))) -> 2 | F14: =COUNTA($M14:INDIRECT(ADDRESS(ROW(),MATCH("",$4:$4,-1),1,1))) -> 4 | G14: =COUNTIF($M14:INDIRECT(ADDRESS(ROW(),MATCH("",$4:$4,-1),1,1)),"조치완료(Y)")+COUNTIF($M14:INDIRECT(ADDRESS(ROW(),MATCH("",$4:$4,-1),1,1)),"Y") -> 1 | H14: =COUNTIF($M14:INDIRECT(ADDRESS(ROW(),MATCH("",$4:$4,-1),1,1)),"Y(즉시조치)")+COUNTIF($M14:INDIRECT(ADDRESS(ROW(),MATCH("",$4:$4,-1),1,1)),"조치완료(즉시조치)") -> 0 | I14: =COUNTIF($M14:INDIRECT(ADDRESS(ROW(),MATCH("",$4:$4,-1),1,1)),"N") -> 3 | J14: =COUNTIF($M14:INDIRECT(ADDRESS(ROW(),MATCH("",$4:$4,-1),1,1)),"N/A")+COUNTIF($M14:INDIRECT(ADDRESS(ROW(),MATCH("",$4:$4,-1),1,1)),"조치완료(N/A)") -> 0 | K14: =VLOOKUP($D14,'parm(hidden)'!$B$8:$C$10,2,FALSE)*($F14-$J14) -> 8 | L14: =VLOOKUP($D14,'parm(hidden)'!$B$8:$C$10,2,FALSE)*($G14+$H14) -> 2 | M14: =HYPERLINK("["&MID(CELL("filename"),SEARCH("[",CELL("filename"))+1,SEARCH("]",CELL("filename"))-SEARCH("[",CELL("filename"))-1)&"]"&ADDRESS(ROW()+16,8,1,TRUE,M$4),INDIRECT(ADDRESS(ROW()+16,8,1,TRUE,M$4))) -> Y | N14: =HYPERLINK("["&MID(CELL("filename"),SEARCH("[",CELL("filename"))+1,SEARCH("]",CELL("filename"))-SEARCH("[",CELL("filename"))-1)&"]"&ADDRESS(ROW()+16,8,1,TRUE,N$4),INDIRECT(ADDRESS(ROW()+16,8,1,TRUE,N$4))) -> N | O14: =HYPERLINK("["&MID(CELL("filename"),SEARCH("[",CELL("filename"))+1,SEARCH("]",CELL("filename"))-SEARCH("[",CELL("filename"))-1)&"]"&ADDRESS(ROW()+16,8,1,TRUE,O$4),INDIRECT(ADDRESS(ROW()+16,8,1,TRUE,O$4))) -> N | P14: =HYPERLINK("["&MID(CELL("filename"),SEARCH("[",CELL("filename"))+1,SEARCH("]",CELL("filename"))-SEARCH("[",CELL("filename"))-1)&"]"&ADDRESS(ROW()+16,8,1,TRUE,P$4),INDIRECT(ADDRESS(ROW()+16,8,1,TRUE,P$4))) -> N
A15: =ChkList!#REF! -> #REF! | B15: =ChkList!#REF! -> #REF! | C15: =ChkList!#REF! -> #REF! | D15: M | E15: =IF(D15="H",3,IF(D15="M",2,IF(D15="L",1,""))) -> 2 | F15: =COUNTA($M15:INDIRECT(ADDRESS(ROW(),MATCH("",$4:$4,-1),1,1))) -> 4 | G15: =COUNTIF($M15:INDIRECT(ADDRESS(ROW(),MATCH("",$4:$4,-1),1,1)),"조치완료(Y)")+COUNTIF($M15:INDIRECT(ADDRESS(ROW(),MATCH("",$4:$4,-1),1,1)),"Y") -> 1 | H15: =COUNTIF($M15:INDIRECT(ADDRESS(ROW(),MATCH("",$4:$4,-1),1,1)),"Y(즉시조치)")+COUNTIF($M15:INDIRECT(ADDRESS(ROW(),MATCH("",$4:$4,-1),1,1)),"조치완료(즉시조치)") -> 0 | I15: =COUNTIF($M15:INDIRECT(ADDRESS(ROW(),MATCH("",$4:$4,-1),1,1)),"N") -> 3 | J15: =COUNTIF($M15:INDIRECT(ADDRESS(ROW(),MATCH("",$4:$4,-1),1,1)),"N/A")+COUNTIF($M15:INDIRECT(ADDRESS(ROW(),MATCH("",$4:$4,-1),1,1)),"조치완료(N/A)") -> 0 | K15: =VLOOKUP($D15,'parm(hidden)'!$B$8:$C$10,2,FALSE)*($F15-$J15) -> 8 | L15: =VLOOKUP($D15,'parm(hidden)'!$B$8:$C$10,2,FALSE)*($G15+$H15) -> 2 | M15: =HYPERLINK("["&MID(CELL("filename"),SEARCH("[",CELL("filename"))+1,SEARCH("]",CELL("filename"))-SEARCH("[",CELL("filename"))-1)&"]"&ADDRESS(ROW()+16,8,1,TRUE,M$4),INDIRECT(ADDRESS(ROW()+16,8,1,TRUE,M$4))) -> Y | N15: =HYPERLINK("["&MID(CELL("filename"),SEARCH("[",CELL("filename"))+1,SEARCH("]",CELL("filename"))-SEARCH("[",CELL("filename"))-1)&"]"&ADDRESS(ROW()+16,8,1,TRUE,N$4),INDIRECT(ADDRESS(ROW()+16,8,1,TRUE,N$4))) -> N | O15: =HYPERLINK("["&MID(CELL("filename"),SEARCH("[",CELL("filename"))+1,SEARCH("]",CELL("filename"))-SEARCH("[",CELL("filename"))-1)&"]"&ADDRESS(ROW()+16,8,1,TRUE,O$4),INDIRECT(ADDRESS(ROW()+16,8,1,TRUE,O$4))) -> N | P15: =HYPERLINK("["&MID(CELL("filename"),SEARCH("[",CELL("filename"))+1,SEARCH("]",CELL("filename"))-SEARCH("[",CELL("filename"))-1)&"]"&ADDRESS(ROW()+16,8,1,TRUE,P$4),INDIRECT(ADDRESS(ROW()+16,8,1,TRUE,P$4))) -> N
A16: =ChkList!$A15 -> 계정 관리 | B16: =ChkList!$B15 -> W-11 | C16: =ChkList!$C15 -> 로컬 로그온 허용 | D16: M | E16: =IF(D16="H",3,IF(D16="M",2,IF(D16="L",1,""))) -> 2 | F16: =COUNTA($M16:INDIRECT(ADDRESS(ROW(),MATCH("",$4:$4,-1),1,1))) -> 4 | G16: =COUNTIF($M16:INDIRECT(ADDRESS(ROW(),MATCH("",$4:$4,-1),1,1)),"조치완료(Y)")+COUNTIF($M16:INDIRECT(ADDRESS(ROW(),MATCH("",$4:$4,-1),1,1)),"Y") -> 1 | H16: =COUNTIF($M16:INDIRECT(ADDRESS(ROW(),MATCH("",$4:$4,-1),1,1)),"Y(즉시조치)")+COUNTIF($M16:INDIRECT(ADDRESS(ROW(),MATCH("",$4:$4,-1),1,1)),"조치완료(즉시조치)") -> 0 | I16: =COUNTIF($M16:INDIRECT(ADDRESS(ROW(),MATCH("",$4:$4,-1),1,1)),"N") -> 3 | J16: =COUNTIF($M16:INDIRECT(ADDRESS(ROW(),MATCH("",$4:$4,-1),1,1)),"N/A")+COUNTIF($M16:INDIRECT(ADDRESS(ROW(),MATCH("",$4:$4,-1),1,1)),"조치완료(N/A)") -> 0 | K16: =VLOOKUP($D16,'parm(hidden)'!$B$8:$C$10,2,FALSE)*($F16-$J16) -> 8 | L16: =VLOOKUP($D16,'parm(hidden)'!$B$8:$C$10,2,FALSE)*($G16+$H16) -> 2 | M16: =HYPERLINK("["&MID(CELL("filename"),SEARCH("[",CELL("filename"))+1,SEARCH("]",CELL("filename"))-SEARCH("[",CELL("filename"))-1)&"]"&ADDRESS(ROW()+16,8,1,TRUE,M$4),INDIRECT(ADDRESS(ROW()+16,8,1,TRUE,M$4))) -> Y | N16: =HYPERLINK("["&MID(CELL("filename"),SEARCH("[",CELL("filename"))+1,SEARCH("]",CELL("filename"))-SEARCH("[",CELL("filename"))-1)&"]"&ADDRESS(ROW()+16,8,1,TRUE,N$4),INDIRECT(ADDRESS(ROW()+16,8,1,TRUE,N$4))) -> N | O16: =HYPERLINK("["&MID(CELL("filename"),SEARCH("[",CELL("filename"))+1,SEARCH("]",CELL("filename"))-SEARCH("[",CELL("filename"))-1)&"]"&ADDRESS(ROW()+16,8,1,TRUE,O$4),INDIRECT(ADDRESS(ROW()+16,8,1,TRUE,O$4))) -> N | P16: =HYPERLINK("["&MID(CELL("filename"),SEARCH("[",CELL("filename"))+1,SEARCH("]",CELL("filename"))-SEARCH("[",CELL("filename"))-1)&"]"&ADDRESS(ROW()+16,8,1,TRUE,P$4),INDIRECT(ADDRESS(ROW()+16,8,1,TRUE,P$4))) -> N
A17: =ChkList!$A16 -> 계정 관리 | B17: =ChkList!$B16 -> W-12 | C17: =ChkList!$C16 -> 익명 SID/이름 변환 허용 해제 | D17: M | E17: =IF(D17="H",3,IF(D17="M",2,IF(D17="L",1,""))) -> 2 | F17: =COUNTA($M17:INDIRECT(ADDRESS(ROW(),MATCH("",$4:$4,-1),1,1))) -> 4 | G17: =COUNTIF($M17:INDIRECT(ADDRESS(ROW(),MATCH("",$4:$4,-1),1,1)),"조치완료(Y)")+COUNTIF($M17:INDIRECT(ADDRESS(ROW(),MATCH("",$4:$4,-1),1,1)),"Y") -> 1 | H17: =COUNTIF($M17:INDIRECT(ADDRESS(ROW(),MATCH("",$4:$4,-1),1,1)),"Y(즉시조치)")+COUNTIF($M17:INDIRECT(ADDRESS(ROW(),MATCH("",$4:$4,-1),1,1)),"조치완료(즉시조치)") -> 0 | I17: =COUNTIF($M17:INDIRECT(ADDRESS(ROW(),MATCH("",$4:$4,-1),1,1)),"N") -> 3 | J17: =COUNTIF($M17:INDIRECT(ADDRESS(ROW(),MATCH("",$4:$4,-1),1,1)),"N/A")+COUNTIF($M17:INDIRECT(ADDRESS(ROW(),MATCH("",$4:$4,-1),1,1)),"조치완료(N/A)") -> 0 | K17: =VLOOKUP($D17,'parm(hidden)'!$B$8:$C$10,2,FALSE)*($F17-$J17) -> 8 | L17: =VLOOKUP($D17,'parm(hidden)'!$B$8:$C$10,2,FALSE)*($G17+$H17) -> 2 | M17: =HYPERLINK("["&MID(CELL("filename"),SEARCH("[",CELL("filename"))+1,SEARCH("]",CELL("filename"))-SEARCH("[",CELL("filename"))-1)&"]"&ADDRESS(ROW()+16,8,1,TRUE,M$4),INDIRECT(ADDRESS(ROW()+16,8,1,TRUE,M$4))) -> Y | N17: =HYPERLINK("["&MID(CELL("filename"),SEARCH("[",CELL("filename"))+1,SEARCH("]",CELL("filename"))-SEARCH("[",CELL("filename"))-1)&"]"&ADDRESS(ROW()+16,8,1,TRUE,N$4),INDIRECT(ADDRESS(ROW()+16,8,1,TRUE,N$4))) -> N | O17: =HYPERLINK("["&MID(CELL("filename"),SEARCH("[",CELL("filename"))+1,SEARCH("]",CELL("filename"))-SEARCH("[",CELL("filename"))-1)&"]"&ADDRESS(ROW()+16,8,1,TRUE,O$4),INDIRECT(ADDRESS(ROW()+16,8,1,TRUE,O$4))) -> N | P17: =HYPERLINK("["&MID(CELL("filename"),SEARCH("[",CELL("filename"))+1,SEARCH("]",CELL("filename"))-SEARCH("[",CELL("filename"))-1)&"]"&ADDRESS(ROW()+16,8,1,TRUE,P$4),INDIRECT(ADDRESS(ROW()+16,8,1,TRUE,P$4))) -> N
A18: =ChkList!$A17 -> 계정 관리 | B18: =ChkList!$B17 -> W-13 | C18: =ChkList!$C17 -> 콘솔 로그온 시 로컬 계정에서 빈 암호 사용 제한 | D18: M | E18: =IF(D18="H",3,IF(D18="M",2,IF(D18="L",1,""))) -> 2 | F18: =COUNTA($M18:INDIRECT(ADDRESS(ROW(),MATCH("",$4:$4,-1),1,1))) -> 4 | G18: =COUNTIF($M18:INDIRECT(ADDRESS(ROW(),MATCH("",$4:$4,-1),1,1)),"조치완료(Y)")+COUNTIF($M18:INDIRECT(ADDRESS(ROW(),MATCH("",$4:$4,-1),1,1)),"Y") -> 1 | H18: =COUNTIF($M18:INDIRECT(ADDRESS(ROW(),MATCH("",$4:$4,-1),1,1)),"Y(즉시조치)")+COUNTIF($M18:INDIRECT(ADDRESS(ROW(),MATCH("",$4:$4,-1),1,1)),"조치완료(즉시조치)") -> 0 | I18: =COUNTIF($M18:INDIRECT(ADDRESS(ROW(),MATCH("",$4:$4,-1),1,1)),"N") -> 3 | J18: =COUNTIF($M18:INDIRECT(ADDRESS(ROW(),MATCH("",$4:$4,-1),1,1)),"N/A")+COUNTIF($M18:INDIRECT(ADDRESS(ROW(),MATCH("",$4:$4,-1),1,1)),"조치완료(N/A)") -> 0 | K18: =VLOOKUP($D18,'parm(hidden)'!$B$8:$C$10,2,FALSE)*($F18-$J18) -> 8 | L18: =VLOOKUP($D18,'parm(hidden)'!$B$8:$C$10,2,FALSE)*($G18+$H18) -> 2 | M18: =HYPERLINK("["&MID(CELL("filename"),SEARCH("[",CELL("filename"))+1,SEARCH("]",CELL("filename"))-SEARCH("[",CELL("filename"))-1)&"]"&ADDRESS(ROW()+16,8,1,TRUE,M$4),INDIRECT(ADDRESS(ROW()+16,8,1,TRUE,M$4))) -> Y | N18: =HYPERLINK("["&MID(CELL("filename"),SEARCH("[",CELL("filename"))+1,SEARCH("]",CELL("filename"))-SEARCH("[",CELL("filename"))-1)&"]"&ADDRESS(ROW()+16,8,1,TRUE,N$4),INDIRECT(ADDRESS(ROW()+16,8,1,TRUE,N$4))) -> N | O18: =HYPERLINK("["&MID(CELL("filename"),SEARCH("[",CELL("filename"))+1,SEARCH("]",CELL("filename"))-SEARCH("[",CELL("filename"))-1)&"]"&ADDRESS(ROW()+16,8,1,TRUE,O$4),INDIRECT(ADDRESS(ROW()+16,8,1,TRUE,O$4))) -> N | P18: =HYPERLINK("["&MID(CELL("filename"),SEARCH("[",CELL("filename"))+1,SEARCH("]",CELL("filename"))-SEARCH("[",CELL("filename"))-1)&"]"&ADDRESS(ROW()+16,8,1,TRUE,P$4),INDIRECT(ADDRESS(ROW()+16,8,1,TRUE,P$4))) -> N
A19: =ChkList!$A18 -> 계정 관리 | B19: =ChkList!$B18 -> W-14 | C19: =ChkList!$C18 -> 원격터미널 접속 가능한 사용자 그룹 제한 | D19: M | E19: =IF(D19="H",3,IF(D19="M",2,IF(D19="L",1,""))) -> 2 | F19: =COUNTA($M19:INDIRECT(ADDRESS(ROW(),MATCH("",$4:$4,-1),1,1))) -> 4 | G19: =COUNTIF($M19:INDIRECT(ADDRESS(ROW(),MATCH("",$4:$4,-1),1,1)),"조치완료(Y)")+COUNTIF($M19:INDIRECT(ADDRESS(ROW(),MATCH("",$4:$4,-1),1,1)),"Y") -> 4 | H19: =COUNTIF($M19:INDIRECT(ADDRESS(ROW(),MATCH("",$4:$4,-1),1,1)),"Y(즉시조치)")+COUNTIF($M19:INDIRECT(ADDRESS(ROW(),MATCH("",$4:$4,-1),1,1)),"조치완료(즉시조치)") -> 0 | I19: =COUNTIF($M19:INDIRECT(ADDRESS(ROW(),MATCH("",$4:$4,-1),1,1)),"N") -> 0 | J19: =COUNTIF($M19:INDIRECT(ADDRESS(ROW(),MATCH("",$4:$4,-1),1,1)),"N/A")+COUNTIF($M19:INDIRECT(ADDRESS(ROW(),MATCH("",$4:$4,-1),1,1)),"조치완료(N/A)") -> 0 | K19: =VLOOKUP($D19,'parm(hidden)'!$B$8:$C$10,2,FALSE)*($F19-$J19) -> 8 | L19: =VLOOKUP($D19,'parm(hidden)'!$B$8:$C$10,2,FALSE)*($G19+$H19) -> 8 | M19: =HYPERLINK("["&MID(CELL("filename"),SEARCH("[",CELL("filename"))+1,SEARCH("]",CELL("filename"))-SEARCH("[",CELL("filename"))-1)&"]"&ADDRESS(ROW()+16,8,1,TRUE,M$4),INDIRECT(ADDRESS(ROW()+16,8,1,TRUE,M$4))) -> Y | N19: =HYPERLINK("["&MID(CELL("filename"),SEARCH("[",CELL("filename"))+1,SEARCH("]",CELL("filename"))-SEARCH("[",CELL("filename"))-1)&"]"&ADDRESS(ROW()+16,8,1,TRUE,N$4),INDIRECT(ADDRESS(ROW()+16,8,1,TRUE,N$4))) -> Y | O19: =HYPERLINK("["&MID(CELL("filename"),SEARCH("[",CELL("filename"))+1,SEARCH("]",CELL("filename"))-SEARCH("[",CELL("filename"))-1)&"]"&ADDRESS(ROW()+16,8,1,TRUE,O$4),INDIRECT(ADDRESS(ROW()+16,8,1,TRUE,O$4))) -> Y | P19: =HYPERLINK("["&MID(CELL("filename"),SEARCH("[",CELL("filename"))+1,SEARCH("]",CELL("filename"))-SEARCH("[",CELL("filename"))-1)&"]"&ADDRESS(ROW()+16,8,1,TRUE,P$4),INDIRECT(ADDRESS(ROW()+16,8,1,TRUE,P$4))) -> Y
A20: =ChkList!$A19 -> 서비스 관리 | B20: =ChkList!$B19 -> W-15 | C20: =ChkList!$C19 -> 사용자 개인키 사용 시 암호 입력 | D20: M | E20: =IF(D20="H",3,IF(D20="M",2,IF(D20="L",1,""))) -> 2 | F20: =COUNTA($M20:INDIRECT(ADDRESS(ROW(),MATCH("",$4:$4,-1),1,1))) -> 4 | G20: =COUNTIF($M20:INDIRECT(ADDRESS(ROW(),MATCH("",$4:$4,-1),1,1)),"조치완료(Y)")+COUNTIF($M20:INDIRECT(ADDRESS(ROW(),MATCH("",$4:$4,-1),1,1)),"Y") -> 1 | H20: =COUNTIF($M20:INDIRECT(ADDRESS(ROW(),MATCH("",$4:$4,-1),1,1)),"Y(즉시조치)")+COUNTIF($M20:INDIRECT(ADDRESS(ROW(),MATCH("",$4:$4,-1),1,1)),"조치완료(즉시조치)") -> 0 | I20: =COUNTIF($M20:INDIRECT(ADDRESS(ROW(),MATCH("",$4:$4,-1),1,1)),"N") -> 3 | J20: =COUNTIF($M20:INDIRECT(ADDRESS(ROW(),MATCH("",$4:$4,-1),1,1)),"N/A")+COUNTIF($M20:INDIRECT(ADDRESS(ROW(),MATCH("",$4:$4,-1),1,1)),"조치완료(N/A)") -> 0 | K20: =VLOOKUP($D20,'parm(hidden)'!$B$8:$C$10,2,FALSE)*($F20-$J20) -> 8 | L20: =VLOOKUP($D20,'parm(hidden)'!$B$8:$C$10,2,FALSE)*($G20+$H20) -> 2 | M20: =HYPERLINK("["&MID(CELL("filename"),SEARCH("[",CELL("filename"))+1,SEARCH("]",CELL("filename"))-SEARCH("[",CELL("filename"))-1)&"]"&ADDRESS(ROW()+16,8,1,TRUE,M$4),INDIRECT(ADDRESS(ROW()+16,8,1,TRUE,M$4))) -> Y | N20: =HYPERLINK("["&MID(CELL("filename"),SEARCH("[",CELL("filename"))+1,SEARCH("]",CELL("filename"))-SEARCH("[",CELL("filename"))-1)&"]"&ADDRESS(ROW()+16,8,1,TRUE,N$4),INDIRECT(ADDRESS(ROW()+16,8,1,TRUE,N$4))) -> N | O20: =HYPERLINK("["&MID(CELL("filename"),SEARCH("[",CELL("filename"))+1,SEARCH("]",CELL("filename"))-SEARCH("[",CELL("filename"))-1)&"]"&ADDRESS(ROW()+16,8,1,TRUE,O$4),INDIRECT(ADDRESS(ROW()+16,8,1,TRUE,O$4))) -> N | P20: =HYPERLINK("["&MID(CELL("filename"),SEARCH("[",CELL("filename"))+1,SEARCH("]",CELL("filename"))-SEARCH("[",CELL("filename"))-1)&"]"&ADDRESS(ROW()+16,8,1,TRUE,P$4),INDIRECT(ADDRESS(ROW()+16,8,1,TRUE,P$4))) -> N
A21: =ChkList!$A20 -> 서비스 관리 | B21: =ChkList!$B20 -> W-16 | C21: =ChkList!$C20 -> 공유 권한 및 사용자 그룹 설정 | D21: M | E21: =IF(D21="H",3,IF(D21="M",2,IF(D21="L",1,""))) -> 2 | F21: =COUNTA($M21:INDIRECT(ADDRESS(ROW(),MATCH("",$4:$4,-1),1,1))) -> 4 | G21: =COUNTIF($M21:INDIRECT(ADDRESS(ROW(),MATCH("",$4:$4,-1),1,1)),"조치완료(Y)")+COUNTIF($M21:INDIRECT(ADDRESS(ROW(),MATCH("",$4:$4,-1),1,1)),"Y") -> 3 | H21: =COUNTIF($M21:INDIRECT(ADDRESS(ROW(),MATCH("",$4:$4,-1),1,1)),"Y(즉시조치)")+COUNTIF($M21:INDIRECT(ADDRESS(ROW(),MATCH("",$4:$4,-1),1,1)),"조치완료(즉시조치)") -> 0 | I21: =COUNTIF($M21:INDIRECT(ADDRESS(ROW(),MATCH("",$4:$4,-1),1,1)),"N") -> 0 | J21: =COUNTIF($M21:INDIRECT(ADDRESS(ROW(),MATCH("",$4:$4,-1),1,1)),"N/A")+COUNTIF($M21:INDIRECT(ADDRESS(ROW(),MATCH("",$4:$4,-1),1,1)),"조치완료(N/A)") -> 1 | K21: =VLOOKUP($D21,'parm(hidden)'!$B$8:$C$10,2,FALSE)*($F21-$J21) -> 6 | L21: =VLOOKUP($D21,'parm(hidden)'!$B$8:$C$10,2,FALSE)*($G21+$H21) -> 6 | M21: =HYPERLINK("["&MID(CELL("filename"),SEARCH("[",CELL("filename"))+1,SEARCH("]",CELL("filename"))-SEARCH("[",CELL("filename"))-1)&"]"&ADDRESS(ROW()+16,8,1,TRUE,M$4),INDIRECT(ADDRESS(ROW()+16,8,1,TRUE,M$4))) -> N/A | N21: =HYPERLINK("["&MID(CELL("filename"),SEARCH("[",CELL("filename"))+1,SEARCH("]",CELL("filename"))-SEARCH("[",CELL("filename"))-1)&"]"&ADDRESS(ROW()+16,8,1,TRUE,N$4),INDIRECT(ADDRESS(ROW()+16,8,1,TRUE,N$4))) -> Y | O21: =HYPERLINK("["&MID(CELL("filename"),SEARCH("[",CELL("filename"))+1,SEARCH("]",CELL("filename"))-SEARCH("[",CELL("filename"))-1)&"]"&ADDRESS(ROW()+16,8,1,TRUE,O$4),INDIRECT(ADDRESS(ROW()+16,8,1,TRUE,O$4))) -> Y | P21: =HYPERLINK("["&MID(CELL("filename"),SEARCH("[",CELL("filename"))+1,SEARCH("]",CELL("filename"))-SEARCH("[",CELL("filename"))-1)&"]"&ADDRESS(ROW()+16,8,1,TRUE,P$4),INDIRECT(ADDRESS(ROW()+16,8,1,TRUE,P$4))) -> Y
A22: =ChkList!$A21 -> 서비스 관리 | B22: =ChkList!$B21 -> W-17 | C22: =ChkList!$C21 -> 하드디스크 기본 공유 제거 | D22: M | E22: =IF(D22="H",3,IF(D22="M",2,IF(D22="L",1,""))) -> 2 | F22: =COUNTA($M22:INDIRECT(ADDRESS(ROW(),MATCH("",$4:$4,-1),1,1))) -> 4 | G22: =COUNTIF($M22:INDIRECT(ADDRESS(ROW(),MATCH("",$4:$4,-1),1,1)),"조치완료(Y)")+COUNTIF($M22:INDIRECT(ADDRESS(ROW(),MATCH("",$4:$4,-1),1,1)),"Y") -> 0 | H22: =COUNTIF($M22:INDIRECT(ADDRESS(ROW(),MATCH("",$4:$4,-1),1,1)),"Y(즉시조치)")+COUNTIF($M22:INDIRECT(ADDRESS(ROW(),MATCH("",$4:$4,-1),1,1)),"조치완료(즉시조치)") -> 0 | I22: =COUNTIF($M22:INDIRECT(ADDRESS(ROW(),MATCH("",$4:$4,-1),1,1)),"N") -> 4 | J22: =COUNTIF($M22:INDIRECT(ADDRESS(ROW(),MATCH("",$4:$4,-1),1,1)),"N/A")+COUNTIF($M22:INDIRECT(ADDRESS(ROW(),MATCH("",$4:$4,-1),1,1)),"조치완료(N/A)") -> 0 | K22: =VLOOKUP($D22,'parm(hidden)'!$B$8:$C$10,2,FALSE)*($F22-$J22) -> 8 | L22: =VLOOKUP($D22,'parm(hidden)'!$B$8:$C$10,2,FALSE)*($G22+$H22) -> 0 | M22: =HYPERLINK("["&MID(CELL("filename"),SEARCH("[",CELL("filename"))+1,SEARCH("]",CELL("filename"))-SEARCH("[",CELL("filename"))-1)&"]"&ADDRESS(ROW()+16,8,1,TRUE,M$4),INDIRECT(ADDRESS(ROW()+16,8,1,TRUE,M$4))) -> N | N22: =HYPERLINK("["&MID(CELL("filename"),SEARCH("[",CELL("filename"))+1,SEARCH("]",CELL("filename"))-SEARCH("[",CELL("filename"))-1)&"]"&ADDRESS(ROW()+16,8,1,TRUE,N$4),INDIRECT(ADDRESS(ROW()+16,8,1,TRUE,N$4))) -> N | O22: =HYPERLINK("["&MID(CELL("filename"),SEARCH("[",CELL("filename"))+1,SEARCH("]",CELL("filename"))-SEARCH("[",CELL("filename"))-1)&"]"&ADDRESS(ROW()+16,8,1,TRUE,O$4),INDIRECT(ADDRESS(ROW()+16,8,1,TRUE,O$4))) -> N | P22: =HYPERLINK("["&MID(CELL("filename"),SEARCH("[",CELL("filename"))+1,SEARCH("]",CELL("filename"))-SEARCH("[",CELL("filename"))-1)&"]"&ADDRESS(ROW()+16,8,1,TRUE,P$4),INDIRECT(ADDRESS(ROW()+16,8,1,TRUE,P$4))) -> N
A23: =ChkList!$A22 -> 서비스 관리 | B23: =ChkList!$B22 -> W-18 | C23: =ChkList!$C22 -> 불필요한 서비스 제거 | D23: M | E23: =IF(D23="H",3,IF(D23="M",2,IF(D23="L",1,""))) -> 2 | F23: =COUNTA($M23:INDIRECT(ADDRESS(ROW(),MATCH("",$4:$4,-1),1,1))) -> 4 | G23: =COUNTIF($M23:INDIRECT(ADDRESS(ROW(),MATCH("",$4:$4,-1),1,1)),"조치완료(Y)")+COUNTIF($M23:INDIRECT(ADDRESS(ROW(),MATCH("",$4:$4,-1),1,1)),"Y") -> 0 | H23: =COUNTIF($M23:INDIRECT(ADDRESS(ROW(),MATCH("",$4:$4,-1),1,1)),"Y(즉시조치)")+COUNTIF($M23:INDIRECT(ADDRESS(ROW(),MATCH("",$4:$4,-1),1,1)),"조치완료(즉시조치)") -> 0 | I23: =COUNTIF($M23:INDIRECT(ADDRESS(ROW(),MATCH("",$4:$4,-1),1,1)),"N") -> 4 | J23: =COUNTIF($M23:INDIRECT(ADDRESS(ROW(),MATCH("",$4:$4,-1),1,1)),"N/A")+COUNTIF($M23:INDIRECT(ADDRESS(ROW(),MATCH("",$4:$4,-1),1,1)),"조치완료(N/A)") -> 0 | K23: =VLOOKUP($D23,'parm(hidden)'!$B$8:$C$10,2,FALSE)*($F23-$J23) -> 8 | L23: =VLOOKUP($D23,'parm(hidden)'!$B$8:$C$10,2,FALSE)*($G23+$H23) -> 0 | M23: =HYPERLINK("["&MID(CELL("filename"),SEARCH("[",CELL("filename"))+1,SEARCH("]",CELL("filename"))-SEARCH("[",CELL("filename"))-1)&"]"&ADDRESS(ROW()+16,8,1,TRUE,M$4),INDIRECT(ADDRESS(ROW()+16,8,1,TRUE,M$4))) -> N | N23: =HYPERLINK("["&MID(CELL("filename"),SEARCH("[",CELL("filename"))+1,SEARCH("]",CELL("filename"))-SEARCH("[",CELL("filename"))-1)&"]"&ADDRESS(ROW()+16,8,1,TRUE,N$4),INDIRECT(ADDRESS(ROW()+16,8,1,TRUE,N$4))) -> N | O23: =HYPERLINK("["&MID(CELL("filename"),SEARCH("[",CELL("filename"))+1,SEARCH("]",CELL("filename"))-SEARCH("[",CELL("filename"))-1)&"]"&ADDRESS(ROW()+16,8,1,TRUE,O$4),INDIRECT(ADDRESS(ROW()+16,8,1,TRUE,O$4))) -> N | P23: =HYPERLINK("["&MID(CELL("filename"),SEARCH("[",CELL("filename"))+1,SEARCH("]",CELL("filename"))-SEARCH("[",CELL("filename"))-1)&"]"&ADDRESS(ROW()+16,8,1,TRUE,P$4),INDIRECT(ADDRESS(ROW()+16,8,1,TRUE,P$4))) -> N
