Workbook
Name _10월_변동내역_메모_확인: #REF!
Name _10월_변동내역_메모_확인: #REF!
Name _10월_변동내역_메모_확인: #REF!
Name _10월_변동내역_메모_확인: #REF!
Name _10월_변동내역_메모_확인: #REF!
Name _10월_변동내역_메모_확인: #REF!
Name _10월_변동내역_메모_확인: #REF!
Name _10월_변동내역_메모_확인: #REF!
Name _10월_변동내역_메모_확인: #REF!
Name _10월_변동내역_메모_확인: #REF!
Name _10월_변동내역_메모_확인: #REF!
Name _10월_변동내역_메모_확인: #REF!
Name _10월_변동내역_메모_확인: #REF!
Name _10월_변동내역_메모_확인: #REF!
Name _10월_변동내역_메모_확인: #REF!
Name _abc: #REF!
Name _abc: #REF!
Name _abc: #REF!
Name _abc: #REF!
Name _abc: #REF!
Name _abc: #REF!
Name _abc: #REF!
Name _abc: #REF!
Name _abc: #REF!
Name _abc: #REF!
Name _abc: #REF!
Name _abc: #REF!
Name _Order1: 255
Name _Order2: 255
Name a: #REF!
Name a: #REF!
Name a: #REF!
Name a: #REF!
Name a: #REF!
Name a: #REF!
Name a: #REF!
Name a: #REF!
Name a: #REF!
Name a: #REF!
Name a: #REF!
Name a: #REF!
Name abc: #REF!
Name abc: #REF!
Name abc: #REF!
Name abc: #REF!
Name abc: #REF!
Name abc: #REF!
Name abc: #REF!
Name abc: #REF!
Name abc: #REF!
Name abc: #REF!
Name abc: #REF!
Name abc: #REF!
Name asd: #REF!
Name asd: #REF!
Name asd: #REF!
Name asd: #REF!
Name asd: #REF!
Name asd: #REF!
Name asd: #REF!

Sheet 표지
F11: 46219

Sheet 자산목록
A1: ■ 자산목록
A3: No. | B3: 호스트명 | C3: IP | D3: 제조업체 | E3: 구분 | F3: 모델명 | G3: OS/SW | H3: 버전 | I3: 자산명/용도 | J3: 설치위치 | K3: 부서 | L3: 담당자 | M3: 비고 | N3: 자산 평가
N4: 기밀성 | O4: 무결성 | P4: 가용성 | Q4: 등급 | R4: 점수(Hidden)
A5: 1 | B5: HQ-CORE-L3-A | C5: 10.10.40.28/28 10.10.40.36/29 10.10.40.68/29 10.10.40.92/28 10.10.40.108/28 10.10.40.116/29 10.10.40.250/30 | D5: CISCO | E5: - | I5: L3 스위치 | J5: 본사 내부망 | K5: 본사 | L5: 홍길동 | Q5: =IF(R5>=7,"H",IF(R5>=5,"M","L")) -> L | R5: =SUM(N5:P5) -> 0
A6: 2 | B6: HQ-CORE-L3-B | C6: 10.10.40.37/29 10.10.40.29/28 10.10.40.69/29 10.10.40.93/28 10.10.40.109/28 10.10.40.117/29 10.10.40.254/30 | D6: CISCO | E6: - | I6: L3 스위치 | J6: 본사 내부망 | K6: 본사 | L6: 홍길동 | Q6: =IF(R6>=7,"H",IF(R6>=5,"M","L")) -> L | R6: =SUM(N6:P6) -> 0 | S6: management 이전
A7: 3 | B7: HQ-DMZ-L3 | C7: 10.10.40.14/28 10.10.40.238/30 10.10.40.241/30 | D7: CISCO | E7: - | I7: L3 스위치 | J7: 본사 DMZ망 | K7: 본사 | L7: 홍길동 | Q7: =IF(R7>=7,"H",IF(R7>=5,"M","L")) -> L | R7: =SUM(N7:P7) -> 0 | S7: conetents
A8: 4 | B8: BR-CORE-L3-A | C8: 10.200.40.28/28 10.200.40.36/29 10.200.40.68/29 10.200.40.76/29 10.200.40.92/28 10.200.10.2/30 | D8: CISCO | E8: - | I8: L3 스위치 | J8: 지사 내부망 | K8: 지사 | L8: 김철수 | Q8: L | R8: =SUM(N8:P8) -> 0
A9: 5 | B9: BR-CORE-L3-B | C9: 10.200.40.29/28 10.200.40.37/29 10.200.40.69/29 10.200.40.77/29 10.200.40.93/28 10.200.20.2/30 | D9: CISCO | E9: - | I9: L3 스위치 | J9: 지사 내부망 | K9: 지사 | L9: 김철수 | Q9: =IF(R9>=7,"H",IF(R9>=5,"M","L")) -> L | R9: =SUM(N9:P9) -> 0 | S9: sales 이전
A10: 6 | B10: BR-DMZ-L3 | C10: 10.200.40.6 10.200.40.9 10.200.40.14 | D10: CISCO | E10: - | I10: L3 스위치 | J10: 지사 DMZ망 | K10: 지사 | L10: 김철수 | Q10: L | R10: =SUM(N10:P10) -> 0
A11: 7 | B11: HQ-BACKUP-SW | C11: - | D11: CISCO | E11: - | I11: L2 스위치 | J11: 본사 서버망 | K11: 본사 | L11: 홍길동 | Q11: =IF(R11>=7,"H",IF(R11>=5,"M","L")) -> L | R11: =SUM(N11:P11) -> 0 | S11: production 이전
A12: 8 | B12: HQ-SERVER-SW | C12: - | D12: CISCO | E12: - | I12: L2 스위치 | J12: 본사 서버망 | K12: 본사 | L12: 홍길동 | Q12: =IF(R12>=7,"H",IF(R12>=5,"M","L")) -> L | R12: =SUM(N12:P12) -> 0
A13: 9 | B13: HQ-HR-SW | C13: - | D13: CISCO | E13: - | I13: L2 스위치 | J13: 본사 사내망 | K13: 본사 인사팀 | L13: 홍길동 | Q13: =IF(R13>=7,"H",IF(R13>=5,"M","L")) -> L | R13: =SUM(N13:P13) -> 0
A14: 10 | B14: HQ-DEV-SW | C14: - | D14: CISCO | E14: - | I14: L2 스위치 | J14: 본사 사내망 | K14: 본사 개발팀 | L14: 홍길동 | Q14: =IF(R14>=7,"H",IF(R14>=5,"M","L")) -> L | R14: =SUM(N14:P14) -> 0
A15: 11 | B15: HQ-OPS-SW | C15: - | D15: CISCO | E15: - | I15: L2 스위치 | J15: 본사 사내망 | K15: 본사 운영팀 | L15: 홍길동 | Q15: =IF(R15>=7,"H",IF(R15>=5,"M","L")) -> L | R15: =SUM(N15:P15) -> 0
A16: 12 | B16: HQ-CS-SW | C16: - | D16: CISCO | E16: - | I16: L2 스위치 | J16: 본사 사내망 | K16: 본사 CS팀 | L16: 홍길동 | Q16: =IF(R16>=7,"H",IF(R16>=5,"M","L")) -> L | R16: =SUM(N16:P16) -> 0
A17: 13 | B17: BR-BACKUP-SW | C17: - | D17: CISCO | E17: - | I17: L2 스위치 | J17: 지사 서버망 | K17: 지사 | L17: 김철수 | Q17: =IF(R17>=7,"H",IF(R17>=5,"M","L")) -> L | R17: =SUM(N17:P17) -> 0
A18: 14 | B18: BR-SERVER-SW | C18: - | D18: CISCO | E18: - | I18: L2 스위치 | J18: 지사 서버망 | K18: 지사 | L18: 김철수 | Q18: =IF(R18>=7,"H",IF(R18>=5,"M","L")) -> L | R18: =SUM(N18:P18) -> 0
A19: 15 | B19: BR-LOGISTICS-SW | C19: - | D19: CISCO | E19: - | I19: L2 스위치 | J19: 지사 사내망 | K19: 지사 물류팀 | L19: 김철수 | Q19: =IF(R19>=7,"H",IF(R19>=5,"M","L")) -> L | R19: =SUM(N19:P19) -> 0
A20: 16 | B20: BR-OPS-SW | C20: - | D20: CISCO | E20: - | I20: L2 스위치 | J20: 지사 사내망 | K20: 지사 운영팀 | L20: 김철수 | Q20: =IF(R20>=7,"H",IF(R20>=5,"M","L")) -> L | R20: =SUM(N20:P20) -> 0
A21: 17 | B21: BR-CS-SW | C21: - | D21: CISCO | E21: - | I21: L2 스위치 | J21: 지사 사내망 | K21: 지사 CS팀 | L21: 김철수 | Q21: =IF(R21>=7,"H",IF(R21>=5,"M","L")) -> L | R21: =SUM(N21:P21) -> 0
A22: 18 | B22: HQ-SCREENING-R | C22: 10.10.40.233/30 | D22: CISCO | E22: - | I22: 라우터 | J22: 본사 외부망 경계 | K22: 본사 | L22: 홍길동 | Q22: =IF(R22>=7,"H",IF(R22>=5,"M","L")) -> L | R22: =SUM(N22:P22) -> 0
A23: 19 | B23: HQ-EDGE-FW | C23: 10.10.40.234/30 10.10.40.237/30 | D23: CISCO | E23: - | I23: 라우터 | J23: 본사 방화벽 | K23: 본사 | L23: 홍길동 | Q23: =IF(R23>=7,"H",IF(R23>=5,"M","L")) -> L | R23: =SUM(N23:P23) -> 0
... A27: 23 | B27: BR-INTERNAL-FW-R | C27: 10.200.40.10/30 10.200.10.1/30 10.200.20.1/30 | D27: CISCO | E27: - | I27: 라우터 | J27: 지사 내부방화벽 | K27: 지사 | L27: 김철수 | Q27: =IF(R27>=7,"H",IF(R27>=5,"M","L")) -> L | R27: =SUM(N27:P27) -> 0

Sheet parm(hidden)
B2: 1. 분류 Code
B3: Code
B4: NW
B6: 2. 중요도, 자산등급, 위협도 점수
B7: 중요도 | C7: 점수
B8: H | C8: 3
B9: M | C9: 2
B10: L | C10: 1
B12: 3. 점검결과 점수
B13: 점검 결과 | C13: 점수
C14: 취약점 진단 | D14: 위험평가
B15: Y | C15: 1 | D15: 0
B16: N | C16: 0 | D16: 3 | F16: P | G16: 0.5 | H16: 0.5
B17: N/A | C17: 0 | D17: 0
B18: R/A | C18: 0 | D18: 0
B19: Y(즉시조치) | C19: 1 | D19: 0
B21: 4. DoA
B22: DoA
B23: 21
B25: 5. 자산등급 점수 범위 | F25: 8_2. 위험평가 방법론
B26: 위험 등급 | C26: 점수 범위
C27: 최저 | D27: 최고
B28: H | C28: 7 | D28: 9
B29: M | C29: 5 | D29: 6
B30: L | C30: 3 | D30: 4
B32: 6. 위협도 점수 범위
B33: 위험 등급 | C33: 점수 범위
C34: 최저 | D34: 최고
B35: H | C35: 5 | D35: 6
B36: M | C36: 4 | D36: 4
B37: L | C37: 2 | D37: 3
B39: 7. 위험도 점수 범위
B40: 위험 등급 | C40: 점수 범위
C41: 최저 | D41: 최고
B42: H | C42: =$B$23 -> 21 | D42: 30
B43: M | C43: 11 | D43: =$C$42-1 -> 20
B44: L | C44: 1 | D44: =$C$43-1 -> 10
B46: 8. 위험도 평가표
B47: 8_1. 위험도 평가표
B48: V' | C48: 보호대책 | D48: Y=0(보호대책 있음) | M48: N=1(보호대책 없음)
...

Sheet ChkList
A1: ■ Check List
A3: 취약점 진단항목 | F3: 개선방안 및 보호대책
A4: 분류 | C4: 진단항목 | D4: 중요도 | E4: 위험도 | F4: Network
A5: 계정 관리 | B5: N-01 | C5: 비밀번호 설정 | D5: H | E5: 3 | F5: 기본 비밀번호를 관리기관의 비밀번호 작성규칙을 준용하여 변경
A6: 계정 관리 | B6: N-02 | C6: 비밀번호 복잡성 설정 | D6: H | E6: 3 | F6: 관리기관의 비밀번호 작성규칙에 맞게 비밀번호 복잡성 정책 및 비밀번호 설정
A7: 계정 관리 | B7: N-03 | C7: 암호화된 비밀번호 사용 | D7: H | E7: 3 | F7: 비밀번호 암호화 설정 적용
A8: 계정 관리 | B8: N-04 | C8: 계정 잠금 임계값 설정 | D8: H | E8: 3 | F8: 로그인 실패 임계값을 5회 이하로 설정
A9: 계정 관리 | B9: N-05 | C9: 사용자·명령어별 권한 설정 | D9: M | E9: 2 | F9: 업무에 맞게 계정별 권한 차등(관리자 권한 최소화) 부여 ※ 한 명의 관리자가 네트워크 장비를 관리할 경우는 해당하지 않음
A10: 접근 관리 | B10: N-06 | C10: VTY 접근(ACL) 설정 | D10: H | E10: 3 | F10: 가상 터미널(VTY)에 특정 IP주소만 접근할 수 있도록 설정
A11: 접근 관리 | B11: N-07 | C11: Session Timeout 설정 | D11: H | E11: 3 | F11: Session Timeout 설정 (10분 이하 권고)
A12: 접근 관리 | B12: N-08 | C12: VTY 접속 시 안전한 프로토콜 사용 | D12: M | E12: 2 | F12: 암호화 프로토콜만 VTY에 접근할 수 있도록 설정
A13: 접근 관리 | B13: N-09 | C13: 불필요한 보조 입출력 포트 사용 금지 | D13: M | E13: 2 | F13: 불필요한 포트 및 인터페이스 사용 제한 또는 비활성화
A14: 접근 관리 | B14: N-10 | C14: 로그인 시 경고 메시지 설정 | D14: M | E14: 2 | F14: 네트워크 장비 접속 시 경고 메시지 설정
A15: 접근 관리 | B15: N-11 | C15: 원격로그 서버 사용 | D15: M | E15: 2 | F15: Syslog 등을 이용하여 로그 저장 설정
A16: 패치 관리 | B16: N-12 | C16: 주기적 보안 패치 및 벤더 권고사항 적용 | D16: H | E16: 3 | F16: 장비별 제공하는 최신 취약점 정보를 파악 후 최신 패치 및 업그레이드를 수행
... A42: 기능 관리 | B42: N-38 | C42: mask-reply 차단 | D42: M | E42: 2 | F42: 각 인터페이스에서 mask-reply 비활성화

Sheet 취약점 진단 통계
A1: ■ 영역별/장비별 보안수준 통계
A3: 1) 영역별 보안수준
A4: 분류 | E4: 진단 결과 | J4: 중요도점수
E5: 전체항목 | F5: 진단항목 | G5: 양호 | H5: 취약 | I5: 해당없음 | J5: 전체점수 | K5: 평가점수 | L5: 보안수준
A6: 계정 관리 | E6: =SUMIF('취약점 진단 항목별 통계'!$A:$A,$A6&"*",'취약점 진단 항목별 통계'!$F:$F) -> 80 | F6: =E6-I6 -> 80 | G6: =SUMIF('취약점 진단 항목별 통계'!$A:$A,$A6&"*",'취약점 진단 항목별 통계'!$G:$G)+SUMIF('취약점 진단 항목별 통계'!$A:$A,$A6&"*",'취약점 진단 항목별 통계'!$H:$H) -> 65 | H6: =SUMIF('취약점 진단 항목별 통계'!$A:$A,$A6&"*",'취약점 진단 항목별 통계'!$I:$I) -> 15 | I6: =SUMIF('취약점 진단 항목별 통계'!$A:$A,$A6&"*",'취약점 진단 항목별 통계'!$J:$J) -> 0 | J6: =SUMIF('취약점 진단 항목별 통계'!$A:$A,$A6&"*",'취약점 진단 항목별 통계'!$K:$K) -> 224 | K6: =SUMIF('취약점 진단 항목별 통계'!$A:$A,$A6&"*",'취약점 진단 항목별 통계'!$L:$L) -> 182 | L6: =IF($I6=$E6,"N/A",(K6/J6)) -> 0.8125
A7: 접근 관리 | E7: =SUMIF('취약점 진단 항목별 통계'!$A:$A,$A7&"*",'취약점 진단 항목별 통계'!$F:$F) -> 96 | F7: =E7-I7 -> 96 | G7: =SUMIF('취약점 진단 항목별 통계'!$A:$A,$A7&"*",'취약점 진단 항목별 통계'!$G:$G)+SUMIF('취약점 진단 항목별 통계'!$A:$A,$A7&"*",'취약점 진단 항목별 통계'!$H:$H) -> 68 | H7: =SUMIF('취약점 진단 항목별 통계'!$A:$A,$A7&"*",'취약점 진단 항목별 통계'!$I:$I) -> 15 | I7: =SUMIF('취약점 진단 항목별 통계'!$A:$A,$A7&"*",'취약점 진단 항목별 통계'!$J:$J) -> 0 | J7: =SUMIF('취약점 진단 항목별 통계'!$A:$A,$A7&"*",'취약점 진단 항목별 통계'!$K:$K) -> 224 | K7: =SUMIF('취약점 진단 항목별 통계'!$A:$A,$A7&"*",'취약점 진단 항목별 통계'!$L:$L) -> 162 | L7: =IF($I7=$E7,"N/A",(K7/J7)) -> 0.72321429
A8: 패치 관리 | E8: =SUMIF('취약점 진단 항목별 통계'!$A:$A,$A8&"*",'취약점 진단 항목별 통계'!$F:$F) -> 16 | F8: =E8-I8 -> 14 | G8: =SUMIF('취약점 진단 항목별 통계'!$A:$A,$A8&"*",'취약점 진단 항목별 통계'!$G:$G)+SUMIF('취약점 진단 항목별 통계'!$A:$A,$A8&"*",'취약점 진단 항목별 통계'!$H:$H) -> 10 | H8: =SUMIF('취약점 진단 항목별 통계'!$A:$A,$A8&"*",'취약점 진단 항목별 통계'!$I:$I) -> 3 | I8: =SUMIF('취약점 진단 항목별 통계'!$A:$A,$A8&"*",'취약점 진단 항목별 통계'!$J:$J) -> 2 | J8: =SUMIF('취약점 진단 항목별 통계'!$A:$A,$A8&"*",'취약점 진단 항목별 통계'!$K:$K) -> 42 | K8: =SUMIF('취약점 진단 항목별 통계'!$A:$A,$A8&"*",'취약점 진단 항목별 통계'!$L:$L) -> 30 | L8: =IF($I8=$E8,"N/A",(K8/J8)) -> 0.71428571
A9: 로그 관리 | E9: =SUMIF('취약점 진단 항목별 통계'!$A:$A,$A9&"*",'취약점 진단 항목별 통계'!$F:$F) -> 64 | F9: =E9-I9 -> 63 | G9: =SUMIF('취약점 진단 항목별 통계'!$A:$A,$A9&"*",'취약점 진단 항목별 통계'!$G:$G)+SUMIF('취약점 진단 항목별 통계'!$A:$A,$A9&"*",'취약점 진단 항목별 통계'!$H:$H) -> 40 | H9: =SUMIF('취약점 진단 항목별 통계'!$A:$A,$A9&"*",'취약점 진단 항목별 통계'!$I:$I) -> 8 | I9: =SUMIF('취약점 진단 항목별 통계'!$A:$A,$A9&"*",'취약점 진단 항목별 통계'!$J:$J) -> 1 | J9: =SUMIF('취약점 진단 항목별 통계'!$A:$A,$A9&"*",'취약점 진단 항목별 통계'!$K:$K) -> 110 | K9: =SUMIF('취약점 진단 항목별 통계'!$A:$A,$A9&"*",'취약점 진단 항목별 통계'!$L:$L) -> 64 | L9: =IF($I9=$E9,"N/A",(K9/J9)) -> 0.58181818
A10: 기능 관리 | E10: =SUMIF('취약점 진단 항목별 통계'!$A:$A,$A10&"*",'취약점 진단 항목별 통계'!$F:$F) -> 352 | F10: =E10-I10 -> 323 | G10: =SUMIF('취약점 진단 항목별 통계'!$A:$A,$A10&"*",'취약점 진단 항목별 통계'!$G:$G)+SUMIF('취약점 진단 항목별 통계'!$A:$A,$A10&"*",'취약점 진단 항목별 통계'!$H:$H) -> 270 | H10: =SUMIF('취약점 진단 항목별 통계'!$A:$A,$A10&"*",'취약점 진단 항목별 통계'!$I:$I) -> 30 | I10: =SUMIF('취약점 진단 항목별 통계'!$A:$A,$A10&"*",'취약점 진단 항목별 통계'!$J:$J) -> 29 | J10: =SUMIF('취약점 진단 항목별 통계'!$A:$A,$A10&"*",'취약점 진단 항목별 통계'!$K:$K) -> 767 | K10: =SUMIF('취약점 진단 항목별 통계'!$A:$A,$A10&"*",'취약점 진단 항목별 통계'!$L:$L) -> 628 | L10: =IF($I10=$E10,"N/A",(K10/J10)) -> 0.81877445
A11: 계 | E11: =SUM(E6:E10) -> 608 | F11: =SUM(F6:F10) -> 576 | G11: =SUM(G6:G10) -> 453 | H11: =SUM(H6:H10) -> 71 | I11: =SUM(I6:I10) -> 32 | J11: =SUM(J6:J10) -> 1367 | K11: =SUM(K6:K10) -> 1066 | L11: =IFERROR(K11/J11,0) -> 0.7798098
A39: 2) 장비별 보안수준
A40: 장비 구분 | E40: 진단 결과 | J40: 중요도점수
E41: 전체항목 | F41: 진단항목 | G41: 양호 | H41: 취약 | I41: 해당없음 | J41: 전체점수 | K41: 평가점수 | L41: 보안수준
A42: =HYPERLINK("["&MID(CELL("filename"),SEARCH("[",CELL("filename"))+1,SEARCH("]",CELL("filename"))-SEARCH("[",CELL("filename"))-1)&"]"&INDIRECT(ADDRESS(ROW()-37,2,1,TRUE,"자산목록"))&"!A1",INDIRECT(ADDRESS(ROW()-37,2,1,TRUE,"자산목록"))) -> HQ-CORE-L3-A | C42: =IFERROR(VLOOKUP($A42,자산목록!$B$1:$M$847,8,FALSE),"-") -> L3 스위치 | E42: =IFERROR(INDIRECT(ADDRESS(17,4,1,TRUE,$A42)),0) -> 38 | F42: =E42-I42 -> 36 | G42: =IFERROR(INDIRECT(ADDRESS(17,5,1,TRUE,$A42)),0) -> 34 | H42: =IFERROR(INDIRECT(ADDRESS(17,6,1,TRUE,$A42)),0) -> 1 | I42: =IFERROR(INDIRECT(ADDRESS(17,7,1,TRUE,$A42)),0) -> 2 | J42: =IFERROR(INDIRECT(ADDRESS(17,18,1,TRUE,$A42)),0) -> 84 | K42: =IFERROR(INDIRECT(ADDRESS(17,19,1,TRUE,$A42)),0) -> 71 | L42: =IFERROR(INDIRECT(ADDRESS(17,8,1,TRUE,$A42)),0) -> 0.8452381
A43: =HYPERLINK("["&MID(CELL("filename"),SEARCH("[",CELL("filename"))+1,SEARCH("]",CELL("filename"))-SEARCH("[",CELL("filename"))-1)&"]"&INDIRECT(ADDRESS(ROW()-37,2,1,TRUE,"자산목록"))&"!A1",INDIRECT(ADDRESS(ROW()-37,2,1,TRUE,"자산목록"))) -> HQ-CORE-L3-B | C43: =IFERROR(VLOOKUP($A43,자산목록!$B$1:$M$847,8,FALSE),"-") -> L3 스위치 | E43: =IFERROR(INDIRECT(ADDRESS(17,4,1,TRUE,$A43)),0) -> 38 | F43: =E43-I43 -> 36 | G43: =IFERROR(INDIRECT(ADDRESS(17,5,1,TRUE,$A43)),0) -> 34 | H43: =IFERROR(INDIRECT(ADDRESS(17,6,1,TRUE,$A43)),0) -> 1 | I43: =IFERROR(INDIRECT(ADDRESS(17,7,1,TRUE,$A43)),0) -> 2 | J43: =IFERROR(INDIRECT(ADDRESS(17,18,1,TRUE,$A43)),0) -> 84 | K43: =IFERROR(INDIRECT(ADDRESS(17,19,1,TRUE,$A43)),0) -> 80 | L43: =IFERROR(INDIRECT(ADDRESS(17,8,1,TRUE,$A43)),0) -> 0.95238095
A44: =HYPERLINK("["&MID(CELL("filename"),SEARCH("[",CELL("filename"))+1,SEARCH("]",CELL("filename"))-SEARCH("[",CELL("filename"))-1)&"]"&INDIRECT(ADDRESS(ROW()-37,2,1,TRUE,"자산목록"))&"!A1",INDIRECT(ADDRESS(ROW()-37,2,1,TRUE,"자산목록"))) -> HQ-DMZ-L3 | C44: =IFERROR(VLOOKUP($A44,자산목록!$B$1:$M$847,8,FALSE),"-") -> L3 스위치 | E44: =IFERROR(INDIRECT(ADDRESS(17,4,1,TRUE,$A44)),0) -> 38 | F44: =E44-I44 -> 36 | G44: =IFERROR(INDIRECT(ADDRESS(17,5,1,TRUE,$A44)),0) -> 33 | H44: =IFERROR(INDIRECT(ADDRESS(17,6,1,TRUE,$A44)),0) -> 1 | I44: =IFERROR(INDIRECT(ADDRESS(17,7,1,TRUE,$A44)),0) -> 2 | J44: =IFERROR(INDIRECT(ADDRESS(17,18,1,TRUE,$A44)),0) -> 85 | K44: =IFERROR(INDIRECT(ADDRESS(17,19,1,TRUE,$A44)),0) -> 76 | L44: =IFERROR(INDIRECT(ADDRESS(17,8,1,TRUE,$A44)),0) -> 0.89411765
A45: =HYPERLINK("["&MID(CELL("filename"),SEARCH("[",CELL("filename"))+1,SEARCH("]",CELL("filename"))-SEARCH("[",CELL("filename"))-1)&"]"&INDIRECT(ADDRESS(ROW()-37,2,1,TRUE,"자산목록"))&"!A1",INDIRECT(ADDRESS(ROW()-37,2,1,TRUE,"자산목록"))) -> BR-CORE-L3-A | C45: =IFERROR(VLOOKUP($A45,자산목록!$B$1:$M$847,8,FALSE),"-") -> L3 스위치 | E45: =IFERROR(INDIRECT(ADDRESS(17,4,1,TRUE,$A45)),0) -> 38 | F45: =E45-I45 -> 38 | G45: =IFERROR(INDIRECT(ADDRESS(17,5,1,TRUE,$A45)),0) -> 4 | H45: =IFERROR(INDIRECT(ADDRESS(17,6,1,TRUE,$A45)),0) -> 32 | I45: =IFERROR(INDIRECT(ADDRESS(17,7,1,TRUE,$A45)),0) -> 0 | J45: =IFERROR(INDIRECT(ADDRESS(17,18,1,TRUE,$A45)),0) -> 90 | K45: =IFERROR(INDIRECT(ADDRESS(17,19,1,TRUE,$A45)),0) -> 10 | L45: =IFERROR(INDIRECT(ADDRESS(17,8,1,TRUE,$A45)),0) -> 0.11111111
A46: =HYPERLINK("["&MID(CELL("filename"),SEARCH("[",CELL("filename"))+1,SEARCH("]",CELL("filename"))-SEARCH("[",CELL("filename"))-1)&"]"&INDIRECT(ADDRESS(ROW()-37,2,1,TRUE,"자산목록"))&"!A1",INDIRECT(ADDRESS(ROW()-37,2,1,TRUE,"자산목록"))) -> BR-CORE-L3-B | C46: =IFERROR(VLOOKUP($A46,자산목록!$B$1:$M$847,8,FALSE),"-") -> L3 스위치 | E46: =IFERROR(INDIRECT(ADDRESS(17,4,1,TRUE,$A46)),0) -> 38 | F46: =E46-I46 -> 25 | G46: =IFERROR(INDIRECT(ADDRESS(17,5,1,TRUE,$A46)),0) -> 4 | H46: =IFERROR(INDIRECT(ADDRESS(17,6,1,TRUE,$A46)),0) -> 18 | I46: =IFERROR(INDIRECT(ADDRESS(17,7,1,TRUE,$A46)),0) -> 13 | J46: =IFERROR(INDIRECT(ADDRESS(17,18,1,TRUE,$A46)),0) -> 62 | K46: =IFERROR(INDIRECT(ADDRESS(17,19,1,TRUE,$A46)),0) -> 10 | L46: =IFERROR(INDIRECT(ADDRESS(17,8,1,TRUE,$A46)),0) -> 0.16129032
A47: =HYPERLINK("["&MID(CELL("filename"),SEARCH("[",CELL("filename"))+1,SEARCH("]",CELL("filename"))-SEARCH("[",CELL("filename"))-1)&"]"&INDIRECT(ADDRESS(ROW()-37,2,1,TRUE,"자산목록"))&"!A1",INDIRECT(ADDRESS(ROW()-37,2,1,TRUE,"자산목록"))) -> BR-DMZ-L3 | C47: =IFERROR(VLOOKUP($A47,자산목록!$B$1:$M$847,8,FALSE),"-") -> L3 스위치 | E47: =IFERROR(INDIRECT(ADDRESS(17,4,1,TRUE,$A47)),0) -> 38 | F47: =E47-I47 -> 25 | G47: =IFERROR(INDIRECT(ADDRESS(17,5,1,TRUE,$A47)),0) -> 4 | H47: =IFERROR(INDIRECT(ADDRESS(17,6,1,TRUE,$A47)),0) -> 18 | I47: =IFERROR(INDIRECT(ADDRESS(17,7,1,TRUE,$A47)),0) -> 13 | J47: =IFERROR(INDIRECT(ADDRESS(17,18,1,TRUE,$A47)),0) -> 62 | K47: =IFERROR(INDIRECT(ADDRESS(17,19,1,TRUE,$A47)),0) -> 10 | L47: =IFERROR(INDIRECT(ADDRESS(17,8,1,TRUE,$A47)),0) -> 0.16129032
A48: =HYPERLINK("["&MID(CELL("filename"),SEARCH("[",CELL("filename"))+1,SEARCH("]",CELL("filename"))-SEARCH("[",CELL("filename"))-1)&"]"&INDIRECT(ADDRESS(ROW()-37,2,1,TRUE,"자산목록"))&"!A1",INDIRECT(ADDRESS(ROW()-37,2,1,TRUE,"자산목록"))) -> HQ-BACKUP-SW | C48: =IFERROR(VLOOKUP($A48,자산목록!$B$1:$M$847,8,FALSE),"-") -> L2 스위치 | E48: =IFERROR(INDIRECT(ADDRESS(17,4,1,TRUE,$A48)),0) -> 38 | F48: =E48-I48 -> 38 | G48: =IFERROR(INDIRECT(ADDRESS(17,5,1,TRUE,$A48)),0) -> 34 | H48: =IFERROR(INDIRECT(ADDRESS(17,6,1,TRUE,$A48)),0) -> 0 | I48: =IFERROR(INDIRECT(ADDRESS(17,7,1,TRUE,$A48)),0) -> 0 | J48: =IFERROR(INDIRECT(ADDRESS(17,18,1,TRUE,$A48)),0) -> 90 | K48: =IFERROR(INDIRECT(ADDRESS(17,19,1,TRUE,$A48)),0) -> 80 | L48: =IFERROR(INDIRECT(ADDRESS(17,8,1,TRUE,$A48)),0) -> 0.88888889
A49: =HYPERLINK("["&MID(CELL("filename"),SEARCH("[",CELL("filename"))+1,SEARCH("]",CELL("filename"))-SEARCH("[",CELL("filename"))-1)&"]"&INDIRECT(ADDRESS(ROW()-37,2,1,TRUE,"자산목록"))&"!A1",INDIRECT(ADDRESS(ROW()-37,2,1,TRUE,"자산목록"))) -> HQ-SERVER-SW | C49: =IFERROR(VLOOKUP($A49,자산목록!$B$1:$M$847,8,FALSE),"-") -> L2 스위치 | E49: =IFERROR(INDIRECT(ADDRESS(17,4,1,TRUE,$A49)),0) -> 38 | F49: =E49-I49 -> 38 | G49: =IFERROR(INDIRECT(ADDRESS(17,5,1,TRUE,$A49)),0) -> 34 | H49: =IFERROR(INDIRECT(ADDRESS(17,6,1,TRUE,$A49)),0) -> 0 | I49: =IFERROR(INDIRECT(ADDRESS(17,7,1,TRUE,$A49)),0) -> 0 | J49: =IFERROR(INDIRECT(ADDRESS(17,18,1,TRUE,$A49)),0) -> 90 | K49: =IFERROR(INDIRECT(ADDRESS(17,19,1,TRUE,$A49)),0) -> 80 | L49: =IFERROR(INDIRECT(ADDRESS(17,8,1,TRUE,$A49)),0) -> 0.88888889
A50: =HYPERLINK("["&MID(CELL("filename"),SEARCH("[",CELL("filename"))+1,SEARCH("]",CELL("filename"))-SEARCH("[",CELL("filename"))-1)&"]"&INDIRECT(ADDRESS(ROW()-37,2,1,TRUE,"자산목록"))&"!A1",INDIRECT(ADDRESS(ROW()-37,2,1,TRUE,"자산목록"))) -> HQ-HR-SW | C50: =IFERROR(VLOOKUP($A50,자산목록!$B$1:$M$847,8,FALSE),"-") -> L2 스위치 | E50: =IFERROR(INDIRECT(ADDRESS(17,4,1,TRUE,$A50)),0) -> 38 | F50: =E50-I50 -> 38 | G50: =IFERROR(INDIRECT(ADDRESS(17,5,1,TRUE,$A50)),0) -> 34 | H50: =IFERROR(INDIRECT(ADDRESS(17,6,1,TRUE,$A50)),0) -> 0 | I50: =IFERROR(INDIRECT(ADDRESS(17,7,1,TRUE,$A50)),0) -> 0 | J50: =IFERROR(INDIRECT(ADDRESS(17,18,1,TRUE,$A50)),0) -> 90 | K50: =IFERROR(INDIRECT(ADDRESS(17,19,1,TRUE,$A50)),0) -> 80 | L50: =IFERROR(INDIRECT(ADDRESS(17,8,1,TRUE,$A50)),0) -> 0.88888889
A51: =HYPERLINK("["&MID(CELL("filename"),SEARCH("[",CELL("filename"))+1,SEARCH("]",CELL("filename"))-SEARCH("[",CELL("filename"))-1)&"]"&INDIRECT(ADDRESS(ROW()-37,2,1,TRUE,"자산목록"))&"!A1",INDIRECT(ADDRESS(ROW()-37,2,1,TRUE,"자산목록"))) -> HQ-DEV-SW | C51: =IFERROR(VLOOKUP($A51,자산목록!$B$1:$M$847,8,FALSE),"-") -> L2 스위치 | E51: =IFERROR(INDIRECT(ADDRESS(17,4,1,TRUE,$A51)),0) -> 38 | F51: =E51-I51 -> 38 | G51: =IFERROR(INDIRECT(ADDRESS(17,5,1,TRUE,$A51)),0) -> 34 | H51: =IFERROR(INDIRECT(ADDRESS(17,6,1,TRUE,$A51)),0) -> 0 | I51: =IFERROR(INDIRECT(ADDRESS(17,7,1,TRUE,$A51)),0) -> 0 | J51: =IFERROR(INDIRECT(ADDRESS(17,18,1,TRUE,$A51)),0) -> 90 | K51: =IFERROR(INDIRECT(ADDRESS(17,19,1,TRUE,$A51)),0) -> 80 | L51: =IFERROR(INDIRECT(ADDRESS(17,8,1,TRUE,$A51)),0) -> 0.88888889
A52: =HYPERLINK("["&MID(CELL("filename"),SEARCH("[",CELL("filename"))+1,SEARCH("]",CELL("filename"))-SEARCH("[",CELL("filename"))-1)&"]"&INDIRECT(ADDRESS(ROW()-37,2,1,TRUE,"자산목록"))&"!A1",INDIRECT(ADDRESS(ROW()-37,2,1,TRUE,"자산목록"))) -> HQ-OPS-SW | C52: =IFERROR(VLOOKUP($A52,자산목록!$B$1:$M$847,8,FALSE),"-") -> L2 스위치 | E52: =IFERROR(INDIRECT(ADDRESS(17,4,1,TRUE,$A52)),0) -> 38 | F52: =E52-I52 -> 38 | G52: =IFERROR(INDIRECT(ADDRESS(17,5,1,TRUE,$A52)),0) -> 34 | H52: =IFERROR(INDIRECT(ADDRESS(17,6,1,TRUE,$A52)),0) -> 0 | I52: =IFERROR(INDIRECT(ADDRESS(17,7,1,TRUE,$A52)),0) -> 0 | J52: =IFERROR(INDIRECT(ADDRESS(17,18,1,TRUE,$A52)),0) -> 90 | K52: =IFERROR(INDIRECT(ADDRESS(17,19,1,TRUE,$A52)),0) -> 80 | L52: =IFERROR(INDIRECT(ADDRESS(17,8,1,TRUE,$A52)),0) -> 0.88888889
A53: =HYPERLINK("["&MID(CELL("filename"),SEARCH("[",CELL("filename"))+1,SEARCH("]",CELL("filename"))-SEARCH("[",CELL("filename"))-1)&"]"&INDIRECT(ADDRESS(ROW()-37,2,1,TRUE,"자산목록"))&"!A1",INDIRECT(ADDRESS(ROW()-37,2,1,TRUE,"자산목록"))) -> HQ-CS-SW | C53: =IFERROR(VLOOKUP($A53,자산목록!$B$1:$M$847,8,FALSE),"-") -> L2 스위치 | E53: =IFERROR(INDIRECT(ADDRESS(17,4,1,TRUE,$A53)),0) -> 38 | F53: =E53-I53 -> 38 | G53: =IFERROR(INDIRECT(ADDRESS(17,5,1,TRUE,$A53)),0) -> 34 | H53: =IFERROR(INDIRECT(ADDRESS(17,6,1,TRUE,$A53)),0) -> 0 | I53: =IFERROR(INDIRECT(ADDRESS(17,7,1,TRUE,$A53)),0) -> 0 | J53: =IFERROR(INDIRECT(ADDRESS(17,18,1,TRUE,$A53)),0) -> 90 | K53: =IFERROR(INDIRECT(ADDRESS(17,19,1,TRUE,$A53)),0) -> 80 | L53: =IFERROR(INDIRECT(ADDRESS(17,8,1,TRUE,$A53)),0) -> 0.88888889
... A64: =HYPERLINK("["&MID(CELL("filename"),SEARCH("[",CELL("filename"))+1,SEARCH("]",CELL("filename"))-SEARCH("[",CELL("filename"))-1)&"]"&INDIRECT(ADDRESS(ROW()-37,2,1,TRUE,"자산목록"))&"!A1",INDIRECT(ADDRESS(ROW()-37,2,1,TRUE,"자산목록"))) -> BR-INTERNAL-FW-R | C64: =IFERROR(VLOOKUP($A64,자산목록!$B$1:$M$847,8,FALSE),"-") -> 라우터 | E64: =IFERROR(INDIRECT(ADDRESS(17,4,1,TRUE,$A64)),0) -> 38 | F64: =E64-I64 -> 38 | G64: =IFERROR(INDIRECT(ADDRESS(17,5,1,TRUE,$A64)),0) -> 34 | H64: =IFERROR(INDIRECT(ADDRESS(17,6,1,TRUE,$A64)),0) -> 0 | I64: =IFERROR(INDIRECT(ADDRESS(17,7,1,TRUE,$A64)),0) -> 0 | J64: =IFERROR(INDIRECT(ADDRESS(17,18,1,TRUE,$A64)),0) -> 90 | K64: =IFERROR(INDIRECT(ADDRESS(17,19,1,TRUE,$A64)),0) -> 80 | L64: =IFERROR(INDIRECT(ADDRESS(17,8,1,TRUE,$A64)),0) -> 0.88888889
A65: 계 | E65: =SUM(E42:E42) -> 38 | F65: =SUM(F42:F42) -> 36 | G65: =SUM(G42:G42) -> 34 | H65: =SUM(H42:H42) -> 1 | I65: =SUM(I42:I42) -> 2 | J65: =SUM(J42:J42) -> 84 | K65: =SUM(K42:K42) -> 71 | L65: =IFERROR(K65/J65,0) -> 0.8452381

Sheet 취약점 진단 항목별 통계
A1: ■ 취약점 진단 항목별 통계
A3: =ChkList!A4 -> 분류 | C3: =ChkList!C4 -> 진단항목 | D3: =ChkList!D4 -> 중요도 | F3: 진단 통계 | K3: 중요도 점수 | M3: 진단결과 | N3: 진단결과 | O3: 진단결과 | P3: 진단결과 | Q3: 진단결과 | R3: 진단결과 | S3: 진단결과 | T3: 진단결과 | U3: 진단결과 | V3: 진단결과 | W3: 진단결과 | X3: 진단결과 | Y3: 진단결과 | Z3: 진단결과 | AA3: 진단결과 | AB3: 진단결과
F4: 전체 | G4: 양호 | H4: 즉시조치 | I4: 취약 | J4: N/A | K4: 전체 | L4: 평가 | M4: =HYPERLINK("["&MID(CELL("filename"),SEARCH("[",CELL("filename"))+1,SEARCH("]",CELL("filename"))-SEARCH("[",CELL("filename"))-1)&"]"&INDIRECT(ADDRESS(COLUMN()-8,2,1,TRUE,"자산목록"))&"!A1",INDIRECT(ADDRESS(COLUMN()-8,2,1,TRUE,"자산목록"))) -> HQ-CORE-L3-A | N4: =HYPERLINK("["&MID(CELL("filename"),SEARCH("[",CELL("filename"))+1,SEARCH("]",CELL("filename"))-SEARCH("[",CELL("filename"))-1)&"]"&INDIRECT(ADDRESS(COLUMN()-8,2,1,TRUE,"자산목록"))&"!A1",INDIRECT(ADDRESS(COLUMN()-8,2,1,TRUE,"자산목록"))) -> HQ-CORE-L3-B | O4: =HYPERLINK("["&MID(CELL("filename"),SEARCH("[",CELL("filename"))+1,SEARCH("]",CELL("filename"))-SEARCH("[",CELL("filename"))-1)&"]"&INDIRECT(ADDRESS(COLUMN()-8,2,1,TRUE,"자산목록"))&"!A1",INDIRECT(ADDRESS(COLUMN()-8,2,1,TRUE,"자산목록"))) -> HQ-DMZ-L3 | P4: =HYPERLINK("["&MID(CELL("filename"),SEARCH("[",CELL("filename"))+1,SEARCH("]",CELL("filename"))-SEARCH("[",CELL("filename"))-1)&"]"&INDIRECT(ADDRESS(COLUMN()-8,2,1,TRUE,"자산목록"))&"!A1",INDIRECT(ADDRESS(COLUMN()-8,2,1,TRUE,"자산목록"))) -> BR-CORE-L3-A | Q4: =HYPERLINK("["&MID(CELL("filename"),SEARCH("[",CELL("filename"))+1,SEARCH("]",CELL("filename"))-SEARCH("[",CELL("filename"))-1)&"]"&INDIRECT(ADDRESS(COLUMN()-8,2,1,TRUE,"자산목록"))&"!A1",INDIRECT(ADDRESS(COLUMN()-8,2,1,TRUE,"자산목록"))) -> BR-CORE-L3-B | R4: =HYPERLINK("["&MID(CELL("filename"),SEARCH("[",CELL("filename"))+1,SEARCH("]",CELL("filename"))-SEARCH("[",CELL("filename"))-1)&"]"&INDIRECT(ADDRESS(COLUMN()-8,2,1,TRUE,"자산목록"))&"!A1",INDIRECT(ADDRESS(COLUMN()-8,2,1,TRUE,"자산목록"))) -> BR-DMZ-L3 | S4: =HYPERLINK("["&MID(CELL("filename"),SEARCH("[",CELL("filename"))+1,SEARCH("]",CELL("filename"))-SEARCH("[",CELL("filename"))-1)&"]"&INDIRECT(ADDRESS(COLUMN()-8,2,1,TRUE,"자산목록"))&"!A1",INDIRECT(ADDRESS(COLUMN()-8,2,1,TRUE,"자산목록"))) -> HQ-BACKUP-SW | T4: =HYPERLINK("["&MID(CELL("filename"),SEARCH("[",CELL("filename"))+1,SEARCH("]",CELL("filename"))-SEARCH("[",CELL("filename"))-1)&"]"&INDIRECT(ADDRESS(COLUMN()-8,2,1,TRUE,"자산목록"))&"!A1",INDIRECT(ADDRESS(COLUMN()-8,2,1,TRUE,"자산목록"))) -> HQ-SERVER-SW | ... AB4: =HYPERLINK("["&MID(CELL("filename"),SEARCH("[",CELL("filename"))+1,SEARCH("]",CELL("filename"))-SEARCH("[",CELL("filename"))-1)&"]"&INDIRECT(ADDRESS(COLUMN()-8,2,1,TRUE,"자산목록"))&"!A1",INDIRECT(ADDRESS(COLUMN()-8,2,1,TRUE,"자산목록"))) -> BR-OPS-SW
A5: =ChkList!A5 -> 계정 관리 | B5: =ChkList!$B5 -> N-01 | C5: =ChkList!$C5 -> 비밀번호 설정 | D5: =ChkList!$D5 -> H | E5: =ChkList!E5 -> 3 | F5: =COUNTA($M5:INDIRECT(ADDRESS(ROW(),MATCH("",$4:$4,-1),1,1))) -> 16 | G5: =COUNTIF($M5:INDIRECT(ADDRESS(ROW(),MATCH("",$4:$4,-1),1,1)),"조치완료(Y)")+COUNTIF($M5:INDIRECT(ADDRESS(ROW(),MATCH("",$4:$4,-1),1,1)),"Y") -> 13 | H5: =COUNTIF($M5:INDIRECT(ADDRESS(ROW(),MATCH("",$4:$4,-1),1,1)),"Y(즉시조치)")+COUNTIF($M5:INDIRECT(ADDRESS(ROW(),MATCH("",$4:$4,-1),1,1)),"조치완료(즉시조치)") -> 0 | I5: =COUNTIF($M5:INDIRECT(ADDRESS(ROW(),MATCH("",$4:$4,-1),1,1)),"N") -> 3 | J5: =COUNTIF($M5:INDIRECT(ADDRESS(ROW(),MATCH("",$4:$4,-1),1,1)),"N/A")+COUNTIF($M5:INDIRECT(ADDRESS(ROW(),MATCH("",$4:$4,-1),1,1)),"조치완료(N/A)") -> 0 | K5: =VLOOKUP($D5,'parm(hidden)'!$B$8:$C$10,2,FALSE)*($F5-$J5) -> 48 | L5: =VLOOKUP($D5,'parm(hidden)'!$B$8:$C$10,2,FALSE)*($G5+$H5) -> 39 | M5: =HYPERLINK("["&MID(CELL("filename"),SEARCH("[",CELL("filename"))+1,SEARCH("]",CELL("filename"))-SEARCH("[",CELL("filename"))-1)&"]"&ADDRESS(ROW()+16,8,1,TRUE,M$4),INDIRECT(ADDRESS(ROW()+16,8,1,TRUE,M$4))) -> Y | N5: =HYPERLINK("["&MID(CELL("filename"),SEARCH("[",CELL("filename"))+1,SEARCH("]",CELL("filename"))-SEARCH("[",CELL("filename"))-1)&"]"&ADDRESS(ROW()+16,8,1,TRUE,N$4),INDIRECT(ADDRESS(ROW()+16,8,1,TRUE,N$4))) -> Y | O5: =HYPERLINK("["&MID(CELL("filename"),SEARCH("[",CELL("filename"))+1,SEARCH("]",CELL("filename"))-SEARCH("[",CELL("filename"))-1)&"]"&ADDRESS(ROW()+16,8,1,TRUE,O$4),INDIRECT(ADDRESS(ROW()+16,8,1,TRUE,O$4))) -> Y | P5: =HYPERLINK("["&MID(CELL("filename"),SEARCH("[",CELL("filename"))+1,SEARCH("]",CELL("filename"))-SEARCH("[",CELL("filename"))-1)&"]"&ADDRESS(ROW()+16,8,1,TRUE,P$4),INDIRECT(ADDRESS(ROW()+16,8,1,TRUE,P$4))) -> N | Q5: =HYPERLINK("["&MID(CELL("filename"),SEARCH("[",CELL("filename"))+1,SEARCH("]",CELL("filename"))-SEARCH("[",CELL("filename"))-1)&"]"&ADDRESS(ROW()+16,8,1,TRUE,Q$4),INDIRECT(ADDRESS(ROW()+16,8,1,TRUE,Q$4))) -> N | R5: =HYPERLINK("["&MID(CELL("filename"),SEARCH("[",CELL("filename"))+1,SEARCH("]",CELL("filename"))-SEARCH("[",CELL("filename"))-1)&"]"&ADDRESS(ROW()+16,8,1,TRUE,R$4),INDIRECT(ADDRESS(ROW()+16,8,1,TRUE,R$4))) -> N | S5: =HYPERLINK("["&MID(CELL("filename"),SEARCH("[",CELL("filename"))+1,SEARCH("]",CELL("filename"))-SEARCH("[",CELL("filename"))-1)&"]"&ADDRESS(ROW()+16,8,1,TRUE,S$4),INDIRECT(ADDRESS(ROW()+16,8,1,TRUE,S$4))) -> Y | T5: =HYPERLINK("["&MID(CELL("filename"),SEARCH("[",CELL("filename"))+1,SEARCH("]",CELL("filename"))-SEARCH("[",CELL("filename"))-1)&"]"&ADDRESS(ROW()+16,8,1,TRUE,T$4),INDIRECT(ADDRESS(ROW()+16,8,1,TRUE,T$4))) -> Y | ... AB5: =HYPERLINK("["&MID(CELL("filename"),SEARCH("[",CELL("filename"))+1,SEARCH("]",CELL("filename"))-SEARCH("[",CELL("filename"))-1)&"]"&ADDRESS(ROW()+16,8,1,TRUE,AB$4),INDIRECT(ADDRESS(ROW()+16,8,1,TRUE,AB$4))) -> Y
A6: =ChkList!A6 -> 계정 관리 | B6: =ChkList!$B6 -> N-02 | C6: =ChkList!$C6 -> 비밀번호 복잡성 설정 | D6: =ChkList!$D6 -> H | E6: =ChkList!E6 -> 3 | F6: =COUNTA($M6:INDIRECT(ADDRESS(ROW(),MATCH("",$4:$4,-1),1,1))) -> 16 | G6: =COUNTIF($M6:INDIRECT(ADDRESS(ROW(),MATCH("",$4:$4,-1),1,1)),"조치완료(Y)")+COUNTIF($M6:INDIRECT(ADDRESS(ROW(),MATCH("",$4:$4,-1),1,1)),"Y") -> 13 | H6: =COUNTIF($M6:INDIRECT(ADDRESS(ROW(),MATCH("",$4:$4,-1),1,1)),"Y(즉시조치)")+COUNTIF($M6:INDIRECT(ADDRESS(ROW(),MATCH("",$4:$4,-1),1,1)),"조치완료(즉시조치)") -> 0 | I6: =COUNTIF($M6:INDIRECT(ADDRESS(ROW(),MATCH("",$4:$4,-1),1,1)),"N") -> 3 | J6: =COUNTIF($M6:INDIRECT(ADDRESS(ROW(),MATCH("",$4:$4,-1),1,1)),"N/A")+COUNTIF($M6:INDIRECT(ADDRESS(ROW(),MATCH("",$4:$4,-1),1,1)),"조치완료(N/A)") -> 0 | K6: =VLOOKUP($D6,'parm(hidden)'!$B$8:$C$10,2,FALSE)*($F6-$J6) -> 48 | L6: =VLOOKUP($D6,'parm(hidden)'!$B$8:$C$10,2,FALSE)*($G6+$H6) -> 39 | M6: =HYPERLINK("["&MID(CELL("filename"),SEARCH("[",CELL("filename"))+1,SEARCH("]",CELL("filename"))-SEARCH("[",CELL("filename"))-1)&"]"&ADDRESS(ROW()+16,8,1,TRUE,M$4),INDIRECT(ADDRESS(ROW()+16,8,1,TRUE,M$4))) -> Y | N6: =HYPERLINK("["&MID(CELL("filename"),SEARCH("[",CELL("filename"))+1,SEARCH("]",CELL("filename"))-SEARCH("[",CELL("filename"))-1)&"]"&ADDRESS(ROW()+16,8,1,TRUE,N$4),INDIRECT(ADDRESS(ROW()+16,8,1,TRUE,N$4))) -> Y | O6: =HYPERLINK("["&MID(CELL("filename"),SEARCH("[",CELL("filename"))+1,SEARCH("]",CELL("filename"))-SEARCH("[",CELL("filename"))-1)&"]"&ADDRESS(ROW()+16,8,1,TRUE,O$4),INDIRECT(ADDRESS(ROW()+16,8,1,TRUE,O$4))) -> Y | P6: =HYPERLINK("["&MID(CELL("filename"),SEARCH("[",CELL("filename"))+1,SEARCH("]",CELL("filename"))-SEARCH("[",CELL("filename"))-1)&"]"&ADDRESS(ROW()+16,8,1,TRUE,P$4),INDIRECT(ADDRESS(ROW()+16,8,1,TRUE,P$4))) -> N | Q6: =HYPERLINK("["&MID(CELL("filename"),SEARCH("[",CELL("filename"))+1,SEARCH("]",CELL("filename"))-SEARCH("[",CELL("filename"))-1)&"]"&ADDRESS(ROW()+16,8,1,TRUE,Q$4),INDIRECT(ADDRESS(ROW()+16,8,1,TRUE,Q$4))) -> N | R6: =HYPERLINK("["&MID(CELL("filename"),SEARCH("[",CELL("filename"))+1,SEARCH("]",CELL("filename"))-SEARCH("[",CELL("filename"))-1)&"]"&ADDRESS(ROW()+16,8,1,TRUE,R$4),INDIRECT(ADDRESS(ROW()+16,8,1,TRUE,R$4))) -> N | S6: =HYPERLINK("["&MID(CELL("filename"),SEARCH("[",CELL("filename"))+1,SEARCH("]",CELL("filename"))-SEARCH("[",CELL("filename"))-1)&"]"&ADDRESS(ROW()+16,8,1,TRUE,S$4),INDIRECT(ADDRESS(ROW()+16,8,1,TRUE,S$4))) -> Y | T6: =HYPERLINK("["&MID(CELL("filename"),SEARCH("[",CELL("filename"))+1,SEARCH("]",CELL("filename"))-SEARCH("[",CELL("filename"))-1)&"]"&ADDRESS(ROW()+16,8,1,TRUE,T$4),INDIRECT(ADDRESS(ROW()+16,8,1,TRUE,T$4))) -> Y | ... AB6: =HYPERLINK("["&MID(CELL("filename"),SEARCH("[",CELL("filename"))+1,SEARCH("]",CELL("filename"))-SEARCH("[",CELL("filename"))-1)&"]"&ADDRESS(ROW()+16,8,1,TRUE,AB$4),INDIRECT(ADDRESS(ROW()+16,8,1,TRUE,AB$4))) -> Y
A7: =ChkList!A7 -> 계정 관리 | B7: =ChkList!$B7 -> N-03 | C7: =ChkList!$C7 -> 암호화된 비밀번호 사용 | D7: =ChkList!$D7 -> H | E7: =ChkList!E7 -> 3 | F7: =COUNTA($M7:INDIRECT(ADDRESS(ROW(),MATCH("",$4:$4,-1),1,1))) -> 16 | G7: =COUNTIF($M7:INDIRECT(ADDRESS(ROW(),MATCH("",$4:$4,-1),1,1)),"조치완료(Y)")+COUNTIF($M7:INDIRECT(ADDRESS(ROW(),MATCH("",$4:$4,-1),1,1)),"Y") -> 13 | H7: =COUNTIF($M7:INDIRECT(ADDRESS(ROW(),MATCH("",$4:$4,-1),1,1)),"Y(즉시조치)")+COUNTIF($M7:INDIRECT(ADDRESS(ROW(),MATCH("",$4:$4,-1),1,1)),"조치완료(즉시조치)") -> 0 | I7: =COUNTIF($M7:INDIRECT(ADDRESS(ROW(),MATCH("",$4:$4,-1),1,1)),"N") -> 3 | J7: =COUNTIF($M7:INDIRECT(ADDRESS(ROW(),MATCH("",$4:$4,-1),1,1)),"N/A")+COUNTIF($M7:INDIRECT(ADDRESS(ROW(),MATCH("",$4:$4,-1),1,1)),"조치완료(N/A)") -> 0 | K7: =VLOOKUP($D7,'parm(hidden)'!$B$8:$C$10,2,FALSE)*($F7-$J7) -> 48 | L7: =VLOOKUP($D7,'parm(hidden)'!$B$8:$C$10,2,FALSE)*($G7+$H7) -> 39 | M7: =HYPERLINK("["&MID(CELL("filename"),SEARCH("[",CELL("filename"))+1,SEARCH("]",CELL("filename"))-SEARCH("[",CELL("filename"))-1)&"]"&ADDRESS(ROW()+16,8,1,TRUE,M$4),INDIRECT(ADDRESS(ROW()+16,8,1,TRUE,M$4))) -> Y | N7: =HYPERLINK("["&MID(CELL("filename"),SEARCH("[",CELL("filename"))+1,SEARCH("]",CELL("filename"))-SEARCH("[",CELL("filename"))-1)&"]"&ADDRESS(ROW()+16,8,1,TRUE,N$4),INDIRECT(ADDRESS(ROW()+16,8,1,TRUE,N$4))) -> Y | O7: =HYPERLINK("["&MID(CELL("filename"),SEARCH("[",CELL("filename"))+1,SEARCH("]",CELL("filename"))-SEARCH("[",CELL("filename"))-1)&"]"&ADDRESS(ROW()+16,8,1,TRUE,O$4),INDIRECT(ADDRESS(ROW()+16,8,1,TRUE,O$4))) -> Y | P7: =HYPERLINK("["&MID(CELL("filename"),SEARCH("[",CELL("filename"))+1,SEARCH("]",CELL("filename"))-SEARCH("[",CELL("filename"))-1)&"]"&ADDRESS(ROW()+16,8,1,TRUE,P$4),INDIRECT(ADDRESS(ROW()+16,8,1,TRUE,P$4))) -> N | Q7: =HYPERLINK("["&MID(CELL("filename"),SEARCH("[",CELL("filename"))+1,SEARCH("]",CELL("filename"))-SEARCH("[",CELL("filename"))-1)&"]"&ADDRESS(ROW()+16,8,1,TRUE,Q$4),INDIRECT(ADDRESS(ROW()+16,8,1,TRUE,Q$4))) -> N | R7: =HYPERLINK("["&MID(CELL("filename"),SEARCH("[",CELL("filename"))+1,SEARCH("]",CELL("filename"))-SEARCH("[",CELL("filename"))-1)&"]"&ADDRESS(ROW()+16,8,1,TRUE,R$4),INDIRECT(ADDRESS(ROW()+16,8,1,TRUE,R$4))) -> N | S7: =HYPERLINK("["&MID(CELL("filename"),SEARCH("[",CELL("filename"))+1,SEARCH("]",CELL("filename"))-SEARCH("[",CELL("filename"))-1)&"]"&ADDRESS(ROW()+16,8,1,TRUE,S$4),INDIRECT(ADDRESS(ROW()+16,8,1,TRUE,S$4))) -> Y | T7: =HYPERLINK("["&MID(CELL("filename"),SEARCH("[",CELL("filename"))+1,SEARCH("]",CELL("filename"))-SEARCH("[",CELL("filename"))-1)&"]"&ADDRESS(ROW()+16,8,1,TRUE,T$4),INDIRECT(ADDRESS(ROW()+16,8,1,TRUE,T$4))) -> Y | ... AB7: =HYPERLINK("["&MID(CELL("filename"),SEARCH("[",CELL("filename"))+1,SEARCH("]",CELL("filename"))-SEARCH("[",CELL("filename"))-1)&"]"&ADDRESS(ROW()+16,8,1,TRUE,AB$4),INDIRECT(ADDRESS(ROW()+16,8,1,TRUE,AB$4))) -> Y
A8: =ChkList!A8 -> 계정 관리 | B8: =ChkList!$B8 -> N-04 | C8: =ChkList!$C8 -> 계정 잠금 임계값 설정 | D8: =ChkList!$D8 -> H | E8: =ChkList!E8 -> 3 | F8: =COUNTA($M8:INDIRECT(ADDRESS(ROW(),MATCH("",$4:$4,-1),1,1))) -> 16 | G8: =COUNTIF($M8:INDIRECT(ADDRESS(ROW(),MATCH("",$4:$4,-1),1,1)),"조치완료(Y)")+COUNTIF($M8:INDIRECT(ADDRESS(ROW(),MATCH("",$4:$4,-1),1,1)),"Y") -> 13 | H8: =COUNTIF($M8:INDIRECT(ADDRESS(ROW(),MATCH("",$4:$4,-1),1,1)),"Y(즉시조치)")+COUNTIF($M8:INDIRECT(ADDRESS(ROW(),MATCH("",$4:$4,-1),1,1)),"조치완료(즉시조치)") -> 0 | I8: =COUNTIF($M8:INDIRECT(ADDRESS(ROW(),MATCH("",$4:$4,-1),1,1)),"N") -> 3 | J8: =COUNTIF($M8:INDIRECT(ADDRESS(ROW(),MATCH("",$4:$4,-1),1,1)),"N/A")+COUNTIF($M8:INDIRECT(ADDRESS(ROW(),MATCH("",$4:$4,-1),1,1)),"조치완료(N/A)") -> 0 | K8: =VLOOKUP($D8,'parm(hidden)'!$B$8:$C$10,2,FALSE)*($F8-$J8) -> 48 | L8: =VLOOKUP($D8,'parm(hidden)'!$B$8:$C$10,2,FALSE)*($G8+$H8) -> 39 | M8: =HYPERLINK("["&MID(CELL("filename"),SEARCH("[",CELL("filename"))+1,SEARCH("]",CELL("filename"))-SEARCH("[",CELL("filename"))-1)&"]"&ADDRESS(ROW()+16,8,1,TRUE,M$4),INDIRECT(ADDRESS(ROW()+16,8,1,TRUE,M$4))) -> Y | N8: =HYPERLINK("["&MID(CELL("filename"),SEARCH("[",CELL("filename"))+1,SEARCH("]",CELL("filename"))-SEARCH("[",CELL("filename"))-1)&"]"&ADDRESS(ROW()+16,8,1,TRUE,N$4),INDIRECT(ADDRESS(ROW()+16,8,1,TRUE,N$4))) -> Y | O8: =HYPERLINK("["&MID(CELL("filename"),SEARCH("[",CELL("filename"))+1,SEARCH("]",CELL("filename"))-SEARCH("[",CELL("filename"))-1)&"]"&ADDRESS(ROW()+16,8,1,TRUE,O$4),INDIRECT(ADDRESS(ROW()+16,8,1,TRUE,O$4))) -> Y | P8: =HYPERLINK("["&MID(CELL("filename"),SEARCH("[",CELL("filename"))+1,SEARCH("]",CELL("filename"))-SEARCH("[",CELL("filename"))-1)&"]"&ADDRESS(ROW()+16,8,1,TRUE,P$4),INDIRECT(ADDRESS(ROW()+16,8,1,TRUE,P$4))) -> N | Q8: =HYPERLINK("["&MID(CELL("filename"),SEARCH("[",CELL("filename"))+1,SEARCH("]",CELL("filename"))-SEARCH("[",CELL("filename"))-1)&"]"&ADDRESS(ROW()+16,8,1,TRUE,Q$4),INDIRECT(ADDRESS(ROW()+16,8,1,TRUE,Q$4))) -> N | R8: =HYPERLINK("["&MID(CELL("filename"),SEARCH("[",CELL("filename"))+1,SEARCH("]",CELL("filename"))-SEARCH("[",CELL("filename"))-1)&"]"&ADDRESS(ROW()+16,8,1,TRUE,R$4),INDIRECT(ADDRESS(ROW()+16,8,1,TRUE,R$4))) -> N | S8: =HYPERLINK("["&MID(CELL("filename"),SEARCH("[",CELL("filename"))+1,SEARCH("]",CELL("filename"))-SEARCH("[",CELL("filename"))-1)&"]"&ADDRESS(ROW()+16,8,1,TRUE,S$4),INDIRECT(ADDRESS(ROW()+16,8,1,TRUE,S$4))) -> Y | T8: =HYPERLINK("["&MID(CELL("filename"),SEARCH("[",CELL("filename"))+1,SEARCH("]",CELL("filename"))-SEARCH("[",CELL("filename"))-1)&"]"&ADDRESS(ROW()+16,8,1,TRUE,T$4),INDIRECT(ADDRESS(ROW()+16,8,1,TRUE,T$4))) -> Y | ... AB8: =HYPERLINK("["&MID(CELL("filename"),SEARCH("[",CELL("filename"))+1,SEARCH("]",CELL("filename"))-SEARCH("[",CELL("filename"))-1)&"]"&ADDRESS(ROW()+16,8,1,TRUE,AB$4),INDIRECT(ADDRESS(ROW()+16,8,1,TRUE,AB$4))) -> Y
A9: =ChkList!A9 -> 계정 관리 | B9: =ChkList!$B9 -> N-05 | C9: =ChkList!$C9 -> 사용자·명령어별 권한 설정 | D9: =ChkList!$D9 -> M | E9: =ChkList!E9 -> 2 | F9: =COUNTA($M9:INDIRECT(ADDRESS(ROW(),MATCH("",$4:$4,-1),1,1))) -> 16 | G9: =COUNTIF($M9:INDIRECT(ADDRESS(ROW(),MATCH("",$4:$4,-1),1,1)),"조치완료(Y)")+COUNTIF($M9:INDIRECT(ADDRESS(ROW(),MATCH("",$4:$4,-1),1,1)),"Y") -> 13 | H9: =COUNTIF($M9:INDIRECT(ADDRESS(ROW(),MATCH("",$4:$4,-1),1,1)),"Y(즉시조치)")+COUNTIF($M9:INDIRECT(ADDRESS(ROW(),MATCH("",$4:$4,-1),1,1)),"조치완료(즉시조치)") -> 0 | I9: =COUNTIF($M9:INDIRECT(ADDRESS(ROW(),MATCH("",$4:$4,-1),1,1)),"N") -> 3 | J9: =COUNTIF($M9:INDIRECT(ADDRESS(ROW(),MATCH("",$4:$4,-1),1,1)),"N/A")+COUNTIF($M9:INDIRECT(ADDRESS(ROW(),MATCH("",$4:$4,-1),1,1)),"조치완료(N/A)") -> 0 | K9: =VLOOKUP($D9,'parm(hidden)'!$B$8:$C$10,2,FALSE)*($F9-$J9) -> 32 | L9: =VLOOKUP($D9,'parm(hidden)'!$B$8:$C$10,2,FALSE)*($G9+$H9) -> 26 | M9: =HYPERLINK("["&MID(CELL("filename"),SEARCH("[",CELL("filename"))+1,SEARCH("]",CELL("filename"))-SEARCH("[",CELL("filename"))-1)&"]"&ADDRESS(ROW()+16,8,1,TRUE,M$4),INDIRECT(ADDRESS(ROW()+16,8,1,TRUE,M$4))) -> Y | N9: =HYPERLINK("["&MID(CELL("filename"),SEARCH("[",CELL("filename"))+1,SEARCH("]",CELL("filename"))-SEARCH("[",CELL("filename"))-1)&"]"&ADDRESS(ROW()+16,8,1,TRUE,N$4),INDIRECT(ADDRESS(ROW()+16,8,1,TRUE,N$4))) -> Y | O9: =HYPERLINK("["&MID(CELL("filename"),SEARCH("[",CELL("filename"))+1,SEARCH("]",CELL("filename"))-SEARCH("[",CELL("filename"))-1)&"]"&ADDRESS(ROW()+16,8,1,TRUE,O$4),INDIRECT(ADDRESS(ROW()+16,8,1,TRUE,O$4))) -> Y | P9: =HYPERLINK("["&MID(CELL("filename"),SEARCH("[",CELL("filename"))+1,SEARCH("]",CELL("filename"))-SEARCH("[",CELL("filename"))-1)&"]"&ADDRESS(ROW()+16,8,1,TRUE,P$4),INDIRECT(ADDRESS(ROW()+16,8,1,TRUE,P$4))) -> N | Q9: =HYPERLINK("["&MID(CELL("filename"),SEARCH("[",CELL("filename"))+1,SEARCH("]",CELL("filename"))-SEARCH("[",CELL("filename"))-1)&"]"&ADDRESS(ROW()+16,8,1,TRUE,Q$4),INDIRECT(ADDRESS(ROW()+16,8,1,TRUE,Q$4))) -> N | R9: =HYPERLINK("["&MID(CELL("filename"),SEARCH("[",CELL("filename"))+1,SEARCH("]",CELL("filename"))-SEARCH("[",CELL("filename"))-1)&"]"&ADDRESS(ROW()+16,8,1,TRUE,R$4),INDIRECT(ADDRESS(ROW()+16,8,1,TRUE,R$4))) -> N | S9: =HYPERLINK("["&MID(CELL("filename"),SEARCH("[",CELL("filename"))+1,SEARCH("]",CELL("filename"))-SEARCH("[",CELL("filename"))-1)&"]"&ADDRESS(ROW()+16,8,1,TRUE,S$4),INDIRECT(ADDRESS(ROW()+16,8,1,TRUE,S$4))) -> Y | T9: =HYPERLINK("["&MID(CELL("filename"),SEARCH("[",CELL("filename"))+1,SEARCH("]",CELL("filename"))-SEARCH("[",CELL("filename"))-1)&"]"&ADDRESS(ROW()+16,8,1,TRUE,T$4),INDIRECT(ADDRESS(ROW()+16,8,1,TRUE,T$4))) -> Y | ... AB9: =HYPERLINK("["&MID(CELL("filename"),SEARCH("[",CELL("filename"))+1,SEARCH("]",CELL("filename"))-SEARCH("[",CELL("filename"))-1)&"]"&ADDRESS(ROW()+16,8,1,TRUE,AB$4),INDIRECT(ADDRESS(ROW()+16,8,1,TRUE,AB$4))) -> Y
A10: =ChkList!A10 -> 접근 관리 | B10: =ChkList!$B10 -> N-06 | C10: =ChkList!$C10 -> VTY 접근(ACL) 설정 | D10: =ChkList!$D10 -> H | E10: =ChkList!E10 -> 3 | F10: =COUNTA($M10:INDIRECT(ADDRESS(ROW(),MATCH("",$4:$4,-1),1,1))) -> 16 | G10: =COUNTIF($M10:INDIRECT(ADDRESS(ROW(),MATCH("",$4:$4,-1),1,1)),"조치완료(Y)")+COUNTIF($M10:INDIRECT(ADDRESS(ROW(),MATCH("",$4:$4,-1),1,1)),"Y") -> 13 | H10: =COUNTIF($M10:INDIRECT(ADDRESS(ROW(),MATCH("",$4:$4,-1),1,1)),"Y(즉시조치)")+COUNTIF($M10:INDIRECT(ADDRESS(ROW(),MATCH("",$4:$4,-1),1,1)),"조치완료(즉시조치)") -> 0 | I10: =COUNTIF($M10:INDIRECT(ADDRESS(ROW(),MATCH("",$4:$4,-1),1,1)),"N") -> 3 | J10: =COUNTIF($M10:INDIRECT(ADDRESS(ROW(),MATCH("",$4:$4,-1),1,1)),"N/A")+COUNTIF($M10:INDIRECT(ADDRESS(ROW(),MATCH("",$4:$4,-1),1,1)),"조치완료(N/A)") -> 0 | K10: =VLOOKUP($D10,'parm(hidden)'!$B$8:$C$10,2,FALSE)*($F10-$J10) -> 48 | L10: =VLOOKUP($D10,'parm(hidden)'!$B$8:$C$10,2,FALSE)*($G10+$H10) -> 39 | M10: =HYPERLINK("["&MID(CELL("filename"),SEARCH("[",CELL("filename"))+1,SEARCH("]",CELL("filename"))-SEARCH("[",CELL("filename"))-1)&"]"&ADDRESS(ROW()+16,8,1,TRUE,M$4),INDIRECT(ADDRESS(ROW()+16,8,1,TRUE,M$4))) -> Y | N10: =HYPERLINK("["&MID(CELL("filename"),SEARCH("[",CELL("filename"))+1,SEARCH("]",CELL("filename"))-SEARCH("[",CELL("filename"))-1)&"]"&ADDRESS(ROW()+16,8,1,TRUE,N$4),INDIRECT(ADDRESS(ROW()+16,8,1,TRUE,N$4))) -> Y | O10: =HYPERLINK("["&MID(CELL("filename"),SEARCH("[",CELL("filename"))+1,SEARCH("]",CELL("filename"))-SEARCH("[",CELL("filename"))-1)&"]"&ADDRESS(ROW()+16,8,1,TRUE,O$4),INDIRECT(ADDRESS(ROW()+16,8,1,TRUE,O$4))) -> Y | P10: =HYPERLINK("["&MID(CELL("filename"),SEARCH("[",CELL("filename"))+1,SEARCH("]",CELL("filename"))-SEARCH("[",CELL("filename"))-1)&"]"&ADDRESS(ROW()+16,8,1,TRUE,P$4),INDIRECT(ADDRESS(ROW()+16,8,1,TRUE,P$4))) -> N | Q10: =HYPERLINK("["&MID(CELL("filename"),SEARCH("[",CELL("filename"))+1,SEARCH("]",CELL("filename"))-SEARCH("[",CELL("filename"))-1)&"]"&ADDRESS(ROW()+16,8,1,TRUE,Q$4),INDIRECT(ADDRESS(ROW()+16,8,1,TRUE,Q$4))) -> N | R10: =HYPERLINK("["&MID(CELL("filename"),SEARCH("[",CELL("filename"))+1,SEARCH("]",CELL("filename"))-SEARCH("[",CELL("filename"))-1)&"]"&ADDRESS(ROW()+16,8,1,TRUE,R$4),INDIRECT(ADDRESS(ROW()+16,8,1,TRUE,R$4))) -> N | S10: =HYPERLINK("["&MID(CELL("filename"),SEARCH("[",CELL("filename"))+1,SEARCH("]",CELL("filename"))-SEARCH("[",CELL("filename"))-1)&"]"&ADDRESS(ROW()+16,8,1,TRUE,S$4),INDIRECT(ADDRESS(ROW()+16,8,1,TRUE,S$4))) -> Y | T10: =HYPERLINK("["&MID(CELL("filename"),SEARCH("[",CELL("filename"))+1,SEARCH("]",CELL("filename"))-SEARCH("[",CELL("filename"))-1)&"]"&ADDRESS(ROW()+16,8,1,TRUE,T$4),INDIRECT(ADDRESS(ROW()+16,8,1,TRUE,T$4))) -> Y | ... AB10: =HYPERLINK("["&MID(CELL("filename"),SEARCH("[",CELL("filename"))+1,SEARCH("]",CELL("filename"))-SEARCH("[",CELL("filename"))-1)&"]"&ADDRESS(ROW()+16,8,1,TRUE,AB$4),INDIRECT(ADDRESS(ROW()+16,8,1,TRUE,AB$4))) -> Y
A11: =ChkList!A11 -> 접근 관리 | B11: =ChkList!$B11 -> N-07 | C11: =ChkList!$C11 -> Session Timeout 설정 | D11: =ChkList!$D11 -> H | E11: =ChkList!E11 -> 3 | F11: =COUNTA($M11:INDIRECT(ADDRESS(ROW(),MATCH("",$4:$4,-1),1,1))) -> 16 | G11: =COUNTIF($M11:INDIRECT(ADDRESS(ROW(),MATCH("",$4:$4,-1),1,1)),"조치완료(Y)")+COUNTIF($M11:INDIRECT(ADDRESS(ROW(),MATCH("",$4:$4,-1),1,1)),"Y") -> 13 | H11: =COUNTIF($M11:INDIRECT(ADDRESS(ROW(),MATCH("",$4:$4,-1),1,1)),"Y(즉시조치)")+COUNTIF($M11:INDIRECT(ADDRESS(ROW(),MATCH("",$4:$4,-1),1,1)),"조치완료(즉시조치)") -> 0 | I11: =COUNTIF($M11:INDIRECT(ADDRESS(ROW(),MATCH("",$4:$4,-1),1,1)),"N") -> 3 | J11: =COUNTIF($M11:INDIRECT(ADDRESS(ROW(),MATCH("",$4:$4,-1),1,1)),"N/A")+COUNTIF($M11:INDIRECT(ADDRESS(ROW(),MATCH("",$4:$4,-1),1,1)),"조치완료(N/A)") -> 0 | K11: =VLOOKUP($D11,'parm(hidden)'!$B$8:$C$10,2,FALSE)*($F11-$J11) -> 48 | L11: =VLOOKUP($D11,'parm(hidden)'!$B$8:$C$10,2,FALSE)*($G11+$H11) -> 39 | M11: =HYPERLINK("["&MID(CELL("filename"),SEARCH("[",CELL("filename"))+1,SEARCH("]",CELL("filename"))-SEARCH("[",CELL("filename"))-1)&"]"&ADDRESS(ROW()+16,8,1,TRUE,M$4),INDIRECT(ADDRESS(ROW()+16,8,1,TRUE,M$4))) -> Y | N11: =HYPERLINK("["&MID(CELL("filename"),SEARCH("[",CELL("filename"))+1,SEARCH("]",CELL("filename"))-SEARCH("[",CELL("filename"))-1)&"]"&ADDRESS(ROW()+16,8,1,TRUE,N$4),INDIRECT(ADDRESS(ROW()+16,8,1,TRUE,N$4))) -> Y | O11: =HYPERLINK("["&MID(CELL("filename"),SEARCH("[",CELL("filename"))+1,SEARCH("]",CELL("filename"))-SEARCH("[",CELL("filename"))-1)&"]"&ADDRESS(ROW()+16,8,1,TRUE,O$4),INDIRECT(ADDRESS(ROW()+16,8,1,TRUE,O$4))) -> Y | P11: =HYPERLINK("["&MID(CELL("filename"),SEARCH("[",CELL("filename"))+1,SEARCH("]",CELL("filename"))-SEARCH("[",CELL("filename"))-1)&"]"&ADDRESS(ROW()+16,8,1,TRUE,P$4),INDIRECT(ADDRESS(ROW()+16,8,1,TRUE,P$4))) -> N | Q11: =HYPERLINK("["&MID(CELL("filename"),SEARCH("[",CELL("filename"))+1,SEARCH("]",CELL("filename"))-SEARCH("[",CELL("filename"))-1)&"]"&ADDRESS(ROW()+16,8,1,TRUE,Q$4),INDIRECT(ADDRESS(ROW()+16,8,1,TRUE,Q$4))) -> N | R11: =HYPERLINK("["&MID(CELL("filename"),SEARCH("[",CELL("filename"))+1,SEARCH("]",CELL("filename"))-SEARCH("[",CELL("filename"))-1)&"]"&ADDRESS(ROW()+16,8,1,TRUE,R$4),INDIRECT(ADDRESS(ROW()+16,8,1,TRUE,R$4))) -> N | S11: =HYPERLINK("["&MID(CELL("filename"),SEARCH("[",CELL("filename"))+1,SEARCH("]",CELL("filename"))-SEARCH("[",CELL("filename"))-1)&"]"&ADDRESS(ROW()+16,8,1,TRUE,S$4),INDIRECT(ADDRESS(ROW()+16,8,1,TRUE,S$4))) -> Y | T11: =HYPERLINK("["&MID(CELL("filename"),SEARCH("[",CELL("filename"))+1,SEARCH("]",CELL("filename"))-SEARCH("[",CELL("filename"))-1)&"]"&ADDRESS(ROW()+16,8,1,TRUE,T$4),INDIRECT(ADDRESS(ROW()+16,8,1,TRUE,T$4))) -> Y | ... AB11: =HYPERLINK("["&MID(CELL("filename"),SEARCH("[",CELL("filename"))+1,SEARCH("]",CELL("filename"))-SEARCH("[",CELL("filename"))-1)&"]"&ADDRESS(ROW()+16,8,1,TRUE,AB$4),INDIRECT(ADDRESS(ROW()+16,8,1,TRUE,AB$4))) -> Y
A12: =ChkList!A12 -> 접근 관리 | B12: =ChkList!$B12 -> N-08 | C12: =ChkList!$C12 -> VTY 접속 시 안전한 프로토콜 사용 | D12: =ChkList!$D12 -> M | E12: =ChkList!E12 -> 2 | F12: =COUNTA($M12:INDIRECT(ADDRESS(ROW(),MATCH("",$4:$4,-1),1,1))) -> 16 | G12: =COUNTIF($M12:INDIRECT(ADDRESS(ROW(),MATCH("",$4:$4,-1),1,1)),"조치완료(Y)")+COUNTIF($M12:INDIRECT(ADDRESS(ROW(),MATCH("",$4:$4,-1),1,1)),"Y") -> 13 | H12: =COUNTIF($M12:INDIRECT(ADDRESS(ROW(),MATCH("",$4:$4,-1),1,1)),"Y(즉시조치)")+COUNTIF($M12:INDIRECT(ADDRESS(ROW(),MATCH("",$4:$4,-1),1,1)),"조치완료(즉시조치)") -> 0 | I12: =COUNTIF($M12:INDIRECT(ADDRESS(ROW(),MATCH("",$4:$4,-1),1,1)),"N") -> 3 | J12: =COUNTIF($M12:INDIRECT(ADDRESS(ROW(),MATCH("",$4:$4,-1),1,1)),"N/A")+COUNTIF($M12:INDIRECT(ADDRESS(ROW(),MATCH("",$4:$4,-1),1,1)),"조치완료(N/A)") -> 0 | K12: =VLOOKUP($D12,'parm(hidden)'!$B$8:$C$10,2,FALSE)*($F12-$J12) -> 32 | L12: =VLOOKUP($D12,'parm(hidden)'!$B$8:$C$10,2,FALSE)*($G12+$H12) -> 26 | M12: =HYPERLINK("["&MID(CELL("filename"),SEARCH("[",CELL("filename"))+1,SEARCH("]",CELL("filename"))-SEARCH("[",CELL("filename"))-1)&"]"&ADDRESS(ROW()+16,8,1,TRUE,M$4),INDIRECT(ADDRESS(ROW()+16,8,1,TRUE,M$4))) -> Y | N12: =HYPERLINK("["&MID(CELL("filename"),SEARCH("[",CELL("filename"))+1,SEARCH("]",CELL("filename"))-SEARCH("[",CELL("filename"))-1)&"]"&ADDRESS(ROW()+16,8,1,TRUE,N$4),INDIRECT(ADDRESS(ROW()+16,8,1,TRUE,N$4))) -> Y | O12: =HYPERLINK("["&MID(CELL("filename"),SEARCH("[",CELL("filename"))+1,SEARCH("]",CELL("filename"))-SEARCH("[",CELL("filename"))-1)&"]"&ADDRESS(ROW()+16,8,1,TRUE,O$4),INDIRECT(ADDRESS(ROW()+16,8,1,TRUE,O$4))) -> Y | P12: =HYPERLINK("["&MID(CELL("filename"),SEARCH("[",CELL("filename"))+1,SEARCH("]",CELL("filename"))-SEARCH("[",CELL("filename"))-1)&"]"&ADDRESS(ROW()+16,8,1,TRUE,P$4),INDIRECT(ADDRESS(ROW()+16,8,1,TRUE,P$4))) -> N | Q12: =HYPERLINK("["&MID(CELL("filename"),SEARCH("[",CELL("filename"))+1,SEARCH("]",CELL("filename"))-SEARCH("[",CELL("filename"))-1)&"]"&ADDRESS(ROW()+16,8,1,TRUE,Q$4),INDIRECT(ADDRESS(ROW()+16,8,1,TRUE,Q$4))) -> N | R12: =HYPERLINK("["&MID(CELL("filename"),SEARCH("[",CELL("filename"))+1,SEARCH("]",CELL("filename"))-SEARCH("[",CELL("filename"))-1)&"]"&ADDRESS(ROW()+16,8,1,TRUE,R$4),INDIRECT(ADDRESS(ROW()+16,8,1,TRUE,R$4))) -> N | S12: =HYPERLINK("["&MID(CELL("filename"),SEARCH("[",CELL("filename"))+1,SEARCH("]",CELL("filename"))-SEARCH("[",CELL("filename"))-1)&"]"&ADDRESS(ROW()+16,8,1,TRUE,S$4),INDIRECT(ADDRESS(ROW()+16,8,1,TRUE,S$4))) -> Y | T12: =HYPERLINK("["&MID(CELL("filename"),SEARCH("[",CELL("filename"))+1,SEARCH("]",CELL("filename"))-SEARCH("[",CELL("filename"))-1)&"]"&ADDRESS(ROW()+16,8,1,TRUE,T$4),INDIRECT(ADDRESS(ROW()+16,8,1,TRUE,T$4))) -> Y | ... AB12: =HYPERLINK("["&MID(CELL("filename"),SEARCH("[",CELL("filename"))+1,SEARCH("]",CELL("filename"))-SEARCH("[",CELL("filename"))-1)&"]"&ADDRESS(ROW()+16,8,1,TRUE,AB$4),INDIRECT(ADDRESS(ROW()+16,8,1,TRUE,AB$4))) -> Y
A13: =ChkList!A13 -> 접근 관리 | B13: =ChkList!$B13 -> N-09 | C13: =ChkList!$C13 -> 불필요한 보조 입출력 포트 사용 금지 | D13: =ChkList!$D13 -> M | E13: =ChkList!E13 -> 2 | F13: =COUNTA($M13:INDIRECT(ADDRESS(ROW(),MATCH("",$4:$4,-1),1,1))) -> 16 | G13: =COUNTIF($M13:INDIRECT(ADDRESS(ROW(),MATCH("",$4:$4,-1),1,1)),"조치완료(Y)")+COUNTIF($M13:INDIRECT(ADDRESS(ROW(),MATCH("",$4:$4,-1),1,1)),"Y") -> 13 | H13: =COUNTIF($M13:INDIRECT(ADDRESS(ROW(),MATCH("",$4:$4,-1),1,1)),"Y(즉시조치)")+COUNTIF($M13:INDIRECT(ADDRESS(ROW(),MATCH("",$4:$4,-1),1,1)),"조치완료(즉시조치)") -> 0 | I13: =COUNTIF($M13:INDIRECT(ADDRESS(ROW(),MATCH("",$4:$4,-1),1,1)),"N") -> 3 | J13: =COUNTIF($M13:INDIRECT(ADDRESS(ROW(),MATCH("",$4:$4,-1),1,1)),"N/A")+COUNTIF($M13:INDIRECT(ADDRESS(ROW(),MATCH("",$4:$4,-1),1,1)),"조치완료(N/A)") -> 0 | K13: =VLOOKUP($D13,'parm(hidden)'!$B$8:$C$10,2,FALSE)*($F13-$J13) -> 32 | L13: =VLOOKUP($D13,'parm(hidden)'!$B$8:$C$10,2,FALSE)*($G13+$H13) -> 26 | M13: =HYPERLINK("["&MID(CELL("filename"),SEARCH("[",CELL("filename"))+1,SEARCH("]",CELL("filename"))-SEARCH("[",CELL("filename"))-1)&"]"&ADDRESS(ROW()+16,8,1,TRUE,M$4),INDIRECT(ADDRESS(ROW()+16,8,1,TRUE,M$4))) -> Y | N13: =HYPERLINK("["&MID(CELL("filename"),SEARCH("[",CELL("filename"))+1,SEARCH("]",CELL("filename"))-SEARCH("[",CELL("filename"))-1)&"]"&ADDRESS(ROW()+16,8,1,TRUE,N$4),INDIRECT(ADDRESS(ROW()+16,8,1,TRUE,N$4))) -> Y | O13: =HYPERLINK("["&MID(CELL("filename"),SEARCH("[",CELL("filename"))+1,SEARCH("]",CELL("filename"))-SEARCH("[",CELL("filename"))-1)&"]"&ADDRESS(ROW()+16,8,1,TRUE,O$4),INDIRECT(ADDRESS(ROW()+16,8,1,TRUE,O$4))) -> Y | P13: =HYPERLINK("["&MID(CELL("filename"),SEARCH("[",CELL("filename"))+1,SEARCH("]",CELL("filename"))-SEARCH("[",CELL("filename"))-1)&"]"&ADDRESS(ROW()+16,8,1,TRUE,P$4),INDIRECT(ADDRESS(ROW()+16,8,1,TRUE,P$4))) -> N | Q13: =HYPERLINK("["&MID(CELL("filename"),SEARCH("[",CELL("filename"))+1,SEARCH("]",CELL("filename"))-SEARCH("[",CELL("filename"))-1)&"]"&ADDRESS(ROW()+16,8,1,TRUE,Q$4),INDIRECT(ADDRESS(ROW()+16,8,1,TRUE,Q$4))) -> N | R13: =HYPERLINK("["&MID(CELL("filename"),SEARCH("[",CELL("filename"))+1,SEARCH("]",CELL("filename"))-SEARCH("[",CELL("filename"))-1)&"]"&ADDRESS(ROW()+16,8,1,TRUE,R$4),INDIRECT(ADDRESS(ROW()+16,8,1,TRUE,R$4))) -> N | S13: =HYPERLINK("["&MID(CELL("filename"),SEARCH("[",CELL("filename"))+1,SEARCH("]",CELL("filename"))-SEARCH("[",CELL("filename"))-1)&"]"&ADDRESS(ROW()+16,8,1,TRUE,S$4),INDIRECT(ADDRESS(ROW()+16,8,1,TRUE,S$4))) -> Y | T13: =HYPERLINK("["&MID(CELL("filename"),SEARCH("[",CELL("filename"))+1,SEARCH("]",CELL("filename"))-SEARCH("[",CELL("filename"))-1)&"]"&ADDRESS(ROW()+16,8,1,TRUE,T$4),INDIRECT(ADDRESS(ROW()+16,8,1,TRUE,T$4))) -> Y | ... AB13: =HYPERLINK("["&MID(CELL("filename"),SEARCH("[",CELL("filename"))+1,SEARCH("]",CELL("filename"))-SEARCH("[",CELL("filename"))-1)&"]"&ADDRESS(ROW()+16,8,1,TRUE,AB$4),INDIRECT(ADDRESS(ROW()+16,8,1,TRUE,AB$4))) -> Y
A14: =ChkList!A14 -> 접근 관리 | B14: =ChkList!$B14 -> N-10 | C14: =ChkList!$C14 -> 로그인 시 경고 메시지 설정 | D14: =ChkList!$D14 -> M | E14: =ChkList!E14 -> 2 | F14: =COUNTA($M14:INDIRECT(ADDRESS(ROW(),MATCH("",$4:$4,-1),1,1))) -> 16 | G14: =COUNTIF($M14:INDIRECT(ADDRESS(ROW(),MATCH("",$4:$4,-1),1,1)),"조치완료(Y)")+COUNTIF($M14:INDIRECT(ADDRESS(ROW(),MATCH("",$4:$4,-1),1,1)),"Y") -> 3 | H14: =COUNTIF($M14:INDIRECT(ADDRESS(ROW(),MATCH("",$4:$4,-1),1,1)),"Y(즉시조치)")+COUNTIF($M14:INDIRECT(ADDRESS(ROW(),MATCH("",$4:$4,-1),1,1)),"조치완료(즉시조치)") -> 0 | I14: =COUNTIF($M14:INDIRECT(ADDRESS(ROW(),MATCH("",$4:$4,-1),1,1)),"N") -> 0 | J14: =COUNTIF($M14:INDIRECT(ADDRESS(ROW(),MATCH("",$4:$4,-1),1,1)),"N/A")+COUNTIF($M14:INDIRECT(ADDRESS(ROW(),MATCH("",$4:$4,-1),1,1)),"조치완료(N/A)") -> 0 | K14: =VLOOKUP($D14,'parm(hidden)'!$B$8:$C$10,2,FALSE)*($F14-$J14) -> 32 | L14: =VLOOKUP($D14,'parm(hidden)'!$B$8:$C$10,2,FALSE)*($G14+$H14) -> 6 | M14: =HYPERLINK("["&MID(CELL("filename"),SEARCH("[",CELL("filename"))+1,SEARCH("]",CELL("filename"))-SEARCH("[",CELL("filename"))-1)&"]"&ADDRESS(ROW()+16,8,1,TRUE,M$4),INDIRECT(ADDRESS(ROW()+16,8,1,TRUE,M$4))) -> Y | N14: =HYPERLINK("["&MID(CELL("filename"),SEARCH("[",CELL("filename"))+1,SEARCH("]",CELL("filename"))-SEARCH("[",CELL("filename"))-1)&"]"&ADDRESS(ROW()+16,8,1,TRUE,N$4),INDIRECT(ADDRESS(ROW()+16,8,1,TRUE,N$4))) -> Y | O14: =HYPERLINK("["&MID(CELL("filename"),SEARCH("[",CELL("filename"))+1,SEARCH("]",CELL("filename"))-SEARCH("[",CELL("filename"))-1)&"]"&ADDRESS(ROW()+16,8,1,TRUE,O$4),INDIRECT(ADDRESS(ROW()+16,8,1,TRUE,O$4))) -> Y | P14: =HYPERLINK("["&MID(CELL("filename"),SEARCH("[",CELL("filename"))+1,SEARCH("]",CELL("filename"))-SEARCH("[",CELL("filename"))-1)&"]"&ADDRESS(ROW()+16,8,1,TRUE,P$4),INDIRECT(ADDRESS(ROW()+16,8,1,TRUE,P$4))) -> 인터뷰 | Q14: =HYPERLINK("["&MID(CELL("filename"),SEARCH("[",CELL("filename"))+1,SEARCH("]",CELL("filename"))-SEARCH("[",CELL("filename"))-1)&"]"&ADDRESS(ROW()+16,8,1,TRUE,Q$4),INDIRECT(ADDRESS(ROW()+16,8,1,TRUE,Q$4))) -> 인터뷰 | R14: =HYPERLINK("["&MID(CELL("filename"),SEARCH("[",CELL("filename"))+1,SEARCH("]",CELL("filename"))-SEARCH("[",CELL("filename"))-1)&"]"&ADDRESS(ROW()+16,8,1,TRUE,R$4),INDIRECT(ADDRESS(ROW()+16,8,1,TRUE,R$4))) -> 인터뷰 | S14: =HYPERLINK("["&MID(CELL("filename"),SEARCH("[",CELL("filename"))+1,SEARCH("]",CELL("filename"))-SEARCH("[",CELL("filename"))-1)&"]"&ADDRESS(ROW()+16,8,1,TRUE,S$4),INDIRECT(ADDRESS(ROW()+16,8,1,TRUE,S$4))) -> 인터뷰 | T14: =HYPERLINK("["&MID(CELL("filename"),SEARCH("[",CELL("filename"))+1,SEARCH("]",CELL("filename"))-SEARCH("[",CELL("filename"))-1)&"]"&ADDRESS(ROW()+16,8,1,TRUE,T$4),INDIRECT(ADDRESS(ROW()+16,8,1,TRUE,T$4))) -> 인터뷰 | ... AB14: =HYPERLINK("["&MID(CELL("filename"),SEARCH("[",CELL("filename"))+1,SEARCH("]",CELL("filename"))-SEARCH("[",CELL("filename"))-1)&"]"&ADDRESS(ROW()+16,8,1,TRUE,AB$4),INDIRECT(ADDRESS(ROW()+16,8,1,TRUE,AB$4))) -> 인터뷰
A15: =ChkList!A15 -> 접근 관리 | B15: =ChkList!$B15 -> N-11 | C15: =ChkList!$C15 -> 원격로그 서버 사용 | D15: =ChkList!$D15 -> M | E15: =ChkList!E15 -> 2 | F15: =COUNTA($M15:INDIRECT(ADDRESS(ROW(),MATCH("",$4:$4,-1),1,1))) -> 16 | G15: =COUNTIF($M15:INDIRECT(ADDRESS(ROW(),MATCH("",$4:$4,-1),1,1)),"조치완료(Y)")+COUNTIF($M15:INDIRECT(ADDRESS(ROW(),MATCH("",$4:$4,-1),1,1)),"Y") -> 13 | H15: =COUNTIF($M15:INDIRECT(ADDRESS(ROW(),MATCH("",$4:$4,-1),1,1)),"Y(즉시조치)")+COUNTIF($M15:INDIRECT(ADDRESS(ROW(),MATCH("",$4:$4,-1),1,1)),"조치완료(즉시조치)") -> 0 | I15: =COUNTIF($M15:INDIRECT(ADDRESS(ROW(),MATCH("",$4:$4,-1),1,1)),"N") -> 3 | J15: =COUNTIF($M15:INDIRECT(ADDRESS(ROW(),MATCH("",$4:$4,-1),1,1)),"N/A")+COUNTIF($M15:INDIRECT(ADDRESS(ROW(),MATCH("",$4:$4,-1),1,1)),"조치완료(N/A)") -> 0 | K15: =VLOOKUP($D15,'parm(hidden)'!$B$8:$C$10,2,FALSE)*($F15-$J15) -> 32 | L15: =VLOOKUP($D15,'parm(hidden)'!$B$8:$C$10,2,FALSE)*($G15+$H15) -> 26 | M15: =HYPERLINK("["&MID(CELL("filename"),SEARCH("[",CELL("filename"))+1,SEARCH("]",CELL("filename"))-SEARCH("[",CELL("filename"))-1)&"]"&ADDRESS(ROW()+16,8,1,TRUE,M$4),INDIRECT(ADDRESS(ROW()+16,8,1,TRUE,M$4))) -> Y | N15: =HYPERLINK("["&MID(CELL("filename"),SEARCH("[",CELL("filename"))+1,SEARCH("]",CELL("filename"))-SEARCH("[",CELL("filename"))-1)&"]"&ADDRESS(ROW()+16,8,1,TRUE,N$4),INDIRECT(ADDRESS(ROW()+16,8,1,TRUE,N$4))) -> Y | O15: =HYPERLINK("["&MID(CELL("filename"),SEARCH("[",CELL("filename"))+1,SEARCH("]",CELL("filename"))-SEARCH("[",CELL("filename"))-1)&"]"&ADDRESS(ROW()+16,8,1,TRUE,O$4),INDIRECT(ADDRESS(ROW()+16,8,1,TRUE,O$4))) -> Y | P15: =HYPERLINK("["&MID(CELL("filename"),SEARCH("[",CELL("filename"))+1,SEARCH("]",CELL("filename"))-SEARCH("[",CELL("filename"))-1)&"]"&ADDRESS(ROW()+16,8,1,TRUE,P$4),INDIRECT(ADDRESS(ROW()+16,8,1,TRUE,P$4))) -> N | Q15: =HYPERLINK("["&MID(CELL("filename"),SEARCH("[",CELL("filename"))+1,SEARCH("]",CELL("filename"))-SEARCH("[",CELL("filename"))-1)&"]"&ADDRESS(ROW()+16,8,1,TRUE,Q$4),INDIRECT(ADDRESS(ROW()+16,8,1,TRUE,Q$4))) -> N | R15: =HYPERLINK("["&MID(CELL("filename"),SEARCH("[",CELL("filename"))+1,SEARCH("]",CELL("filename"))-SEARCH("[",CELL("filename"))-1)&"]"&ADDRESS(ROW()+16,8,1,TRUE,R$4),INDIRECT(ADDRESS(ROW()+16,8,1,TRUE,R$4))) -> N | S15: =HYPERLINK("["&MID(CELL("filename"),SEARCH("[",CELL("filename"))+1,SEARCH("]",CELL("filename"))-SEARCH("[",CELL("filename"))-1)&"]"&ADDRESS(ROW()+16,8,1,TRUE,S$4),INDIRECT(ADDRESS(ROW()+16,8,1,TRUE,S$4))) -> Y | T15: =HYPERLINK("["&MID(CELL("filename"),SEARCH("[",CELL("filename"))+1,SEARCH("]",CELL("filename"))-SEARCH("[",CELL("filename"))-1)&"]"&ADDRESS(ROW()+16,8,1,TRUE,T$4),INDIRECT(ADDRESS(ROW()+16,8,1,TRUE,T$4))) -> Y | ... AB15: =HYPERLINK("["&MID(CELL("filename"),SEARCH("[",CELL("filename"))+1,SEARCH("]",CELL("filename"))-SEARCH("[",CELL("filename"))-1)&"]"&ADDRESS(ROW()+16,8,1,TRUE,AB$4),INDIRECT(ADDRESS(ROW()+16,8,1,TRUE,AB$4))) -> Y
A16: =ChkList!A16 -> 패치 관리 | B16: =ChkList!$B16 -> N-12 | C16: =ChkList!$C16 -> 주기적 보안 패치 및 벤더 권고사항 적용 | D16: =ChkList!$D16 -> H | E16: =ChkList!E16 -> 3 | F16: =COUNTA($M16:INDIRECT(ADDRESS(ROW(),MATCH("",$4:$4,-1),1,1))) -> 16 | G16: =COUNTIF($M16:INDIRECT(ADDRESS(ROW(),MATCH("",$4:$4,-1),1,1)),"조치완료(Y)")+COUNTIF($M16:INDIRECT(ADDRESS(ROW(),MATCH("",$4:$4,-1),1,1)),"Y") -> 10 | H16: =COUNTIF($M16:INDIRECT(ADDRESS(ROW(),MATCH("",$4:$4,-1),1,1)),"Y(즉시조치)")+COUNTIF($M16:INDIRECT(ADDRESS(ROW(),MATCH("",$4:$4,-1),1,1)),"조치완료(즉시조치)") -> 0 | I16: =COUNTIF($M16:INDIRECT(ADDRESS(ROW(),MATCH("",$4:$4,-1),1,1)),"N") -> 3 | J16: =COUNTIF($M16:INDIRECT(ADDRESS(ROW(),MATCH("",$4:$4,-1),1,1)),"N/A")+COUNTIF($M16:INDIRECT(ADDRESS(ROW(),MATCH("",$4:$4,-1),1,1)),"조치완료(N/A)") -> 2 | K16: =VLOOKUP($D16,'parm(hidden)'!$B$8:$C$10,2,FALSE)*($F16-$J16) -> 42 | L16: =VLOOKUP($D16,'parm(hidden)'!$B$8:$C$10,2,FALSE)*($G16+$H16) -> 30 | M16: =HYPERLINK("["&MID(CELL("filename"),SEARCH("[",CELL("filename"))+1,SEARCH("]",CELL("filename"))-SEARCH("[",CELL("filename"))-1)&"]"&ADDRESS(ROW()+16,8,1,TRUE,M$4),INDIRECT(ADDRESS(ROW()+16,8,1,TRUE,M$4))) -> N/A | N16: =HYPERLINK("["&MID(CELL("filename"),SEARCH("[",CELL("filename"))+1,SEARCH("]",CELL("filename"))-SEARCH("[",CELL("filename"))-1)&"]"&ADDRESS(ROW()+16,8,1,TRUE,N$4),INDIRECT(ADDRESS(ROW()+16,8,1,TRUE,N$4))) -> N/A | O16: =HYPERLINK("["&MID(CELL("filename"),SEARCH("[",CELL("filename"))+1,SEARCH("]",CELL("filename"))-SEARCH("[",CELL("filename"))-1)&"]"&ADDRESS(ROW()+16,8,1,TRUE,O$4),INDIRECT(ADDRESS(ROW()+16,8,1,TRUE,O$4))) -> 인터뷰 | P16: =HYPERLINK("["&MID(CELL("filename"),SEARCH("[",CELL("filename"))+1,SEARCH("]",CELL("filename"))-SEARCH("[",CELL("filename"))-1)&"]"&ADDRESS(ROW()+16,8,1,TRUE,P$4),INDIRECT(ADDRESS(ROW()+16,8,1,TRUE,P$4))) -> N | Q16: =HYPERLINK("["&MID(CELL("filename"),SEARCH("[",CELL("filename"))+1,SEARCH("]",CELL("filename"))-SEARCH("[",CELL("filename"))-1)&"]"&ADDRESS(ROW()+16,8,1,TRUE,Q$4),INDIRECT(ADDRESS(ROW()+16,8,1,TRUE,Q$4))) -> N | R16: =HYPERLINK("["&MID(CELL("filename"),SEARCH("[",CELL("filename"))+1,SEARCH("]",CELL("filename"))-SEARCH("[",CELL("filename"))-1)&"]"&ADDRESS(ROW()+16,8,1,TRUE,R$4),INDIRECT(ADDRESS(ROW()+16,8,1,TRUE,R$4))) -> N | S16: =HYPERLINK("["&MID(CELL("filename"),SEARCH("[",CELL("filename"))+1,SEARCH("]",CELL("filename"))-SEARCH("[",CELL("filename"))-1)&"]"&ADDRESS(ROW()+16,8,1,TRUE,S$4),INDIRECT(ADDRESS(ROW()+16,8,1,TRUE,S$4))) -> Y | T16: =HYPERLINK("["&MID(CELL("filename"),SEARCH("[",CELL("filename"))+1,SEARCH("]",CELL("filename"))-SEARCH("[",CELL("filename"))-1)&"]"&ADDRESS(ROW()+16,8,1,TRUE,T$4),INDIRECT(ADDRESS(ROW()+16,8,1,TRUE,T$4))) -> Y | ... AB16: =HYPERLINK("["&MID(CELL("filename"),SEARCH("[",CELL("filename"))+1,SEARCH("]",CELL("filename"))-SEARCH("[",CELL("filename"))-1)&"]"&ADDRESS(ROW()+16,8,1,TRUE,AB$4),INDIRECT(ADDRESS(ROW()+16,8,1,TRUE,AB$4))) -> Y
