Workbook

Sheet 표지
F11: 46219

Sheet 자산목록
A1: ■ 자산목록
A3: No. | B3: 호스트명 | C3: IP | D3: 제조업체 | E3: 구분 | F3: 모델명 | G3: OS/SW | H3: 버전 | I3: 자산명/용도 | J3: 설치위치 | K3: 부서 | L3: 담당자 | M3: 비고 | N3: 자산 평가
N4: 기밀성 | O4: 무결성 | P4: 가용성 | Q4: 등급 | R4: 점수(Hidden)
A5: 1 | B5: P-01 | C5: 10.0.16.1/24 | G5: Windows 10 | H5: 10 | I5: 사원 PC | J5: 본사 | K5: 관리부 전산팀 | L5: 홍길동 | N5: 3 | O5: 3 | P5: 3 | Q5: =IF(R5>=7,"H",IF(R5>=5,"M","L")) -> H | R5: =SUM(N5:P5) -> 9
A6: 2 | B6: P-02 | C6: 10.0.16.2/24 | G6: Windows 10 | H6: 10 | I6: 사원 PC | J6: 본사 | K6: 관리부 전산팀 | L6: 홍길동 | N6: 3 | O6: 3 | P6: 3 | Q6: =IF(R6>=7,"H",IF(R6>=5,"M","L")) -> H | R6: =SUM(N6:P6) -> 9
A7: 3 | B7: P-03 | C7: 10.0.17.1/24 | G7: Windows 10 | H7: 10 | I7: 사원 PC | J7: 본사 | K7: 관리부 전산팀 | L7: 홍길동 | N7: 3 | O7: 3 | P7: 3 | Q7: =IF(R7>=7,"H",IF(R7>=5,"M","L")) -> H | R7: =SUM(N7:P7) -> 9
A8: 4 | B8: P-04 | C8: 10.0.17.2/24 | G8: Windows 10 | H8: 10 | I8: 사원 PC | J8: 본사 | K8: 관리부 전산팀 | L8: 홍길동 | N8: 3 | O8: 3 | P8: 3 | Q8: =IF(R8>=7,"H",IF(R8>=5,"M","L")) -> H | R8: =SUM(N8:P8) -> 9
A9: 5 | B9: P-05 | C9: 10.0.18.1/24 | G9: Windows 10 | H9: 10 | I9: 사원 PC | J9: 본사 | K9: 관리부 전산팀 | L9: 홍길동 | N9: 3 | O9: 3 | P9: 3 | Q9: =IF(R9>=7,"H",IF(R9>=5,"M","L")) -> H | R9: =SUM(N9:P9) -> 9
A10: 6 | B10: P-06 | C10: 10.0.18.2/24 | G10: Windows 10 | H10: 10 | I10: 사원 PC | J10: 본사 | K10: 관리부 전산팀 | L10: 홍길동 | N10: 3 | O10: 3 | P10: 3 | Q10: =IF(R10>=7,"H",IF(R10>=5,"M","L")) -> H | R10: =SUM(N10:P10) -> 9
A11: 7 | B11: P-07 | C11: 10.0.19.1/24 | G11: Windows 10 | H11: 10 | I11: 사원 PC | J11: 본사 | K11: 관리부 전산팀 | L11: 홍길동 | N11: 3 | O11: 3 | P11: 3 | Q11: =IF(R11>=7,"H",IF(R11>=5,"M","L")) -> H | R11: =SUM(N11:P11) -> 9
A12: 8 | B12: P-08 | C12: 10.0.19.2/24 | G12: Windows 10 | H12: 10 | I12: 사원 PC | J12: 본사 | K12: 관리부 전산팀 | L12: 홍길동 | N12: 3 | O12: 3 | P12: 3 | Q12: =IF(R12>=7,"H",IF(R12>=5,"M","L")) -> H | R12: =SUM(N12:P12) -> 9
A13: 9 | B13: P-09 | C13: 10.0.20.1/24 | G13: Windows 10 | H13: 10 | I13: 사원 PC | J13: 본사 | K13: 관리부 전산팀 | L13: 홍길동 | N13: 3 | O13: 3 | P13: 3 | Q13: =IF(R13>=7,"H",IF(R13>=5,"M","L")) -> H | R13: =SUM(N13:P13) -> 9
A14: 10 | B14: P-10 | C14: 10.0.20.2/24 | G14: Windows 10 | H14: 10 | I14: 사원 PC | J14: 본사 | K14: 관리부 전산팀 | L14: 홍길동 | N14: 3 | O14: 3 | P14: 3 | Q14: =IF(R14>=7,"H",IF(R14>=5,"M","L")) -> H | R14: =SUM(N14:P14) -> 9
A15: 11 | B15: P-11 | C15: 10.0.21.1/24 | G15: Windows 10 | H15: 10 | I15: 사원 PC | J15: 본사 | K15: 관리부 전산팀 | L15: 홍길동 | N15: 3 | O15: 3 | P15: 3 | Q15: =IF(R15>=7,"H",IF(R15>=5,"M","L")) -> H | R15: =SUM(N15:P15) -> 9
A16: 12 | B16: P-12 | C16: 10.0.21.2/24 | G16: Windows 10 | H16: 10 | I16: 사원 PC | J16: 본사 | K16: 관리부 전산팀 | L16: 홍길동 | N16: 3 | O16: 3 | P16: 3 | Q16: =IF(R16>=7,"H",IF(R16>=5,"M","L")) -> H | R16: =SUM(N16:P16) -> 9
... A30: 26 | B30: P-26 | C30: 10.0.52.2/24 | G30: Windows 10 | H30: 10 | I30: 사원 PC | J30: 지사 | K30: 관리부 전산팀 | L30: 김철수 | N30: 3 | O30: 3 | P30: 3 | Q30: =IF(R30>=7,"H",IF(R30>=5,"M","L")) -> H | R30: =SUM(N30:P30) -> 9

Sheet parm(hidden)
B2: 1. 분류 Code
B3: Code
B4: NW
B6: 2. 중요도, 자산등급, 위협도 점수
B7: 중요도 | C7: 점수
B8: H | C8: 3
B9: M | C9: 2
B10: L | C10: 1
B12: 3. 점검결과 점수
B13: 점검 결과 | C13: 점수
C14: 취약점 진단 | D14: 위험평가
B15: Y | C15: 1 | D15: 0
B16: N | C16: 0 | D16: 3 | F16: P | G16: 0.5 | H16: 0.5
B17: N/A | C17: 0 | D17: 0
B18: R/A | C18: 0 | D18: 0
B19: Y(즉시조치) | C19: 1 | D19: 0
B21: 4. DoA
B22: DoA
B23: 21
B25: 5. 자산등급 점수 범위 | F25: 8_2. 위험평가 방법론
B26: 위험 등급 | C26: 점수 범위
C27: 최저 | D27: 최고
B28: H | C28: 7 | D28: 9
B29: M | C29: 5 | D29: 6
B30: L | C30: 3 | D30: 4
B32: 6. 위협도 점수 범위
B33: 위험 등급 | C33: 점수 범위
C34: 최저 | D34: 최고
B35: H | C35: 5 | D35: 6
B36: M | C36: 4 | D36: 4
B37: L | C37: 2 | D37: 3
B39: 7. 위험도 점수 범위
B40: 위험 등급 | C40: 점수 범위
C41: 최저 | D41: 최고
B42: H | C42: =$B$23 -> 21 | D42: 30
B43: M | C43: 11 | D43: =$C$42-1 -> 20
B44: L | C44: 1 | D44: =$C$43-1 -> 10
B46: 8. 위험도 평가표
B47: 8_1. 위험도 평가표
B48: V' | C48: 보호대책 | D48: Y=0(보호대책 있음) | M48: N=1(보호대책 없음)
...

Sheet ChkList
A1: ■ Check List
A3: 취약점 진단항목 | F3: 개선방안 및 보호대책
A4: 분류 | C4: 진단항목 | D4: 중요도 | E4: 위험도 | F4: PC
A5: 계정 관리 | B5: PC-01 | C5: 비밀번호의 주기적 변경 | D5: H | E5: 3 | F5: ※ 최대 암호 사용 기간 “90일” 설정 ※ 최소 암호 사용 기간 “1일” 설정 ※ 최근 암호 기억 설정 (권장: 24개의 비밀번호 기억) ※ 사용자가 새 비밀번호를 변경하기 전에 이를 유지해야 하는 일수를 결정. 비밀번호 변경 후 편의성 때문에 기존 비밀번호로 다시 설정하는 경우가 많으므로 최소 사용 기간을 설정 ※ 이전 비밀번호를 다시 사용한다면 변경 주기가 의미가 없으므로 기존에 사용하던 비밀번호를 기억해서 사용하지 못하게 함
A6: 계정 관리 | B6: PC-02 | C6: 비밀번호 관리정책 설정 | D6: H | E6: 3 | F6: 비밀번호 정책을 해당 기관의 보안 정책에 적합하게 설정
A7: 계정관리 | B7: PC-03 | C7: 복구 콘솔에서 자동 로그온을 금지하도록 설정 | D7: M | E7: 2 | F7: 복구 콘솔 자동 로그온 허용 “사용 안 함”으로 설정
A8: 서비스 관리 | B8: PC-04 | C8: 공유 폴더 제거 | D8: H | E8: 3 | F8: Ÿ 공유 폴더 불필요 시 삭제 Ÿ 공유 폴더 필요하면 적절한 접근 권한 부여 및 비밀번호 설정 Ÿ 조치 후 “AutoShareWks”값 변경으로 자동 공유 방지
A9: 서비스 관리 | B9: PC-05 | C9: 항목의 불필요한 서비스 제거 | D9: H | E9: 3 | F9: 불필요한 서비스 중지 설정
A10: 서비스 관리 | B10: PC-06 | C10: 비인가 상용 메신저 사용 금지 | D10: H | E10: 3 | F10: “Windows Messenger를 실행하지 않음” 설정 및 상용 메신저 삭제
A11: 서비스 관리 | B11: PC-07 | C11: 파일 시스템이 NTFS 포맷으로 설정 | D11: M | E11: 2 | F11: 모든 디스크 볼륨에 대해 파일 시스템 NTFS로 변경
A12: 서비스 관리 | B12: PC-08 | D12: M | E12: 2 | F12: 하나의 OS만 설치하여 운영함
A13: 서비스 관리 | B13: PC-09 | C13: 브라우저 종료 시 임시 인터넷 파일 폴더의 내용을 삭제하도록 설정 | D13: L | E13: 1 | F13: 하나의 OS만 설치하여 운영함
A14: 패치 관리 | B14: PC-10 | C14: 주기적 보안 패치 및 벤더 권고사항 적용 | D14: H | E14: 3 | F14: Windows Update 사이트에 접속하여 최신 패치 존재 여부 확인 및 패치 적용
A15: 패치 관리 | B15: PC-11 | C15: 지원이 종료되지 않은 Windows OS Build 적용 | D15: H | E15: 3 | F15: Windows Update 사이트에 접속하여 최신 서비스팩 여부 확인 및 적용
A16: 보안 관리 | B16: PC-12 | C16: Windows 자동 로그인 점검 | D16: M | E16: 2 | F16: Windows 자동 로그인 비활성화 설정
A17: 보안 관리 | B17: PC-13 | C17: 바이러스 백신 프로그램 설치 및 주기적 업데이트 | D17: H | E17: 3 | F17: 바이러스 백신 설치 및 최신 업데이트 적용
A18: 보안 관리 | B18: PC-14 | C18: 바이러스 백신 프로그램에서 제공하는 실시간 감시 기능 활성화 | D18: H | E18: 3 | F18: 바이러스 백신 실시간 감시 기능 설정
A19: 보안 관리 | B19: PC-15 | C19: OS에서 제공하는 침입차단 기능 활성화 | D19: H | E19: 3 | F19: Windows 방화벽 “사용”으로 설정 또는 유·무료 기타 방화벽을 사용
A20: 보안 관리 | B20: PC-16 | C20: 화면보호기 대기 시간 설정 및 재시작 시 암호 보호 설정 | D20: H | E20: 3 | F20: 화면보호기 설정 및 비밀번호 보호 설정
A21: 보안 관리 | B21: PC-17 | C21: CD, DVD, USB 메모리 등과 같은 미디어의 자동 실행 방지 등 이동식 미디어에 대한 보안대책 수립 | D21: H | E21: 3 | F21: 미디어 자동 실행 방지 설정
A22: 보안 관리 | B22: PC-18 | C22: 원격 지원을 금지하도록 정책이 설정 | D22: M | E22: 2 | F22: 원격 지원 서비스 비활성화

Sheet 취약점 진단 통계
A1: ■ 영역별/장비별 보안수준 통계
A3: 1) 영역별 보안수준
A4: 분류 | E4: 진단 결과 | J4: 중요도점수
E5: 전체항목 | F5: 진단항목 | G5: 양호 | H5: 취약 | I5: 해당없음 | J5: 전체점수 | K5: 평가점수 | L5: 보안수준
A6: =ChkList!A5 -> 계정 관리 | E6: =SUMIF('취약점 진단 항목별 통계'!$A:$A,$A6&"*",'취약점 진단 항목별 통계'!$F:$F) -> 6 | F6: =E6-I6 -> 6 | G6: =SUMIF('취약점 진단 항목별 통계'!$A:$A,$A6&"*",'취약점 진단 항목별 통계'!$G:$G)+SUMIF('취약점 진단 항목별 통계'!$A:$A,$A6&"*",'취약점 진단 항목별 통계'!$H:$H) -> 3 | H6: =SUMIF('취약점 진단 항목별 통계'!$A:$A,$A6&"*",'취약점 진단 항목별 통계'!$I:$I) -> 0 | I6: =SUMIF('취약점 진단 항목별 통계'!$A:$A,$A6&"*",'취약점 진단 항목별 통계'!$J:$J) -> 0 | J6: =SUMIF('취약점 진단 항목별 통계'!$A:$A,$A6&"*",'취약점 진단 항목별 통계'!$K:$K) -> 18 | K6: =SUMIF('취약점 진단 항목별 통계'!$A:$A,$A6&"*",'취약점 진단 항목별 통계'!$L:$L) -> 9 | L6: =IF($I6=$E6, "N/A", (K6/J6)) -> 0.5
A7: =ChkList!A8 -> 서비스 관리 | E7: =SUMIF('취약점 진단 항목별 통계'!$A:$A,$A7&"*",'취약점 진단 항목별 통계'!$F:$F) -> 18 | F7: =E7-I7 -> 18 | G7: =SUMIF('취약점 진단 항목별 통계'!$A:$A,$A7&"*",'취약점 진단 항목별 통계'!$G:$G)+SUMIF('취약점 진단 항목별 통계'!$A:$A,$A7&"*",'취약점 진단 항목별 통계'!$H:$H) -> 9 | H7: =SUMIF('취약점 진단 항목별 통계'!$A:$A,$A7&"*",'취약점 진단 항목별 통계'!$I:$I) -> 6 | I7: =SUMIF('취약점 진단 항목별 통계'!$A:$A,$A7&"*",'취약점 진단 항목별 통계'!$J:$J) -> 0 | J7: =SUMIF('취약점 진단 항목별 통계'!$A:$A,$A7&"*",'취약점 진단 항목별 통계'!$K:$K) -> 42 | K7: =SUMIF('취약점 진단 항목별 통계'!$A:$A,$A7&"*",'취약점 진단 항목별 통계'!$L:$L) -> 18 | L7: =IF($I7=$E7, "N/A", (K7/J7)) -> 0.42857143
A8: =ChkList!A14 -> 패치 관리 | E8: =SUMIF('취약점 진단 항목별 통계'!$A:$A,$A8&"*",'취약점 진단 항목별 통계'!$F:$F) -> 6 | F8: =E8-I8 -> 6 | G8: =SUMIF('취약점 진단 항목별 통계'!$A:$A,$A8&"*",'취약점 진단 항목별 통계'!$G:$G)+SUMIF('취약점 진단 항목별 통계'!$A:$A,$A8&"*",'취약점 진단 항목별 통계'!$H:$H) -> 0 | H8: =SUMIF('취약점 진단 항목별 통계'!$A:$A,$A8&"*",'취약점 진단 항목별 통계'!$I:$I) -> 0 | I8: =SUMIF('취약점 진단 항목별 통계'!$A:$A,$A8&"*",'취약점 진단 항목별 통계'!$J:$J) -> 0 | J8: =SUMIF('취약점 진단 항목별 통계'!$A:$A,$A8&"*",'취약점 진단 항목별 통계'!$K:$K) -> 18 | K8: =SUMIF('취약점 진단 항목별 통계'!$A:$A,$A8&"*",'취약점 진단 항목별 통계'!$L:$L) -> 0 | L8: =IF($I8=$E8, "N/A", (K8/J8)) -> 0
A9: =ChkList!A17 -> 보안 관리 | E9: =SUMIF('취약점 진단 항목별 통계'!$A:$A,$A9&"*",'취약점 진단 항목별 통계'!$F:$F) -> 21 | F9: =E9-I9 -> 18 | G9: =SUMIF('취약점 진단 항목별 통계'!$A:$A,$A9&"*",'취약점 진단 항목별 통계'!$G:$G)+SUMIF('취약점 진단 항목별 통계'!$A:$A,$A9&"*",'취약점 진단 항목별 통계'!$H:$H) -> 9 | H9: =SUMIF('취약점 진단 항목별 통계'!$A:$A,$A9&"*",'취약점 진단 항목별 통계'!$I:$I) -> 9 | I9: =SUMIF('취약점 진단 항목별 통계'!$A:$A,$A9&"*",'취약점 진단 항목별 통계'!$J:$J) -> 3 | J9: =SUMIF('취약점 진단 항목별 통계'!$A:$A,$A9&"*",'취약점 진단 항목별 통계'!$K:$K) -> 51 | K9: =SUMIF('취약점 진단 항목별 통계'!$A:$A,$A9&"*",'취약점 진단 항목별 통계'!$L:$L) -> 24 | L9: =IF($I9=$E9, "N/A", (K9/J9)) -> 0.47058824
A10: 계 | E10: =SUM(E6:E9) -> 51 | F10: =SUM(F6:F9) -> 48 | G10: =SUM(G6:G9) -> 21 | H10: =SUM(H6:H9) -> 15 | I10: =SUM(I6:I9) -> 3 | J10: =SUM(J6:J9) -> 129 | K10: =SUM(K6:K9) -> 51 | L10: =IFERROR(K10/J10, 0) -> 0.39534884
A38: 2) 장비별 보안수준
A39: 장비 구분 | E39: 진단 결과 | J39: 중요도점수
E40: 전체항목 | F40: 진단항목 | G40: 양호 | H40: 취약 | I40: 해당없음 | J40: 전체점수 | K40: 평가점수 | L40: 보안수준
A41: =HYPERLINK("#'P-01'!A1", "P-01") -> P-01 | C41: =IFERROR(VLOOKUP($A41,자산목록!$B$1:$M$833,6,FALSE),"-") -> Windows 10 | E41: =IFERROR(INDIRECT(ADDRESS(16, 4, 1, TRUE, $A41)), 0) -> 17 | F41: =E41-I41 -> 17 | G41: =IFERROR(INDIRECT(ADDRESS(16, 5, 1,TRUE,$A41)),0) -> 7 | H41: =IFERROR(INDIRECT(ADDRESS(16, 6, 1,TRUE,$A41)),0) -> 5 | I41: =IFERROR(INDIRECT(ADDRESS(17, 7, 1,TRUE,$A41)),0) -> 0 | J41: =IFERROR(INDIRECT(ADDRESS(16, 18, 1,TRUE,$A41)),0) -> 0 | K41: =IFERROR(INDIRECT(ADDRESS(16, 18, 1,TRUE,$A41)),0) -> 0 | L41: =IFERROR(INDIRECT(ADDRESS(16,8, 1,TRUE,$A41)),0) -> 0
A42: =HYPERLINK("#'P-02'!A1", "P-02") -> P-02 | C42: =IFERROR(VLOOKUP($A42,자산목록!$B$1:$M$833,6,FALSE),"-") -> Windows 10 | E42: =IFERROR(INDIRECT(ADDRESS(16, 4, 1, TRUE, $A42)), 0) -> 17 | F42: =E42-I42 -> 17 | G42: =IFERROR(INDIRECT(ADDRESS(16, 5, 1,TRUE,$A42)),0) -> 7 | H42: =IFERROR(INDIRECT(ADDRESS(16, 6, 1,TRUE,$A42)),0) -> 5 | I42: =IFERROR(INDIRECT(ADDRESS(17, 7, 1,TRUE,$A42)),0) -> 0 | J42: =IFERROR(INDIRECT(ADDRESS(16, 18, 1,TRUE,$A42)),0) -> 43 | K42: =IFERROR(INDIRECT(ADDRESS(16, 18, 1,TRUE,$A42)),0) -> 43 | L42: =IFERROR(INDIRECT(ADDRESS(16,8, 1,TRUE,$A42)),0) -> 0.39534884
A43: =HYPERLINK("#'P-03'!A1", "P-03") -> P-03 | C43: =IFERROR(VLOOKUP($A43,자산목록!$B$1:$M$833,6,FALSE),"-") -> Windows 10 | E43: =IFERROR(INDIRECT(ADDRESS(16, 4, 1, TRUE, $A43)), 0) -> 19 | F43: =E43-I43 -> 19 | G43: =IFERROR(INDIRECT(ADDRESS(16, 5, 1,TRUE,$A43)),0) -> 9 | H43: =IFERROR(INDIRECT(ADDRESS(16, 6, 1,TRUE,$A43)),0) -> 5 | I43: =IFERROR(INDIRECT(ADDRESS(17, 7, 1,TRUE,$A43)),0) -> 0 | J43: =IFERROR(INDIRECT(ADDRESS(16, 18, 1,TRUE,$A43)),0) -> 0 | K43: =IFERROR(INDIRECT(ADDRESS(16, 18, 1,TRUE,$A43)),0) -> 0 | L43: =IFERROR(INDIRECT(ADDRESS(16,8, 1,TRUE,$A43)),0) -> 0
A44: =HYPERLINK("#'P-04'!A1", "P-04") -> P-04 | C44: =IFERROR(VLOOKUP($A44,자산목록!$B$1:$M$833,6,FALSE),"-") -> Windows 10 | E44: =IFERROR(INDIRECT(ADDRESS(16, 4, 1, TRUE, $A44)), 0) -> 19 | F44: =E44-I44 -> 19 | G44: =IFERROR(INDIRECT(ADDRESS(16, 5, 1,TRUE,$A44)),0) -> 9 | H44: =IFERROR(INDIRECT(ADDRESS(16, 6, 1,TRUE,$A44)),0) -> 5 | I44: =IFERROR(INDIRECT(ADDRESS(17, 7, 1,TRUE,$A44)),0) -> 0 | J44: =IFERROR(INDIRECT(ADDRESS(16, 18, 1,TRUE,$A44)),0) -> 0 | K44: =IFERROR(INDIRECT(ADDRESS(16, 18, 1,TRUE,$A44)),0) -> 0 | L44: =IFERROR(INDIRECT(ADDRESS(16,8, 1,TRUE,$A44)),0) -> 0
A45: =HYPERLINK("#'P-05'!A1", "P-05") -> P-05 | C45: =IFERROR(VLOOKUP($A45,자산목록!$B$1:$M$833,6,FALSE),"-") -> Windows 10 | E45: =IFERROR(INDIRECT(ADDRESS(16, 4, 1, TRUE, $A45)), 0) -> 19 | F45: =E45-I45 -> 19 | G45: =IFERROR(INDIRECT(ADDRESS(16, 5, 1,TRUE,$A45)),0) -> 9 | H45: =IFERROR(INDIRECT(ADDRESS(16, 6, 1,TRUE,$A45)),0) -> 5 | I45: =IFERROR(INDIRECT(ADDRESS(17, 7, 1,TRUE,$A45)),0) -> 0 | J45: =IFERROR(INDIRECT(ADDRESS(16, 18, 1,TRUE,$A45)),0) -> 0 | K45: =IFERROR(INDIRECT(ADDRESS(16, 18, 1,TRUE,$A45)),0) -> 0 | L45: =IFERROR(INDIRECT(ADDRESS(16,8, 1,TRUE,$A45)),0) -> 0
A46: =HYPERLINK("#'P-06'!A1", "P-06") -> P-06 | C46: =IFERROR(VLOOKUP($A46,자산목록!$B$1:$M$833,6,FALSE),"-") -> Windows 10 | E46: =IFERROR(INDIRECT(ADDRESS(16, 4, 1, TRUE, $A46)), 0) -> 19 | F46: =E46-I46 -> 19 | G46: =IFERROR(INDIRECT(ADDRESS(16, 5, 1,TRUE,$A46)),0) -> 9 | H46: =IFERROR(INDIRECT(ADDRESS(16, 6, 1,TRUE,$A46)),0) -> 5 | I46: =IFERROR(INDIRECT(ADDRESS(17, 7, 1,TRUE,$A46)),0) -> 0 | J46: =IFERROR(INDIRECT(ADDRESS(16, 18, 1,TRUE,$A46)),0) -> 0 | K46: =IFERROR(INDIRECT(ADDRESS(16, 18, 1,TRUE,$A46)),0) -> 0 | L46: =IFERROR(INDIRECT(ADDRESS(16,8, 1,TRUE,$A46)),0) -> 0
A47: =HYPERLINK("#'P-07'!A1", "P-07") -> P-07 | C47: =IFERROR(VLOOKUP($A47,자산목록!$B$1:$M$833,6,FALSE),"-") -> Windows 10 | E47: =IFERROR(INDIRECT(ADDRESS(16, 4, 1, TRUE, $A47)), 0) -> 19 | F47: =E47-I47 -> 19 | G47: =IFERROR(INDIRECT(ADDRESS(16, 5, 1,TRUE,$A47)),0) -> 9 | H47: =IFERROR(INDIRECT(ADDRESS(16, 6, 1,TRUE,$A47)),0) -> 5 | I47: =IFERROR(INDIRECT(ADDRESS(17, 7, 1,TRUE,$A47)),0) -> 0 | J47: =IFERROR(INDIRECT(ADDRESS(16, 18, 1,TRUE,$A47)),0) -> 0 | K47: =IFERROR(INDIRECT(ADDRESS(16, 18, 1,TRUE,$A47)),0) -> 0 | L47: =IFERROR(INDIRECT(ADDRESS(16,8, 1,TRUE,$A47)),0) -> 0
A48: =HYPERLINK("#'P-08'!A1", "P-08") -> P-08 | C48: =IFERROR(VLOOKUP($A48,자산목록!$B$1:$M$833,6,FALSE),"-") -> Windows 10 | E48: =IFERROR(INDIRECT(ADDRESS(16, 4, 1, TRUE, $A48)), 0) -> 19 | F48: =E48-I48 -> 19 | G48: =IFERROR(INDIRECT(ADDRESS(16, 5, 1,TRUE,$A48)),0) -> 9 | H48: =IFERROR(INDIRECT(ADDRESS(16, 6, 1,TRUE,$A48)),0) -> 5 | I48: =IFERROR(INDIRECT(ADDRESS(17, 7, 1,TRUE,$A48)),0) -> 0 | J48: =IFERROR(INDIRECT(ADDRESS(16, 18, 1,TRUE,$A48)),0) -> 0 | K48: =IFERROR(INDIRECT(ADDRESS(16, 18, 1,TRUE,$A48)),0) -> 0 | L48: =IFERROR(INDIRECT(ADDRESS(16,8, 1,TRUE,$A48)),0) -> 0
A49: =HYPERLINK("#'P-09'!A1", "P-09") -> P-09 | C49: =IFERROR(VLOOKUP($A49,자산목록!$B$1:$M$833,6,FALSE),"-") -> Windows 10 | E49: =IFERROR(INDIRECT(ADDRESS(16, 4, 1, TRUE, $A49)), 0) -> 19 | F49: =E49-I49 -> 19 | G49: =IFERROR(INDIRECT(ADDRESS(16, 5, 1,TRUE,$A49)),0) -> 9 | H49: =IFERROR(INDIRECT(ADDRESS(16, 6, 1,TRUE,$A49)),0) -> 5 | I49: =IFERROR(INDIRECT(ADDRESS(17, 7, 1,TRUE,$A49)),0) -> 0 | J49: =IFERROR(INDIRECT(ADDRESS(16, 18, 1,TRUE,$A49)),0) -> 0 | K49: =IFERROR(INDIRECT(ADDRESS(16, 18, 1,TRUE,$A49)),0) -> 0 | L49: =IFERROR(INDIRECT(ADDRESS(16,8, 1,TRUE,$A49)),0) -> 0
A50: =HYPERLINK("#'P-10'!A1", "P-10") -> P-10 | C50: =IFERROR(VLOOKUP($A50,자산목록!$B$1:$M$833,6,FALSE),"-") -> Windows 10 | E50: =IFERROR(INDIRECT(ADDRESS(16, 4, 1, TRUE, $A50)), 0) -> 19 | F50: =E50-I50 -> 19 | G50: =IFERROR(INDIRECT(ADDRESS(16, 5, 1,TRUE,$A50)),0) -> 9 | H50: =IFERROR(INDIRECT(ADDRESS(16, 6, 1,TRUE,$A50)),0) -> 5 | I50: =IFERROR(INDIRECT(ADDRESS(17, 7, 1,TRUE,$A50)),0) -> 0 | J50: =IFERROR(INDIRECT(ADDRESS(16, 18, 1,TRUE,$A50)),0) -> 0 | K50: =IFERROR(INDIRECT(ADDRESS(16, 18, 1,TRUE,$A50)),0) -> 0 | L50: =IFERROR(INDIRECT(ADDRESS(16,8, 1,TRUE,$A50)),0) -> 0
A51: =HYPERLINK("#'P-11'!A1", "P-11") -> P-11 | C51: =IFERROR(VLOOKUP($A51,자산목록!$B$1:$M$833,6,FALSE),"-") -> Windows 10 | E51: =IFERROR(INDIRECT(ADDRESS(16, 4, 1, TRUE, $A51)), 0) -> 19 | F51: =E51-I51 -> 19 | G51: =IFERROR(INDIRECT(ADDRESS(16, 5, 1,TRUE,$A51)),0) -> 9 | H51: =IFERROR(INDIRECT(ADDRESS(16, 6, 1,TRUE,$A51)),0) -> 5 | I51: =IFERROR(INDIRECT(ADDRESS(17, 7, 1,TRUE,$A51)),0) -> 0 | J51: =IFERROR(INDIRECT(ADDRESS(16, 18, 1,TRUE,$A51)),0) -> 0 | K51: =IFERROR(INDIRECT(ADDRESS(16, 18, 1,TRUE,$A51)),0) -> 0 | L51: =IFERROR(INDIRECT(ADDRESS(16,8, 1,TRUE,$A51)),0) -> 0
A52: =HYPERLINK("#'P-12'!A1", "P-12") -> P-12 | C52: =IFERROR(VLOOKUP($A52,자산목록!$B$1:$M$833,6,FALSE),"-") -> Windows 10 | E52: =IFERROR(INDIRECT(ADDRESS(16, 4, 1, TRUE, $A52)), 0) -> 19 | F52: =E52-I52 -> 19 | G52: =IFERROR(INDIRECT(ADDRESS(16, 5, 1,TRUE,$A52)),0) -> 9 | H52: =IFERROR(INDIRECT(ADDRESS(16, 6, 1,TRUE,$A52)),0) -> 5 | I52: =IFERROR(INDIRECT(ADDRESS(17, 7, 1,TRUE,$A52)),0) -> 0 | J52: =IFERROR(INDIRECT(ADDRESS(16, 18, 1,TRUE,$A52)),0) -> 0 | K52: =IFERROR(INDIRECT(ADDRESS(16, 18, 1,TRUE,$A52)),0) -> 0 | L52: =IFERROR(INDIRECT(ADDRESS(16,8, 1,TRUE,$A52)),0) -> 0
A53: =HYPERLINK("#'P-13'!A1", "P-13") -> P-13 | C53: =IFERROR(VLOOKUP($A53,자산목록!$B$1:$M$833,6,FALSE),"-") -> Windows 10 | E53: =IFERROR(INDIRECT(ADDRESS(16, 4, 1, TRUE, $A53)), 0) -> 19 | F53: =E53-I53 -> 19 | G53: =IFERROR(INDIRECT(ADDRESS(16, 5, 1,TRUE,$A53)),0) -> 9 | H53: =IFERROR(INDIRECT(ADDRESS(16, 6, 1,TRUE,$A53)),0) -> 5 | I53: =IFERROR(INDIRECT(ADDRESS(17, 7, 1,TRUE,$A53)),0) -> 0 | J53: =IFERROR(INDIRECT(ADDRESS(16, 18, 1,TRUE,$A53)),0) -> 0 | K53: =IFERROR(INDIRECT(ADDRESS(16, 18, 1,TRUE,$A53)),0) -> 0 | L53: =IFERROR(INDIRECT(ADDRESS(16,8, 1,TRUE,$A53)),0) -> 0
A54: =HYPERLINK("#'P-14'!A1", "P-14") -> P-14 | C54: =IFERROR(VLOOKUP($A54,자산목록!$B$1:$M$833,6,FALSE),"-") -> Windows 10 | E54: =IFERROR(INDIRECT(ADDRESS(16, 4, 1, TRUE, $A54)), 0) -> 19 | F54: =E54-I54 -> 19 | G54: =IFERROR(INDIRECT(ADDRESS(16, 5, 1,TRUE,$A54)),0) -> 9 | H54: =IFERROR(INDIRECT(ADDRESS(16, 6, 1,TRUE,$A54)),0) -> 5 | I54: =IFERROR(INDIRECT(ADDRESS(17, 7, 1,TRUE,$A54)),0) -> 0 | J54: =IFERROR(INDIRECT(ADDRESS(16, 18, 1,TRUE,$A54)),0) -> 0 | K54: =IFERROR(INDIRECT(ADDRESS(16, 18, 1,TRUE,$A54)),0) -> 0 | L54: =IFERROR(INDIRECT(ADDRESS(16,8, 1,TRUE,$A54)),0) -> 0
A55: =HYPERLINK("#'P-15'!A1", "P-15") -> P-15 | C55: =IFERROR(VLOOKUP($A55,자산목록!$B$1:$M$833,6,FALSE),"-") -> Windows 10 | E55: =IFERROR(INDIRECT(ADDRESS(16, 4, 1, TRUE, $A55)), 0) -> 19 | F55: =E55-I55 -> 19 | G55: =IFERROR(INDIRECT(ADDRESS(16, 5, 1,TRUE,$A55)),0) -> 9 | H55: =IFERROR(INDIRECT(ADDRESS(16, 6, 1,TRUE,$A55)),0) -> 5 | I55: =IFERROR(INDIRECT(ADDRESS(17, 7, 1,TRUE,$A55)),0) -> 0 | J55: =IFERROR(INDIRECT(ADDRESS(16, 18, 1,TRUE,$A55)),0) -> 0 | K55: =IFERROR(INDIRECT(ADDRESS(16, 18, 1,TRUE,$A55)),0) -> 0 | L55: =IFERROR(INDIRECT(ADDRESS(16,8, 1,TRUE,$A55)),0) -> 0
A56: =HYPERLINK("#'P-16'!A1", "P-16") -> P-16 | C56: =IFERROR(VLOOKUP($A56,자산목록!$B$1:$M$833,6,FALSE),"-") -> Windows 10 | E56: =IFERROR(INDIRECT(ADDRESS(16, 4, 1, TRUE, $A56)), 0) -> 19 | F56: =E56-I56 -> 19 | G56: =IFERROR(INDIRECT(ADDRESS(16, 5, 1,TRUE,$A56)),0) -> 9 | H56: =IFERROR(INDIRECT(ADDRESS(16, 6, 1,TRUE,$A56)),0) -> 5 | I56: =IFERROR(INDIRECT(ADDRESS(17, 7, 1,TRUE,$A56)),0) -> 0 | J56: =IFERROR(INDIRECT(ADDRESS(16, 18, 1,TRUE,$A56)),0) -> 0 | K56: =IFERROR(INDIRECT(ADDRESS(16, 18, 1,TRUE,$A56)),0) -> 0 | L56: =IFERROR(INDIRECT(ADDRESS(16,8, 1,TRUE,$A56)),0) -> 0
A57: =HYPERLINK("#'P-17'!A1", "P-17") -> P-17 | C57: =IFERROR(VLOOKUP($A57,자산목록!$B$1:$M$833,6,FALSE),"-") -> Windows 10 | E57: =IFERROR(INDIRECT(ADDRESS(16, 4, 1, TRUE, $A57)), 0) -> 19 | F57: =E57-I57 -> 19 | G57: =IFERROR(INDIRECT(ADDRESS(16, 5, 1,TRUE,$A57)),0) -> 9 | H57: =IFERROR(INDIRECT(ADDRESS(16, 6, 1,TRUE,$A57)),0) -> 5 | I57: =IFERROR(INDIRECT(ADDRESS(17, 7, 1,TRUE,$A57)),0) -> 0 | J57: =IFERROR(INDIRECT(ADDRESS(16, 18, 1,TRUE,$A57)),0) -> 0 | K57: =IFERROR(INDIRECT(ADDRESS(16, 18, 1,TRUE,$A57)),0) -> 0 | L57: =IFERROR(INDIRECT(ADDRESS(16,8, 1,TRUE,$A57)),0) -> 0
A58: =HYPERLINK("#'P-18'!A1", "P-18") -> P-18 | C58: =IFERROR(VLOOKUP($A58,자산목록!$B$1:$M$833,6,FALSE),"-") -> Windows 10 | E58: =IFERROR(INDIRECT(ADDRESS(16, 4, 1, TRUE, $A58)), 0) -> 19 | F58: =E58-I58 -> 19 | G58: =IFERROR(INDIRECT(ADDRESS(16, 5, 1,TRUE,$A58)),0) -> 9 | H58: =IFERROR(INDIRECT(ADDRESS(16, 6, 1,TRUE,$A58)),0) -> 5 | I58: =IFERROR(INDIRECT(ADDRESS(17, 7, 1,TRUE,$A58)),0) -> 0 | J58: =IFERROR(INDIRECT(ADDRESS(16, 18, 1,TRUE,$A58)),0) -> 0 | K58: =IFERROR(INDIRECT(ADDRESS(16, 18, 1,TRUE,$A58)),0) -> 0 | L58: =IFERROR(INDIRECT(ADDRESS(16,8, 1,TRUE,$A58)),0) -> 0
A59: =HYPERLINK("#'P-19'!A1", "P-19") -> P-19 | C59: =IFERROR(VLOOKUP($A59,자산목록!$B$1:$M$833,6,FALSE),"-") -> Windows 10 | E59: =IFERROR(INDIRECT(ADDRESS(16, 4, 1, TRUE, $A59)), 0) -> 19 | F59: =E59-I59 -> 19 | G59: =IFERROR(INDIRECT(ADDRESS(16, 5, 1,TRUE,$A59)),0) -> 9 | H59: =IFERROR(INDIRECT(ADDRESS(16, 6, 1,TRUE,$A59)),0) -> 5 | I59: =IFERROR(INDIRECT(ADDRESS(17, 7, 1,TRUE,$A59)),0) -> 0 | J59: =IFERROR(INDIRECT(ADDRESS(16, 18, 1,TRUE,$A59)),0) -> 0 | K59: =IFERROR(INDIRECT(ADDRESS(16, 18, 1,TRUE,$A59)),0) -> 0 | L59: =IFERROR(INDIRECT(ADDRESS(16,8, 1,TRUE,$A59)),0) -> 0
A60: =HYPERLINK("#'P-20'!A1", "P-20") -> P-20 | C60: =IFERROR(VLOOKUP($A60,자산목록!$B$1:$M$833,6,FALSE),"-") -> Windows 10 | E60: =IFERROR(INDIRECT(ADDRESS(16, 4, 1, TRUE, $A60)), 0) -> 19 | F60: =E60-I60 -> 19 | G60: =IFERROR(INDIRECT(ADDRESS(16, 5, 1,TRUE,$A60)),0) -> 9 | H60: =IFERROR(INDIRECT(ADDRESS(16, 6, 1,TRUE,$A60)),0) -> 5 | I60: =IFERROR(INDIRECT(ADDRESS(17, 7, 1,TRUE,$A60)),0) -> 0 | J60: =IFERROR(INDIRECT(ADDRESS(16, 18, 1,TRUE,$A60)),0) -> 0 | K60: =IFERROR(INDIRECT(ADDRESS(16, 18, 1,TRUE,$A60)),0) -> 0 | L60: =IFERROR(INDIRECT(ADDRESS(16,8, 1,TRUE,$A60)),0) -> 0
A61: =HYPERLINK("#'P-21'!A1", "P-21") -> P-21 | C61: =IFERROR(VLOOKUP($A61,자산목록!$B$1:$M$833,6,FALSE),"-") -> Windows 10 | E61: =IFERROR(INDIRECT(ADDRESS(16, 4, 1, TRUE, $A61)), 0) -> 19 | F61: =E61-I61 -> 19 | G61: =IFERROR(INDIRECT(ADDRESS(16, 5, 1,TRUE,$A61)),0) -> 9 | H61: =IFERROR(INDIRECT(ADDRESS(16, 6, 1,TRUE,$A61)),0) -> 5 | I61: =IFERROR(INDIRECT(ADDRESS(17, 7, 1,TRUE,$A61)),0) -> 0 | J61: =IFERROR(INDIRECT(ADDRESS(16, 18, 1,TRUE,$A61)),0) -> 0 | K61: =IFERROR(INDIRECT(ADDRESS(16, 18, 1,TRUE,$A61)),0) -> 0 | L61: =IFERROR(INDIRECT(ADDRESS(16,8, 1,TRUE,$A61)),0) -> 0
A62: =HYPERLINK("#'P-22'!A1", "P-22") -> P-22 | C62: =IFERROR(VLOOKUP($A62,자산목록!$B$1:$M$833,6,FALSE),"-") -> Windows 10 | E62: =IFERROR(INDIRECT(ADDRESS(16, 4, 1, TRUE, $A62)), 0) -> 19 | F62: =E62-I62 -> 19 | G62: =IFERROR(INDIRECT(ADDRESS(16, 5, 1,TRUE,$A62)),0) -> 9 | H62: =IFERROR(INDIRECT(ADDRESS(16, 6, 1,TRUE,$A62)),0) -> 5 | I62: =IFERROR(INDIRECT(ADDRESS(17, 7, 1,TRUE,$A62)),0) -> 0 | J62: =IFERROR(INDIRECT(ADDRESS(16, 18, 1,TRUE,$A62)),0) -> 0 | K62: =IFERROR(INDIRECT(ADDRESS(16, 18, 1,TRUE,$A62)),0) -> 0 | L62: =IFERROR(INDIRECT(ADDRESS(16,8, 1,TRUE,$A62)),0) -> 0
A63: =HYPERLINK("#'P-23'!A1", "P-23") -> P-23 | C63: =IFERROR(VLOOKUP($A63,자산목록!$B$1:$M$833,6,FALSE),"-") -> Windows 10 | E63: =IFERROR(INDIRECT(ADDRESS(16, 4, 1, TRUE, $A63)), 0) -> 19 | F63: =E63-I63 -> 19 | G63: =IFERROR(INDIRECT(ADDRESS(16, 5, 1,TRUE,$A63)),0) -> 9 | H63: =IFERROR(INDIRECT(ADDRESS(16, 6, 1,TRUE,$A63)),0) -> 5 | I63: =IFERROR(INDIRECT(ADDRESS(17, 7, 1,TRUE,$A63)),0) -> 0 | J63: =IFERROR(INDIRECT(ADDRESS(16, 18, 1,TRUE,$A63)),0) -> 0 | K63: =IFERROR(INDIRECT(ADDRESS(16, 18, 1,TRUE,$A63)),0) -> 0 | L63: =IFERROR(INDIRECT(ADDRESS(16,8, 1,TRUE,$A63)),0) -> 0
A64: =HYPERLINK("#'P-24'!A1", "P-24") -> P-24 | C64: =IFERROR(VLOOKUP($A64,자산목록!$B$1:$M$833,6,FALSE),"-") -> Windows 10 | E64: =IFERROR(INDIRECT(ADDRESS(16, 4, 1, TRUE, $A64)), 0) -> 19 | F64: =E64-I64 -> 19 | G64: =IFERROR(INDIRECT(ADDRESS(16, 5, 1,TRUE,$A64)),0) -> 9 | H64: =IFERROR(INDIRECT(ADDRESS(16, 6, 1,TRUE,$A64)),0) -> 5 | I64: =IFERROR(INDIRECT(ADDRESS(17, 7, 1,TRUE,$A64)),0) -> 0 | J64: =IFERROR(INDIRECT(ADDRESS(16, 18, 1,TRUE,$A64)),0) -> 0 | K64: =IFERROR(INDIRECT(ADDRESS(16, 18, 1,TRUE,$A64)),0) -> 0 | L64: =IFERROR(INDIRECT(ADDRESS(16,8, 1,TRUE,$A64)),0) -> 0
A65: =HYPERLINK("#'P-25'!A1", "P-25") -> P-25 | C65: =IFERROR(VLOOKUP($A65,자산목록!$B$1:$M$833,6,FALSE),"-") -> Windows 10 | E65: =IFERROR(INDIRECT(ADDRESS(16, 4, 1, TRUE, $A65)), 0) -> 19 | F65: =E65-I65 -> 19 | G65: =IFERROR(INDIRECT(ADDRESS(16, 5, 1,TRUE,$A65)),0) -> 9 | H65: =IFERROR(INDIRECT(ADDRESS(16, 6, 1,TRUE,$A65)),0) -> 5 | I65: =IFERROR(INDIRECT(ADDRESS(17, 7, 1,TRUE,$A65)),0) -> 0 | J65: =IFERROR(INDIRECT(ADDRESS(16, 18, 1,TRUE,$A65)),0) -> 0 | K65: =IFERROR(INDIRECT(ADDRESS(16, 18, 1,TRUE,$A65)),0) -> 0 | L65: =IFERROR(INDIRECT(ADDRESS(16,8, 1,TRUE,$A65)),0) -> 0
A66: =HYPERLINK("#'P-25'!A1", "P-25") -> P-25 | C66: =IFERROR(VLOOKUP($A66,자산목록!$B$1:$M$833,6,FALSE),"-") -> Windows 10 | E66: =IFERROR(INDIRECT(ADDRESS(16, 4, 1, TRUE, $A66)), 0) -> 19 | F66: =E66-I66 -> 19 | G66: =IFERROR(INDIRECT(ADDRESS(16, 5, 1,TRUE,$A66)),0) -> 9 | H66: =IFERROR(INDIRECT(ADDRESS(16, 6, 1,TRUE,$A66)),0) -> 5 | I66: =IFERROR(INDIRECT(ADDRESS(17, 7, 1,TRUE,$A66)),0) -> 0 | J66: =IFERROR(INDIRECT(ADDRESS(16, 18, 1,TRUE,$A66)),0) -> 0 | K66: =IFERROR(INDIRECT(ADDRESS(16, 18, 1,TRUE,$A66)),0) -> 0 | L66: =IFERROR(INDIRECT(ADDRESS(16,8, 1,TRUE,$A66)),0) -> 0
A67: 계 | E67: =SUM(E41:E41) -> 17 | F67: =SUM(F41:F41) -> 17 | G67: =SUM(G41:G41) -> 7 | H67: =SUM(H41:H41) -> 5 | I67: =SUM(I41:I41) -> 0 | J67: =SUM(J41:J41) -> 0 | K67: =SUM(K41:K41) -> 0 | L67: =IFERROR(K67/J67, 0) -> 0

Sheet 취약점 진단 통계 (이행)
A1: ■ 영역별/장비별 보안수준 통계
A3: 1) 영역별 보안수준
A4: 분류 | E4: 진단 결과 | J4: 이행 결과 | O4: 중요도점수
E5: 전체항목 | F5: 진단항목 | G5: 양호 | H5: 취약 | I5: 해당없음 | J5: 조치 | K5: 미조치 | L5: 위험수용 | M5: 해당없음 | N5: 잔여취약점 (미조치+위험수용) | O5: 전체점수 (이행전) | P5: 전체점수 (이행후) | Q5: 평가점수 (이행전) | R5: 평가점수 (이행후) | S5: 이행율 | T5: 보안수준 (이행 전) | U5: 보안수준 (이행 후)
A6: =ChkList!A5 -> 계정 관리 | E6: =SUMIF('취약점 진단 항목별 통계 (이행)'!$A:$A,$A6&"*",'취약점 진단 항목별 통계 (이행)'!$F:$F) -> 6 | F6: =E6-I6 -> 6 | G6: =SUMIF('취약점 진단 항목별 통계'!$A:$A,$A6&"*",'취약점 진단 항목별 통계'!$G:$G)+SUMIF('취약점 진단 항목별 통계'!$A:$A,$A6&"*",'취약점 진단 항목별 통계'!$H:$H) -> 3 | H6: =SUMIF('취약점 진단 항목별 통계'!$A:$A,$A6&"*",'취약점 진단 항목별 통계'!$I:$I) -> 0 | I6: =SUMIF('취약점 진단 항목별 통계'!$A:$A,$A6&"*",'취약점 진단 항목별 통계'!$J:$J) -> 0 | J6: =SUMIF('취약점 진단 항목별 통계 (이행)'!$A:$A,$A6&"*",'취약점 진단 항목별 통계 (이행)'!$K:$K) -> 0 | K6: =SUMIF('취약점 진단 항목별 통계 (이행)'!$A:$A,$A6&"*",'취약점 진단 항목별 통계 (이행)'!$L:$L) -> 3 | L6: =SUMIF('취약점 진단 항목별 통계 (이행)'!$A:$A,$A6&"*",'취약점 진단 항목별 통계 (이행)'!$M:$M) -> 0 | M6: =SUMIF('취약점 진단 항목별 통계 (이행)'!$A:$A,$A6&"*",'취약점 진단 항목별 통계 (이행)'!$N:$N) -> 0 | N6: =K6+L6 -> 3 | O6: =SUMIF('취약점 진단 항목별 통계 (이행)'!$A:$A,$A6&"*",'취약점 진단 항목별 통계 (이행)'!$O:$O) -> 18 | P6: =SUMIF('취약점 진단 항목별 통계 (이행)'!$A:$A,$A6&"*",'취약점 진단 항목별 통계 (이행)'!$P:$P) -> 18 | Q6: =SUMIF('취약점 진단 항목별 통계 (이행)'!$A:$A,$A6&"*",'취약점 진단 항목별 통계 (이행)'!$Q:$Q) -> 9 | R6: =SUMIF('취약점 진단 항목별 통계 (이행)'!$A:$A,$A6&"*",'취약점 진단 항목별 통계 (이행)'!$R:$R) -> 9 | S6: =IFERROR($J6/($H6-(M6-I6)),"N/A") -> N/A | T6: =IF($I6=$E6, "N/A", (Q6/O6)) -> 0.5 | U6: =IF(OR($I6=$E6,$E6=$M6),"N/A", ($R6/$P6)) -> 0.5
A7: =ChkList!A8 -> 서비스 관리 | E7: =SUMIF('취약점 진단 항목별 통계 (이행)'!$A:$A,$A7&"*",'취약점 진단 항목별 통계 (이행)'!$F:$F) -> 18 | F7: =E7-I7 -> 18 | G7: =SUMIF('취약점 진단 항목별 통계'!$A:$A,$A7&"*",'취약점 진단 항목별 통계'!$G:$G)+SUMIF('취약점 진단 항목별 통계'!$A:$A,$A7&"*",'취약점 진단 항목별 통계'!$H:$H) -> 9 | H7: =SUMIF('취약점 진단 항목별 통계'!$A:$A,$A7&"*",'취약점 진단 항목별 통계'!$I:$I) -> 6 | I7: =SUMIF('취약점 진단 항목별 통계'!$A:$A,$A7&"*",'취약점 진단 항목별 통계'!$J:$J) -> 0 | J7: =SUMIF('취약점 진단 항목별 통계 (이행)'!$A:$A,$A7&"*",'취약점 진단 항목별 통계 (이행)'!$K:$K) -> 6 | K7: =SUMIF('취약점 진단 항목별 통계 (이행)'!$A:$A,$A7&"*",'취약점 진단 항목별 통계 (이행)'!$L:$L) -> 3 | L7: =SUMIF('취약점 진단 항목별 통계 (이행)'!$A:$A,$A7&"*",'취약점 진단 항목별 통계 (이행)'!$M:$M) -> 0 | M7: =SUMIF('취약점 진단 항목별 통계 (이행)'!$A:$A,$A7&"*",'취약점 진단 항목별 통계 (이행)'!$N:$N) -> 0 | N7: =K7+L7 -> 3 | O7: =SUMIF('취약점 진단 항목별 통계 (이행)'!$A:$A,$A7&"*",'취약점 진단 항목별 통계 (이행)'!$O:$O) -> 42 | P7: =SUMIF('취약점 진단 항목별 통계 (이행)'!$A:$A,$A7&"*",'취약점 진단 항목별 통계 (이행)'!$P:$P) -> 42 | Q7: =SUMIF('취약점 진단 항목별 통계 (이행)'!$A:$A,$A7&"*",'취약점 진단 항목별 통계 (이행)'!$Q:$Q) -> 18 | R7: =SUMIF('취약점 진단 항목별 통계 (이행)'!$A:$A,$A7&"*",'취약점 진단 항목별 통계 (이행)'!$R:$R) -> 36 | S7: =IFERROR($J7/($H7-(M7-I7)),"N/A") -> 1 | T7: =IF($I7=$E7, "N/A", (Q7/O7)) -> 0.42857143 | U7: =IF(OR($I7=$E7,$E7=$M7),"N/A", ($R7/$P7)) -> 0.85714286
A8: =ChkList!A14 -> 패치 관리 | E8: =SUMIF('취약점 진단 항목별 통계 (이행)'!$A:$A,$A8&"*",'취약점 진단 항목별 통계 (이행)'!$F:$F) -> 6 | F8: =E8-I8 -> 6 | G8: =SUMIF('취약점 진단 항목별 통계'!$A:$A,$A8&"*",'취약점 진단 항목별 통계'!$G:$G)+SUMIF('취약점 진단 항목별 통계'!$A:$A,$A8&"*",'취약점 진단 항목별 통계'!$H:$H) -> 0 | H8: =SUMIF('취약점 진단 항목별 통계'!$A:$A,$A8&"*",'취약점 진단 항목별 통계'!$I:$I) -> 0 | I8: =SUMIF('취약점 진단 항목별 통계'!$A:$A,$A8&"*",'취약점 진단 항목별 통계'!$J:$J) -> 0 | J8: =SUMIF('취약점 진단 항목별 통계 (이행)'!$A:$A,$A8&"*",'취약점 진단 항목별 통계 (이행)'!$K:$K) -> 0 | K8: =SUMIF('취약점 진단 항목별 통계 (이행)'!$A:$A,$A8&"*",'취약점 진단 항목별 통계 (이행)'!$L:$L) -> 6 | L8: =SUMIF('취약점 진단 항목별 통계 (이행)'!$A:$A,$A8&"*",'취약점 진단 항목별 통계 (이행)'!$M:$M) -> 0 | M8: =SUMIF('취약점 진단 항목별 통계 (이행)'!$A:$A,$A8&"*",'취약점 진단 항목별 통계 (이행)'!$N:$N) -> 0 | N8: =K8+L8 -> 6 | O8: =SUMIF('취약점 진단 항목별 통계 (이행)'!$A:$A,$A8&"*",'취약점 진단 항목별 통계 (이행)'!$O:$O) -> 18 | P8: =SUMIF('취약점 진단 항목별 통계 (이행)'!$A:$A,$A8&"*",'취약점 진단 항목별 통계 (이행)'!$P:$P) -> 18 | Q8: =SUMIF('취약점 진단 항목별 통계 (이행)'!$A:$A,$A8&"*",'취약점 진단 항목별 통계 (이행)'!$Q:$Q) -> 0 | R8: =SUMIF('취약점 진단 항목별 통계 (이행)'!$A:$A,$A8&"*",'취약점 진단 항목별 통계 (이행)'!$R:$R) -> 0 | S8: =IFERROR($J8/($H8-(M8-I8)),"N/A") -> N/A | T8: =IF($I8=$E8, "N/A", (Q8/O8)) -> 0 | U8: =IF(OR($I8=$E8,$E8=$M8),"N/A", ($R8/$P8)) -> 0
A9: =ChkList!A17 -> 보안 관리 | E9: =SUMIF('취약점 진단 항목별 통계 (이행)'!$A:$A,$A9&"*",'취약점 진단 항목별 통계 (이행)'!$F:$F) -> 21 | F9: =E9-I9 -> 18 | G9: =SUMIF('취약점 진단 항목별 통계'!$A:$A,$A9&"*",'취약점 진단 항목별 통계'!$G:$G)+SUMIF('취약점 진단 항목별 통계'!$A:$A,$A9&"*",'취약점 진단 항목별 통계'!$H:$H) -> 9 | H9: =SUMIF('취약점 진단 항목별 통계'!$A:$A,$A9&"*",'취약점 진단 항목별 통계'!$I:$I) -> 9 | I9: =SUMIF('취약점 진단 항목별 통계'!$A:$A,$A9&"*",'취약점 진단 항목별 통계'!$J:$J) -> 3 | J9: =SUMIF('취약점 진단 항목별 통계 (이행)'!$A:$A,$A9&"*",'취약점 진단 항목별 통계 (이행)'!$K:$K) -> 9 | K9: =SUMIF('취약점 진단 항목별 통계 (이행)'!$A:$A,$A9&"*",'취약점 진단 항목별 통계 (이행)'!$L:$L) -> 0 | L9: =SUMIF('취약점 진단 항목별 통계 (이행)'!$A:$A,$A9&"*",'취약점 진단 항목별 통계 (이행)'!$M:$M) -> 0 | M9: =SUMIF('취약점 진단 항목별 통계 (이행)'!$A:$A,$A9&"*",'취약점 진단 항목별 통계 (이행)'!$N:$N) -> 1 | N9: =K9+L9 -> 0 | O9: =SUMIF('취약점 진단 항목별 통계 (이행)'!$A:$A,$A9&"*",'취약점 진단 항목별 통계 (이행)'!$O:$O) -> 51 | P9: =SUMIF('취약점 진단 항목별 통계 (이행)'!$A:$A,$A9&"*",'취약점 진단 항목별 통계 (이행)'!$P:$P) -> 55 | Q9: =SUMIF('취약점 진단 항목별 통계 (이행)'!$A:$A,$A9&"*",'취약점 진단 항목별 통계 (이행)'!$Q:$Q) -> 24 | R9: =SUMIF('취약점 진단 항목별 통계 (이행)'!$A:$A,$A9&"*",'취약점 진단 항목별 통계 (이행)'!$R:$R) -> 51 | S9: =IFERROR($J9/($H9-(M9-I9)),"N/A") -> 0.81818182 | T9: =IF($I9=$E9, "N/A", (Q9/O9)) -> 0.47058824 | U9: =IF(OR($I9=$E9,$E9=$M9),"N/A", ($R9/$P9)) -> 0.92727273
A10: 계 | E10: =SUM(E6:E9) -> 51 | F10: =SUM(F6:F9) -> 48 | G10: =SUM(G6:G9) -> 21 | H10: =SUM(H6:H9) -> 15 | I10: =SUM(I6:I9) -> 3 | J10: =SUM(J6:J9) -> 15 | K10: =SUM(K6:K9) -> 12 | L10: =SUM(L6:L9) -> 0 | ... R10: =SUM(R6:R9) -> 96 | S10: =IFERROR($J10/($H10-(M10-I10)),"N/A") -> 0.88235294 | T10: =IF($I10=$E10, "N/A", (Q10/O10)) -> 0.39534884 | U10: =IF(OR($I10=$E10,$E10=$M10),"N/A", ($R10/$P10)) -> 0.72180451
A38: 2) 장비별 보안수준
A39: 장비 구분 | E39: 진단 결과 | J39: 이행 결과 | O39: 중요도점수
E40: 전체항목 | F40: 진단항목 | G40: 양호 | H40: 취약 | I40: 해당없음 | J40: 조치 | K40: 미조치 | L40: 위험수용 | M40: 해당없음 | N40: 잔여취약점 (미조치+위험수용) | O40: 전체점수 (이행전) | P40: 전체점수 (이행후) | Q40: 평가점수 (이행전) | R40: 평가점수 (이행후) | S40: 이행율 | T40: 보안수준 (이행 전) | U40: 보안수준 (이행 후)
A41: =자산목록!B5 -> P-01 | C41: =IFERROR(VLOOKUP($A41,자산목록!$B$1:$M$834,6,FALSE),"-") -> Windows 10 | E41: =IFERROR(INDIRECT(ADDRESS(16, 4, 1,TRUE,$A41)),0) -> 17 | F41: =E41-I41 -> 16 | G41: =IFERROR(INDIRECT(ADDRESS(16,5, 1,TRUE,$A41)),0) -> 7 | H41: =IFERROR(INDIRECT(ADDRESS(16,6, 1,TRUE,$A41)),0) -> 5 | I41: =IFERROR(INDIRECT(ADDRESS(16,7, 1,TRUE,$A41)),0) -> 1 | J41: =IFERROR(INDIRECT(ADDRESS(17,10, 1,TRUE,$A41)),0) -> 0 | K41: =IFERROR(INDIRECT(ADDRESS(17,11, 1,TRUE,$A41)),0) -> 0 | L41: =IFERROR(INDIRECT(ADDRESS(17,12, 1,TRUE,$A41)),0) -> 0 | M41: =IFERROR(INDIRECT(ADDRESS(17,13, 1,TRUE,$A41)),0) -> 0 | N41: =K41+L41 -> 0 | O41: =IFERROR(INDIRECT(ADDRESS(16,18, 1,TRUE,$A41)),0) -> 0 | P41: =IFERROR(INDIRECT(ADDRESS(17,21, 1,TRUE,$A41)),0) -> 0 | Q41: =IFERROR(INDIRECT(ADDRESS(16,19, 1,TRUE,$A41)),0) -> 14 | R41: =IFERROR(INDIRECT(ADDRESS(17,20, 1,TRUE,$A41)),0) -> 0 | S41: =IFERROR(INDIRECT(ADDRESS(17,14, 1,TRUE,$A41)),0) -> 0 | T41: =IFERROR(INDIRECT(ADDRESS(16,8, 1,TRUE,$A41)),0) -> 0 | U41: =IFERROR(INDIRECT(ADDRESS(17,15, 1,TRUE,$A41)),0) -> 0
A42: =자산목록!B6 -> P-02 | C42: =IFERROR(VLOOKUP($A42,자산목록!$B$1:$M$834,6,FALSE),"-") -> Windows 10 | E42: =IFERROR(INDIRECT(ADDRESS(16, 4, 1,TRUE,$A42)),0) -> 17 | F42: =E42-I42 -> 16 | G42: =IFERROR(INDIRECT(ADDRESS(16,5, 1,TRUE,$A42)),0) -> 7 | H42: =IFERROR(INDIRECT(ADDRESS(16,6, 1,TRUE,$A42)),0) -> 5 | I42: =IFERROR(INDIRECT(ADDRESS(16,7, 1,TRUE,$A42)),0) -> 1 | J42: =IFERROR(INDIRECT(ADDRESS(17,10, 1,TRUE,$A42)),0) -> 0 | K42: =IFERROR(INDIRECT(ADDRESS(17,11, 1,TRUE,$A42)),0) -> 0 | L42: =IFERROR(INDIRECT(ADDRESS(17,12, 1,TRUE,$A42)),0) -> 0 | M42: =IFERROR(INDIRECT(ADDRESS(17,13, 1,TRUE,$A42)),0) -> 0 | N42: =K42+L42 -> 0 | O42: =IFERROR(INDIRECT(ADDRESS(16,18, 1,TRUE,$A42)),0) -> 43 | P42: =IFERROR(INDIRECT(ADDRESS(17,21, 1,TRUE,$A42)),0) -> 0 | Q42: =IFERROR(INDIRECT(ADDRESS(16,19, 1,TRUE,$A42)),0) -> 17 | R42: =IFERROR(INDIRECT(ADDRESS(17,20, 1,TRUE,$A42)),0) -> 0 | S42: =IFERROR(INDIRECT(ADDRESS(17,14, 1,TRUE,$A42)),0) -> 0 | T42: =IFERROR(INDIRECT(ADDRESS(16,8, 1,TRUE,$A42)),0) -> 0.39534884 | U42: =IFERROR(INDIRECT(ADDRESS(17,15, 1,TRUE,$A42)),0) -> 0
A43: =자산목록!B7 -> P-03 | C43: =IFERROR(VLOOKUP($A43,자산목록!$B$1:$M$834,6,FALSE),"-") -> Windows 10 | E43: =IFERROR(INDIRECT(ADDRESS(16, 4, 1,TRUE,$A43)),0) -> 19 | F43: =E43-I43 -> 18 | G43: =IFERROR(INDIRECT(ADDRESS(16,5, 1,TRUE,$A43)),0) -> 9 | H43: =IFERROR(INDIRECT(ADDRESS(16,6, 1,TRUE,$A43)),0) -> 5 | I43: =IFERROR(INDIRECT(ADDRESS(16,7, 1,TRUE,$A43)),0) -> 1 | J43: =IFERROR(INDIRECT(ADDRESS(17,10, 1,TRUE,$A43)),0) -> 0 | K43: =IFERROR(INDIRECT(ADDRESS(17,11, 1,TRUE,$A43)),0) -> 0 | L43: =IFERROR(INDIRECT(ADDRESS(17,12, 1,TRUE,$A43)),0) -> 0 | M43: =IFERROR(INDIRECT(ADDRESS(17,13, 1,TRUE,$A43)),0) -> 0 | N43: =K43+L43 -> 0 | O43: =IFERROR(INDIRECT(ADDRESS(16,18, 1,TRUE,$A43)),0) -> 0 | P43: =IFERROR(INDIRECT(ADDRESS(17,21, 1,TRUE,$A43)),0) -> 0 | Q43: =IFERROR(INDIRECT(ADDRESS(16,19, 1,TRUE,$A43)),0) -> 19 | R43: =IFERROR(INDIRECT(ADDRESS(17,20, 1,TRUE,$A43)),0) -> 0 | S43: =IFERROR(INDIRECT(ADDRESS(17,14, 1,TRUE,$A43)),0) -> 0 | T43: =IFERROR(INDIRECT(ADDRESS(16,8, 1,TRUE,$A43)),0) -> 0 | U43: =IFERROR(INDIRECT(ADDRESS(17,15, 1,TRUE,$A43)),0) -> 0
A44: =자산목록!B8 -> P-04 | C44: =IFERROR(VLOOKUP($A44,자산목록!$B$1:$M$834,6,FALSE),"-") -> Windows 10 | E44: =IFERROR(INDIRECT(ADDRESS(16, 4, 1,TRUE,$A44)),0) -> 19 | F44: =E44-I44 -> 18 | G44: =IFERROR(INDIRECT(ADDRESS(16,5, 1,TRUE,$A44)),0) -> 9 | H44: =IFERROR(INDIRECT(ADDRESS(16,6, 1,TRUE,$A44)),0) -> 5 | I44: =IFERROR(INDIRECT(ADDRESS(16,7, 1,TRUE,$A44)),0) -> 1 | J44: =IFERROR(INDIRECT(ADDRESS(17,10, 1,TRUE,$A44)),0) -> 0 | K44: =IFERROR(INDIRECT(ADDRESS(17,11, 1,TRUE,$A44)),0) -> 0 | L44: =IFERROR(INDIRECT(ADDRESS(17,12, 1,TRUE,$A44)),0) -> 0 | M44: =IFERROR(INDIRECT(ADDRESS(17,13, 1,TRUE,$A44)),0) -> 0 | N44: =K44+L44 -> 0 | O44: =IFERROR(INDIRECT(ADDRESS(16,18, 1,TRUE,$A44)),0) -> 0 | P44: =IFERROR(INDIRECT(ADDRESS(17,21, 1,TRUE,$A44)),0) -> 0 | Q44: =IFERROR(INDIRECT(ADDRESS(16,19, 1,TRUE,$A44)),0) -> 19 | R44: =IFERROR(INDIRECT(ADDRESS(17,20, 1,TRUE,$A44)),0) -> 0 | S44: =IFERROR(INDIRECT(ADDRESS(17,14, 1,TRUE,$A44)),0) -> 0 | T44: =IFERROR(INDIRECT(ADDRESS(16,8, 1,TRUE,$A44)),0) -> 0 | U44: =IFERROR(INDIRECT(ADDRESS(17,15, 1,TRUE,$A44)),0) -> 0
A45: =자산목록!B9 -> P-05 | C45: =IFERROR(VLOOKUP($A45,자산목록!$B$1:$M$834,6,FALSE),"-") -> Windows 10 | E45: =IFERROR(INDIRECT(ADDRESS(16, 4, 1,TRUE,$A45)),0) -> 19 | F45: =E45-I45 -> 18 | G45: =IFERROR(INDIRECT(ADDRESS(16,5, 1,TRUE,$A45)),0) -> 9 | H45: =IFERROR(INDIRECT(ADDRESS(16,6, 1,TRUE,$A45)),0) -> 5 | I45: =IFERROR(INDIRECT(ADDRESS(16,7, 1,TRUE,$A45)),0) -> 1 | J45: =IFERROR(INDIRECT(ADDRESS(17,10, 1,TRUE,$A45)),0) -> 0 | K45: =IFERROR(INDIRECT(ADDRESS(17,11, 1,TRUE,$A45)),0) -> 0 | L45: =IFERROR(INDIRECT(ADDRESS(17,12, 1,TRUE,$A45)),0) -> 0 | M45: =IFERROR(INDIRECT(ADDRESS(17,13, 1,TRUE,$A45)),0) -> 0 | N45: =K45+L45 -> 0 | O45: =IFERROR(INDIRECT(ADDRESS(16,18, 1,TRUE,$A45)),0) -> 0 | P45: =IFERROR(INDIRECT(ADDRESS(17,21, 1,TRUE,$A45)),0) -> 0 | Q45: =IFERROR(INDIRECT(ADDRESS(16,19, 1,TRUE,$A45)),0) -> 19 | R45: =IFERROR(INDIRECT(ADDRESS(17,20, 1,TRUE,$A45)),0) -> 0 | S45: =IFERROR(INDIRECT(ADDRESS(17,14, 1,TRUE,$A45)),0) -> 0 | T45: =IFERROR(INDIRECT(ADDRESS(16,8, 1,TRUE,$A45)),0) -> 0 | U45: =IFERROR(INDIRECT(ADDRESS(17,15, 1,TRUE,$A45)),0) -> 0
A46: =자산목록!B10 -> P-06 | C46: =IFERROR(VLOOKUP($A46,자산목록!$B$1:$M$834,6,FALSE),"-") -> Windows 10 | E46: =IFERROR(INDIRECT(ADDRESS(16, 4, 1,TRUE,$A46)),0) -> 19 | F46: =E46-I46 -> 18 | G46: =IFERROR(INDIRECT(ADDRESS(16,5, 1,TRUE,$A46)),0) -> 9 | H46: =IFERROR(INDIRECT(ADDRESS(16,6, 1,TRUE,$A46)),0) -> 5 | I46: =IFERROR(INDIRECT(ADDRESS(16,7, 1,TRUE,$A46)),0) -> 1 | J46: =IFERROR(INDIRECT(ADDRESS(17,10, 1,TRUE,$A46)),0) -> 0 | K46: =IFERROR(INDIRECT(ADDRESS(17,11, 1,TRUE,$A46)),0) -> 0 | L46: =IFERROR(INDIRECT(ADDRESS(17,12, 1,TRUE,$A46)),0) -> 0 | M46: =IFERROR(INDIRECT(ADDRESS(17,13, 1,TRUE,$A46)),0) -> 0 | N46: =K46+L46 -> 0 | O46: =IFERROR(INDIRECT(ADDRESS(16,18, 1,TRUE,$A46)),0) -> 0 | P46: =IFERROR(INDIRECT(ADDRESS(17,21, 1,TRUE,$A46)),0) -> 0 | Q46: =IFERROR(INDIRECT(ADDRESS(16,19, 1,TRUE,$A46)),0) -> 19 | R46: =IFERROR(INDIRECT(ADDRESS(17,20, 1,TRUE,$A46)),0) -> 0 | S46: =IFERROR(INDIRECT(ADDRESS(17,14, 1,TRUE,$A46)),0) -> 0 | T46: =IFERROR(INDIRECT(ADDRESS(16,8, 1,TRUE,$A46)),0) -> 0 | U46: =IFERROR(INDIRECT(ADDRESS(17,15, 1,TRUE,$A46)),0) -> 0
A47: =자산목록!B11 -> P-07 | C47: =IFERROR(VLOOKUP($A47,자산목록!$B$1:$M$834,6,FALSE),"-") -> Windows 10 | E47: =IFERROR(INDIRECT(ADDRESS(16, 4, 1,TRUE,$A47)),0) -> 19 | F47: =E47-I47 -> 18 | G47: =IFERROR(INDIRECT(ADDRESS(16,5, 1,TRUE,$A47)),0) -> 9 | H47: =IFERROR(INDIRECT(ADDRESS(16,6, 1,TRUE,$A47)),0) -> 5 | I47: =IFERROR(INDIRECT(ADDRESS(16,7, 1,TRUE,$A47)),0) -> 1 | J47: =IFERROR(INDIRECT(ADDRESS(17,10, 1,TRUE,$A47)),0) -> 0 | K47: =IFERROR(INDIRECT(ADDRESS(17,11, 1,TRUE,$A47)),0) -> 0 | L47: =IFERROR(INDIRECT(ADDRESS(17,12, 1,TRUE,$A47)),0) -> 0 | M47: =IFERROR(INDIRECT(ADDRESS(17,13, 1,TRUE,$A47)),0) -> 0 | N47: =K47+L47 -> 0 | O47: =IFERROR(INDIRECT(ADDRESS(16,18, 1,TRUE,$A47)),0) -> 0 | P47: =IFERROR(INDIRECT(ADDRESS(17,21, 1,TRUE,$A47)),0) -> 0 | Q47: =IFERROR(INDIRECT(ADDRESS(16,19, 1,TRUE,$A47)),0) -> 19 | R47: =IFERROR(INDIRECT(ADDRESS(17,20, 1,TRUE,$A47)),0) -> 0 | S47: =IFERROR(INDIRECT(ADDRESS(17,14, 1,TRUE,$A47)),0) -> 0 | T47: =IFERROR(INDIRECT(ADDRESS(16,8, 1,TRUE,$A47)),0) -> 0 | U47: =IFERROR(INDIRECT(ADDRESS(17,15, 1,TRUE,$A47)),0) -> 0
A48: =자산목록!B12 -> P-08 | C48: =IFERROR(VLOOKUP($A48,자산목록!$B$1:$M$834,6,FALSE),"-") -> Windows 10 | E48: =IFERROR(INDIRECT(ADDRESS(16, 4, 1,TRUE,$A48)),0) -> 19 | F48: =E48-I48 -> 18 | G48: =IFERROR(INDIRECT(ADDRESS(16,5, 1,TRUE,$A48)),0) -> 9 | H48: =IFERROR(INDIRECT(ADDRESS(16,6, 1,TRUE,$A48)),0) -> 5 | I48: =IFERROR(INDIRECT(ADDRESS(16,7, 1,TRUE,$A48)),0) -> 1 | J48: =IFERROR(INDIRECT(ADDRESS(17,10, 1,TRUE,$A48)),0) -> 0 | K48: =IFERROR(INDIRECT(ADDRESS(17,11, 1,TRUE,$A48)),0) -> 0 | L48: =IFERROR(INDIRECT(ADDRESS(17,12, 1,TRUE,$A48)),0) -> 0 | M48: =IFERROR(INDIRECT(ADDRESS(17,13, 1,TRUE,$A48)),0) -> 0 | N48: =K48+L48 -> 0 | O48: =IFERROR(INDIRECT(ADDRESS(16,18, 1,TRUE,$A48)),0) -> 0 | P48: =IFERROR(INDIRECT(ADDRESS(17,21, 1,TRUE,$A48)),0) -> 0 | Q48: =IFERROR(INDIRECT(ADDRESS(16,19, 1,TRUE,$A48)),0) -> 19 | R48: =IFERROR(INDIRECT(ADDRESS(17,20, 1,TRUE,$A48)),0) -> 0 | S48: =IFERROR(INDIRECT(ADDRESS(17,14, 1,TRUE,$A48)),0) -> 0 | T48: =IFERROR(INDIRECT(ADDRESS(16,8, 1,TRUE,$A48)),0) -> 0 | U48: =IFERROR(INDIRECT(ADDRESS(17,15, 1,TRUE,$A48)),0) -> 0
A49: =자산목록!B13 -> P-09 | C49: =IFERROR(VLOOKUP($A49,자산목록!$B$1:$M$834,6,FALSE),"-") -> Windows 10 | E49: =IFERROR(INDIRECT(ADDRESS(16, 4, 1,TRUE,$A49)),0) -> 19 | F49: =E49-I49 -> 18 | G49: =IFERROR(INDIRECT(ADDRESS(16,5, 1,TRUE,$A49)),0) -> 9 | H49: =IFERROR(INDIRECT(ADDRESS(16,6, 1,TRUE,$A49)),0) -> 5 | I49: =IFERROR(INDIRECT(ADDRESS(16,7, 1,TRUE,$A49)),0) -> 1 | J49: =IFERROR(INDIRECT(ADDRESS(17,10, 1,TRUE,$A49)),0) -> 0 | K49: =IFERROR(INDIRECT(ADDRESS(17,11, 1,TRUE,$A49)),0) -> 0 | L49: =IFERROR(INDIRECT(ADDRESS(17,12, 1,TRUE,$A49)),0) -> 0 | M49: =IFERROR(INDIRECT(ADDRESS(17,13, 1,TRUE,$A49)),0) -> 0 | N49: =K49+L49 -> 0 | O49: =IFERROR(INDIRECT(ADDRESS(16,18, 1,TRUE,$A49)),0) -> 0 | P49: =IFERROR(INDIRECT(ADDRESS(17,21, 1,TRUE,$A49)),0) -> 0 | Q49: =IFERROR(INDIRECT(ADDRESS(16,19, 1,TRUE,$A49)),0) -> 19 | R49: =IFERROR(INDIRECT(ADDRESS(17,20, 1,TRUE,$A49)),0) -> 0 | S49: =IFERROR(INDIRECT(ADDRESS(17,14, 1,TRUE,$A49)),0) -> 0 | T49: =IFERROR(INDIRECT(ADDRESS(16,8, 1,TRUE,$A49)),0) -> 0 | U49: =IFERROR(INDIRECT(ADDRESS(17,15, 1,TRUE,$A49)),0) -> 0
A50: =자산목록!B14 -> P-10 | C50: =IFERROR(VLOOKUP($A50,자산목록!$B$1:$M$834,6,FALSE),"-") -> Windows 10 | E50: =IFERROR(INDIRECT(ADDRESS(16, 4, 1,TRUE,$A50)),0) -> 19 | F50: =E50-I50 -> 18 | G50: =IFERROR(INDIRECT(ADDRESS(16,5, 1,TRUE,$A50)),0) -> 9 | H50: =IFERROR(INDIRECT(ADDRESS(16,6, 1,TRUE,$A50)),0) -> 5 | I50: =IFERROR(INDIRECT(ADDRESS(16,7, 1,TRUE,$A50)),0) -> 1 | J50: =IFERROR(INDIRECT(ADDRESS(17,10, 1,TRUE,$A50)),0) -> 0 | K50: =IFERROR(INDIRECT(ADDRESS(17,11, 1,TRUE,$A50)),0) -> 0 | L50: =IFERROR(INDIRECT(ADDRESS(17,12, 1,TRUE,$A50)),0) -> 0 | M50: =IFERROR(INDIRECT(ADDRESS(17,13, 1,TRUE,$A50)),0) -> 0 | N50: =K50+L50 -> 0 | O50: =IFERROR(INDIRECT(ADDRESS(16,18, 1,TRUE,$A50)),0) -> 0 | P50: =IFERROR(INDIRECT(ADDRESS(17,21, 1,TRUE,$A50)),0) -> 0 | Q50: =IFERROR(INDIRECT(ADDRESS(16,19, 1,TRUE,$A50)),0) -> 19 | R50: =IFERROR(INDIRECT(ADDRESS(17,20, 1,TRUE,$A50)),0) -> 0 | S50: =IFERROR(INDIRECT(ADDRESS(17,14, 1,TRUE,$A50)),0) -> 0 | T50: =IFERROR(INDIRECT(ADDRESS(16,8, 1,TRUE,$A50)),0) -> 0 | U50: =IFERROR(INDIRECT(ADDRESS(17,15, 1,TRUE,$A50)),0) -> 0
A51: =자산목록!B15 -> P-11 | C51: =IFERROR(VLOOKUP($A51,자산목록!$B$1:$M$834,6,FALSE),"-") -> Windows 10 | E51: =IFERROR(INDIRECT(ADDRESS(16, 4, 1,TRUE,$A51)),0) -> 19 | F51: =E51-I51 -> 18 | G51: =IFERROR(INDIRECT(ADDRESS(16,5, 1,TRUE,$A51)),0) -> 9 | H51: =IFERROR(INDIRECT(ADDRESS(16,6, 1,TRUE,$A51)),0) -> 5 | I51: =IFERROR(INDIRECT(ADDRESS(16,7, 1,TRUE,$A51)),0) -> 1 | J51: =IFERROR(INDIRECT(ADDRESS(17,10, 1,TRUE,$A51)),0) -> 0 | K51: =IFERROR(INDIRECT(ADDRESS(17,11, 1,TRUE,$A51)),0) -> 0 | L51: =IFERROR(INDIRECT(ADDRESS(17,12, 1,TRUE,$A51)),0) -> 0 | M51: =IFERROR(INDIRECT(ADDRESS(17,13, 1,TRUE,$A51)),0) -> 0 | N51: =K51+L51 -> 0 | O51: =IFERROR(INDIRECT(ADDRESS(16,18, 1,TRUE,$A51)),0) -> 0 | P51: =IFERROR(INDIRECT(ADDRESS(17,21, 1,TRUE,$A51)),0) -> 0 | Q51: =IFERROR(INDIRECT(ADDRESS(16,19, 1,TRUE,$A51)),0) -> 19 | R51: =IFERROR(INDIRECT(ADDRESS(17,20, 1,TRUE,$A51)),0) -> 0 | S51: =IFERROR(INDIRECT(ADDRESS(17,14, 1,TRUE,$A51)),0) -> 0 | T51: =IFERROR(INDIRECT(ADDRESS(16,8, 1,TRUE,$A51)),0) -> 0 | U51: =IFERROR(INDIRECT(ADDRESS(17,15, 1,TRUE,$A51)),0) -> 0
A52: =자산목록!B16 -> P-12 | C52: =IFERROR(VLOOKUP($A52,자산목록!$B$1:$M$834,6,FALSE),"-") -> Windows 10 | E52: =IFERROR(INDIRECT(ADDRESS(16, 4, 1,TRUE,$A52)),0) -> 19 | F52: =E52-I52 -> 18 | G52: =IFERROR(INDIRECT(ADDRESS(16,5, 1,TRUE,$A52)),0) -> 9 | H52: =IFERROR(INDIRECT(ADDRESS(16,6, 1,TRUE,$A52)),0) -> 5 | I52: =IFERROR(INDIRECT(ADDRESS(16,7, 1,TRUE,$A52)),0) -> 1 | J52: =IFERROR(INDIRECT(ADDRESS(17,10, 1,TRUE,$A52)),0) -> 0 | K52: =IFERROR(INDIRECT(ADDRESS(17,11, 1,TRUE,$A52)),0) -> 0 | L52: =IFERROR(INDIRECT(ADDRESS(17,12, 1,TRUE,$A52)),0) -> 0 | M52: =IFERROR(INDIRECT(ADDRESS(17,13, 1,TRUE,$A52)),0) -> 0 | N52: =K52+L52 -> 0 | O52: =IFERROR(INDIRECT(ADDRESS(16,18, 1,TRUE,$A52)),0) -> 0 | P52: =IFERROR(INDIRECT(ADDRESS(17,21, 1,TRUE,$A52)),0) -> 0 | Q52: =IFERROR(INDIRECT(ADDRESS(16,19, 1,TRUE,$A52)),0) -> 19 | R52: =IFERROR(INDIRECT(ADDRESS(17,20, 1,TRUE,$A52)),0) -> 0 | S52: =IFERROR(INDIRECT(ADDRESS(17,14, 1,TRUE,$A52)),0) -> 0 | T52: =IFERROR(INDIRECT(ADDRESS(16,8, 1,TRUE,$A52)),0) -> 0 | U52: =IFERROR(INDIRECT(ADDRESS(17,15, 1,TRUE,$A52)),0) -> 0
... A66: =자산목록!B30 -> P-26 | C66: =IFERROR(VLOOKUP($A66,자산목록!$B$1:$M$834,6,FALSE),"-") -> Windows 10 | E66: =IFERROR(INDIRECT(ADDRESS(16, 4, 1,TRUE,$A66)),0) -> 19 | F66: =E66-I66 -> 18 | G66: =IFERROR(INDIRECT(ADDRESS(16,5, 1,TRUE,$A66)),0) -> 9 | H66: =IFERROR(INDIRECT(ADDRESS(16,6, 1,TRUE,$A66)),0) -> 5 | I66: =IFERROR(INDIRECT(ADDRESS(16,7, 1,TRUE,$A66)),0) -> 1 | J66: =IFERROR(INDIRECT(ADDRESS(17,10, 1,TRUE,$A66)),0) -> 0 | K66: =IFERROR(INDIRECT(ADDRESS(17,11, 1,TRUE,$A66)),0) -> 0 | L66: =IFERROR(INDIRECT(ADDRESS(17,12, 1,TRUE,$A66)),0) -> 0 | M66: =IFERROR(INDIRECT(ADDRESS(17,13, 1,TRUE,$A66)),0) -> 0 | N66: =K66+L66 -> 0 | O66: =IFERROR(INDIRECT(ADDRESS(16,18, 1,TRUE,$A66)),0) -> 0 | P66: =IFERROR(INDIRECT(ADDRESS(17,21, 1,TRUE,$A66)),0) -> 0 | Q66: =IFERROR(INDIRECT(ADDRESS(16,19, 1,TRUE,$A66)),0) -> 19 | R66: =IFERROR(INDIRECT(ADDRESS(17,20, 1,TRUE,$A66)),0) -> 0 | S66: =IFERROR(INDIRECT(ADDRESS(17,14, 1,TRUE,$A66)),0) -> 0 | T66: =IFERROR(INDIRECT(ADDRESS(16,8, 1,TRUE,$A66)),0) -> 0 | U66: =IFERROR(INDIRECT(ADDRESS(17,15, 1,TRUE,$A66)),0) -> 0
A67: 계 | E67: =SUM(E41:E66) -> 490 | F67: =SUM(F41:F66) -> 464 | G67: =SUM(G41:G66) -> 230 | H67: =SUM(H41:H66) -> 130 | I67: =SUM(I41:I66) -> 26 | J67: =SUM(J41:J66) -> 0 | K67: =SUM(K41:K66) -> 0 | L67: =SUM(L41:L66) -> 0 | ... R67: =SUM(R41:R66) -> 0 | S67: =IFERROR($J67/($H67-(M67-I67)),"N/A") -> 0 | T67: =IF($I67=$E67, "N/A", (Q67/O67)) -> 11.325581 | U67: =IF(OR($I67=$E67,$E67=$M67),"N/A", ($R67/$P67)) -> #DIV/0!

Sheet 취약점 진단 항목별 통계
A1: ■ 취약점 진단 항목별 통계
A3: =ChkList!A4 -> 분류 | C3: =ChkList!C4 -> 진단항목 | D3: =ChkList!D4 -> 중요도 | F3: 진단 통계 | K3: 중요도 점수 | M3: 진단결과 | N3: 진단결과 | O3: 진단결과
F4: 전체 | G4: 양호 | H4: 즉시조치 | I4: 취약 | J4: N/A | K4: 전체 | L4: 평가 | M4: =HYPERLINK("[" & MID(CELL("filename"),SEARCH("[",CELL("filename"))+1, SEARCH("]",CELL("filename"))-SEARCH("[",CELL("filename"))-1) & "]" & INDIRECT(ADDRESS(COLUMN()-8,2,1,TRUE,"자산목록")) & "!A1",INDIRECT(ADDRESS(COLUMN()-8,2,1,TRUE,"자산목록"))) -> P-01 | N4: =HYPERLINK("[" & MID(CELL("filename"),SEARCH("[",CELL("filename"))+1, SEARCH("]",CELL("filename"))-SEARCH("[",CELL("filename"))-1) & "]" & INDIRECT(ADDRESS(COLUMN()-8,2,1,TRUE,"자산목록")) & "!A1",INDIRECT(ADDRESS(COLUMN()-8,2,1,TRUE,"자산목록"))) -> P-02 | O4: =HYPERLINK("[" & MID(CELL("filename"),SEARCH("[",CELL("filename"))+1, SEARCH("]",CELL("filename"))-SEARCH("[",CELL("filename"))-1) & "]" & INDIRECT(ADDRESS(COLUMN()-8,2,1,TRUE,"자산목록")) & "!A1",INDIRECT(ADDRESS(COLUMN()-8,2,1,TRUE,"자산목록"))) -> P-03
A5: =ChkList!A5 -> 계정 관리 | B5: =ChkList!B5 -> PC-01 | C5: =ChkList!C5 -> 비밀번호의 주기적 변경 | D5: =ChkList!D5 -> H | E5: =ChkList!E5 -> 3 | F5: =COUNTA($M5:INDIRECT(ADDRESS(ROW(),MATCH("",$4:$4,-1),1,1))) -> 3 | G5: =COUNTIF($M5:INDIRECT(ADDRESS(ROW(),MATCH("",$4:$4,-1),1,1)),"조치완료(Y)")+COUNTIF($M5:INDIRECT(ADDRESS(ROW(),MATCH("",$4:$4,-1),1,1)),"Y") -> 3 | H5: =COUNTIF($M5:INDIRECT(ADDRESS(ROW(),MATCH("",$4:$4,-1),1,1)),"Y(즉시조치)")+COUNTIF($M5:INDIRECT(ADDRESS(ROW(),MATCH("",$4:$4,-1),1,1)),"조치완료(즉시조치)") -> 0 | I5: =COUNTIF($M5:INDIRECT(ADDRESS(ROW(),MATCH("",$4:$4,-1),1,1)),"N") -> 0 | J5: =COUNTIF($M5:INDIRECT(ADDRESS(ROW(),MATCH("",$4:$4,-1),1,1)),"N/A")+COUNTIF($M5:INDIRECT(ADDRESS(ROW(),MATCH("",$4:$4,-1),1,1)),"조치완료(N/A)") -> 0 | K5: =VLOOKUP($D5,'parm(hidden)'!$B$8:$C$10,2,FALSE)*($F5-$J5) -> 9 | L5: =VLOOKUP($D5,'parm(hidden)'!$B$8:$C$10,2,FALSE)*($G5+$H5) -> 9 | M5: =HYPERLINK("#'" & M$4 & "'!" & ADDRESS(ROW()+15, 8), INDIRECT("'" & M$4 & "'!" & ADDRESS(ROW()+15, 8))) -> Y | N5: =HYPERLINK("#'" & N$4 & "'!" & ADDRESS(ROW()+15, 8), INDIRECT("'" & N$4 & "'!" & ADDRESS(ROW()+15, 8))) -> Y | O5: =HYPERLINK("#'" & O$4 & "'!" & ADDRESS(ROW()+15, 8), INDIRECT("'" & O$4 & "'!" & ADDRESS(ROW()+15, 8))) -> Y
A6: =ChkList!A6 -> 계정 관리 | B6: =ChkList!B6 -> PC-02 | C6: =ChkList!C6 -> 비밀번호 관리정책 설정 | D6: =ChkList!D6 -> H | E6: =ChkList!E6 -> 3 | F6: =COUNTA($M6:INDIRECT(ADDRESS(ROW(),MATCH("",$4:$4,-1),1,1))) -> 3 | G6: =COUNTIF($M6:INDIRECT(ADDRESS(ROW(),MATCH("",$4:$4,-1),1,1)),"조치완료(Y)")+COUNTIF($M6:INDIRECT(ADDRESS(ROW(),MATCH("",$4:$4,-1),1,1)),"Y") -> 0 | H6: =COUNTIF($M6:INDIRECT(ADDRESS(ROW(),MATCH("",$4:$4,-1),1,1)),"Y(즉시조치)")+COUNTIF($M6:INDIRECT(ADDRESS(ROW(),MATCH("",$4:$4,-1),1,1)),"조치완료(즉시조치)") -> 0 | I6: =COUNTIF($M6:INDIRECT(ADDRESS(ROW(),MATCH("",$4:$4,-1),1,1)),"N") -> 0 | J6: =COUNTIF($M6:INDIRECT(ADDRESS(ROW(),MATCH("",$4:$4,-1),1,1)),"N/A")+COUNTIF($M6:INDIRECT(ADDRESS(ROW(),MATCH("",$4:$4,-1),1,1)),"조치완료(N/A)") -> 0 | K6: =VLOOKUP($D6,'parm(hidden)'!$B$8:$C$10,2,FALSE)*($F6-$J6) -> 9 | L6: =VLOOKUP($D6,'parm(hidden)'!$B$8:$C$10,2,FALSE)*($G6+$H6) -> 0 | M6: =HYPERLINK("#'" & M$4 & "'!" & ADDRESS(ROW()+15, 8), INDIRECT("'" & M$4 & "'!" & ADDRESS(ROW()+15, 8))) -> 인터뷰 | N6: =HYPERLINK("#'" & N$4 & "'!" & ADDRESS(ROW()+15, 8), INDIRECT("'" & N$4 & "'!" & ADDRESS(ROW()+15, 8))) -> 인터뷰 | O6: =HYPERLINK("#'" & O$4 & "'!" & ADDRESS(ROW()+15, 8), INDIRECT("'" & O$4 & "'!" & ADDRESS(ROW()+15, 8))) -> 인터뷰
A7: =ChkList!A7 -> 계정관리 | B7: =ChkList!B7 -> PC-03 | C7: =ChkList!C7 -> 복구 콘솔에서 자동 로그온을 금지하도록 설정 | D7: =ChkList!D7 -> M | E7: =ChkList!E7 -> 2 | F7: =COUNTA($M7:INDIRECT(ADDRESS(ROW(),MATCH("",$4:$4,-1),1,1))) -> 3 | G7: =COUNTIF($M7:INDIRECT(ADDRESS(ROW(),MATCH("",$4:$4,-1),1,1)),"조치완료(Y)")+COUNTIF($M7:INDIRECT(ADDRESS(ROW(),MATCH("",$4:$4,-1),1,1)),"Y") -> 3 | H7: =COUNTIF($M7:INDIRECT(ADDRESS(ROW(),MATCH("",$4:$4,-1),1,1)),"Y(즉시조치)")+COUNTIF($M7:INDIRECT(ADDRESS(ROW(),MATCH("",$4:$4,-1),1,1)),"조치완료(즉시조치)") -> 0 | I7: =COUNTIF($M7:INDIRECT(ADDRESS(ROW(),MATCH("",$4:$4,-1),1,1)),"N") -> 0 | J7: =COUNTIF($M7:INDIRECT(ADDRESS(ROW(),MATCH("",$4:$4,-1),1,1)),"N/A")+COUNTIF($M7:INDIRECT(ADDRESS(ROW(),MATCH("",$4:$4,-1),1,1)),"조치완료(N/A)") -> 0 | K7: =VLOOKUP($D7,'parm(hidden)'!$B$8:$C$10,2,FALSE)*($F7-$J7) -> 6 | L7: =VLOOKUP($D7,'parm(hidden)'!$B$8:$C$10,2,FALSE)*($G7+$H7) -> 6 | M7: =HYPERLINK("#'" & M$4 & "'!" & ADDRESS(ROW()+15, 8), INDIRECT("'" & M$4 & "'!" & ADDRESS(ROW()+15, 8))) -> Y | N7: =HYPERLINK("#'" & N$4 & "'!" & ADDRESS(ROW()+15, 8), INDIRECT("'" & N$4 & "'!" & ADDRESS(ROW()+15, 8))) -> Y | O7: =HYPERLINK("#'" & O$4 & "'!" & ADDRESS(ROW()+15, 8), INDIRECT("'" & O$4 & "'!" & ADDRESS(ROW()+15, 8))) -> Y
A8: =ChkList!A8 -> 서비스 관리 | B8: =ChkList!B8 -> PC-04 | C8: =ChkList!C8 -> 공유 폴더 제거 | D8: =ChkList!D8 -> H | E8: =ChkList!E8 -> 3 | F8: =COUNTA($M8:INDIRECT(ADDRESS(ROW(),MATCH("",$4:$4,-1),1,1))) -> 3 | G8: =COUNTIF($M8:INDIRECT(ADDRESS(ROW(),MATCH("",$4:$4,-1),1,1)),"조치완료(Y)")+COUNTIF($M8:INDIRECT(ADDRESS(ROW(),MATCH("",$4:$4,-1),1,1)),"Y") -> 0 | H8: =COUNTIF($M8:INDIRECT(ADDRESS(ROW(),MATCH("",$4:$4,-1),1,1)),"Y(즉시조치)")+COUNTIF($M8:INDIRECT(ADDRESS(ROW(),MATCH("",$4:$4,-1),1,1)),"조치완료(즉시조치)") -> 0 | I8: =COUNTIF($M8:INDIRECT(ADDRESS(ROW(),MATCH("",$4:$4,-1),1,1)),"N") -> 3 | J8: =COUNTIF($M8:INDIRECT(ADDRESS(ROW(),MATCH("",$4:$4,-1),1,1)),"N/A")+COUNTIF($M8:INDIRECT(ADDRESS(ROW(),MATCH("",$4:$4,-1),1,1)),"조치완료(N/A)") -> 0 | K8: =VLOOKUP($D8,'parm(hidden)'!$B$8:$C$10,2,FALSE)*($F8-$J8) -> 9 | L8: =VLOOKUP($D8,'parm(hidden)'!$B$8:$C$10,2,FALSE)*($G8+$H8) -> 0 | M8: =HYPERLINK("#'" & M$4 & "'!" & ADDRESS(ROW()+15, 8), INDIRECT("'" & M$4 & "'!" & ADDRESS(ROW()+15, 8))) -> N | N8: =HYPERLINK("#'" & N$4 & "'!" & ADDRESS(ROW()+15, 8), INDIRECT("'" & N$4 & "'!" & ADDRESS(ROW()+15, 8))) -> N | O8: =HYPERLINK("#'" & O$4 & "'!" & ADDRESS(ROW()+15, 8), INDIRECT("'" & O$4 & "'!" & ADDRESS(ROW()+15, 8))) -> N
A9: =ChkList!A9 -> 서비스 관리 | B9: =ChkList!B9 -> PC-05 | C9: =ChkList!C9 -> 항목의 불필요한 서비스 제거 | D9: =ChkList!D9 -> H | E9: =ChkList!E9 -> 3 | F9: =COUNTA($M9:INDIRECT(ADDRESS(ROW(),MATCH("",$4:$4,-1),1,1))) -> 3 | G9: =COUNTIF($M9:INDIRECT(ADDRESS(ROW(),MATCH("",$4:$4,-1),1,1)),"조치완료(Y)")+COUNTIF($M9:INDIRECT(ADDRESS(ROW(),MATCH("",$4:$4,-1),1,1)),"Y") -> 0 | H9: =COUNTIF($M9:INDIRECT(ADDRESS(ROW(),MATCH("",$4:$4,-1),1,1)),"Y(즉시조치)")+COUNTIF($M9:INDIRECT(ADDRESS(ROW(),MATCH("",$4:$4,-1),1,1)),"조치완료(즉시조치)") -> 0 | I9: =COUNTIF($M9:INDIRECT(ADDRESS(ROW(),MATCH("",$4:$4,-1),1,1)),"N") -> 3 | J9: =COUNTIF($M9:INDIRECT(ADDRESS(ROW(),MATCH("",$4:$4,-1),1,1)),"N/A")+COUNTIF($M9:INDIRECT(ADDRESS(ROW(),MATCH("",$4:$4,-1),1,1)),"조치완료(N/A)") -> 0 | K9: =VLOOKUP($D9,'parm(hidden)'!$B$8:$C$10,2,FALSE)*($F9-$J9) -> 9 | L9: =VLOOKUP($D9,'parm(hidden)'!$B$8:$C$10,2,FALSE)*($G9+$H9) -> 0 | M9: =HYPERLINK("#'" & M$4 & "'!" & ADDRESS(ROW()+15, 8), INDIRECT("'" & M$4 & "'!" & ADDRESS(ROW()+15, 8))) -> N | N9: =HYPERLINK("#'" & N$4 & "'!" & ADDRESS(ROW()+15, 8), INDIRECT("'" & N$4 & "'!" & ADDRESS(ROW()+15, 8))) -> N | O9: =HYPERLINK("#'" & O$4 & "'!" & ADDRESS(ROW()+15, 8), INDIRECT("'" & O$4 & "'!" & ADDRESS(ROW()+15, 8))) -> N
A10: =ChkList!A10 -> 서비스 관리 | B10: =ChkList!B10 -> PC-06 | C10: =ChkList!C10 -> 비인가 상용 메신저 사용 금지 | D10: =ChkList!D10 -> H | E10: =ChkList!E10 -> 3 | F10: =COUNTA($M10:INDIRECT(ADDRESS(ROW(),MATCH("",$4:$4,-1),1,1))) -> 3 | G10: =COUNTIF($M10:INDIRECT(ADDRESS(ROW(),MATCH("",$4:$4,-1),1,1)),"조치완료(Y)")+COUNTIF($M10:INDIRECT(ADDRESS(ROW(),MATCH("",$4:$4,-1),1,1)),"Y") -> 3 | H10: =COUNTIF($M10:INDIRECT(ADDRESS(ROW(),MATCH("",$4:$4,-1),1,1)),"Y(즉시조치)")+COUNTIF($M10:INDIRECT(ADDRESS(ROW(),MATCH("",$4:$4,-1),1,1)),"조치완료(즉시조치)") -> 0 | I10: =COUNTIF($M10:INDIRECT(ADDRESS(ROW(),MATCH("",$4:$4,-1),1,1)),"N") -> 0 | J10: =COUNTIF($M10:INDIRECT(ADDRESS(ROW(),MATCH("",$4:$4,-1),1,1)),"N/A")+COUNTIF($M10:INDIRECT(ADDRESS(ROW(),MATCH("",$4:$4,-1),1,1)),"조치완료(N/A)") -> 0 | K10: =VLOOKUP($D10,'parm(hidden)'!$B$8:$C$10,2,FALSE)*($F10-$J10) -> 9 | L10: =VLOOKUP($D10,'parm(hidden)'!$B$8:$C$10,2,FALSE)*($G10+$H10) -> 9 | M10: =HYPERLINK("#'" & M$4 & "'!" & ADDRESS(ROW()+15, 8), INDIRECT("'" & M$4 & "'!" & ADDRESS(ROW()+15, 8))) -> Y | N10: =HYPERLINK("#'" & N$4 & "'!" & ADDRESS(ROW()+15, 8), INDIRECT("'" & N$4 & "'!" & ADDRESS(ROW()+15, 8))) -> Y | O10: =HYPERLINK("#'" & O$4 & "'!" & ADDRESS(ROW()+15, 8), INDIRECT("'" & O$4 & "'!" & ADDRESS(ROW()+15, 8))) -> Y
A11: =ChkList!A11 -> 서비스 관리 | B11: =ChkList!B11 -> PC-07 | C11: =ChkList!C11 -> 파일 시스템이 NTFS 포맷으로 설정 | D11: =ChkList!D11 -> M | E11: =ChkList!E11 -> 2 | F11: =COUNTA($M11:INDIRECT(ADDRESS(ROW(),MATCH("",$4:$4,-1),1,1))) -> 3 | G11: =COUNTIF($M11:INDIRECT(ADDRESS(ROW(),MATCH("",$4:$4,-1),1,1)),"조치완료(Y)")+COUNTIF($M11:INDIRECT(ADDRESS(ROW(),MATCH("",$4:$4,-1),1,1)),"Y") -> 0 | H11: =COUNTIF($M11:INDIRECT(ADDRESS(ROW(),MATCH("",$4:$4,-1),1,1)),"Y(즉시조치)")+COUNTIF($M11:INDIRECT(ADDRESS(ROW(),MATCH("",$4:$4,-1),1,1)),"조치완료(즉시조치)") -> 0 | I11: =COUNTIF($M11:INDIRECT(ADDRESS(ROW(),MATCH("",$4:$4,-1),1,1)),"N") -> 0 | J11: =COUNTIF($M11:INDIRECT(ADDRESS(ROW(),MATCH("",$4:$4,-1),1,1)),"N/A")+COUNTIF($M11:INDIRECT(ADDRESS(ROW(),MATCH("",$4:$4,-1),1,1)),"조치완료(N/A)") -> 0 | K11: =VLOOKUP($D11,'parm(hidden)'!$B$8:$C$10,2,FALSE)*($F11-$J11) -> 6 | L11: =VLOOKUP($D11,'parm(hidden)'!$B$8:$C$10,2,FALSE)*($G11+$H11) -> 0 | M11: =HYPERLINK("#'" & M$4 & "'!" & ADDRESS(ROW()+15, 8), INDIRECT("'" & M$4 & "'!" & ADDRESS(ROW()+15, 8))) -> 인터뷰 | N11: =HYPERLINK("#'" & N$4 & "'!" & ADDRESS(ROW()+15, 8), INDIRECT("'" & N$4 & "'!" & ADDRESS(ROW()+15, 8))) -> 인터뷰 | O11: =HYPERLINK("#'" & O$4 & "'!" & ADDRESS(ROW()+15, 8), INDIRECT("'" & O$4 & "'!" & ADDRESS(ROW()+15, 8))) -> 인터뷰
A12: =ChkList!A12 -> 서비스 관리 | B12: =ChkList!B12 -> PC-08 | C12: =ChkList!C12 -> 0 | D12: =ChkList!D12 -> M | E12: =ChkList!E12 -> 2 | F12: =COUNTA($M12:INDIRECT(ADDRESS(ROW(),MATCH("",$4:$4,-1),1,1))) -> 3 | G12: =COUNTIF($M12:INDIRECT(ADDRESS(ROW(),MATCH("",$4:$4,-1),1,1)),"조치완료(Y)")+COUNTIF($M12:INDIRECT(ADDRESS(ROW(),MATCH("",$4:$4,-1),1,1)),"Y") -> 3 | H12: =COUNTIF($M12:INDIRECT(ADDRESS(ROW(),MATCH("",$4:$4,-1),1,1)),"Y(즉시조치)")+COUNTIF($M12:INDIRECT(ADDRESS(ROW(),MATCH("",$4:$4,-1),1,1)),"조치완료(즉시조치)") -> 0 | I12: =COUNTIF($M12:INDIRECT(ADDRESS(ROW(),MATCH("",$4:$4,-1),1,1)),"N") -> 0 | J12: =COUNTIF($M12:INDIRECT(ADDRESS(ROW(),MATCH("",$4:$4,-1),1,1)),"N/A")+COUNTIF($M12:INDIRECT(ADDRESS(ROW(),MATCH("",$4:$4,-1),1,1)),"조치완료(N/A)") -> 0 | K12: =VLOOKUP($D12,'parm(hidden)'!$B$8:$C$10,2,FALSE)*($F12-$J12) -> 6 | L12: =VLOOKUP($D12,'parm(hidden)'!$B$8:$C$10,2,FALSE)*($G12+$H12) -> 6 | M12: =HYPERLINK("#'" & M$4 & "'!" & ADDRESS(ROW()+15, 8), INDIRECT("'" & M$4 & "'!" & ADDRESS(ROW()+15, 8))) -> Y | N12: =HYPERLINK("#'" & N$4 & "'!" & ADDRESS(ROW()+15, 8), INDIRECT("'" & N$4 & "'!" & ADDRESS(ROW()+15, 8))) -> Y | O12: =HYPERLINK("#'" & O$4 & "'!" & ADDRESS(ROW()+15, 8), INDIRECT("'" & O$4 & "'!" & ADDRESS(ROW()+15, 8))) -> Y
A13: =ChkList!A13 -> 서비스 관리 | B13: =ChkList!B13 -> PC-09 | C13: =ChkList!C13 -> 브라우저 종료 시 임시 인터넷 파일 폴더의 내용을 삭제하도록 설정 | D13: =ChkList!D13 -> L | E13: =ChkList!E13 -> 1 | F13: =COUNTA($M13:INDIRECT(ADDRESS(ROW(),MATCH("",$4:$4,-1),1,1))) -> 3 | G13: =COUNTIF($M13:INDIRECT(ADDRESS(ROW(),MATCH("",$4:$4,-1),1,1)),"조치완료(Y)")+COUNTIF($M13:INDIRECT(ADDRESS(ROW(),MATCH("",$4:$4,-1),1,1)),"Y") -> 3 | H13: =COUNTIF($M13:INDIRECT(ADDRESS(ROW(),MATCH("",$4:$4,-1),1,1)),"Y(즉시조치)")+COUNTIF($M13:INDIRECT(ADDRESS(ROW(),MATCH("",$4:$4,-1),1,1)),"조치완료(즉시조치)") -> 0 | I13: =COUNTIF($M13:INDIRECT(ADDRESS(ROW(),MATCH("",$4:$4,-1),1,1)),"N") -> 0 | J13: =COUNTIF($M13:INDIRECT(ADDRESS(ROW(),MATCH("",$4:$4,-1),1,1)),"N/A")+COUNTIF($M13:INDIRECT(ADDRESS(ROW(),MATCH("",$4:$4,-1),1,1)),"조치완료(N/A)") -> 0 | K13: =VLOOKUP($D13,'parm(hidden)'!$B$8:$C$10,2,FALSE)*($F13-$J13) -> 3 | L13: =VLOOKUP($D13,'parm(hidden)'!$B$8:$C$10,2,FALSE)*($G13+$H13) -> 3 | M13: =HYPERLINK("#'" & M$4 & "'!" & ADDRESS(ROW()+15, 8), INDIRECT("'" & M$4 & "'!" & ADDRESS(ROW()+15, 8))) -> Y | N13: =HYPERLINK("#'" & N$4 & "'!" & ADDRESS(ROW()+15, 8), INDIRECT("'" & N$4 & "'!" & ADDRESS(ROW()+15, 8))) -> Y | O13: =HYPERLINK("#'" & O$4 & "'!" & ADDRESS(ROW()+15, 8), INDIRECT("'" & O$4 & "'!" & ADDRESS(ROW()+15, 8))) -> Y
A14: =ChkList!A14 -> 패치 관리 | B14: =ChkList!B14 -> PC-10 | C14: =ChkList!C14 -> 주기적 보안 패치 및 벤더 권고사항 적용 | D14: =ChkList!D14 -> H | E14: =ChkList!E14 -> 3 | F14: =COUNTA($M14:INDIRECT(ADDRESS(ROW(),MATCH("",$4:$4,-1),1,1))) -> 3 | G14: =COUNTIF($M14:INDIRECT(ADDRESS(ROW(),MATCH("",$4:$4,-1),1,1)),"조치완료(Y)")+COUNTIF($M14:INDIRECT(ADDRESS(ROW(),MATCH("",$4:$4,-1),1,1)),"Y") -> 0 | H14: =COUNTIF($M14:INDIRECT(ADDRESS(ROW(),MATCH("",$4:$4,-1),1,1)),"Y(즉시조치)")+COUNTIF($M14:INDIRECT(ADDRESS(ROW(),MATCH("",$4:$4,-1),1,1)),"조치완료(즉시조치)") -> 0 | I14: =COUNTIF($M14:INDIRECT(ADDRESS(ROW(),MATCH("",$4:$4,-1),1,1)),"N") -> 0 | J14: =COUNTIF($M14:INDIRECT(ADDRESS(ROW(),MATCH("",$4:$4,-1),1,1)),"N/A")+COUNTIF($M14:INDIRECT(ADDRESS(ROW(),MATCH("",$4:$4,-1),1,1)),"조치완료(N/A)") -> 0 | K14: =VLOOKUP($D14,'parm(hidden)'!$B$8:$C$10,2,FALSE)*($F14-$J14) -> 9 | L14: =VLOOKUP($D14,'parm(hidden)'!$B$8:$C$10,2,FALSE)*($G14+$H14) -> 0 | M14: =HYPERLINK("#'" & M$4 & "'!" & ADDRESS(ROW()+15, 8), INDIRECT("'" & M$4 & "'!" & ADDRESS(ROW()+15, 8))) -> 인터뷰 | N14: =HYPERLINK("#'" & N$4 & "'!" & ADDRESS(ROW()+15, 8), INDIRECT("'" & N$4 & "'!" & ADDRESS(ROW()+15, 8))) -> 인터뷰 | O14: =HYPERLINK("#'" & O$4 & "'!" & ADDRESS(ROW()+15, 8), INDIRECT("'" & O$4 & "'!" & ADDRESS(ROW()+15, 8))) -> 인터뷰
A15: =ChkList!A15 -> 패치 관리 | B15: =ChkList!B15 -> PC-11 | C15: =ChkList!C15 -> 지원이 종료되지 않은 Windows OS Build 적용 | D15: =ChkList!D15 -> H | E15: =ChkList!E15 -> 3 | F15: =COUNTA($M15:INDIRECT(ADDRESS(ROW(),MATCH("",$4:$4,-1),1,1))) -> 3 | G15: =COUNTIF($M15:INDIRECT(ADDRESS(ROW(),MATCH("",$4:$4,-1),1,1)),"조치완료(Y)")+COUNTIF($M15:INDIRECT(ADDRESS(ROW(),MATCH("",$4:$4,-1),1,1)),"Y") -> 0 | H15: =COUNTIF($M15:INDIRECT(ADDRESS(ROW(),MATCH("",$4:$4,-1),1,1)),"Y(즉시조치)")+COUNTIF($M15:INDIRECT(ADDRESS(ROW(),MATCH("",$4:$4,-1),1,1)),"조치완료(즉시조치)") -> 0 | I15: =COUNTIF($M15:INDIRECT(ADDRESS(ROW(),MATCH("",$4:$4,-1),1,1)),"N") -> 0 | J15: =COUNTIF($M15:INDIRECT(ADDRESS(ROW(),MATCH("",$4:$4,-1),1,1)),"N/A")+COUNTIF($M15:INDIRECT(ADDRESS(ROW(),MATCH("",$4:$4,-1),1,1)),"조치완료(N/A)") -> 0 | K15: =VLOOKUP($D15,'parm(hidden)'!$B$8:$C$10,2,FALSE)*($F15-$J15) -> 9 | L15: =VLOOKUP($D15,'parm(hidden)'!$B$8:$C$10,2,FALSE)*($G15+$H15) -> 0 | M15: =HYPERLINK("#'" & M$4 & "'!" & ADDRESS(ROW()+15, 8), INDIRECT("'" & M$4 & "'!" & ADDRESS(ROW()+15, 8))) -> 인터뷰 | N15: =HYPERLINK("#'" & N$4 & "'!" & ADDRESS(ROW()+15, 8), INDIRECT("'" & N$4 & "'!" & ADDRESS(ROW()+15, 8))) -> 인터뷰 | O15: =HYPERLINK("#'" & O$4 & "'!" & ADDRESS(ROW()+15, 8), INDIRECT("'" & O$4 & "'!" & ADDRESS(ROW()+15, 8))) -> 인터뷰
