Workbook
Name _10월_변동내역_메모_확인: #REF!
Name _10월_변동내역_메모_확인: #REF!
Name _10월_변동내역_메모_확인: #REF!
Name _Order1: 255
Name _Order2: 255
Name asd: #REF!
Name asd: #REF!
Name asd: #REF!
Name HTML_CodePage: 949
Name HTML_Control: {"'손익현황'!$A$1:$J$29"}
Name HTML_Description: ""
Name HTML_Email: ""
Name HTML_Header: "손익현황"
Name HTML_LastUpdate: "99-04-13"
Name HTML_LineAfter: FALSE
Name HTML_LineBefore: FALSE
Name HTML_Name: "윤찬영"
Name HTML_OBDlg2: TRUE
Name HTML_OBDlg4: TRUE
Name HTML_OS: 0
Name HTML_PathFile: "C:\d7100\MyHTML.htm"
Name HTML_Title: "결산요약보고3월"
Name MPLS: #REF!
Name MPLS: #REF!
Name MPLS: #REF!
Name MPLS2: #REF!
Name MPLS2: #REF!
Name MPLS2: #REF!
Name MPLSLine: #REF!
Name MPLSLine: #REF!
Name MPLSLine: #REF!
Name N_A: #REF!
Name N_A: #REF!
Name N_A: #REF!
Name O: #REF!
Name O: #REF!
Name O: #REF!
Name P: #REF!
Name P: #REF!
Name P: #REF!
Name PC: [1]목록!$T$7:$T$9
Name X: #REF!
Name X: #REF!
Name X: #REF!
Name 건물: {"'손익현황'!$A$1:$J$29"}
Name 건물임.: {"'손익현황'!$A$1:$J$29"}
Name 공: {"'손익현황'!$A$1:$J$29"}
Name 공구: {"'손익현황'!$A$1:$J$29"}
Name 공구기구: {"'손익현황'!$A$1:$J$29"}
Name 구: {"'손익현황'!$A$1:$J$29"}
Name 구축물: {"'손익현황'!$A$1:$J$29"}
Name 구축물임: {"'손익현황'!$A$1:$J$29"}
Name 기계장치: {"'손익현황'!$A$1:$J$29"}
Name 기술2팀: #REF!
Name 기술2팀: #REF!
Name 기술2팀: #REF!
Name 기준반영: #REF!
Name 기준반영: #REF!
Name 기준반영: #REF!
Name 네트워크: [1]목록!$R$7:$R$9

Sheet 표지
F11: 46219

Sheet 자산목록
A1: ■ 자산목록
A3: No. | B3: 호스트명 | C3: IP | D3: 제조업체 | E3: 구분 | F3: 모델명 | G3: OS/SW | H3: 버전 | I3: 자산명/용도 | J3: 설치위치 | K3: 부서 | L3: 담당자 | M3: 비고 | N3: 자산 평가
N4: 기밀성 | O4: 무결성 | P4: 가용성 | Q4: 등급 | R4: 점수(Hidden)
A5: 1 | B5: DB_HQ_Rocky | C5: 10.10.40.18 | D5: Oracle | E5: DB | F5: - | G5: MySQL Server | H5: 8.0.43 | I5: DB / 딩동독 서비스 MySQL | J5: 본사 내부 서버망 | K5: 개발팀 | L5: 이지훈 | M5: - | N5: 3 | O5: 3 | P5: 3 | Q5: =IF(R5>=7,"H",IF(R5>=5,"M","L")) -> H | R5: =SUM(N5:P5) -> 9
A6: 2 | B6: DB_BR_Rocky | C6: 10.200.40.18 | D6: MariaDB Corporation | E6: DB | F6: - | G6: MariaDB Server | H6: 10.3.39 | I6: DB / php 서비스 Maria | J6: 지사 내부 서버망 | K6: 개발팀 | L6: 김승우 | M6: - | N6: 3 | O6: 3 | P6: 3 | Q6: =IF(R6>=7,"H",IF(R6>=5,"M","L")) -> H | R6: =SUM(N6:P6) -> 9
A7: 1 | B7: BDB_HQ_Rocky | C7: 10.10.40.33 | D7: Oracle | E7: DB | F7: - | G7: MySQL Server | H7: 8.0.43 | I7: 지사 DB 데이터 백업 | J7: 본사 백업 서버망 | K7: 개발팀 | L7: 이지훈 | M7: - | N7: 3 | O7: 3 | P7: 3 | Q7: =IF(R7>=7,"H",IF(R7>=5,"M","L")) -> H | R7: =SUM(N7:P7) -> 9
A8: 2 | B8: BDB_BR_Rocky | C8: 10.200.40.33 | D8: MariaDB Corporation | E8: DB | F8: - | G8: MariaDB Server | H8: 10.3.39 | I8: 본사 DB 데이터 백업 | J8: 지사 백업 서버망 | K8: 개발팀 | L8: 김승우 | M8: - | N8: 3 | O8: 3 | P8: 3 | Q8: =IF(R8>=7,"H",IF(R8>=5,"M","L")) -> H | R8: =SUM(N8:P8) -> 9

Sheet parm(hidden)
B2: 1. 분류 Code
B3: Code
B4: NW
B6: 2. 중요도, 자산등급, 위협도 점수
B7: 중요도 | C7: 점수
B8: H | C8: 3
B9: M | C9: 2
B10: L | C10: 1
B12: 3. 점검결과 점수
B13: 점검 결과 | C13: 점수
C14: 취약점 진단 | D14: 위험평가
B15: Y | C15: 1 | D15: 0
B16: N | C16: 0 | D16: 3 | F16: P | G16: 0.5 | H16: 0.5
B17: N/A | C17: 0 | D17: 0
B18: R/A | C18: 0 | D18: 0
B19: Y(즉시조치) | C19: 1 | D19: 0
B21: 4. DoA
B22: DoA
B23: 21
B25: 5. 자산등급 점수 범위 | F25: 8_2. 위험평가 방법론
B26: 위험 등급 | C26: 점수 범위
C27: 최저 | D27: 최고
B28: H | C28: 7 | D28: 9
B29: M | C29: 5 | D29: 6
B30: L | C30: 3 | D30: 4
B32: 6. 위협도 점수 범위
B33: 위험 등급 | C33: 점수 범위
C34: 최저 | D34: 최고
B35: H | C35: 5 | D35: 6
B36: M | C36: 4 | D36: 4
B37: L | C37: 2 | D37: 3
B39: 7. 위험도 점수 범위
B40: 위험 등급 | C40: 점수 범위
C41: 최저 | D41: 최고
B42: H | C42: =$B$23 -> 21 | D42: 30
B43: M | C43: 11 | D43: =$C$42-1 -> 20
B44: L | C44: 1 | D44: =$C$43-1 -> 10
B46: 8. 위험도 평가표
B47: 8_1. 위험도 평가표
B48: V' | C48: 보호대책 | D48: Y=0(보호대책 있음) | M48: N=1(보호대책 없음)
...

Sheet ChkList
A1: ■ Check List
A3: 취약점 진단항목 | F3: 개선방안 및 보호대책
A4: 분류 | C4: 진단항목 | D4: 중요도 | E4: 위험도 | F4: DBMS
A5: 계정 관리 | B5: D-01 | C5: 기본 계정의 비밀번호, 정책 등을 변경하여 사용 | D5: H | E5: 3 | F5: 기본(관리자) 계정의 초기 비밀번호 및 권한 정책 변경
A6: 계정 관리 | B6: D-02 | C6: 데이터베이스의 불필요 계정을 제거하거나, 잠금설정 후 사용 | D6: H | E6: 3 | F6: 계정별 용도를 파악한 후 불필요한 계정 삭제
A7: 계정 관리 | B7: D-03 | C7: 비밀번호 사용 기간 및 복잡도를 기관의 정책에 맞도록 설정 | D7: H | E7: 3 | F7: 기관 정책에 맞게 비밀번호 사용 기간 및 복잡도 정책 설정
A8: 계정 관리 | B8: D-04 | C8: 데이터베이스 관리자 권한을 꼭 필요한 계정 및 그룹에 대해서만 허용 | D8: H | E8: 3 | F8: 관리자 권한이 필요한 계정 및 그룹에만 관리자 권한 부여
A9: 계정 관리 | B9: D-05 | C9: 비밀번호 재사용에 대한 제약 설정 | D9: M | E9: 2 | F9: 비밀번호 재사용 제한 정책을 설정하여 동일 비밀번호의 반복 사용 제한
A10: 계정 관리 | B10: D-06 | C10: DB 사용자 계정을 개별적으로 부여하여 사용 | D10: M | E10: 2 | F10: DB 사용자 계정을 공동 사용하지 않고 사용자별로 개별 부여
A11: 계정 관리 | B11: D-07 | C11: root 권한으로 서비스 구동 제한 | D11: M | E11: 2 | F11: DBMS 서비스를 root 권한이 아닌 별도 서비스 계정으로 구동
A12: 계정 관리 | B12: D-08 | C12: 안전한 암호화 알고리즘 사용 | D12: H | E12: 3 | F12: 안전한 암호화 알고리즘을 사용하도록 설정
A13: 계정 관리 | B13: D-09 | C13: 일정 횟수의 로그인 실패 시 이에 대한 잠금정책 설정 | D13: M | E13: 2 | F13: 일정 횟수 이상 로그인 실패 시 계정 잠금 정책 설정
A14: 접근 관리 | B14: D-10 | C14: 원격에서 DB 서버로의 접속 제한 | D14: H | E14: 3 | F14: 원격에서 DB 서버로의 접속을 허용된 IP 또는 사용자로 제한
A15: 접근 관리 | B15: D-11 | C15: DBA 이외의 인가되지 않은 사용자가 시스템 테이블에 접근할 수 없도록 설정 | D15: H | E15: 3 | F15: DBA 이외의 인가되지 않은 사용자의 시스템 테이블 접근 권한 제한
A16: 접근 관리 | B16: D-12 | C16: 안전한 리스너 비밀번호 설정 및 사용 | D16: H | E16: 3 | F16: 리스너에 안전한 비밀번호를 설정하고 권한 없는 접근 제한
... A30: 패치 관리 | B30: D-26 | C30: 데이터베이스의 접근, 변경, 삭제 등의 감사 기록이 기관의 감사 기록 정책에 적합하도록 설정 | D30: H | E30: 3 | F30: DBMS에 대한 감사 로그 저장 정책 수립, 적용

Sheet 취약점 진단 통계
A1: ■ 영역별/장비별 보안수준 통계
A3: 1) 영역별 보안수준
A4: 분류 | E4: 진단 결과 | J4: 중요도점수
E5: 전체항목 | F5: 진단항목 | G5: 양호 | H5: 취약 | I5: 해당없음 | J5: 전체점수 | K5: 평가점수 | L5: 보안수준
A6: 계정 관리 | E6: =SUMIF('취약점 진단 항목별 통계'!$A:$A,$A6&"*",'취약점 진단 항목별 통계'!$F:$F) -> 36 | F6: =E6-I6 -> 28 | G6: =SUMIF('취약점 진단 항목별 통계'!$A:$A,$A6&"*",'취약점 진단 항목별 통계'!$G:$G)+SUMIF('취약점 진단 항목별 통계'!$A:$A,$A6&"*",'취약점 진단 항목별 통계'!$H:$H) -> 19 | H6: =SUMIF('취약점 진단 항목별 통계'!$A:$A,$A6&"*",'취약점 진단 항목별 통계'!$I:$I) -> 4 | I6: =SUMIF('취약점 진단 항목별 통계'!$A:$A,$A6&"*",'취약점 진단 항목별 통계'!$J:$J) -> 8 | J6: =SUMIF('취약점 진단 항목별 통계'!$A:$A,$A6&"*",'취약점 진단 항목별 통계'!$K:$K) -> 76 | K6: =SUMIF('취약점 진단 항목별 통계'!$A:$A,$A6&"*",'취약점 진단 항목별 통계'!$L:$L) -> 53 | L6: =IF($I6=$E6, "N/A", (K6/J6)) -> 0.69736842
A7: 접근 관리 | E7: =SUMIF('취약점 진단 항목별 통계'!$A:$A,$A7&"*",'취약점 진단 항목별 통계'!$F:$F) -> 28 | F7: =E7-I7 -> 10 | G7: =SUMIF('취약점 진단 항목별 통계'!$A:$A,$A7&"*",'취약점 진단 항목별 통계'!$G:$G)+SUMIF('취약점 진단 항목별 통계'!$A:$A,$A7&"*",'취약점 진단 항목별 통계'!$H:$H) -> 10 | H7: =SUMIF('취약점 진단 항목별 통계'!$A:$A,$A7&"*",'취약점 진단 항목별 통계'!$I:$I) -> 0 | I7: =SUMIF('취약점 진단 항목별 통계'!$A:$A,$A7&"*",'취약점 진단 항목별 통계'!$J:$J) -> 18 | J7: =SUMIF('취약점 진단 항목별 통계'!$A:$A,$A7&"*",'취약점 진단 항목별 통계'!$K:$K) -> 26 | K7: =SUMIF('취약점 진단 항목별 통계'!$A:$A,$A7&"*",'취약점 진단 항목별 통계'!$L:$L) -> 26 | L7: =IF($I7=$E7, "N/A", (K7/J7)) -> 1
A8: 옵션 관리 | E8: =SUMIF('취약점 진단 항목별 통계'!$A:$A,$A8&"*",'취약점 진단 항목별 통계'!$F:$F) -> 32 | F8: =E8-I8 -> 6 | G8: =SUMIF('취약점 진단 항목별 통계'!$A:$A,$A8&"*",'취약점 진단 항목별 통계'!$G:$G)+SUMIF('취약점 진단 항목별 통계'!$A:$A,$A8&"*",'취약점 진단 항목별 통계'!$H:$H) -> 3 | H8: =SUMIF('취약점 진단 항목별 통계'!$A:$A,$A8&"*",'취약점 진단 항목별 통계'!$I:$I) -> 0 | I8: =SUMIF('취약점 진단 항목별 통계'!$A:$A,$A8&"*",'취약점 진단 항목별 통계'!$J:$J) -> 26 | J8: =SUMIF('취약점 진단 항목별 통계'!$A:$A,$A8&"*",'취약점 진단 항목별 통계'!$K:$K) -> 16 | K8: =SUMIF('취약점 진단 항목별 통계'!$A:$A,$A8&"*",'취약점 진단 항목별 통계'!$L:$L) -> 9 | L8: =IF($I8=$E8, "N/A", (K8/J8)) -> 0.5625
A9: 패치 관리 | E9: =SUMIF('취약점 진단 항목별 통계'!$A:$A,$A9&"*",'취약점 진단 항목별 통계'!$F:$F) -> 8 | F9: =E9-I9 -> 6 | G9: =SUMIF('취약점 진단 항목별 통계'!$A:$A,$A9&"*",'취약점 진단 항목별 통계'!$G:$G)+SUMIF('취약점 진단 항목별 통계'!$A:$A,$A9&"*",'취약점 진단 항목별 통계'!$H:$H) -> 2 | H9: =SUMIF('취약점 진단 항목별 통계'!$A:$A,$A9&"*",'취약점 진단 항목별 통계'!$I:$I) -> 0 | I9: =SUMIF('취약점 진단 항목별 통계'!$A:$A,$A9&"*",'취약점 진단 항목별 통계'!$J:$J) -> 2 | J9: =SUMIF('취약점 진단 항목별 통계'!$A:$A,$A9&"*",'취약점 진단 항목별 통계'!$K:$K) -> 18 | K9: =SUMIF('취약점 진단 항목별 통계'!$A:$A,$A9&"*",'취약점 진단 항목별 통계'!$L:$L) -> 6 | L9: =IF($I9=$E9, "N/A", (K9/J9)) -> 0.33333333
A10: 로그 관리 | E10: =SUMIF('취약점 진단 항목별 통계'!$A:$A,$A10&"*",'취약점 진단 항목별 통계'!$F:$F) -> 0 | F10: =E10-I10 -> 0 | G10: =SUMIF('취약점 진단 항목별 통계'!$A:$A,$A10&"*",'취약점 진단 항목별 통계'!$G:$G)+SUMIF('취약점 진단 항목별 통계'!$A:$A,$A10&"*",'취약점 진단 항목별 통계'!$H:$H) -> 0 | H10: =SUMIF('취약점 진단 항목별 통계'!$A:$A,$A10&"*",'취약점 진단 항목별 통계'!$I:$I) -> 0 | I10: =SUMIF('취약점 진단 항목별 통계'!$A:$A,$A10&"*",'취약점 진단 항목별 통계'!$J:$J) -> 0 | J10: =SUMIF('취약점 진단 항목별 통계'!$A:$A,$A10&"*",'취약점 진단 항목별 통계'!$K:$K) -> 0 | K10: =SUMIF('취약점 진단 항목별 통계'!$A:$A,$A10&"*",'취약점 진단 항목별 통계'!$L:$L) -> 0 | L10: =IF($I10=$E10, "N/A", (K10/J10)) -> N/A
A11: 계 | E11: =SUM(E6:E10) -> 104 | F11: =SUM(F6:F10) -> 50 | G11: =SUM(G6:G10) -> 34 | H11: =SUM(H6:H10) -> 4 | I11: =SUM(I6:I10) -> 54 | J11: =SUM(J6:J10) -> 136 | K11: =SUM(K6:K10) -> 94 | L11: =IFERROR(K11/J11, 0) -> 0.69117647
A39: 2) 장비별 보안수준
A40: 장비 구분 | E40: 진단 결과 | J40: 중요도점수
E41: 전체항목 | F41: 진단항목 | G41: 양호 | H41: 취약 | I41: 해당없음 | J41: 전체점수 | K41: 평가점수 | L41: 보안수준
A42: =HYPERLINK("[" & MID(CELL("filename"),SEARCH("[",CELL("filename"))+1, SEARCH("]",CELL("filename"))-SEARCH("[",CELL("filename"))-1) & "]" & INDIRECT(ADDRESS(ROW()-37,2,1,TRUE,"자산목록")) & "!A1",INDIRECT(ADDRESS(ROW()-37,2,1,TRUE,"자산목록"))) -> DB_HQ_Rocky | C42: =IFERROR(VLOOKUP($A42,자산목록!$B$1:$M$832,6,FALSE),"-") -> MySQL Server | E42: =IFERROR(INDIRECT(ADDRESS(17, 4, 1,TRUE,$A42)),0) -> 26 | F42: =E42-I42 -> 11 | G42: =IFERROR(INDIRECT(ADDRESS(17, 5, 1,TRUE,$A42)),0) -> 7 | H42: =IFERROR(INDIRECT(ADDRESS(17, 6, 1,TRUE,$A42)),0) -> 2 | I42: =IFERROR(INDIRECT(ADDRESS(17, 7, 1,TRUE,$A42)),0) -> 15 | J42: =IFERROR(INDIRECT(ADDRESS(17, 18, 1,TRUE,$A42)),0) -> 27 | K42: =IFERROR(INDIRECT(ADDRESS(17, 19, 1,TRUE,$A42)),0) -> 17 | L42: =IFERROR(INDIRECT(ADDRESS(17,8, 1,TRUE,$A42)),0) -> 0.62962963
A43: =HYPERLINK("[" & MID(CELL("filename"),SEARCH("[",CELL("filename"))+1, SEARCH("]",CELL("filename"))-SEARCH("[",CELL("filename"))-1) & "]" & INDIRECT(ADDRESS(ROW()-37,2,1,TRUE,"자산목록")) & "!A1",INDIRECT(ADDRESS(ROW()-37,2,1,TRUE,"자산목록"))) -> DB_BR_Rocky | C43: =IFERROR(VLOOKUP($A43,자산목록!$B$1:$M$832,6,FALSE),"-") -> MariaDB Server | E43: =IFERROR(INDIRECT(ADDRESS(17, 4, 1,TRUE,$A43)),0) -> 26 | F43: =E43-I43 -> 11 | G43: =IFERROR(INDIRECT(ADDRESS(17, 5, 1,TRUE,$A43)),0) -> 7 | H43: =IFERROR(INDIRECT(ADDRESS(17, 6, 1,TRUE,$A43)),0) -> 2 | I43: =IFERROR(INDIRECT(ADDRESS(17, 7, 1,TRUE,$A43)),0) -> 15 | J43: =IFERROR(INDIRECT(ADDRESS(17, 18, 1,TRUE,$A43)),0) -> 27 | K43: =IFERROR(INDIRECT(ADDRESS(17, 19, 1,TRUE,$A43)),0) -> 17 | L43: =IFERROR(INDIRECT(ADDRESS(17,8, 1,TRUE,$A43)),0) -> 0.62962963
A44: =HYPERLINK("[" & MID(CELL("filename"),SEARCH("[",CELL("filename"))+1, SEARCH("]",CELL("filename"))-SEARCH("[",CELL("filename"))-1) & "]" & INDIRECT(ADDRESS(ROW()-37,2,1,TRUE,"자산목록")) & "!A1",INDIRECT(ADDRESS(ROW()-37,2,1,TRUE,"자산목록"))) -> BDB_HQ_Rocky | C44: =IFERROR(VLOOKUP($A44,자산목록!$B$1:$M$832,6,FALSE),"-") -> MySQL Server | E44: =IFERROR(INDIRECT(ADDRESS(17, 4, 1,TRUE,$A44)),0) -> 26 | F44: =E44-I44 -> 14 | G44: =IFERROR(INDIRECT(ADDRESS(17, 5, 1,TRUE,$A44)),0) -> 9 | H44: =IFERROR(INDIRECT(ADDRESS(17, 6, 1,TRUE,$A44)),0) -> 0 | I44: =IFERROR(INDIRECT(ADDRESS(17, 7, 1,TRUE,$A44)),0) -> 12 | J44: =IFERROR(INDIRECT(ADDRESS(17, 18, 1,TRUE,$A44)),0) -> 32 | K44: =IFERROR(INDIRECT(ADDRESS(17, 19, 1,TRUE,$A44)),0) -> 24 | L44: =IFERROR(INDIRECT(ADDRESS(17,8, 1,TRUE,$A44)),0) -> 0.75
A45: =HYPERLINK("[" & MID(CELL("filename"),SEARCH("[",CELL("filename"))+1, SEARCH("]",CELL("filename"))-SEARCH("[",CELL("filename"))-1) & "]" & INDIRECT(ADDRESS(ROW()-37,2,1,TRUE,"자산목록")) & "!A1",INDIRECT(ADDRESS(ROW()-37,2,1,TRUE,"자산목록"))) -> BDB_BR_Rocky | C45: =IFERROR(VLOOKUP($A45,자산목록!$B$1:$M$832,6,FALSE),"-") -> MariaDB Server | E45: =IFERROR(INDIRECT(ADDRESS(17, 4, 1,TRUE,$A45)),0) -> 26 | F45: =E45-I45 -> 14 | G45: =IFERROR(INDIRECT(ADDRESS(17, 5, 1,TRUE,$A45)),0) -> 11 | H45: =IFERROR(INDIRECT(ADDRESS(17, 6, 1,TRUE,$A45)),0) -> 0 | I45: =IFERROR(INDIRECT(ADDRESS(17, 7, 1,TRUE,$A45)),0) -> 12 | J45: =IFERROR(INDIRECT(ADDRESS(17, 18, 1,TRUE,$A45)),0) -> 32 | K45: =IFERROR(INDIRECT(ADDRESS(17, 19, 1,TRUE,$A45)),0) -> 27 | L45: =IFERROR(INDIRECT(ADDRESS(17,8, 1,TRUE,$A45)),0) -> 0.84375
A46: 계 | E46: =SUM(E42:E42) -> 26 | F46: =SUM(F42:F42) -> 11 | G46: =SUM(G42:G42) -> 7 | H46: =SUM(H42:H42) -> 2 | I46: =SUM(I42:I42) -> 15 | J46: =SUM(J42:J42) -> 27 | K46: =SUM(K42:K42) -> 17 | L46: =IFERROR(K46/J46, 0) -> 0.62962963

Sheet 취약점 진단 항목별 통계
A1: ■ 취약점 진단 항목별 통계
A3: =ChkList!A4 -> 분류 | C3: =ChkList!C4 -> 진단항목 | D3: =ChkList!D4 -> 중요도 | F3: 진단 통계 | K3: 중요도 점수 | M3: 진단결과 | N3: 진단결과 | O3: 진단결과 | P3: 진단결과
F4: 전체 | G4: 양호 | H4: 즉시조치 | I4: 취약 | J4: N/A | K4: 전체 | L4: 평가 | M4: =HYPERLINK("[" & MID(CELL("filename"),SEARCH("[",CELL("filename"))+1, SEARCH("]",CELL("filename"))-SEARCH("[",CELL("filename"))-1) & "]" & INDIRECT(ADDRESS(COLUMN()-8,2,1,TRUE,"자산목록")) & "!A1",INDIRECT(ADDRESS(COLUMN()-8,2,1,TRUE,"자산목록"))) -> DB_HQ_Rocky | N4: =HYPERLINK("[" & MID(CELL("filename"),SEARCH("[",CELL("filename"))+1, SEARCH("]",CELL("filename"))-SEARCH("[",CELL("filename"))-1) & "]" & INDIRECT(ADDRESS(COLUMN()-8,2,1,TRUE,"자산목록")) & "!A1",INDIRECT(ADDRESS(COLUMN()-8,2,1,TRUE,"자산목록"))) -> DB_BR_Rocky | O4: =HYPERLINK("[" & MID(CELL("filename"),SEARCH("[",CELL("filename"))+1, SEARCH("]",CELL("filename"))-SEARCH("[",CELL("filename"))-1) & "]" & INDIRECT(ADDRESS(COLUMN()-8,2,1,TRUE,"자산목록")) & "!A1",INDIRECT(ADDRESS(COLUMN()-8,2,1,TRUE,"자산목록"))) -> BDB_HQ_Rocky | P4: =HYPERLINK("[" & MID(CELL("filename"),SEARCH("[",CELL("filename"))+1, SEARCH("]",CELL("filename"))-SEARCH("[",CELL("filename"))-1) & "]" & INDIRECT(ADDRESS(COLUMN()-8,2,1,TRUE,"자산목록")) & "!A1",INDIRECT(ADDRESS(COLUMN()-8,2,1,TRUE,"자산목록"))) -> BDB_BR_Rocky
A5: =ChkList!A5 -> 계정 관리 | B5: =ChkList!$B5 -> D-01 | C5: =ChkList!$C5 -> 기본 계정의 비밀번호, 정책 등을 변경하여 사용 | D5: =ChkList!$D5 -> H | E5: =IF(TRIM(D5)="H", "3", IF(TRIM(D5)="M", "2", IF(TRIM(D5)="L", "1", ""))) -> 3 | F5: =COUNTA($M5:INDIRECT(ADDRESS(ROW(),MATCH("",$4:$4,-1),1,1))) -> 4 | G5: =COUNTIF($M5:INDIRECT(ADDRESS(ROW(),MATCH("",$4:$4,-1),1,1)),"조치완료(Y)")+COUNTIF($M5:INDIRECT(ADDRESS(ROW(),MATCH("",$4:$4,-1),1,1)),"Y") -> 4 | H5: =COUNTIF($M5:INDIRECT(ADDRESS(ROW(),MATCH("",$4:$4,-1),1,1)),"Y(즉시조치)")+COUNTIF($M5:INDIRECT(ADDRESS(ROW(),MATCH("",$4:$4,-1),1,1)),"조치완료(즉시조치)") -> 0 | I5: =COUNTIF($M5:INDIRECT(ADDRESS(ROW(),MATCH("",$4:$4,-1),1,1)),"N") -> 0 | J5: =COUNTIF($M5:INDIRECT(ADDRESS(ROW(),MATCH("",$4:$4,-1),1,1)),"N/A")+COUNTIF($M5:INDIRECT(ADDRESS(ROW(),MATCH("",$4:$4,-1),1,1)),"조치완료(N/A)") -> 0 | K5: =VLOOKUP($D5,'parm(hidden)'!$B$8:$C$10,2,FALSE)*($F5-$J5) -> 12 | L5: =VLOOKUP($D5,'parm(hidden)'!$B$8:$C$10,2,FALSE)*($G5+$H5) -> 12 | M5: =HYPERLINK("[" & MID(CELL("filename"),SEARCH("[",CELL("filename"))+1, SEARCH("]",CELL("filename"))-SEARCH("[",CELL("filename"))-1) & "]" & ADDRESS(ROW()+16,8,1,TRUE,M$4),INDIRECT(ADDRESS(ROW()+16,8,1,TRUE,M$4))) -> Y | N5: =HYPERLINK("[" & MID(CELL("filename"),SEARCH("[",CELL("filename"))+1, SEARCH("]",CELL("filename"))-SEARCH("[",CELL("filename"))-1) & "]" & ADDRESS(ROW()+16,8,1,TRUE,N$4),INDIRECT(ADDRESS(ROW()+16,8,1,TRUE,N$4))) -> Y | O5: =HYPERLINK("[" & MID(CELL("filename"),SEARCH("[",CELL("filename"))+1, SEARCH("]",CELL("filename"))-SEARCH("[",CELL("filename"))-1) & "]" & ADDRESS(ROW()+16,8,1,TRUE,O$4),INDIRECT(ADDRESS(ROW()+16,8,1,TRUE,O$4))) -> Y | P5: =HYPERLINK("[" & MID(CELL("filename"),SEARCH("[",CELL("filename"))+1, SEARCH("]",CELL("filename"))-SEARCH("[",CELL("filename"))-1) & "]" & ADDRESS(ROW()+16,8,1,TRUE,P$4),INDIRECT(ADDRESS(ROW()+16,8,1,TRUE,P$4))) -> Y
A6: =ChkList!A6 -> 계정 관리 | B6: =ChkList!$B6 -> D-02 | C6: =ChkList!$C6 -> 데이터베이스의 불필요 계정을 제거하거나, 잠금설정 후 사용 | D6: =ChkList!$D6 -> H | E6: =IF(TRIM(D6)="H", "3", IF(TRIM(D6)="M", "2", IF(TRIM(D6)="L", "1", ""))) -> 3 | F6: =COUNTA($M6:INDIRECT(ADDRESS(ROW(),MATCH("",$4:$4,-1),1,1))) -> 4 | G6: =COUNTIF($M6:INDIRECT(ADDRESS(ROW(),MATCH("",$4:$4,-1),1,1)),"조치완료(Y)")+COUNTIF($M6:INDIRECT(ADDRESS(ROW(),MATCH("",$4:$4,-1),1,1)),"Y") -> 4 | H6: =COUNTIF($M6:INDIRECT(ADDRESS(ROW(),MATCH("",$4:$4,-1),1,1)),"Y(즉시조치)")+COUNTIF($M6:INDIRECT(ADDRESS(ROW(),MATCH("",$4:$4,-1),1,1)),"조치완료(즉시조치)") -> 0 | I6: =COUNTIF($M6:INDIRECT(ADDRESS(ROW(),MATCH("",$4:$4,-1),1,1)),"N") -> 0 | J6: =COUNTIF($M6:INDIRECT(ADDRESS(ROW(),MATCH("",$4:$4,-1),1,1)),"N/A")+COUNTIF($M6:INDIRECT(ADDRESS(ROW(),MATCH("",$4:$4,-1),1,1)),"조치완료(N/A)") -> 0 | K6: =VLOOKUP($D6,'parm(hidden)'!$B$8:$C$10,2,FALSE)*($F6-$J6) -> 12 | L6: =VLOOKUP($D6,'parm(hidden)'!$B$8:$C$10,2,FALSE)*($G6+$H6) -> 12 | M6: =HYPERLINK("[" & MID(CELL("filename"),SEARCH("[",CELL("filename"))+1, SEARCH("]",CELL("filename"))-SEARCH("[",CELL("filename"))-1) & "]" & ADDRESS(ROW()+16,8,1,TRUE,M$4),INDIRECT(ADDRESS(ROW()+16,8,1,TRUE,M$4))) -> Y | N6: =HYPERLINK("[" & MID(CELL("filename"),SEARCH("[",CELL("filename"))+1, SEARCH("]",CELL("filename"))-SEARCH("[",CELL("filename"))-1) & "]" & ADDRESS(ROW()+16,8,1,TRUE,N$4),INDIRECT(ADDRESS(ROW()+16,8,1,TRUE,N$4))) -> Y | O6: =HYPERLINK("[" & MID(CELL("filename"),SEARCH("[",CELL("filename"))+1, SEARCH("]",CELL("filename"))-SEARCH("[",CELL("filename"))-1) & "]" & ADDRESS(ROW()+16,8,1,TRUE,O$4),INDIRECT(ADDRESS(ROW()+16,8,1,TRUE,O$4))) -> Y | P6: =HYPERLINK("[" & MID(CELL("filename"),SEARCH("[",CELL("filename"))+1, SEARCH("]",CELL("filename"))-SEARCH("[",CELL("filename"))-1) & "]" & ADDRESS(ROW()+16,8,1,TRUE,P$4),INDIRECT(ADDRESS(ROW()+16,8,1,TRUE,P$4))) -> Y
A7: =ChkList!A7 -> 계정 관리 | B7: =ChkList!$B7 -> D-03 | C7: =ChkList!$C7 -> 비밀번호 사용 기간 및 복잡도를 기관의 정책에 맞도록 설정 | D7: =ChkList!$D7 -> H | E7: =IF(TRIM(D7)="H", "3", IF(TRIM(D7)="M", "2", IF(TRIM(D7)="L", "1", ""))) -> 3 | F7: =COUNTA($M7:INDIRECT(ADDRESS(ROW(),MATCH("",$4:$4,-1),1,1))) -> 4 | G7: =COUNTIF($M7:INDIRECT(ADDRESS(ROW(),MATCH("",$4:$4,-1),1,1)),"조치완료(Y)")+COUNTIF($M7:INDIRECT(ADDRESS(ROW(),MATCH("",$4:$4,-1),1,1)),"Y") -> 1 | H7: =COUNTIF($M7:INDIRECT(ADDRESS(ROW(),MATCH("",$4:$4,-1),1,1)),"Y(즉시조치)")+COUNTIF($M7:INDIRECT(ADDRESS(ROW(),MATCH("",$4:$4,-1),1,1)),"조치완료(즉시조치)") -> 0 | I7: =COUNTIF($M7:INDIRECT(ADDRESS(ROW(),MATCH("",$4:$4,-1),1,1)),"N") -> 0 | J7: =COUNTIF($M7:INDIRECT(ADDRESS(ROW(),MATCH("",$4:$4,-1),1,1)),"N/A")+COUNTIF($M7:INDIRECT(ADDRESS(ROW(),MATCH("",$4:$4,-1),1,1)),"조치완료(N/A)") -> 0 | K7: =VLOOKUP($D7,'parm(hidden)'!$B$8:$C$10,2,FALSE)*($F7-$J7) -> 12 | L7: =VLOOKUP($D7,'parm(hidden)'!$B$8:$C$10,2,FALSE)*($G7+$H7) -> 3 | M7: =HYPERLINK("[" & MID(CELL("filename"),SEARCH("[",CELL("filename"))+1, SEARCH("]",CELL("filename"))-SEARCH("[",CELL("filename"))-1) & "]" & ADDRESS(ROW()+16,8,1,TRUE,M$4),INDIRECT(ADDRESS(ROW()+16,8,1,TRUE,M$4))) -> 인터뷰 | N7: =HYPERLINK("[" & MID(CELL("filename"),SEARCH("[",CELL("filename"))+1, SEARCH("]",CELL("filename"))-SEARCH("[",CELL("filename"))-1) & "]" & ADDRESS(ROW()+16,8,1,TRUE,N$4),INDIRECT(ADDRESS(ROW()+16,8,1,TRUE,N$4))) -> 인터뷰 | O7: =HYPERLINK("[" & MID(CELL("filename"),SEARCH("[",CELL("filename"))+1, SEARCH("]",CELL("filename"))-SEARCH("[",CELL("filename"))-1) & "]" & ADDRESS(ROW()+16,8,1,TRUE,O$4),INDIRECT(ADDRESS(ROW()+16,8,1,TRUE,O$4))) -> 인터뷰 | P7: =HYPERLINK("[" & MID(CELL("filename"),SEARCH("[",CELL("filename"))+1, SEARCH("]",CELL("filename"))-SEARCH("[",CELL("filename"))-1) & "]" & ADDRESS(ROW()+16,8,1,TRUE,P$4),INDIRECT(ADDRESS(ROW()+16,8,1,TRUE,P$4))) -> Y
A8: =ChkList!A8 -> 계정 관리 | B8: =ChkList!$B8 -> D-04 | C8: =ChkList!$C8 -> 데이터베이스 관리자 권한을 꼭 필요한 계정 및 그룹에 대해서만 허용 | D8: =ChkList!$D8 -> H | E8: =IF(TRIM(D8)="H", "3", IF(TRIM(D8)="M", "2", IF(TRIM(D8)="L", "1", ""))) -> 3 | F8: =COUNTA($M8:INDIRECT(ADDRESS(ROW(),MATCH("",$4:$4,-1),1,1))) -> 4 | G8: =COUNTIF($M8:INDIRECT(ADDRESS(ROW(),MATCH("",$4:$4,-1),1,1)),"조치완료(Y)")+COUNTIF($M8:INDIRECT(ADDRESS(ROW(),MATCH("",$4:$4,-1),1,1)),"Y") -> 4 | H8: =COUNTIF($M8:INDIRECT(ADDRESS(ROW(),MATCH("",$4:$4,-1),1,1)),"Y(즉시조치)")+COUNTIF($M8:INDIRECT(ADDRESS(ROW(),MATCH("",$4:$4,-1),1,1)),"조치완료(즉시조치)") -> 0 | I8: =COUNTIF($M8:INDIRECT(ADDRESS(ROW(),MATCH("",$4:$4,-1),1,1)),"N") -> 0 | J8: =COUNTIF($M8:INDIRECT(ADDRESS(ROW(),MATCH("",$4:$4,-1),1,1)),"N/A")+COUNTIF($M8:INDIRECT(ADDRESS(ROW(),MATCH("",$4:$4,-1),1,1)),"조치완료(N/A)") -> 0 | K8: =VLOOKUP($D8,'parm(hidden)'!$B$8:$C$10,2,FALSE)*($F8-$J8) -> 12 | L8: =VLOOKUP($D8,'parm(hidden)'!$B$8:$C$10,2,FALSE)*($G8+$H8) -> 12 | M8: =HYPERLINK("[" & MID(CELL("filename"),SEARCH("[",CELL("filename"))+1, SEARCH("]",CELL("filename"))-SEARCH("[",CELL("filename"))-1) & "]" & ADDRESS(ROW()+16,8,1,TRUE,M$4),INDIRECT(ADDRESS(ROW()+16,8,1,TRUE,M$4))) -> Y | N8: =HYPERLINK("[" & MID(CELL("filename"),SEARCH("[",CELL("filename"))+1, SEARCH("]",CELL("filename"))-SEARCH("[",CELL("filename"))-1) & "]" & ADDRESS(ROW()+16,8,1,TRUE,N$4),INDIRECT(ADDRESS(ROW()+16,8,1,TRUE,N$4))) -> Y | O8: =HYPERLINK("[" & MID(CELL("filename"),SEARCH("[",CELL("filename"))+1, SEARCH("]",CELL("filename"))-SEARCH("[",CELL("filename"))-1) & "]" & ADDRESS(ROW()+16,8,1,TRUE,O$4),INDIRECT(ADDRESS(ROW()+16,8,1,TRUE,O$4))) -> Y | P8: =HYPERLINK("[" & MID(CELL("filename"),SEARCH("[",CELL("filename"))+1, SEARCH("]",CELL("filename"))-SEARCH("[",CELL("filename"))-1) & "]" & ADDRESS(ROW()+16,8,1,TRUE,P$4),INDIRECT(ADDRESS(ROW()+16,8,1,TRUE,P$4))) -> Y
A9: =ChkList!A9 -> 계정 관리 | B9: =ChkList!$B9 -> D-05 | C9: =ChkList!$C9 -> 비밀번호 재사용에 대한 제약 설정 | D9: =ChkList!$D9 -> M | E9: =IF(TRIM(D9)="H", "3", IF(TRIM(D9)="M", "2", IF(TRIM(D9)="L", "1", ""))) -> 2 | F9: =COUNTA($M9:INDIRECT(ADDRESS(ROW(),MATCH("",$4:$4,-1),1,1))) -> 4 | G9: =COUNTIF($M9:INDIRECT(ADDRESS(ROW(),MATCH("",$4:$4,-1),1,1)),"조치완료(Y)")+COUNTIF($M9:INDIRECT(ADDRESS(ROW(),MATCH("",$4:$4,-1),1,1)),"Y") -> 0 | H9: =COUNTIF($M9:INDIRECT(ADDRESS(ROW(),MATCH("",$4:$4,-1),1,1)),"Y(즉시조치)")+COUNTIF($M9:INDIRECT(ADDRESS(ROW(),MATCH("",$4:$4,-1),1,1)),"조치완료(즉시조치)") -> 0 | I9: =COUNTIF($M9:INDIRECT(ADDRESS(ROW(),MATCH("",$4:$4,-1),1,1)),"N") -> 0 | J9: =COUNTIF($M9:INDIRECT(ADDRESS(ROW(),MATCH("",$4:$4,-1),1,1)),"N/A")+COUNTIF($M9:INDIRECT(ADDRESS(ROW(),MATCH("",$4:$4,-1),1,1)),"조치완료(N/A)") -> 4 | K9: =VLOOKUP($D9,'parm(hidden)'!$B$8:$C$10,2,FALSE)*($F9-$J9) -> 0 | L9: =VLOOKUP($D9,'parm(hidden)'!$B$8:$C$10,2,FALSE)*($G9+$H9) -> 0 | M9: =HYPERLINK("[" & MID(CELL("filename"),SEARCH("[",CELL("filename"))+1, SEARCH("]",CELL("filename"))-SEARCH("[",CELL("filename"))-1) & "]" & ADDRESS(ROW()+16,8,1,TRUE,M$4),INDIRECT(ADDRESS(ROW()+16,8,1,TRUE,M$4))) -> N/A | N9: =HYPERLINK("[" & MID(CELL("filename"),SEARCH("[",CELL("filename"))+1, SEARCH("]",CELL("filename"))-SEARCH("[",CELL("filename"))-1) & "]" & ADDRESS(ROW()+16,8,1,TRUE,N$4),INDIRECT(ADDRESS(ROW()+16,8,1,TRUE,N$4))) -> N/A | O9: =HYPERLINK("[" & MID(CELL("filename"),SEARCH("[",CELL("filename"))+1, SEARCH("]",CELL("filename"))-SEARCH("[",CELL("filename"))-1) & "]" & ADDRESS(ROW()+16,8,1,TRUE,O$4),INDIRECT(ADDRESS(ROW()+16,8,1,TRUE,O$4))) -> N/A | P9: =HYPERLINK("[" & MID(CELL("filename"),SEARCH("[",CELL("filename"))+1, SEARCH("]",CELL("filename"))-SEARCH("[",CELL("filename"))-1) & "]" & ADDRESS(ROW()+16,8,1,TRUE,P$4),INDIRECT(ADDRESS(ROW()+16,8,1,TRUE,P$4))) -> N/A
A10: =ChkList!A10 -> 계정 관리 | B10: =ChkList!$B10 -> D-06 | C10: =ChkList!$C10 -> DB 사용자 계정을 개별적으로 부여하여 사용 | D10: =ChkList!$D10 -> M | E10: =IF(TRIM(D10)="H", "3", IF(TRIM(D10)="M", "2", IF(TRIM(D10)="L", "1", ""))) -> 2 | F10: =COUNTA($M10:INDIRECT(ADDRESS(ROW(),MATCH("",$4:$4,-1),1,1))) -> 4 | G10: =COUNTIF($M10:INDIRECT(ADDRESS(ROW(),MATCH("",$4:$4,-1),1,1)),"조치완료(Y)")+COUNTIF($M10:INDIRECT(ADDRESS(ROW(),MATCH("",$4:$4,-1),1,1)),"Y") -> 2 | H10: =COUNTIF($M10:INDIRECT(ADDRESS(ROW(),MATCH("",$4:$4,-1),1,1)),"Y(즉시조치)")+COUNTIF($M10:INDIRECT(ADDRESS(ROW(),MATCH("",$4:$4,-1),1,1)),"조치완료(즉시조치)") -> 0 | I10: =COUNTIF($M10:INDIRECT(ADDRESS(ROW(),MATCH("",$4:$4,-1),1,1)),"N") -> 2 | J10: =COUNTIF($M10:INDIRECT(ADDRESS(ROW(),MATCH("",$4:$4,-1),1,1)),"N/A")+COUNTIF($M10:INDIRECT(ADDRESS(ROW(),MATCH("",$4:$4,-1),1,1)),"조치완료(N/A)") -> 0 | K10: =VLOOKUP($D10,'parm(hidden)'!$B$8:$C$10,2,FALSE)*($F10-$J10) -> 8 | L10: =VLOOKUP($D10,'parm(hidden)'!$B$8:$C$10,2,FALSE)*($G10+$H10) -> 4 | M10: =HYPERLINK("[" & MID(CELL("filename"),SEARCH("[",CELL("filename"))+1, SEARCH("]",CELL("filename"))-SEARCH("[",CELL("filename"))-1) & "]" & ADDRESS(ROW()+16,8,1,TRUE,M$4),INDIRECT(ADDRESS(ROW()+16,8,1,TRUE,M$4))) -> N | N10: =HYPERLINK("[" & MID(CELL("filename"),SEARCH("[",CELL("filename"))+1, SEARCH("]",CELL("filename"))-SEARCH("[",CELL("filename"))-1) & "]" & ADDRESS(ROW()+16,8,1,TRUE,N$4),INDIRECT(ADDRESS(ROW()+16,8,1,TRUE,N$4))) -> N | O10: =HYPERLINK("[" & MID(CELL("filename"),SEARCH("[",CELL("filename"))+1, SEARCH("]",CELL("filename"))-SEARCH("[",CELL("filename"))-1) & "]" & ADDRESS(ROW()+16,8,1,TRUE,O$4),INDIRECT(ADDRESS(ROW()+16,8,1,TRUE,O$4))) -> Y | P10: =HYPERLINK("[" & MID(CELL("filename"),SEARCH("[",CELL("filename"))+1, SEARCH("]",CELL("filename"))-SEARCH("[",CELL("filename"))-1) & "]" & ADDRESS(ROW()+16,8,1,TRUE,P$4),INDIRECT(ADDRESS(ROW()+16,8,1,TRUE,P$4))) -> Y
A11: =ChkList!A11 -> 계정 관리 | B11: =ChkList!$B11 -> D-07 | C11: =ChkList!$C11 -> root 권한으로 서비스 구동 제한 | D11: =ChkList!$D11 -> M | E11: =IF(TRIM(D11)="H", "3", IF(TRIM(D11)="M", "2", IF(TRIM(D11)="L", "1", ""))) -> 2 | F11: =COUNTA($M11:INDIRECT(ADDRESS(ROW(),MATCH("",$4:$4,-1),1,1))) -> 4 | G11: =COUNTIF($M11:INDIRECT(ADDRESS(ROW(),MATCH("",$4:$4,-1),1,1)),"조치완료(Y)")+COUNTIF($M11:INDIRECT(ADDRESS(ROW(),MATCH("",$4:$4,-1),1,1)),"Y") -> 2 | H11: =COUNTIF($M11:INDIRECT(ADDRESS(ROW(),MATCH("",$4:$4,-1),1,1)),"Y(즉시조치)")+COUNTIF($M11:INDIRECT(ADDRESS(ROW(),MATCH("",$4:$4,-1),1,1)),"조치완료(즉시조치)") -> 0 | I11: =COUNTIF($M11:INDIRECT(ADDRESS(ROW(),MATCH("",$4:$4,-1),1,1)),"N") -> 0 | J11: =COUNTIF($M11:INDIRECT(ADDRESS(ROW(),MATCH("",$4:$4,-1),1,1)),"N/A")+COUNTIF($M11:INDIRECT(ADDRESS(ROW(),MATCH("",$4:$4,-1),1,1)),"조치완료(N/A)") -> 0 | K11: =VLOOKUP($D11,'parm(hidden)'!$B$8:$C$10,2,FALSE)*($F11-$J11) -> 8 | L11: =VLOOKUP($D11,'parm(hidden)'!$B$8:$C$10,2,FALSE)*($G11+$H11) -> 4 | M11: =HYPERLINK("[" & MID(CELL("filename"),SEARCH("[",CELL("filename"))+1, SEARCH("]",CELL("filename"))-SEARCH("[",CELL("filename"))-1) & "]" & ADDRESS(ROW()+16,8,1,TRUE,M$4),INDIRECT(ADDRESS(ROW()+16,8,1,TRUE,M$4))) -> 인터뷰 | N11: =HYPERLINK("[" & MID(CELL("filename"),SEARCH("[",CELL("filename"))+1, SEARCH("]",CELL("filename"))-SEARCH("[",CELL("filename"))-1) & "]" & ADDRESS(ROW()+16,8,1,TRUE,N$4),INDIRECT(ADDRESS(ROW()+16,8,1,TRUE,N$4))) -> 인터뷰 | O11: =HYPERLINK("[" & MID(CELL("filename"),SEARCH("[",CELL("filename"))+1, SEARCH("]",CELL("filename"))-SEARCH("[",CELL("filename"))-1) & "]" & ADDRESS(ROW()+16,8,1,TRUE,O$4),INDIRECT(ADDRESS(ROW()+16,8,1,TRUE,O$4))) -> Y | P11: =HYPERLINK("[" & MID(CELL("filename"),SEARCH("[",CELL("filename"))+1, SEARCH("]",CELL("filename"))-SEARCH("[",CELL("filename"))-1) & "]" & ADDRESS(ROW()+16,8,1,TRUE,P$4),INDIRECT(ADDRESS(ROW()+16,8,1,TRUE,P$4))) -> Y
A12: =ChkList!A12 -> 계정 관리 | B12: =ChkList!$B12 -> D-08 | C12: =ChkList!$C12 -> 안전한 암호화 알고리즘 사용 | D12: =ChkList!$D12 -> H | E12: =IF(TRIM(D12)="H", "3", IF(TRIM(D12)="M", "2", IF(TRIM(D12)="L", "1", ""))) -> 3 | F12: =COUNTA($M12:INDIRECT(ADDRESS(ROW(),MATCH("",$4:$4,-1),1,1))) -> 4 | G12: =COUNTIF($M12:INDIRECT(ADDRESS(ROW(),MATCH("",$4:$4,-1),1,1)),"조치완료(Y)")+COUNTIF($M12:INDIRECT(ADDRESS(ROW(),MATCH("",$4:$4,-1),1,1)),"Y") -> 2 | H12: =COUNTIF($M12:INDIRECT(ADDRESS(ROW(),MATCH("",$4:$4,-1),1,1)),"Y(즉시조치)")+COUNTIF($M12:INDIRECT(ADDRESS(ROW(),MATCH("",$4:$4,-1),1,1)),"조치완료(즉시조치)") -> 0 | I12: =COUNTIF($M12:INDIRECT(ADDRESS(ROW(),MATCH("",$4:$4,-1),1,1)),"N") -> 2 | J12: =COUNTIF($M12:INDIRECT(ADDRESS(ROW(),MATCH("",$4:$4,-1),1,1)),"N/A")+COUNTIF($M12:INDIRECT(ADDRESS(ROW(),MATCH("",$4:$4,-1),1,1)),"조치완료(N/A)") -> 0 | K12: =VLOOKUP($D12,'parm(hidden)'!$B$8:$C$10,2,FALSE)*($F12-$J12) -> 12 | L12: =VLOOKUP($D12,'parm(hidden)'!$B$8:$C$10,2,FALSE)*($G12+$H12) -> 6 | M12: =HYPERLINK("[" & MID(CELL("filename"),SEARCH("[",CELL("filename"))+1, SEARCH("]",CELL("filename"))-SEARCH("[",CELL("filename"))-1) & "]" & ADDRESS(ROW()+16,8,1,TRUE,M$4),INDIRECT(ADDRESS(ROW()+16,8,1,TRUE,M$4))) -> N | N12: =HYPERLINK("[" & MID(CELL("filename"),SEARCH("[",CELL("filename"))+1, SEARCH("]",CELL("filename"))-SEARCH("[",CELL("filename"))-1) & "]" & ADDRESS(ROW()+16,8,1,TRUE,N$4),INDIRECT(ADDRESS(ROW()+16,8,1,TRUE,N$4))) -> N | O12: =HYPERLINK("[" & MID(CELL("filename"),SEARCH("[",CELL("filename"))+1, SEARCH("]",CELL("filename"))-SEARCH("[",CELL("filename"))-1) & "]" & ADDRESS(ROW()+16,8,1,TRUE,O$4),INDIRECT(ADDRESS(ROW()+16,8,1,TRUE,O$4))) -> Y | P12: =HYPERLINK("[" & MID(CELL("filename"),SEARCH("[",CELL("filename"))+1, SEARCH("]",CELL("filename"))-SEARCH("[",CELL("filename"))-1) & "]" & ADDRESS(ROW()+16,8,1,TRUE,P$4),INDIRECT(ADDRESS(ROW()+16,8,1,TRUE,P$4))) -> Y
A13: =ChkList!A13 -> 계정 관리 | B13: =ChkList!$B13 -> D-09 | C13: =ChkList!$C13 -> 일정 횟수의 로그인 실패 시 이에 대한 잠금정책 설정 | D13: =ChkList!$D13 -> M | E13: =IF(TRIM(D13)="H", "3", IF(TRIM(D13)="M", "2", IF(TRIM(D13)="L", "1", ""))) -> 2 | F13: =COUNTA($M13:INDIRECT(ADDRESS(ROW(),MATCH("",$4:$4,-1),1,1))) -> 4 | G13: =COUNTIF($M13:INDIRECT(ADDRESS(ROW(),MATCH("",$4:$4,-1),1,1)),"조치완료(Y)")+COUNTIF($M13:INDIRECT(ADDRESS(ROW(),MATCH("",$4:$4,-1),1,1)),"Y") -> 0 | H13: =COUNTIF($M13:INDIRECT(ADDRESS(ROW(),MATCH("",$4:$4,-1),1,1)),"Y(즉시조치)")+COUNTIF($M13:INDIRECT(ADDRESS(ROW(),MATCH("",$4:$4,-1),1,1)),"조치완료(즉시조치)") -> 0 | I13: =COUNTIF($M13:INDIRECT(ADDRESS(ROW(),MATCH("",$4:$4,-1),1,1)),"N") -> 0 | J13: =COUNTIF($M13:INDIRECT(ADDRESS(ROW(),MATCH("",$4:$4,-1),1,1)),"N/A")+COUNTIF($M13:INDIRECT(ADDRESS(ROW(),MATCH("",$4:$4,-1),1,1)),"조치완료(N/A)") -> 4 | K13: =VLOOKUP($D13,'parm(hidden)'!$B$8:$C$10,2,FALSE)*($F13-$J13) -> 0 | L13: =VLOOKUP($D13,'parm(hidden)'!$B$8:$C$10,2,FALSE)*($G13+$H13) -> 0 | M13: =HYPERLINK("[" & MID(CELL("filename"),SEARCH("[",CELL("filename"))+1, SEARCH("]",CELL("filename"))-SEARCH("[",CELL("filename"))-1) & "]" & ADDRESS(ROW()+16,8,1,TRUE,M$4),INDIRECT(ADDRESS(ROW()+16,8,1,TRUE,M$4))) -> N/A | N13: =HYPERLINK("[" & MID(CELL("filename"),SEARCH("[",CELL("filename"))+1, SEARCH("]",CELL("filename"))-SEARCH("[",CELL("filename"))-1) & "]" & ADDRESS(ROW()+16,8,1,TRUE,N$4),INDIRECT(ADDRESS(ROW()+16,8,1,TRUE,N$4))) -> N/A | O13: =HYPERLINK("[" & MID(CELL("filename"),SEARCH("[",CELL("filename"))+1, SEARCH("]",CELL("filename"))-SEARCH("[",CELL("filename"))-1) & "]" & ADDRESS(ROW()+16,8,1,TRUE,O$4),INDIRECT(ADDRESS(ROW()+16,8,1,TRUE,O$4))) -> N/A | P13: =HYPERLINK("[" & MID(CELL("filename"),SEARCH("[",CELL("filename"))+1, SEARCH("]",CELL("filename"))-SEARCH("[",CELL("filename"))-1) & "]" & ADDRESS(ROW()+16,8,1,TRUE,P$4),INDIRECT(ADDRESS(ROW()+16,8,1,TRUE,P$4))) -> N/A
A14: =ChkList!A14 -> 접근 관리 | B14: =ChkList!$B14 -> D-10 | C14: =ChkList!$C14 -> 원격에서 DB 서버로의 접속 제한 | D14: =ChkList!$D14 -> H | E14: =IF(TRIM(D14)="H", "3", IF(TRIM(D14)="M", "2", IF(TRIM(D14)="L", "1", ""))) -> 3 | F14: =COUNTA($M14:INDIRECT(ADDRESS(ROW(),MATCH("",$4:$4,-1),1,1))) -> 4 | G14: =COUNTIF($M14:INDIRECT(ADDRESS(ROW(),MATCH("",$4:$4,-1),1,1)),"조치완료(Y)")+COUNTIF($M14:INDIRECT(ADDRESS(ROW(),MATCH("",$4:$4,-1),1,1)),"Y") -> 2 | H14: =COUNTIF($M14:INDIRECT(ADDRESS(ROW(),MATCH("",$4:$4,-1),1,1)),"Y(즉시조치)")+COUNTIF($M14:INDIRECT(ADDRESS(ROW(),MATCH("",$4:$4,-1),1,1)),"조치완료(즉시조치)") -> 0 | I14: =COUNTIF($M14:INDIRECT(ADDRESS(ROW(),MATCH("",$4:$4,-1),1,1)),"N") -> 0 | J14: =COUNTIF($M14:INDIRECT(ADDRESS(ROW(),MATCH("",$4:$4,-1),1,1)),"N/A")+COUNTIF($M14:INDIRECT(ADDRESS(ROW(),MATCH("",$4:$4,-1),1,1)),"조치완료(N/A)") -> 2 | K14: =VLOOKUP($D14,'parm(hidden)'!$B$8:$C$10,2,FALSE)*($F14-$J14) -> 6 | L14: =VLOOKUP($D14,'parm(hidden)'!$B$8:$C$10,2,FALSE)*($G14+$H14) -> 6 | M14: =HYPERLINK("[" & MID(CELL("filename"),SEARCH("[",CELL("filename"))+1, SEARCH("]",CELL("filename"))-SEARCH("[",CELL("filename"))-1) & "]" & ADDRESS(ROW()+16,8,1,TRUE,M$4),INDIRECT(ADDRESS(ROW()+16,8,1,TRUE,M$4))) -> Y | N14: =HYPERLINK("[" & MID(CELL("filename"),SEARCH("[",CELL("filename"))+1, SEARCH("]",CELL("filename"))-SEARCH("[",CELL("filename"))-1) & "]" & ADDRESS(ROW()+16,8,1,TRUE,N$4),INDIRECT(ADDRESS(ROW()+16,8,1,TRUE,N$4))) -> Y | O14: =HYPERLINK("[" & MID(CELL("filename"),SEARCH("[",CELL("filename"))+1, SEARCH("]",CELL("filename"))-SEARCH("[",CELL("filename"))-1) & "]" & ADDRESS(ROW()+16,8,1,TRUE,O$4),INDIRECT(ADDRESS(ROW()+16,8,1,TRUE,O$4))) -> N/A | P14: =HYPERLINK("[" & MID(CELL("filename"),SEARCH("[",CELL("filename"))+1, SEARCH("]",CELL("filename"))-SEARCH("[",CELL("filename"))-1) & "]" & ADDRESS(ROW()+16,8,1,TRUE,P$4),INDIRECT(ADDRESS(ROW()+16,8,1,TRUE,P$4))) -> N/A
A15: =ChkList!A15 -> 접근 관리 | B15: =ChkList!$B15 -> D-11 | C15: =ChkList!$C15 -> DBA 이외의 인가되지 않은 사용자가 시스템 테이블에 접근할 수 없도록 설정 | D15: =ChkList!$D15 -> H | E15: =IF(TRIM(D15)="H", "3", IF(TRIM(D15)="M", "2", IF(TRIM(D15)="L", "1", ""))) -> 3 | F15: =COUNTA($M15:INDIRECT(ADDRESS(ROW(),MATCH("",$4:$4,-1),1,1))) -> 4 | G15: =COUNTIF($M15:INDIRECT(ADDRESS(ROW(),MATCH("",$4:$4,-1),1,1)),"조치완료(Y)")+COUNTIF($M15:INDIRECT(ADDRESS(ROW(),MATCH("",$4:$4,-1),1,1)),"Y") -> 2 | H15: =COUNTIF($M15:INDIRECT(ADDRESS(ROW(),MATCH("",$4:$4,-1),1,1)),"Y(즉시조치)")+COUNTIF($M15:INDIRECT(ADDRESS(ROW(),MATCH("",$4:$4,-1),1,1)),"조치완료(즉시조치)") -> 0 | I15: =COUNTIF($M15:INDIRECT(ADDRESS(ROW(),MATCH("",$4:$4,-1),1,1)),"N") -> 0 | J15: =COUNTIF($M15:INDIRECT(ADDRESS(ROW(),MATCH("",$4:$4,-1),1,1)),"N/A")+COUNTIF($M15:INDIRECT(ADDRESS(ROW(),MATCH("",$4:$4,-1),1,1)),"조치완료(N/A)") -> 2 | K15: =VLOOKUP($D15,'parm(hidden)'!$B$8:$C$10,2,FALSE)*($F15-$J15) -> 6 | L15: =VLOOKUP($D15,'parm(hidden)'!$B$8:$C$10,2,FALSE)*($G15+$H15) -> 6 | M15: =HYPERLINK("[" & MID(CELL("filename"),SEARCH("[",CELL("filename"))+1, SEARCH("]",CELL("filename"))-SEARCH("[",CELL("filename"))-1) & "]" & ADDRESS(ROW()+16,8,1,TRUE,M$4),INDIRECT(ADDRESS(ROW()+16,8,1,TRUE,M$4))) -> Y | N15: =HYPERLINK("[" & MID(CELL("filename"),SEARCH("[",CELL("filename"))+1, SEARCH("]",CELL("filename"))-SEARCH("[",CELL("filename"))-1) & "]" & ADDRESS(ROW()+16,8,1,TRUE,N$4),INDIRECT(ADDRESS(ROW()+16,8,1,TRUE,N$4))) -> Y | O15: =HYPERLINK("[" & MID(CELL("filename"),SEARCH("[",CELL("filename"))+1, SEARCH("]",CELL("filename"))-SEARCH("[",CELL("filename"))-1) & "]" & ADDRESS(ROW()+16,8,1,TRUE,O$4),INDIRECT(ADDRESS(ROW()+16,8,1,TRUE,O$4))) -> N/A | P15: =HYPERLINK("[" & MID(CELL("filename"),SEARCH("[",CELL("filename"))+1, SEARCH("]",CELL("filename"))-SEARCH("[",CELL("filename"))-1) & "]" & ADDRESS(ROW()+16,8,1,TRUE,P$4),INDIRECT(ADDRESS(ROW()+16,8,1,TRUE,P$4))) -> N/A
A16: =ChkList!A16 -> 접근 관리 | B16: =ChkList!$B16 -> D-12 | C16: =ChkList!$C16 -> 안전한 리스너 비밀번호 설정 및 사용 | D16: =ChkList!$D16 -> H | E16: =IF(TRIM(D16)="H", "3", IF(TRIM(D16)="M", "2", IF(TRIM(D16)="L", "1", ""))) -> 3 | F16: =COUNTA($M16:INDIRECT(ADDRESS(ROW(),MATCH("",$4:$4,-1),1,1))) -> 4 | G16: =COUNTIF($M16:INDIRECT(ADDRESS(ROW(),MATCH("",$4:$4,-1),1,1)),"조치완료(Y)")+COUNTIF($M16:INDIRECT(ADDRESS(ROW(),MATCH("",$4:$4,-1),1,1)),"Y") -> 2 | H16: =COUNTIF($M16:INDIRECT(ADDRESS(ROW(),MATCH("",$4:$4,-1),1,1)),"Y(즉시조치)")+COUNTIF($M16:INDIRECT(ADDRESS(ROW(),MATCH("",$4:$4,-1),1,1)),"조치완료(즉시조치)") -> 0 | I16: =COUNTIF($M16:INDIRECT(ADDRESS(ROW(),MATCH("",$4:$4,-1),1,1)),"N") -> 0 | J16: =COUNTIF($M16:INDIRECT(ADDRESS(ROW(),MATCH("",$4:$4,-1),1,1)),"N/A")+COUNTIF($M16:INDIRECT(ADDRESS(ROW(),MATCH("",$4:$4,-1),1,1)),"조치완료(N/A)") -> 2 | K16: =VLOOKUP($D16,'parm(hidden)'!$B$8:$C$10,2,FALSE)*($F16-$J16) -> 6 | L16: =VLOOKUP($D16,'parm(hidden)'!$B$8:$C$10,2,FALSE)*($G16+$H16) -> 6 | M16: =HYPERLINK("[" & MID(CELL("filename"),SEARCH("[",CELL("filename"))+1, SEARCH("]",CELL("filename"))-SEARCH("[",CELL("filename"))-1) & "]" & ADDRESS(ROW()+16,8,1,TRUE,M$4),INDIRECT(ADDRESS(ROW()+16,8,1,TRUE,M$4))) -> N/A | N16: =HYPERLINK("[" & MID(CELL("filename"),SEARCH("[",CELL("filename"))+1, SEARCH("]",CELL("filename"))-SEARCH("[",CELL("filename"))-1) & "]" & ADDRESS(ROW()+16,8,1,TRUE,N$4),INDIRECT(ADDRESS(ROW()+16,8,1,TRUE,N$4))) -> N/A | O16: =HYPERLINK("[" & MID(CELL("filename"),SEARCH("[",CELL("filename"))+1, SEARCH("]",CELL("filename"))-SEARCH("[",CELL("filename"))-1) & "]" & ADDRESS(ROW()+16,8,1,TRUE,O$4),INDIRECT(ADDRESS(ROW()+16,8,1,TRUE,O$4))) -> Y | P16: =HYPERLINK("[" & MID(CELL("filename"),SEARCH("[",CELL("filename"))+1, SEARCH("]",CELL("filename"))-SEARCH("[",CELL("filename"))-1) & "]" & ADDRESS(ROW()+16,8,1,TRUE,P$4),INDIRECT(ADDRESS(ROW()+16,8,1,TRUE,P$4))) -> Y
... A30: =ChkList!A30 -> 패치 관리 | B30: =ChkList!$B30 -> D-26 | C30: =ChkList!$C30 -> 데이터베이스의 접근, 변경, 삭제 등의 감사 기록이 기관의 감사 기록 정책에 적합하도록 설정 | D30: =ChkList!$D30 -> H | E30: =IF(TRIM(D30)="H", "3", IF(TRIM(D30)="M", "2", IF(TRIM(D30)="L", "1", ""))) -> 3 | F30: =COUNTA($M30:INDIRECT(ADDRESS(ROW(),MATCH("",$4:$4,-1),1,1))) -> 4 | G30: =COUNTIF($M30:INDIRECT(ADDRESS(ROW(),MATCH("",$4:$4,-1),1,1)),"조치완료(Y)")+COUNTIF($M30:INDIRECT(ADDRESS(ROW(),MATCH("",$4:$4,-1),1,1)),"Y") -> 0 | H30: =COUNTIF($M30:INDIRECT(ADDRESS(ROW(),MATCH("",$4:$4,-1),1,1)),"Y(즉시조치)")+COUNTIF($M30:INDIRECT(ADDRESS(ROW(),MATCH("",$4:$4,-1),1,1)),"조치완료(즉시조치)") -> 0 | I30: =COUNTIF($M30:INDIRECT(ADDRESS(ROW(),MATCH("",$4:$4,-1),1,1)),"N") -> 0 | J30: =COUNTIF($M30:INDIRECT(ADDRESS(ROW(),MATCH("",$4:$4,-1),1,1)),"N/A")+COUNTIF($M30:INDIRECT(ADDRESS(ROW(),MATCH("",$4:$4,-1),1,1)),"조치완료(N/A)") -> 2 | K30: =VLOOKUP($D30,'parm(hidden)'!$B$8:$C$10,2,FALSE)*($F30-$J30) -> 6 | L30: =VLOOKUP($D30,'parm(hidden)'!$B$8:$C$10,2,FALSE)*($G30+$H30) -> 0 | M30: =HYPERLINK("[" & MID(CELL("filename"),SEARCH("[",CELL("filename"))+1, SEARCH("]",CELL("filename"))-SEARCH("[",CELL("filename"))-1) & "]" & ADDRESS(ROW()+16,8,1,TRUE,M$4),INDIRECT(ADDRESS(ROW()+16,8,1,TRUE,M$4))) -> N/A | N30: =HYPERLINK("[" & MID(CELL("filename"),SEARCH("[",CELL("filename"))+1, SEARCH("]",CELL("filename"))-SEARCH("[",CELL("filename"))-1) & "]" & ADDRESS(ROW()+16,8,1,TRUE,N$4),INDIRECT(ADDRESS(ROW()+16,8,1,TRUE,N$4))) -> N/A | O30: =HYPERLINK("[" & MID(CELL("filename"),SEARCH("[",CELL("filename"))+1, SEARCH("]",CELL("filename"))-SEARCH("[",CELL("filename"))-1) & "]" & ADDRESS(ROW()+16,8,1,TRUE,O$4),INDIRECT(ADDRESS(ROW()+16,8,1,TRUE,O$4))) -> 0 | P30: =HYPERLINK("[" & MID(CELL("filename"),SEARCH("[",CELL("filename"))+1, SEARCH("]",CELL("filename"))-SEARCH("[",CELL("filename"))-1) & "]" & ADDRESS(ROW()+16,8,1,TRUE,P$4),INDIRECT(ADDRESS(ROW()+16,8,1,TRUE,P$4))) -> 0
F31: =SUM(F5:F30) -> 104 | G31: =SUM(G5:G30) -> 34 | H31: =SUM(H5:H30) -> 0 | I31: =SUM(I5:I30) -> 4 | J31: =SUM(J5:J30) -> 54 | K31: =SUM(K5:K30) -> 136 | L31: =SUM(L5:L30) -> 94 | M31: =SUM(M5:M30) -> 0 | N31: =COUNTIFS(N$5:N$30,"<>",N$5:N$30,"<>0") -> 26 | O31: =COUNTIFS(O$5:O$30,"<>",O$5:O$30,"<>0") -> 24 | P31: =COUNTIFS(P$5:P$30,"<>",P$5:P$30,"<>0") -> 24

Sheet 취약점 진단 통계 (이행)
A1: ■ 영역별/장비별 보안수준 통계
A3: 1) 영역별 보안수준
A4: 분류 | E4: 진단 결과 | J4: 이행 결과 | O4: 중요도점수
E5: 전체항목 | F5: 진단항목 | G5: 양호 | H5: 취약 | I5: 해당없음 | J5: 조치 | K5: 미조치 | L5: 위험수용 | M5: 해당없음 | N5: 잔여취약점 (미조치+위험수용) | O5: 전체점수 (이행전) | P5: 전체점수 (이행후) | Q5: 평가점수 (이행전) | R5: 평가점수 (이행후) | S5: 이행율 | T5: 보안수준 (이행 전) | U5: 보안수준 (이행 후)
A6: 계정 관리 | E6: =SUMIF('취약점 진단 항목별 통계 (이행)'!$A:$A,$A6&"*",'취약점 진단 항목별 통계 (이행)'!$F:$F) -> 36 | F6: =E6-I6 -> 28 | G6: =SUMIF('취약점 진단 항목별 통계'!$A:$A,$A6&"*",'취약점 진단 항목별 통계'!$G:$G)+SUMIF('취약점 진단 항목별 통계'!$A:$A,$A6&"*",'취약점 진단 항목별 통계'!$H:$H) -> 19 | H6: =SUMIF('취약점 진단 항목별 통계'!$A:$A,$A6&"*",'취약점 진단 항목별 통계'!$I:$I) -> 4 | I6: =SUMIF('취약점 진단 항목별 통계'!$A:$A,$A6&"*",'취약점 진단 항목별 통계'!$J:$J) -> 8 | J6: =SUMIF('취약점 진단 항목별 통계 (이행)'!$A:$A,$A6&"*",'취약점 진단 항목별 통계 (이행)'!$K:$K) -> 4 | K6: =SUMIF('취약점 진단 항목별 통계 (이행)'!$A:$A,$A6&"*",'취약점 진단 항목별 통계 (이행)'!$L:$L) -> 4 | L6: =SUMIF('취약점 진단 항목별 통계 (이행)'!$A:$A,$A6&"*",'취약점 진단 항목별 통계 (이행)'!$M:$M) -> 0 | M6: =SUMIF('취약점 진단 항목별 통계 (이행)'!$A:$A,$A6&"*",'취약점 진단 항목별 통계 (이행)'!$N:$N) -> 4 | N6: =K6+L6 -> 4 | O6: =SUMIF('취약점 진단 항목별 통계 (이행)'!$A:$A,$A6&"*",'취약점 진단 항목별 통계 (이행)'!$O:$O) -> 76 | P6: =SUMIF('취약점 진단 항목별 통계 (이행)'!$A:$A,$A6&"*",'취약점 진단 항목별 통계 (이행)'!$P:$P) -> 84 | Q6: =SUMIF('취약점 진단 항목별 통계 (이행)'!$A:$A,$A6&"*",'취약점 진단 항목별 통계 (이행)'!$Q:$Q) -> 53 | R6: =SUMIF('취약점 진단 항목별 통계 (이행)'!$A:$A,$A6&"*",'취약점 진단 항목별 통계 (이행)'!$R:$R) -> 63 | S6: =IFERROR($J6/($H6-(M6-I6)),"N/A") -> 0.5 | T6: =IF($I6=$E6, "N/A", (Q6/O6)) -> 0.69736842 | U6: =IF(OR($I6=$E6,$E6=$M6),"N/A", ($R6/$P6)) -> 0.75
A7: 접근 관리 | E7: =SUMIF('취약점 진단 항목별 통계 (이행)'!$A:$A,$A7&"*",'취약점 진단 항목별 통계 (이행)'!$F:$F) -> 28 | F7: =E7-I7 -> 10 | G7: =SUMIF('취약점 진단 항목별 통계'!$A:$A,$A7&"*",'취약점 진단 항목별 통계'!$G:$G)+SUMIF('취약점 진단 항목별 통계'!$A:$A,$A7&"*",'취약점 진단 항목별 통계'!$H:$H) -> 10 | H7: =SUMIF('취약점 진단 항목별 통계'!$A:$A,$A7&"*",'취약점 진단 항목별 통계'!$I:$I) -> 0 | I7: =SUMIF('취약점 진단 항목별 통계'!$A:$A,$A7&"*",'취약점 진단 항목별 통계'!$J:$J) -> 18 | J7: =SUMIF('취약점 진단 항목별 통계 (이행)'!$A:$A,$A7&"*",'취약점 진단 항목별 통계 (이행)'!$K:$K) -> 0 | K7: =SUMIF('취약점 진단 항목별 통계 (이행)'!$A:$A,$A7&"*",'취약점 진단 항목별 통계 (이행)'!$L:$L) -> 0 | L7: =SUMIF('취약점 진단 항목별 통계 (이행)'!$A:$A,$A7&"*",'취약점 진단 항목별 통계 (이행)'!$M:$M) -> 0 | M7: =SUMIF('취약점 진단 항목별 통계 (이행)'!$A:$A,$A7&"*",'취약점 진단 항목별 통계 (이행)'!$N:$N) -> 8 | N7: =K7+L7 -> 0 | O7: =SUMIF('취약점 진단 항목별 통계 (이행)'!$A:$A,$A7&"*",'취약점 진단 항목별 통계 (이행)'!$O:$O) -> 26 | P7: =SUMIF('취약점 진단 항목별 통계 (이행)'!$A:$A,$A7&"*",'취약점 진단 항목별 통계 (이행)'!$P:$P) -> 46 | Q7: =SUMIF('취약점 진단 항목별 통계 (이행)'!$A:$A,$A7&"*",'취약점 진단 항목별 통계 (이행)'!$Q:$Q) -> 26 | R7: =SUMIF('취약점 진단 항목별 통계 (이행)'!$A:$A,$A7&"*",'취약점 진단 항목별 통계 (이행)'!$R:$R) -> 26 | S7: =IFERROR($J7/($H7-(M7-I7)),"N/A") -> 0 | T7: =IF($I7=$E7, "N/A", (Q7/O7)) -> 1 | U7: =IF(OR($I7=$E7,$E7=$M7),"N/A", ($R7/$P7)) -> 0.56521739
A8: 옵션 관리 | E8: =SUMIF('취약점 진단 항목별 통계 (이행)'!$A:$A,$A8&"*",'취약점 진단 항목별 통계 (이행)'!$F:$F) -> 32 | F8: =E8-I8 -> 6 | G8: =SUMIF('취약점 진단 항목별 통계'!$A:$A,$A8&"*",'취약점 진단 항목별 통계'!$G:$G)+SUMIF('취약점 진단 항목별 통계'!$A:$A,$A8&"*",'취약점 진단 항목별 통계'!$H:$H) -> 3 | H8: =SUMIF('취약점 진단 항목별 통계'!$A:$A,$A8&"*",'취약점 진단 항목별 통계'!$I:$I) -> 0 | I8: =SUMIF('취약점 진단 항목별 통계'!$A:$A,$A8&"*",'취약점 진단 항목별 통계'!$J:$J) -> 26 | J8: =SUMIF('취약점 진단 항목별 통계 (이행)'!$A:$A,$A8&"*",'취약점 진단 항목별 통계 (이행)'!$K:$K) -> 0 | K8: =SUMIF('취약점 진단 항목별 통계 (이행)'!$A:$A,$A8&"*",'취약점 진단 항목별 통계 (이행)'!$L:$L) -> 0 | L8: =SUMIF('취약점 진단 항목별 통계 (이행)'!$A:$A,$A8&"*",'취약점 진단 항목별 통계 (이행)'!$M:$M) -> 0 | M8: =SUMIF('취약점 진단 항목별 통계 (이행)'!$A:$A,$A8&"*",'취약점 진단 항목별 통계 (이행)'!$N:$N) -> 16 | N8: =K8+L8 -> 0 | O8: =SUMIF('취약점 진단 항목별 통계 (이행)'!$A:$A,$A8&"*",'취약점 진단 항목별 통계 (이행)'!$O:$O) -> 16 | P8: =SUMIF('취약점 진단 항목별 통계 (이행)'!$A:$A,$A8&"*",'취약점 진단 항목별 통계 (이행)'!$P:$P) -> 34 | Q8: =SUMIF('취약점 진단 항목별 통계 (이행)'!$A:$A,$A8&"*",'취약점 진단 항목별 통계 (이행)'!$Q:$Q) -> 9 | R8: =SUMIF('취약점 진단 항목별 통계 (이행)'!$A:$A,$A8&"*",'취약점 진단 항목별 통계 (이행)'!$R:$R) -> 9 | S8: =IFERROR($J8/($H8-(M8-I8)),"N/A") -> 0 | T8: =IF($I8=$E8, "N/A", (Q8/O8)) -> 0.5625 | U8: =IF(OR($I8=$E8,$E8=$M8),"N/A", ($R8/$P8)) -> 0.26470588
A9: 패치 관리 | E9: =SUMIF('취약점 진단 항목별 통계 (이행)'!$A:$A,$A9&"*",'취약점 진단 항목별 통계 (이행)'!$F:$F) -> 8 | F9: =E9-I9 -> 6 | G9: =SUMIF('취약점 진단 항목별 통계'!$A:$A,$A9&"*",'취약점 진단 항목별 통계'!$G:$G)+SUMIF('취약점 진단 항목별 통계'!$A:$A,$A9&"*",'취약점 진단 항목별 통계'!$H:$H) -> 2 | H9: =SUMIF('취약점 진단 항목별 통계'!$A:$A,$A9&"*",'취약점 진단 항목별 통계'!$I:$I) -> 0 | I9: =SUMIF('취약점 진단 항목별 통계'!$A:$A,$A9&"*",'취약점 진단 항목별 통계'!$J:$J) -> 2 | J9: =SUMIF('취약점 진단 항목별 통계 (이행)'!$A:$A,$A9&"*",'취약점 진단 항목별 통계 (이행)'!$K:$K) -> 0 | K9: =SUMIF('취약점 진단 항목별 통계 (이행)'!$A:$A,$A9&"*",'취약점 진단 항목별 통계 (이행)'!$L:$L) -> 0 | L9: =SUMIF('취약점 진단 항목별 통계 (이행)'!$A:$A,$A9&"*",'취약점 진단 항목별 통계 (이행)'!$M:$M) -> 0 | M9: =SUMIF('취약점 진단 항목별 통계 (이행)'!$A:$A,$A9&"*",'취약점 진단 항목별 통계 (이행)'!$N:$N) -> 1 | N9: =K9+L9 -> 0 | O9: =SUMIF('취약점 진단 항목별 통계 (이행)'!$A:$A,$A9&"*",'취약점 진단 항목별 통계 (이행)'!$O:$O) -> 18 | P9: =SUMIF('취약점 진단 항목별 통계 (이행)'!$A:$A,$A9&"*",'취약점 진단 항목별 통계 (이행)'!$P:$P) -> 21 | Q9: =SUMIF('취약점 진단 항목별 통계 (이행)'!$A:$A,$A9&"*",'취약점 진단 항목별 통계 (이행)'!$Q:$Q) -> 6 | R9: =SUMIF('취약점 진단 항목별 통계 (이행)'!$A:$A,$A9&"*",'취약점 진단 항목별 통계 (이행)'!$R:$R) -> 6 | S9: =IFERROR($J9/($H9-(M9-I9)),"N/A") -> 0 | T9: =IF($I9=$E9, "N/A", (Q9/O9)) -> 0.33333333 | U9: =IF(OR($I9=$E9,$E9=$M9),"N/A", ($R9/$P9)) -> 0.28571429
A10: 로그 관리 | E10: =SUMIF('취약점 진단 항목별 통계 (이행)'!$A:$A,$A10&"*",'취약점 진단 항목별 통계 (이행)'!$F:$F) -> 0 | F10: =E10-I10 -> 0 | G10: =SUMIF('취약점 진단 항목별 통계'!$A:$A,$A10&"*",'취약점 진단 항목별 통계'!$G:$G)+SUMIF('취약점 진단 항목별 통계'!$A:$A,$A10&"*",'취약점 진단 항목별 통계'!$H:$H) -> 0 | H10: =SUMIF('취약점 진단 항목별 통계'!$A:$A,$A10&"*",'취약점 진단 항목별 통계'!$I:$I) -> 0 | I10: =SUMIF('취약점 진단 항목별 통계'!$A:$A,$A10&"*",'취약점 진단 항목별 통계'!$J:$J) -> 0 | J10: =SUMIF('취약점 진단 항목별 통계 (이행)'!$A:$A,$A10&"*",'취약점 진단 항목별 통계 (이행)'!$K:$K) -> 0 | K10: =SUMIF('취약점 진단 항목별 통계 (이행)'!$A:$A,$A10&"*",'취약점 진단 항목별 통계 (이행)'!$L:$L) -> 0 | L10: =SUMIF('취약점 진단 항목별 통계 (이행)'!$A:$A,$A10&"*",'취약점 진단 항목별 통계 (이행)'!$M:$M) -> 0 | M10: =SUMIF('취약점 진단 항목별 통계 (이행)'!$A:$A,$A10&"*",'취약점 진단 항목별 통계 (이행)'!$N:$N) -> 0 | N10: =K10+L10 -> 0 | O10: =SUMIF('취약점 진단 항목별 통계 (이행)'!$A:$A,$A10&"*",'취약점 진단 항목별 통계 (이행)'!$O:$O) -> 0 | P10: =SUMIF('취약점 진단 항목별 통계 (이행)'!$A:$A,$A10&"*",'취약점 진단 항목별 통계 (이행)'!$P:$P) -> 0 | Q10: =SUMIF('취약점 진단 항목별 통계 (이행)'!$A:$A,$A10&"*",'취약점 진단 항목별 통계 (이행)'!$Q:$Q) -> 0 | R10: =SUMIF('취약점 진단 항목별 통계 (이행)'!$A:$A,$A10&"*",'취약점 진단 항목별 통계 (이행)'!$R:$R) -> 0 | S10: =IFERROR($J10/($H10-(M10-I10)),"N/A") -> N/A | T10: =IF($I10=$E10, "N/A", (Q10/O10)) -> N/A | U10: =IF(OR($I10=$E10,$E10=$M10),"N/A", ($R10/$P10)) -> N/A
A11: 계 | E11: =SUM(E6:E10) -> 104 | F11: =SUM(F6:F10) -> 50 | G11: =SUM(G6:G10) -> 34 | H11: =SUM(H6:H10) -> 4 | I11: =SUM(I6:I10) -> 54 | J11: =SUM(J6:J10) -> 4 | K11: =SUM(K6:K10) -> 4 | L11: =SUM(L6:L10) -> 0 | ... R11: =SUM(R6:R10) -> 104 | S11: =IFERROR($J11/($H11-(M11-I11)),"N/A") -> 0.13793103 | T11: =IF($I11=$E11, "N/A", (Q11/O11)) -> 0.69117647 | U11: =IF(OR($I11=$E11,$E11=$M11),"N/A", ($R11/$P11)) -> 0.56216216
A39: 2) 장비별 보안수준
A40: 장비 구분 | E40: 진단 결과 | J40: 이행 결과 | O40: 중요도점수
E41: 전체항목 | F41: 진단항목 | G41: 양호 | H41: 취약 | I41: 해당없음 | J41: 조치 | K41: 미조치 | L41: 위험수용 | M41: 해당없음 | N41: 잔여취약점 (미조치+위험수용) | O41: 전체점수 (이행전) | P41: 전체점수 (이행후) | Q41: 평가점수 (이행전) | R41: 평가점수 (이행후) | S41: 이행율 | T41: 보안수준 (이행 전) | U41: 보안수준 (이행 후)
A42: =HYPERLINK("[" & MID(CELL("filename"),SEARCH("[",CELL("filename"))+1, SEARCH("]",CELL("filename"))-SEARCH("[",CELL("filename"))-1) & "]" & INDIRECT(ADDRESS(ROW()-37,2,1,TRUE,"자산목록")) & "!A1",INDIRECT(ADDRESS(ROW()-37,2,1,TRUE,"자산목록"))) -> DB_HQ_Rocky | C42: =IFERROR(VLOOKUP($A42,자산목록!$B$1:$M$832,6,FALSE),"-") -> MySQL Server | E42: =IFERROR(INDIRECT(ADDRESS(17, 4, 1,TRUE,$A42)),0) -> 26 | F42: =E42-I42 -> 11 | G42: =IFERROR(INDIRECT(ADDRESS(17,5, 1,TRUE,$A42)),0) -> 7 | H42: =IFERROR(INDIRECT(ADDRESS(17,6, 1,TRUE,$A42)),0) -> 2 | I42: =IFERROR(INDIRECT(ADDRESS(17,7, 1,TRUE,$A42)),0) -> 15 | J42: =IFERROR(INDIRECT(ADDRESS(17,10, 1,TRUE,$A42)),0) -> 2 | K42: =IFERROR(INDIRECT(ADDRESS(17,11, 1,TRUE,$A42)),0) -> 2 | L42: =IFERROR(INDIRECT(ADDRESS(17,12, 1,TRUE,$A42)),0) -> 0 | M42: =IFERROR(INDIRECT(ADDRESS(17,13, 1,TRUE,$A42)),0) -> 15 | N42: =K42+L42 -> 2 | O42: =IFERROR(INDIRECT(ADDRESS(17,18, 1,TRUE,$A42)),0) -> 27 | P42: =IFERROR(INDIRECT(ADDRESS(17,21, 1,TRUE,$A42)),0) -> 32 | Q42: =IFERROR(INDIRECT(ADDRESS(17,19, 1,TRUE,$A42)),0) -> 17 | R42: =IFERROR(INDIRECT(ADDRESS(17,20, 1,TRUE,$A42)),0) -> 22 | S42: =IFERROR(INDIRECT(ADDRESS(17,14, 1,TRUE,$A42)),0) -> 1 | T42: =IFERROR(INDIRECT(ADDRESS(17,8, 1,TRUE,$A42)),0) -> 0.62962963 | U42: =IFERROR(INDIRECT(ADDRESS(17,15, 1,TRUE,$A42)),0) -> 0.6875
A43: =HYPERLINK("[" & MID(CELL("filename"),SEARCH("[",CELL("filename"))+1, SEARCH("]",CELL("filename"))-SEARCH("[",CELL("filename"))-1) & "]" & INDIRECT(ADDRESS(ROW()-37,2,1,TRUE,"자산목록")) & "!A1",INDIRECT(ADDRESS(ROW()-37,2,1,TRUE,"자산목록"))) -> DB_BR_Rocky | C43: =IFERROR(VLOOKUP($A43,자산목록!$B$1:$M$832,6,FALSE),"-") -> MariaDB Server | E43: =IFERROR(INDIRECT(ADDRESS(17, 4, 1,TRUE,$A43)),0) -> 26 | F43: =E43-I43 -> 11 | G43: =IFERROR(INDIRECT(ADDRESS(17,5, 1,TRUE,$A43)),0) -> 7 | H43: =IFERROR(INDIRECT(ADDRESS(17,6, 1,TRUE,$A43)),0) -> 2 | I43: =IFERROR(INDIRECT(ADDRESS(17,7, 1,TRUE,$A43)),0) -> 15 | J43: =IFERROR(INDIRECT(ADDRESS(17,10, 1,TRUE,$A43)),0) -> 2 | K43: =IFERROR(INDIRECT(ADDRESS(17,11, 1,TRUE,$A43)),0) -> 2 | L43: =IFERROR(INDIRECT(ADDRESS(17,12, 1,TRUE,$A43)),0) -> 0 | M43: =IFERROR(INDIRECT(ADDRESS(17,13, 1,TRUE,$A43)),0) -> 14 | N43: =K43+L43 -> 2 | O43: =IFERROR(INDIRECT(ADDRESS(17,18, 1,TRUE,$A43)),0) -> 27 | P43: =IFERROR(INDIRECT(ADDRESS(17,21, 1,TRUE,$A43)),0) -> 32 | Q43: =IFERROR(INDIRECT(ADDRESS(17,19, 1,TRUE,$A43)),0) -> 17 | R43: =IFERROR(INDIRECT(ADDRESS(17,20, 1,TRUE,$A43)),0) -> 22 | S43: =IFERROR(INDIRECT(ADDRESS(17,14, 1,TRUE,$A43)),0) -> 0.66666667 | T43: =IFERROR(INDIRECT(ADDRESS(17,8, 1,TRUE,$A43)),0) -> 0.62962963 | U43: =IFERROR(INDIRECT(ADDRESS(17,15, 1,TRUE,$A43)),0) -> 0.6875
A44: =HYPERLINK("[" & MID(CELL("filename"),SEARCH("[",CELL("filename"))+1, SEARCH("]",CELL("filename"))-SEARCH("[",CELL("filename"))-1) & "]" & INDIRECT(ADDRESS(ROW()-37,2,1,TRUE,"자산목록")) & "!A1",INDIRECT(ADDRESS(ROW()-37,2,1,TRUE,"자산목록"))) -> BDB_HQ_Rocky | C44: =IFERROR(VLOOKUP($A44,자산목록!$B$1:$M$832,6,FALSE),"-") -> MySQL Server | E44: =IFERROR(INDIRECT(ADDRESS(17, 4, 1,TRUE,$A44)),0) -> 26 | F44: =E44-I44 -> 14 | G44: =IFERROR(INDIRECT(ADDRESS(17,5, 1,TRUE,$A44)),0) -> 9 | H44: =IFERROR(INDIRECT(ADDRESS(17,6, 1,TRUE,$A44)),0) -> 0 | I44: =IFERROR(INDIRECT(ADDRESS(17,7, 1,TRUE,$A44)),0) -> 12 | J44: =IFERROR(INDIRECT(ADDRESS(17,10, 1,TRUE,$A44)),0) -> 0 | K44: =IFERROR(INDIRECT(ADDRESS(17,11, 1,TRUE,$A44)),0) -> 0 | L44: =IFERROR(INDIRECT(ADDRESS(17,12, 1,TRUE,$A44)),0) -> 0 | M44: =IFERROR(INDIRECT(ADDRESS(17,13, 1,TRUE,$A44)),0) -> 0 | N44: =K44+L44 -> 0 | O44: =IFERROR(INDIRECT(ADDRESS(17,18, 1,TRUE,$A44)),0) -> 32 | P44: =IFERROR(INDIRECT(ADDRESS(17,21, 1,TRUE,$A44)),0) -> 55 | Q44: =IFERROR(INDIRECT(ADDRESS(17,19, 1,TRUE,$A44)),0) -> 24 | R44: =IFERROR(INDIRECT(ADDRESS(17,20, 1,TRUE,$A44)),0) -> 0 | S44: =IFERROR(INDIRECT(ADDRESS(17,14, 1,TRUE,$A44)),0) -> 0 | T44: =IFERROR(INDIRECT(ADDRESS(17,8, 1,TRUE,$A44)),0) -> 0.75
A45: =HYPERLINK("[" & MID(CELL("filename"),SEARCH("[",CELL("filename"))+1, SEARCH("]",CELL("filename"))-SEARCH("[",CELL("filename"))-1) & "]" & INDIRECT(ADDRESS(ROW()-37,2,1,TRUE,"자산목록")) & "!A1",INDIRECT(ADDRESS(ROW()-37,2,1,TRUE,"자산목록"))) -> BDB_BR_Rocky | C45: =IFERROR(VLOOKUP($A45,자산목록!$B$1:$M$832,6,FALSE),"-") -> MariaDB Server | E45: =IFERROR(INDIRECT(ADDRESS(17, 4, 1,TRUE,$A45)),0) -> 26 | F45: =E45-I45 -> 14 | G45: =IFERROR(INDIRECT(ADDRESS(17,5, 1,TRUE,$A45)),0) -> 11 | H45: =IFERROR(INDIRECT(ADDRESS(17,6, 1,TRUE,$A45)),0) -> 0 | I45: =IFERROR(INDIRECT(ADDRESS(17,7, 1,TRUE,$A45)),0) -> 12 | J45: =IFERROR(INDIRECT(ADDRESS(17,10, 1,TRUE,$A45)),0) -> 0 | K45: =IFERROR(INDIRECT(ADDRESS(17,11, 1,TRUE,$A45)),0) -> 0 | L45: =IFERROR(INDIRECT(ADDRESS(17,12, 1,TRUE,$A45)),0) -> 0 | M45: =IFERROR(INDIRECT(ADDRESS(17,13, 1,TRUE,$A45)),0) -> 0 | N45: =K45+L45 -> 0 | O45: =IFERROR(INDIRECT(ADDRESS(17,18, 1,TRUE,$A45)),0) -> 32 | P45: =IFERROR(INDIRECT(ADDRESS(17,21, 1,TRUE,$A45)),0) -> 55 | Q45: =IFERROR(INDIRECT(ADDRESS(17,19, 1,TRUE,$A45)),0) -> 27 | R45: =IFERROR(INDIRECT(ADDRESS(17,20, 1,TRUE,$A45)),0) -> 0 | S45: =IFERROR(INDIRECT(ADDRESS(17,14, 1,TRUE,$A45)),0) -> 0 | T45: =IFERROR(INDIRECT(ADDRESS(17,8, 1,TRUE,$A45)),0) -> 0.84375 | U45: =IFERROR(INDIRECT(ADDRESS(17,15, 1,TRUE,$A45)),0) -> 0
A46: 계 | E46: =SUM(E42:E45) -> 104 | F46: =SUM(F42:F45) -> 50 | G46: =SUM(G42:G45) -> 34 | H46: =SUM(H42:H45) -> 4 | I46: =SUM(I42:I45) -> 54 | J46: =SUM(J42:J45) -> 4 | K46: =SUM(K42:K45) -> 4 | L46: =SUM(L42:L45) -> 0 | ... R46: =SUM(R42:R45) -> 44 | S46: =IFERROR($J46/($H46-(M46-I46)),"N/A") -> 0.13793103 | T46: =IF($I46=$E46, "N/A", (Q46/O46)) -> 0.72033898 | U46: =IF(OR($I46=$E46,$E46=$M46),"N/A", ($R46/$P46)) -> 0.25287356

Sheet 취약점 진단 항목별 통계 (이행)
A1: ■ 취약점 진단 항목별 통계
A3: =ChkList!A4 -> 분류 | C3: =ChkList!C4 -> 진단항목 | D3: =ChkList!D4 -> 중요도 | F3: 진단 통계 | K3: 이행 진단 통계 | O3: 중요도 점수 | S3: 진단결과 | T3: 진단결과 | U3: 진단결과 | V3: 진단결과
F4: 전체 | G4: 양호 | H4: 즉시조치 | I4: 취약 | J4: N/A | K4: 조치 | L4: 미조치 | M4: 위험수용 | N4: N/A | O4: 전체이행전 | P4: 전체이행후 | Q4: 평가이행전 | R4: 평가이행후 | S4: =HYPERLINK("[" & MID(CELL("filename"),SEARCH("[",CELL("filename"))+1, SEARCH("]",CELL("filename"))-SEARCH("[",CELL("filename"))-1) & "]" & INDIRECT(ADDRESS(COLUMN()-14,2,1,TRUE,"자산목록")) & "!A1",INDIRECT(ADDRESS(COLUMN()-14,2,1,TRUE,"자산목록"))) -> DB_HQ_Rocky | T4: =HYPERLINK("[" & MID(CELL("filename"),SEARCH("[",CELL("filename"))+1, SEARCH("]",CELL("filename"))-SEARCH("[",CELL("filename"))-1) & "]" & INDIRECT(ADDRESS(COLUMN()-14,2,1,TRUE,"자산목록")) & "!A1",INDIRECT(ADDRESS(COLUMN()-14,2,1,TRUE,"자산목록"))) -> DB_BR_Rocky | U4: =HYPERLINK("[" & MID(CELL("filename"),SEARCH("[",CELL("filename"))+1, SEARCH("]",CELL("filename"))-SEARCH("[",CELL("filename"))-1) & "]" & INDIRECT(ADDRESS(COLUMN()-14,2,1,TRUE,"자산목록")) & "!A1",INDIRECT(ADDRESS(COLUMN()-14,2,1,TRUE,"자산목록"))) -> BDB_HQ_Rocky | V4: =HYPERLINK("[" & MID(CELL("filename"),SEARCH("[",CELL("filename"))+1, SEARCH("]",CELL("filename"))-SEARCH("[",CELL("filename"))-1) & "]" & INDIRECT(ADDRESS(COLUMN()-14,2,1,TRUE,"자산목록")) & "!A1",INDIRECT(ADDRESS(COLUMN()-14,2,1,TRUE,"자산목록"))) -> BDB_BR_Rocky
A5: =ChkList!A5 -> 계정 관리 | B5: =ChkList!$B5 -> D-01 | C5: =ChkList!$C5 -> 기본 계정의 비밀번호, 정책 등을 변경하여 사용 | D5: =ChkList!$D5 -> H | E5: =ChkList!E5 -> 3 | F5: =COUNTA($S5:INDIRECT(ADDRESS(ROW(),MATCH("",$4:$4,-1),1,1))) -> 4 | G5: ='취약점 진단 항목별 통계'!G5 -> 4 | H5: ='취약점 진단 항목별 통계'!H5 -> 0 | I5: ='취약점 진단 항목별 통계'!I5 -> 0 | J5: ='취약점 진단 항목별 통계'!J5 -> 0 | K5: =COUNTIF($S5:INDIRECT(ADDRESS(ROW(),MATCH("",$4:$4,-1),1,1)),"조치") -> 0 | L5: =COUNTIF($S5:INDIRECT(ADDRESS(ROW(),MATCH("",$4:$4,-1),1,1)),"미조치") -> 0 | M5: =COUNTIF($S5:INDIRECT(ADDRESS(ROW(),MATCH("",$4:$4,-1),1,1)),"위험수용") -> 0 | N5: =COUNTIF($S5:INDIRECT(ADDRESS(ROW(),MATCH("",$4:$4,-1),1,1)),"N/A") -> 0 | O5: =VLOOKUP($D5,'parm(hidden)'!$B$8:$C$10,2,FALSE)*($F5-$J5) -> 12 | P5: =VLOOKUP($D5,'parm(hidden)'!$B$8:$C$10,2,FALSE)*($F5-$N5) -> 12 | Q5: =VLOOKUP($D5,'parm(hidden)'!$B$8:$C$10,2,FALSE)*($G5+$H5) -> 12 | R5: =VLOOKUP($D5,'parm(hidden)'!$B$8:$C$10,2,FALSE)*($G5+$H5+$K5) -> 12 | S5: =HYPERLINK("[" & MID(CELL("filename"),SEARCH("[",CELL("filename"))+1, SEARCH("]",CELL("filename"))-SEARCH("[",CELL("filename"))-1) & "]" & ADDRESS(ROW()+16,11,1,TRUE,S$4),INDIRECT(ADDRESS(ROW()+16,11,1,TRUE,S$4))) -> Y | T5: =HYPERLINK("[" & MID(CELL("filename"),SEARCH("[",CELL("filename"))+1, SEARCH("]",CELL("filename"))-SEARCH("[",CELL("filename"))-1) & "]" & ADDRESS(ROW()+16,11,1,TRUE,T$4),INDIRECT(ADDRESS(ROW()+16,11,1,TRUE,T$4))) -> Y | U5: =HYPERLINK("[" & MID(CELL("filename"),SEARCH("[",CELL("filename"))+1, SEARCH("]",CELL("filename"))-SEARCH("[",CELL("filename"))-1) & "]" & ADDRESS(ROW()+16,11,1,TRUE,U$4),INDIRECT(ADDRESS(ROW()+16,11,1,TRUE,U$4))) | V5: =HYPERLINK("[" & MID(CELL("filename"),SEARCH("[",CELL("filename"))+1, SEARCH("]",CELL("filename"))-SEARCH("[",CELL("filename"))-1) & "]" & ADDRESS(ROW()+16,11,1,TRUE,V$4),INDIRECT(ADDRESS(ROW()+16,11,1,TRUE,V$4)))
A6: =ChkList!A6 -> 계정 관리 | B6: =ChkList!$B6 -> D-02 | C6: =ChkList!$C6 -> 데이터베이스의 불필요 계정을 제거하거나, 잠금설정 후 사용 | D6: =ChkList!$D6 -> H | E6: =ChkList!E6 -> 3 | F6: =COUNTA($S6:INDIRECT(ADDRESS(ROW(),MATCH("",$4:$4,-1),1,1))) -> 4 | G6: ='취약점 진단 항목별 통계'!G6 -> 4 | H6: ='취약점 진단 항목별 통계'!H6 -> 0 | I6: ='취약점 진단 항목별 통계'!I6 -> 0 | J6: ='취약점 진단 항목별 통계'!J6 -> 0 | K6: =COUNTIF($S6:INDIRECT(ADDRESS(ROW(),MATCH("",$4:$4,-1),1,1)),"조치") -> 0 | L6: =COUNTIF($S6:INDIRECT(ADDRESS(ROW(),MATCH("",$4:$4,-1),1,1)),"미조치") -> 0 | M6: =COUNTIF($S6:INDIRECT(ADDRESS(ROW(),MATCH("",$4:$4,-1),1,1)),"위험수용") -> 0 | N6: =COUNTIF($S6:INDIRECT(ADDRESS(ROW(),MATCH("",$4:$4,-1),1,1)),"N/A") -> 0 | O6: =VLOOKUP($D6,'parm(hidden)'!$B$8:$C$10,2,FALSE)*($F6-$J6) -> 12 | P6: =VLOOKUP($D6,'parm(hidden)'!$B$8:$C$10,2,FALSE)*($F6-$N6) -> 12 | Q6: =VLOOKUP($D6,'parm(hidden)'!$B$8:$C$10,2,FALSE)*($G6+$H6) -> 12 | R6: =VLOOKUP($D6,'parm(hidden)'!$B$8:$C$10,2,FALSE)*($G6+$H6+$K6) -> 12 | S6: =HYPERLINK("[" & MID(CELL("filename"),SEARCH("[",CELL("filename"))+1, SEARCH("]",CELL("filename"))-SEARCH("[",CELL("filename"))-1) & "]" & ADDRESS(ROW()+16,11,1,TRUE,S$4),INDIRECT(ADDRESS(ROW()+16,11,1,TRUE,S$4))) -> Y | T6: =HYPERLINK("[" & MID(CELL("filename"),SEARCH("[",CELL("filename"))+1, SEARCH("]",CELL("filename"))-SEARCH("[",CELL("filename"))-1) & "]" & ADDRESS(ROW()+16,11,1,TRUE,T$4),INDIRECT(ADDRESS(ROW()+16,11,1,TRUE,T$4))) -> Y | U6: =HYPERLINK("[" & MID(CELL("filename"),SEARCH("[",CELL("filename"))+1, SEARCH("]",CELL("filename"))-SEARCH("[",CELL("filename"))-1) & "]" & ADDRESS(ROW()+16,11,1,TRUE,U$4),INDIRECT(ADDRESS(ROW()+16,11,1,TRUE,U$4))) | V6: =HYPERLINK("[" & MID(CELL("filename"),SEARCH("[",CELL("filename"))+1, SEARCH("]",CELL("filename"))-SEARCH("[",CELL("filename"))-1) & "]" & ADDRESS(ROW()+16,11,1,TRUE,V$4),INDIRECT(ADDRESS(ROW()+16,11,1,TRUE,V$4)))
A7: =ChkList!A7 -> 계정 관리 | B7: =ChkList!$B7 -> D-03 | C7: =ChkList!$C7 -> 비밀번호 사용 기간 및 복잡도를 기관의 정책에 맞도록 설정 | D7: =ChkList!$D7 -> H | E7: =ChkList!E7 -> 3 | F7: =COUNTA($S7:INDIRECT(ADDRESS(ROW(),MATCH("",$4:$4,-1),1,1))) -> 4 | G7: ='취약점 진단 항목별 통계'!G7 -> 1 | H7: ='취약점 진단 항목별 통계'!H7 -> 0 | I7: ='취약점 진단 항목별 통계'!I7 -> 0 | J7: ='취약점 진단 항목별 통계'!J7 -> 0 | K7: =COUNTIF($S7:INDIRECT(ADDRESS(ROW(),MATCH("",$4:$4,-1),1,1)),"조치") -> 0 | L7: =COUNTIF($S7:INDIRECT(ADDRESS(ROW(),MATCH("",$4:$4,-1),1,1)),"미조치") -> 2 | M7: =COUNTIF($S7:INDIRECT(ADDRESS(ROW(),MATCH("",$4:$4,-1),1,1)),"위험수용") -> 0 | N7: =COUNTIF($S7:INDIRECT(ADDRESS(ROW(),MATCH("",$4:$4,-1),1,1)),"N/A") -> 0 | O7: =VLOOKUP($D7,'parm(hidden)'!$B$8:$C$10,2,FALSE)*($F7-$J7) -> 12 | P7: =VLOOKUP($D7,'parm(hidden)'!$B$8:$C$10,2,FALSE)*($F7-$N7) -> 12 | Q7: =VLOOKUP($D7,'parm(hidden)'!$B$8:$C$10,2,FALSE)*($G7+$H7) -> 3 | R7: =VLOOKUP($D7,'parm(hidden)'!$B$8:$C$10,2,FALSE)*($G7+$H7+$K7) -> 3 | S7: =HYPERLINK("[" & MID(CELL("filename"),SEARCH("[",CELL("filename"))+1, SEARCH("]",CELL("filename"))-SEARCH("[",CELL("filename"))-1) & "]" & ADDRESS(ROW()+16,11,1,TRUE,S$4),INDIRECT(ADDRESS(ROW()+16,11,1,TRUE,S$4))) -> 미조치 | T7: =HYPERLINK("[" & MID(CELL("filename"),SEARCH("[",CELL("filename"))+1, SEARCH("]",CELL("filename"))-SEARCH("[",CELL("filename"))-1) & "]" & ADDRESS(ROW()+16,11,1,TRUE,T$4),INDIRECT(ADDRESS(ROW()+16,11,1,TRUE,T$4))) -> 미조치 | U7: =HYPERLINK("[" & MID(CELL("filename"),SEARCH("[",CELL("filename"))+1, SEARCH("]",CELL("filename"))-SEARCH("[",CELL("filename"))-1) & "]" & ADDRESS(ROW()+16,11,1,TRUE,U$4),INDIRECT(ADDRESS(ROW()+16,11,1,TRUE,U$4))) | V7: =HYPERLINK("[" & MID(CELL("filename"),SEARCH("[",CELL("filename"))+1, SEARCH("]",CELL("filename"))-SEARCH("[",CELL("filename"))-1) & "]" & ADDRESS(ROW()+16,11,1,TRUE,V$4),INDIRECT(ADDRESS(ROW()+16,11,1,TRUE,V$4)))
A8: =ChkList!A8 -> 계정 관리 | B8: =ChkList!$B8 -> D-04 | C8: =ChkList!$C8 -> 데이터베이스 관리자 권한을 꼭 필요한 계정 및 그룹에 대해서만 허용 | D8: =ChkList!$D8 -> H | E8: =ChkList!E8 -> 3 | F8: =COUNTA($S8:INDIRECT(ADDRESS(ROW(),MATCH("",$4:$4,-1),1,1))) -> 4 | G8: ='취약점 진단 항목별 통계'!G8 -> 4 | H8: ='취약점 진단 항목별 통계'!H8 -> 0 | I8: ='취약점 진단 항목별 통계'!I8 -> 0 | J8: ='취약점 진단 항목별 통계'!J8 -> 0 | K8: =COUNTIF($S8:INDIRECT(ADDRESS(ROW(),MATCH("",$4:$4,-1),1,1)),"조치") -> 0 | L8: =COUNTIF($S8:INDIRECT(ADDRESS(ROW(),MATCH("",$4:$4,-1),1,1)),"미조치") -> 0 | M8: =COUNTIF($S8:INDIRECT(ADDRESS(ROW(),MATCH("",$4:$4,-1),1,1)),"위험수용") -> 0 | N8: =COUNTIF($S8:INDIRECT(ADDRESS(ROW(),MATCH("",$4:$4,-1),1,1)),"N/A") -> 0 | O8: =VLOOKUP($D8,'parm(hidden)'!$B$8:$C$10,2,FALSE)*($F8-$J8) -> 12 | P8: =VLOOKUP($D8,'parm(hidden)'!$B$8:$C$10,2,FALSE)*($F8-$N8) -> 12 | Q8: =VLOOKUP($D8,'parm(hidden)'!$B$8:$C$10,2,FALSE)*($G8+$H8) -> 12 | R8: =VLOOKUP($D8,'parm(hidden)'!$B$8:$C$10,2,FALSE)*($G8+$H8+$K8) -> 12 | S8: =HYPERLINK("[" & MID(CELL("filename"),SEARCH("[",CELL("filename"))+1, SEARCH("]",CELL("filename"))-SEARCH("[",CELL("filename"))-1) & "]" & ADDRESS(ROW()+16,11,1,TRUE,S$4),INDIRECT(ADDRESS(ROW()+16,11,1,TRUE,S$4))) -> Y | T8: =HYPERLINK("[" & MID(CELL("filename"),SEARCH("[",CELL("filename"))+1, SEARCH("]",CELL("filename"))-SEARCH("[",CELL("filename"))-1) & "]" & ADDRESS(ROW()+16,11,1,TRUE,T$4),INDIRECT(ADDRESS(ROW()+16,11,1,TRUE,T$4))) -> Y | U8: =HYPERLINK("[" & MID(CELL("filename"),SEARCH("[",CELL("filename"))+1, SEARCH("]",CELL("filename"))-SEARCH("[",CELL("filename"))-1) & "]" & ADDRESS(ROW()+16,11,1,TRUE,U$4),INDIRECT(ADDRESS(ROW()+16,11,1,TRUE,U$4))) | V8: =HYPERLINK("[" & MID(CELL("filename"),SEARCH("[",CELL("filename"))+1, SEARCH("]",CELL("filename"))-SEARCH("[",CELL("filename"))-1) & "]" & ADDRESS(ROW()+16,11,1,TRUE,V$4),INDIRECT(ADDRESS(ROW()+16,11,1,TRUE,V$4)))
